ply
format ascii 1.0
comment : MagicaVoxel @ Ephtracy
element vertex 1124
property float x
property float y
property float z
property uchar red
property uchar green
property uchar blue
end_header
-2 -38 22 42 22 4
-1 -38 22 42 22 4
0 -38 22 42 22 4
1 -38 22 42 22 4
2 -38 22 42 22 4
3 -38 22 42 22 4
-2 -37 22 42 22 4
-1 -37 22 42 22 4
0 -37 22 42 22 4
1 -37 22 42 22 4
2 -37 22 42 22 4
3 -37 22 42 22 4
-2 -36 22 42 22 4
-1 -36 22 42 22 4
0 -36 22 42 22 4
1 -36 22 42 22 4
2 -36 22 42 22 4
3 -36 22 42 22 4
-2 -35 22 42 22 4
-1 -35 22 42 22 4
0 -35 22 42 22 4
1 -35 22 42 22 4
2 -35 22 42 22 4
3 -35 22 42 22 4
-3 -34 22 42 22 4
-2 -34 22 42 22 4
-1 -34 22 42 22 4
0 -34 22 42 22 4
1 -34 22 42 22 4
2 -34 22 42 22 4
3 -34 22 42 22 4
4 -34 22 42 22 4
-3 -33 22 42 22 4
-2 -33 22 42 22 4
-1 -33 22 42 22 4
0 -33 22 42 22 4
1 -33 22 42 22 4
2 -33 22 42 22 4
3 -33 22 42 22 4
4 -33 22 42 22 4
-2 -32 22 42 22 4
-1 -32 22 42 22 4
0 -32 22 42 22 4
1 -32 22 42 22 4
2 -32 22 42 22 4
3 -32 22 42 22 4
-2 -31 22 42 22 4
-1 -31 22 42 22 4
0 -31 22 42 22 4
1 -31 22 42 22 4
2 -31 22 42 22 4
3 -31 22 42 22 4
-2 -30 22 42 22 4
-1 -30 22 42 22 4
0 -30 22 42 22 4
1 -30 22 42 22 4
2 -30 22 42 22 4
3 -30 22 42 22 4
-2 -29 22 42 22 4
-1 -29 22 42 22 4
0 -29 22 42 22 4
1 -29 22 42 22 4
2 -29 22 42 22 4
3 -29 22 42 22 4
-2 -28 22 42 22 4
-1 -28 22 42 22 4
0 -28 22 42 22 4
1 -28 22 42 22 4
2 -28 22 42 22 4
3 -28 22 42 22 4
-3 -27 22 42 22 4
-2 -27 22 42 22 4
-1 -27 22 42 22 4
0 -27 22 42 22 4
1 -27 22 42 22 4
2 -27 22 42 22 4
3 -27 22 42 22 4
4 -27 22 42 22 4
-3 -26 22 42 22 4
-2 -26 22 42 22 4
-1 -26 22 42 22 4
0 -26 22 42 22 4
1 -26 22 42 22 4
2 -26 22 42 22 4
3 -26 22 42 22 4
4 -26 22 42 22 4
-2 -25 22 42 22 4
-1 -25 22 42 22 4
0 -25 22 42 22 4
1 -25 22 42 22 4
2 -25 22 42 22 4
3 -25 22 42 22 4
-2 -24 22 42 22 4
-1 -24 22 42 22 4
0 -24 22 42 22 4
1 -24 22 42 22 4
2 -24 22 42 22 4
3 -24 22 42 22 4
-2 -23 22 42 22 4
-1 -23 22 42 22 4
0 -23 22 42 22 4
1 -23 22 42 22 4
2 -23 22 42 22 4
3 -23 22 42 22 4
0 -22 22 42 22 4
1 -22 22 42 22 4
-10 -38 23 42 22 4
-9 -38 23 42 22 4
-8 -38 23 42 22 4
-7 -38 23 42 22 4
-6 -38 23 42 22 4
-5 -38 23 42 22 4
-4 -38 23 42 22 4
-3 -38 23 42 22 4
-2 -38 23 102 51 51
-1 -38 23 102 51 51
2 -38 23 102 51 51
3 -38 23 102 51 51
4 -38 23 42 22 4
5 -38 23 42 22 4
6 -38 23 42 22 4
7 -38 23 42 22 4
8 -38 23 42 22 4
9 -38 23 42 22 4
10 -38 23 42 22 4
11 -38 23 42 22 4
-10 -37 23 42 22 4
-9 -37 23 42 22 4
-8 -37 23 42 22 4
-7 -37 23 42 22 4
-6 -37 23 42 22 4
-5 -37 23 42 22 4
-4 -37 23 42 22 4
-3 -37 23 42 22 4
-2 -37 23 67 67 255
-1 -37 23 67 67 255
3 -37 23 0 204 0
4 -37 23 42 22 4
5 -37 23 42 22 4
6 -37 23 42 22 4
7 -37 23 42 22 4
8 -37 23 42 22 4
9 -37 23 42 22 4
10 -37 23 42 22 4
11 -37 23 42 22 4
-10 -36 23 42 22 4
-9 -36 23 42 22 4
-8 -36 23 42 22 4
-7 -36 23 42 22 4
-6 -36 23 42 22 4
-5 -36 23 42 22 4
-4 -36 23 42 22 4
-3 -36 23 42 22 4
-2 -36 23 67 67 255
4 -36 23 42 22 4
5 -36 23 42 22 4
6 -36 23 42 22 4
7 -36 23 42 22 4
8 -36 23 42 22 4
9 -36 23 42 22 4
10 -36 23 42 22 4
11 -36 23 42 22 4
-10 -35 23 42 22 4
-9 -35 23 42 22 4
-8 -35 23 42 22 4
-7 -35 23 42 22 4
-6 -35 23 42 22 4
-5 -35 23 42 22 4
-4 -35 23 42 22 4
-3 -35 23 42 22 4
4 -35 23 42 22 4
5 -35 23 42 22 4
6 -35 23 42 22 4
7 -35 23 42 22 4
8 -35 23 42 22 4
9 -35 23 42 22 4
10 -35 23 42 22 4
11 -35 23 42 22 4
-10 -34 23 42 22 4
-9 -34 23 42 22 4
-8 -34 23 42 22 4
-7 -34 23 42 22 4
-6 -34 23 42 22 4
-5 -34 23 42 22 4
-4 -34 23 42 22 4
-3 -34 23 0 0 0
4 -34 23 0 0 0
5 -34 23 42 22 4
6 -34 23 42 22 4
7 -34 23 42 22 4
8 -34 23 42 22 4
9 -34 23 42 22 4
10 -34 23 42 22 4
11 -34 23 42 22 4
-10 -33 23 42 22 4
-9 -33 23 42 22 4
-8 -33 23 42 22 4
-7 -33 23 42 22 4
-6 -33 23 42 22 4
-5 -33 23 42 22 4
-4 -33 23 42 22 4
-3 -33 23 0 0 0
4 -33 23 0 0 0
5 -33 23 42 22 4
6 -33 23 42 22 4
7 -33 23 42 22 4
8 -33 23 42 22 4
9 -33 23 42 22 4
10 -33 23 42 22 4
11 -33 23 42 22 4
-10 -32 23 42 22 4
-9 -32 23 42 22 4
-8 -32 23 42 22 4
-7 -32 23 42 22 4
-6 -32 23 42 22 4
-5 -32 23 42 22 4
-4 -32 23 42 22 4
-3 -32 23 42 22 4
-2 -32 23 255 102 0
3 -32 23 255 102 0
4 -32 23 42 22 4
5 -32 23 42 22 4
6 -32 23 42 22 4
7 -32 23 42 22 4
8 -32 23 42 22 4
9 -32 23 42 22 4
10 -32 23 42 22 4
11 -32 23 42 22 4
-10 -31 23 42 22 4
-9 -31 23 42 22 4
-8 -31 23 42 22 4
-7 -31 23 42 22 4
-6 -31 23 42 22 4
-5 -31 23 42 22 4
-4 -31 23 42 22 4
-3 -31 23 42 22 4
-2 -31 23 221 0 0
3 -31 23 221 0 0
4 -31 23 42 22 4
5 -31 23 42 22 4
6 -31 23 42 22 4
7 -31 23 42 22 4
8 -31 23 42 22 4
9 -31 23 42 22 4
10 -31 23 42 22 4
11 -31 23 42 22 4
-10 -30 23 42 22 4
-9 -30 23 42 22 4
-8 -30 23 42 22 4
-7 -30 23 42 22 4
-6 -30 23 42 22 4
-5 -30 23 42 22 4
-4 -30 23 42 22 4
-3 -30 23 42 22 4
-2 -30 23 67 67 255
3 -30 23 0 0 153
4 -30 23 42 22 4
5 -30 23 42 22 4
6 -30 23 42 22 4
7 -30 23 42 22 4
8 -30 23 42 22 4
9 -30 23 42 22 4
10 -30 23 42 22 4
11 -30 23 42 22 4
-10 -29 23 42 22 4
-9 -29 23 42 22 4
-8 -29 23 42 22 4
-7 -29 23 42 22 4
-6 -29 23 42 22 4
-5 -29 23 42 22 4
-4 -29 23 42 22 4
-3 -29 23 42 22 4
-2 -29 23 0 204 0
4 -29 23 42 22 4
5 -29 23 42 22 4
6 -29 23 42 22 4
7 -29 23 42 22 4
8 -29 23 42 22 4
9 -29 23 42 22 4
10 -29 23 42 22 4
11 -29 23 42 22 4
-10 -28 23 42 22 4
-9 -28 23 42 22 4
-8 -28 23 42 22 4
-7 -28 23 42 22 4
-6 -28 23 42 22 4
-5 -28 23 42 22 4
-4 -28 23 42 22 4
-3 -28 23 42 22 4
4 -28 23 42 22 4
5 -28 23 42 22 4
6 -28 23 42 22 4
7 -28 23 42 22 4
8 -28 23 42 22 4
9 -28 23 42 22 4
10 -28 23 42 22 4
11 -28 23 42 22 4
-10 -27 23 42 22 4
-9 -27 23 42 22 4
-8 -27 23 42 22 4
-7 -27 23 42 22 4
-6 -27 23 42 22 4
-5 -27 23 42 22 4
-4 -27 23 42 22 4
-3 -27 23 0 0 0
4 -27 23 0 0 0
5 -27 23 42 22 4
6 -27 23 42 22 4
7 -27 23 42 22 4
8 -27 23 42 22 4
9 -27 23 42 22 4
10 -27 23 42 22 4
11 -27 23 42 22 4
-10 -26 23 42 22 4
-9 -26 23 42 22 4
-8 -26 23 42 22 4
-7 -26 23 42 22 4
-6 -26 23 42 22 4
-5 -26 23 42 22 4
-4 -26 23 42 22 4
-3 -26 23 0 0 0
4 -26 23 0 0 0
5 -26 23 42 22 4
6 -26 23 42 22 4
7 -26 23 42 22 4
8 -26 23 42 22 4
9 -26 23 42 22 4
10 -26 23 42 22 4
11 -26 23 42 22 4
-10 -25 23 42 22 4
-9 -25 23 42 22 4
-8 -25 23 42 22 4
-7 -25 23 42 22 4
-6 -25 23 42 22 4
-5 -25 23 42 22 4
-4 -25 23 42 22 4
-3 -25 23 42 22 4
-2 -25 23 255 102 0
3 -25 23 255 102 0
4 -25 23 42 22 4
5 -25 23 42 22 4
6 -25 23 42 22 4
7 -25 23 42 22 4
8 -25 23 42 22 4
9 -25 23 42 22 4
10 -25 23 42 22 4
11 -25 23 42 22 4
-10 -24 23 42 22 4
-9 -24 23 42 22 4
-8 -24 23 42 22 4
-7 -24 23 42 22 4
-6 -24 23 42 22 4
-5 -24 23 42 22 4
-4 -24 23 42 22 4
-3 -24 23 42 22 4
-2 -24 23 221 0 0
3 -24 23 221 0 0
4 -24 23 42 22 4
5 -24 23 42 22 4
6 -24 23 42 22 4
7 -24 23 42 22 4
8 -24 23 42 22 4
9 -24 23 42 22 4
10 -24 23 42 22 4
11 -24 23 42 22 4
-10 -23 23 42 22 4
-9 -23 23 42 22 4
-8 -23 23 42 22 4
-7 -23 23 42 22 4
-6 -23 23 42 22 4
-5 -23 23 42 22 4
-4 -23 23 42 22 4
-3 -23 23 42 22 4
-2 -23 23 67 67 255
-1 -23 23 0 0 153
3 -23 23 0 204 0
4 -23 23 42 22 4
5 -23 23 42 22 4
6 -23 23 42 22 4
7 -23 23 42 22 4
8 -23 23 42 22 4
9 -23 23 42 22 4
10 -23 23 42 22 4
11 -23 23 42 22 4
-10 -22 23 42 22 4
-9 -22 23 42 22 4
-8 -22 23 42 22 4
-7 -22 23 42 22 4
-6 -22 23 42 22 4
-5 -22 23 42 22 4
-4 -22 23 42 22 4
-3 -22 23 42 22 4
-2 -22 23 42 22 4
-1 -22 23 42 22 4
0 -22 23 0 0 0
1 -22 23 0 0 0
2 -22 23 42 22 4
3 -22 23 42 22 4
4 -22 23 42 22 4
5 -22 23 42 22 4
6 -22 23 42 22 4
7 -22 23 42 22 4
8 -22 23 42 22 4
9 -22 23 42 22 4
10 -22 23 42 22 4
11 -22 23 42 22 4
-10 -21 23 42 22 4
-9 -21 23 42 22 4
-8 -21 23 42 22 4
-7 -21 23 42 22 4
-6 -21 23 42 22 4
-5 -21 23 42 22 4
-4 -21 23 42 22 4
-3 -21 23 42 22 4
-2 -21 23 42 22 4
-1 -21 23 42 22 4
0 -21 23 42 22 4
1 -21 23 42 22 4
2 -21 23 42 22 4
3 -21 23 42 22 4
4 -21 23 42 22 4
5 -21 23 42 22 4
6 -21 23 42 22 4
7 -21 23 42 22 4
8 -21 23 42 22 4
9 -21 23 42 22 4
10 -21 23 42 22 4
11 -21 23 42 22 4
-10 -20 23 42 22 4
-9 -20 23 42 22 4
-8 -20 23 42 22 4
-7 -20 23 42 22 4
-6 -20 23 42 22 4
-5 -20 23 42 22 4
-4 -20 23 42 22 4
-3 -20 23 42 22 4
-2 -20 23 42 22 4
-1 -20 23 42 22 4
0 -20 23 42 22 4
1 -20 23 42 22 4
2 -20 23 42 22 4
3 -20 23 42 22 4
4 -20 23 42 22 4
5 -20 23 42 22 4
6 -20 23 42 22 4
7 -20 23 42 22 4
8 -20 23 42 22 4
9 -20 23 42 22 4
10 -20 23 42 22 4
11 -20 23 42 22 4
-10 -19 23 42 22 4
-9 -19 23 42 22 4
-8 -19 23 42 22 4
-7 -19 23 42 22 4
-6 -19 23 42 22 4
-5 -19 23 42 22 4
-4 -19 23 42 22 4
-3 -19 23 42 22 4
-2 -19 23 42 22 4
-1 -19 23 42 22 4
0 -19 23 42 22 4
1 -19 23 42 22 4
2 -19 23 42 22 4
3 -19 23 42 22 4
4 -19 23 42 22 4
5 -19 23 42 22 4
6 -19 23 42 22 4
7 -19 23 42 22 4
8 -19 23 42 22 4
9 -19 23 42 22 4
10 -19 23 42 22 4
11 -19 23 42 22 4
-10 -18 23 42 22 4
-9 -18 23 42 22 4
-8 -18 23 42 22 4
-7 -18 23 42 22 4
-6 -18 23 42 22 4
-5 -18 23 42 22 4
-4 -18 23 42 22 4
-3 -18 23 42 22 4
-2 -18 23 42 22 4
-1 -18 23 42 22 4
0 -18 23 42 22 4
1 -18 23 42 22 4
2 -18 23 42 22 4
3 -18 23 42 22 4
4 -18 23 42 22 4
5 -18 23 42 22 4
6 -18 23 42 22 4
7 -18 23 42 22 4
8 -18 23 42 22 4
9 -18 23 42 22 4
10 -18 23 42 22 4
11 -18 23 42 22 4
-10 -17 23 42 22 4
-9 -17 23 42 22 4
-8 -17 23 42 22 4
-7 -17 23 42 22 4
-6 -17 23 42 22 4
-5 -17 23 42 22 4
-4 -17 23 42 22 4
-3 -17 23 42 22 4
-2 -17 23 42 22 4
-1 -17 23 42 22 4
0 -17 23 42 22 4
1 -17 23 42 22 4
2 -17 23 42 22 4
3 -17 23 42 22 4
4 -17 23 42 22 4
5 -17 23 42 22 4
6 -17 23 42 22 4
7 -17 23 42 22 4
8 -17 23 42 22 4
9 -17 23 42 22 4
10 -17 23 42 22 4
11 -17 23 42 22 4
-10 -16 23 42 22 4
-9 -16 23 42 22 4
-8 -16 23 42 22 4
-7 -16 23 42 22 4
-6 -16 23 42 22 4
-5 -16 23 42 22 4
-4 -16 23 42 22 4
-3 -16 23 42 22 4
-2 -16 23 42 22 4
-1 -16 23 42 22 4
0 -16 23 42 22 4
1 -16 23 42 22 4
2 -16 23 42 22 4
3 -16 23 42 22 4
4 -16 23 42 22 4
5 -16 23 42 22 4
6 -16 23 42 22 4
7 -16 23 42 22 4
8 -16 23 42 22 4
9 -16 23 42 22 4
10 -16 23 42 22 4
11 -16 23 42 22 4
-10 -15 23 42 22 4
-9 -15 23 42 22 4
-8 -15 23 42 22 4
-7 -15 23 42 22 4
-6 -15 23 42 22 4
-5 -15 23 42 22 4
-4 -15 23 42 22 4
-3 -15 23 42 22 4
-2 -15 23 42 22 4
-1 -15 23 42 22 4
0 -15 23 42 22 4
1 -15 23 42 22 4
2 -15 23 42 22 4
3 -15 23 42 22 4
4 -15 23 42 22 4
5 -15 23 42 22 4
6 -15 23 42 22 4
7 -15 23 42 22 4
8 -15 23 42 22 4
9 -15 23 42 22 4
10 -15 23 42 22 4
11 -15 23 42 22 4
-11 -38 24 102 51 51
-10 -38 24 102 51 51
-9 -38 24 102 51 51
-8 -38 24 102 51 51
-7 -38 24 102 51 51
-6 -38 24 102 51 51
-5 -38 24 102 51 51
-4 -38 24 102 51 51
-3 -38 24 102 51 51
-2 -38 24 102 51 51
-1 -38 24 102 51 51
2 -38 24 102 51 51
3 -38 24 102 51 51
4 -38 24 102 51 51
5 -38 24 102 51 51
6 -38 24 102 51 51
7 -38 24 102 51 51
8 -38 24 102 51 51
9 -38 24 102 51 51
10 -38 24 102 51 51
11 -38 24 102 51 51
12 -38 24 102 51 51
-11 -37 24 102 51 51
-10 -37 24 168 168 168
-9 -37 24 67 67 255
-5 -37 24 0 0 153
-3 -37 24 168 168 168
3 -37 24 0 204 0
4 -37 24 168 168 168
5 -37 24 0 0 153
6 -37 24 67 67 255
10 -37 24 0 0 153
11 -37 24 168 168 168
12 -37 24 102 51 51
-11 -36 24 102 51 51
-10 -36 24 67 67 255
-3 -36 24 50 50 50
4 -36 24 50 50 50
11 -36 24 67 67 255
12 -36 24 102 51 51
-11 -35 24 102 51 51
-8 -35 24 0 204 0
-3 -35 24 50 50 50
4 -35 24 50 50 50
9 -35 24 0 204 0
12 -35 24 102 51 51
-11 -34 24 102 51 51
-8 -34 24 0 255 204
-7 -34 24 221 0 0
-6 -34 24 255 102 0
7 -34 24 255 102 0
8 -34 24 221 0 0
9 -34 24 0 255 204
12 -34 24 102 51 51
-11 -33 24 102 51 51
-8 -33 24 255 255 255
-7 -33 24 221 0 0
-6 -33 24 255 102 0
7 -33 24 255 102 0
8 -33 24 221 0 0
9 -33 24 255 255 255
12 -33 24 102 51 51
-11 -32 24 102 51 51
-8 -32 24 0 204 0
-3 -32 24 50 50 50
4 -32 24 50 50 50
9 -32 24 0 204 0
12 -32 24 102 51 51
-11 -31 24 102 51 51
-10 -31 24 67 67 255
-3 -31 24 50 50 50
4 -31 24 50 50 50
12 -31 24 102 51 51
-11 -30 24 102 51 51
-10 -30 24 168 168 168
-9 -30 24 0 0 153
-3 -30 24 168 168 168
3 -30 24 0 0 153
4 -30 24 168 168 168
10 -30 24 0 0 153
11 -30 24 168 168 168
12 -30 24 102 51 51
-11 -29 24 102 51 51
-10 -29 24 0 0 153
-3 -29 24 50 50 50
-2 -29 24 0 204 0
4 -29 24 50 50 50
11 -29 24 67 67 255
12 -29 24 102 51 51
-11 -28 24 102 51 51
-7 -28 24 255 102 0
-6 -28 24 255 102 0
-3 -28 24 50 50 50
4 -28 24 50 50 50
7 -28 24 255 102 0
8 -28 24 255 102 0
12 -28 24 102 51 51
-11 -27 24 102 51 51
-7 -27 24 221 0 0
-6 -27 24 221 0 0
7 -27 24 221 0 0
8 -27 24 221 0 0
12 -27 24 102 51 51
-11 -26 24 102 51 51
-7 -26 24 221 0 0
-6 -26 24 221 0 0
7 -26 24 221 0 0
8 -26 24 221 0 0
12 -26 24 102 51 51
-11 -25 24 102 51 51
-10 -25 24 0 204 0
-7 -25 24 255 102 0
-6 -25 24 255 102 0
-3 -25 24 50 50 50
4 -25 24 50 50 50
7 -25 24 255 102 0
8 -25 24 255 102 0
12 -25 24 102 51 51
-11 -24 24 102 51 51
-10 -24 24 0 0 153
-3 -24 24 50 50 50
4 -24 24 50 50 50
11 -24 24 0 0 153
12 -24 24 102 51 51
-11 -23 24 102 51 51
-10 -23 24 168 168 168
-3 -23 24 168 168 168
3 -23 24 0 204 0
4 -23 24 168 168 168
11 -23 24 168 168 168
12 -23 24 102 51 51
-11 -22 24 102 51 51
-10 -22 24 67 67 255
-3 -22 24 67 67 255
-2 -22 24 50 50 50
-1 -22 24 50 50 50
2 -22 24 50 50 50
3 -22 24 50 50 50
4 -22 24 67 67 255
11 -22 24 67 67 255
12 -22 24 102 51 51
-11 -21 24 102 51 51
-10 -21 24 67 67 255
-8 -21 24 255 102 0
-7 -21 24 221 0 0
-6 -21 24 221 0 0
-5 -21 24 255 102 0
6 -21 24 255 102 0
7 -21 24 221 0 0
8 -21 24 221 0 0
9 -21 24 255 102 0
12 -21 24 102 51 51
-11 -20 24 102 51 51
-8 -20 24 255 102 0
-7 -20 24 221 0 0
-6 -20 24 221 0 0
-5 -20 24 255 102 0
6 -20 24 255 102 0
7 -20 24 221 0 0
8 -20 24 221 0 0
9 -20 24 255 102 0
12 -20 24 102 51 51
-11 -19 24 102 51 51
12 -19 24 102 51 51
-11 -18 24 102 51 51
11 -18 24 0 0 153
12 -18 24 102 51 51
-11 -17 24 102 51 51
-10 -17 24 0 0 153
-1 -17 24 0 255 131
0 -17 24 0 255 131
1 -17 24 0 255 131
2 -17 24 0 255 131
4 -17 24 67 67 255
5 -17 24 153 0 153
6 -17 24 255 255 255
7 -17 24 153 0 153
8 -17 24 255 255 255
11 -17 24 0 0 153
12 -17 24 102 51 51
-11 -16 24 102 51 51
-10 -16 24 168 168 168
-7 -16 24 153 51 205
-6 -16 24 255 255 255
-5 -16 24 255 255 255
-4 -16 24 0 0 153
-3 -16 24 168 168 168
-2 -16 24 0 255 131
3 -16 24 0 255 131
4 -16 24 168 168 168
5 -16 24 255 255 255
6 -16 24 255 255 255
7 -16 24 255 255 255
8 -16 24 255 255 255
10 -16 24 102 0 0
11 -16 24 168 168 168
12 -16 24 102 51 51
-11 -15 24 102 51 51
-10 -15 24 102 51 51
-9 -15 24 102 51 51
-8 -15 24 102 51 51
-7 -15 24 102 51 51
-6 -15 24 102 51 51
-5 -15 24 102 51 51
-4 -15 24 102 51 51
-3 -15 24 102 51 51
4 -15 24 102 51 51
5 -15 24 102 51 51
6 -15 24 102 51 51
7 -15 24 102 51 51
8 -15 24 102 51 51
9 -15 24 102 51 51
10 -15 24 102 51 51
11 -15 24 102 51 51
-11 -38 25 102 51 51
12 -38 25 102 51 51
-11 -37 25 102 51 51
-10 -37 25 168 168 168
-3 -37 25 168 168 168
4 -37 25 168 168 168
11 -37 25 168 168 168
12 -37 25 102 51 51
-11 -36 25 102 51 51
12 -36 25 102 51 51
-11 -35 25 102 51 51
-8 -35 25 0 204 0
9 -35 25 0 204 0
12 -35 25 102 51 51
-8 -34 25 255 255 255
9 -34 25 255 255 255
-8 -33 25 255 255 255
9 -33 25 255 255 255
-11 -32 25 102 51 51
-8 -32 25 0 204 0
9 -32 25 0 204 0
12 -32 25 102 51 51
-11 -31 25 102 51 51
12 -31 25 102 51 51
-11 -30 25 102 51 51
-10 -30 25 168 168 168
-3 -30 25 168 168 168
4 -30 25 168 168 168
11 -30 25 168 168 168
12 -30 25 102 51 51
-11 -29 25 102 51 51
12 -29 25 102 51 51
-11 -28 25 102 51 51
12 -28 25 102 51 51
-11 -25 25 102 51 51
-10 -25 25 0 204 0
12 -25 25 102 51 51
-11 -24 25 102 51 51
12 -24 25 102 51 51
-11 -23 25 102 51 51
-10 -23 25 168 168 168
-3 -23 25 168 168 168
4 -23 25 168 168 168
11 -23 25 168 168 168
12 -23 25 102 51 51
-11 -22 25 102 51 51
12 -22 25 102 51 51
-11 -21 25 102 51 51
12 -21 25 102 51 51
-11 -18 25 102 51 51
12 -18 25 102 51 51
-11 -17 25 102 51 51
5 -17 25 255 255 255
6 -17 25 255 255 255
7 -17 25 255 255 255
8 -17 25 255 255 255
11 -17 25 0 0 153
12 -17 25 102 51 51
-11 -16 25 102 51 51
-10 -16 25 168 168 168
-7 -16 25 255 255 255
-6 -16 25 255 255 255
-5 -16 25 255 255 255
-3 -16 25 168 168 168
4 -16 25 168 168 168
5 -16 25 255 255 255
6 -16 25 255 255 255
7 -16 25 255 255 255
8 -16 25 255 255 255
9 -16 25 102 0 0
11 -16 25 168 168 168
12 -16 25 102 51 51
-11 -15 25 102 51 51
-10 -15 25 102 51 51
-9 -15 25 102 51 51
-8 -15 25 102 51 51
-7 -15 25 102 51 51
-6 -15 25 102 51 51
-5 -15 25 102 51 51
-4 -15 25 102 51 51
-3 -15 25 102 51 51
4 -15 25 102 51 51
5 -15 25 102 51 51
6 -15 25 102 51 51
7 -15 25 102 51 51
8 -15 25 102 51 51
9 -15 25 102 51 51
10 -15 25 102 51 51
11 -15 25 102 51 51
-11 -38 26 102 51 51
12 -38 26 102 51 51
-11 -37 26 102 51 51
-10 -37 26 168 168 168
-3 -37 26 168 168 168
4 -37 26 168 168 168
11 -37 26 168 168 168
12 -37 26 102 51 51
-11 -36 26 102 51 51
-3 -36 26 255 255 0
4 -36 26 255 255 0
12 -36 26 102 51 51
-11 -35 26 102 51 51
12 -35 26 102 51 51
-11 -32 26 102 51 51
12 -32 26 102 51 51
-11 -31 26 102 51 51
-3 -31 26 255 255 0
4 -31 26 255 255 0
12 -31 26 102 51 51
-11 -30 26 102 51 51
-10 -30 26 168 168 168
-9 -30 26 255 255 0
-4 -30 26 255 153 102
-3 -30 26 168 168 168
-2 -30 26 255 153 102
3 -30 26 255 153 102
4 -30 26 168 168 168
5 -30 26 255 153 102
10 -30 26 255 255 0
11 -30 26 168 168 168
12 -30 26 102 51 51
-11 -29 26 102 51 51
-3 -29 26 255 255 0
4 -29 26 255 255 0
12 -29 26 102 51 51
-11 -28 26 102 51 51
12 -28 26 102 51 51
-11 -25 26 102 51 51
12 -25 26 102 51 51
-11 -24 26 102 51 51
-3 -24 26 255 255 0
4 -24 26 255 255 0
12 -24 26 102 51 51
-11 -23 26 102 51 51
-10 -23 26 168 168 168
-9 -23 26 255 255 0
-4 -23 26 255 153 102
-3 -23 26 168 168 168
-2 -23 26 255 153 102
4 -23 26 168 168 168
5 -23 26 255 153 102
10 -23 26 255 255 0
11 -23 26 168 168 168
12 -23 26 102 51 51
-11 -22 26 102 51 51
-3 -22 26 255 255 0
4 -22 26 255 255 0
12 -22 26 102 51 51
-11 -21 26 102 51 51
12 -21 26 102 51 51
-11 -18 26 102 51 51
12 -18 26 102 51 51
-11 -17 26 102 51 51
-3 -17 26 255 255 0
4 -17 26 255 255 0
12 -17 26 102 51 51
-11 -16 26 102 51 51
-10 -16 26 168 168 168
-7 -16 26 255 255 255
-6 -16 26 255 255 255
-5 -16 26 255 255 255
-3 -16 26 168 168 168
4 -16 26 168 168 168
11 -16 26 168 168 168
12 -16 26 102 51 51
-11 -15 26 102 51 51
-10 -15 26 102 51 51
-9 -15 26 102 51 51
-8 -15 26 102 51 51
-7 -15 26 102 51 51
-6 -15 26 102 51 51
-5 -15 26 102 51 51
-4 -15 26 102 51 51
-3 -15 26 102 51 51
4 -15 26 102 51 51
5 -15 26 102 51 51
6 -15 26 102 51 51
7 -15 26 102 51 51
8 -15 26 102 51 51
9 -15 26 102 51 51
10 -15 26 102 51 51
11 -15 26 102 51 51
-11 -38 27 102 51 51
12 -38 27 102 51 51
-11 -37 27 102 51 51
-10 -37 27 168 168 168
-3 -37 27 168 168 168
4 -37 27 168 168 168
11 -37 27 168 168 168
12 -37 27 102 51 51
-11 -36 27 102 51 51
12 -36 27 102 51 51
-11 -35 27 102 51 51
12 -35 27 102 51 51
-11 -34 27 102 51 51
12 -34 27 102 51 51
-11 -33 27 102 51 51
12 -33 27 102 51 51
-11 -32 27 102 51 51
12 -32 27 102 51 51
-11 -31 27 102 51 51
12 -31 27 102 51 51
-11 -30 27 102 51 51
-10 -30 27 168 168 168
-3 -30 27 168 168 168
4 -30 27 168 168 168
11 -30 27 168 168 168
12 -30 27 102 51 51
-11 -29 27 102 51 51
12 -29 27 102 51 51
-11 -28 27 102 51 51
12 -28 27 102 51 51
-11 -27 27 102 51 51
12 -27 27 102 51 51
-11 -26 27 102 51 51
12 -26 27 102 51 51
-11 -25 27 102 51 51
12 -25 27 102 51 51
-11 -24 27 102 51 51
12 -24 27 102 51 51
-11 -23 27 102 51 51
-10 -23 27 168 168 168
-3 -23 27 168 168 168
4 -23 27 168 168 168
11 -23 27 168 168 168
12 -23 27 102 51 51
-11 -22 27 102 51 51
12 -22 27 102 51 51
-11 -21 27 102 51 51
12 -21 27 102 51 51
-11 -20 27 102 51 51
12 -20 27 102 51 51
-11 -19 27 102 51 51
12 -19 27 102 51 51
-11 -18 27 102 51 51
12 -18 27 102 51 51
-11 -17 27 102 51 51
-3 -17 27 255 153 102
4 -17 27 255 153 102
12 -17 27 102 51 51
-11 -16 27 102 51 51
-10 -16 27 168 168 168
-3 -16 27 168 168 168
4 -16 27 168 168 168
11 -16 27 168 168 168
12 -16 27 102 51 51
-11 -15 27 102 51 51
-10 -15 27 102 51 51
-9 -15 27 102 51 51
-8 -15 27 102 51 51
-7 -15 27 102 51 51
-6 -15 27 102 51 51
-5 -15 27 102 51 51
-4 -15 27 102 51 51
-3 -15 27 102 51 51
-2 -15 27 102 51 51
3 -15 27 102 51 51
4 -15 27 102 51 51
5 -15 27 102 51 51
6 -15 27 102 51 51
7 -15 27 102 51 51
8 -15 27 102 51 51
9 -15 27 102 51 51
10 -15 27 102 51 51
11 -15 27 102 51 51
-11 -38 28 102 51 51
12 -38 28 102 51 51
-11 -37 28 102 51 51
-10 -37 28 168 168 168
-3 -37 28 168 168 168
4 -37 28 168 168 168
11 -37 28 168 168 168
12 -37 28 102 51 51
-11 -36 28 102 51 51
12 -36 28 102 51 51
-11 -35 28 102 51 51
12 -35 28 102 51 51
-11 -34 28 102 51 51
12 -34 28 102 51 51
-11 -33 28 102 51 51
12 -33 28 102 51 51
-11 -32 28 102 51 51
12 -32 28 102 51 51
-11 -31 28 102 51 51
12 -31 28 102 51 51
-11 -30 28 102 51 51
-10 -30 28 168 168 168
-3 -30 28 168 168 168
4 -30 28 168 168 168
11 -30 28 168 168 168
12 -30 28 102 51 51
-11 -29 28 102 51 51
12 -29 28 102 51 51
-11 -28 28 102 51 51
12 -28 28 102 51 51
-11 -27 28 102 51 51
12 -27 28 102 51 51
-11 -26 28 102 51 51
12 -26 28 102 51 51
-11 -25 28 102 51 51
12 -25 28 102 51 51
-11 -24 28 102 51 51
12 -24 28 102 51 51
-11 -23 28 102 51 51
-10 -23 28 168 168 168
-3 -23 28 168 168 168
4 -23 28 168 168 168
11 -23 28 168 168 168
12 -23 28 102 51 51
-11 -22 28 102 51 51
12 -22 28 102 51 51
-11 -21 28 102 51 51
12 -21 28 102 51 51
-11 -20 28 102 51 51
12 -20 28 102 51 51
-11 -19 28 102 51 51
12 -19 28 102 51 51
-11 -18 28 102 51 51
12 -18 28 102 51 51
-11 -17 28 102 51 51
12 -17 28 102 51 51
-11 -16 28 102 51 51
-10 -16 28 168 168 168
-3 -16 28 168 168 168
4 -16 28 168 168 168
11 -16 28 168 168 168
12 -16 28 102 51 51
-11 -15 28 102 51 51
-10 -15 28 102 51 51
-9 -15 28 102 51 51
-8 -15 28 102 51 51
-7 -15 28 102 51 51
-6 -15 28 102 51 51
-5 -15 28 102 51 51
-4 -15 28 102 51 51
-3 -15 28 102 51 51
-2 -15 28 102 51 51
-1 -15 28 102 51 51
0 -15 28 102 51 51
1 -15 28 102 51 51
2 -15 28 102 51 51
3 -15 28 102 51 51
4 -15 28 102 51 51
5 -15 28 102 51 51
6 -15 28 102 51 51
7 -15 28 102 51 51
8 -15 28 102 51 51
9 -15 28 102 51 51
10 -15 28 102 51 51
11 -15 28 102 51 51
