ply
format ascii 1.0
comment : MagicaVoxel @ Ephtracy
element vertex 1443
property float x
property float y
property float z
property uchar red
property uchar green
property uchar blue
end_header
-22 28 16 255 227 48
-32 34 14 102 51 51
-50 30 18 50 50 50
-45 34 14 102 51 51
-43 28 15 67 67 255
-34 16 13 67 67 255
-33 17 13 42 22 4
-33 16 13 0 0 153
-34 15 13 0 0 153
-35 15 13 0 0 153
-36 15 13 50 50 50
-37 15 13 50 50 50
-37 15 12 42 22 4
-47 19 13 42 22 4
-33 18 13 0 0 153
-34 18 13 67 67 255
-41 20 15 255 255 254
-56 34 21 102 51 51
-22 27 16 255 227 48
-22 26 16 255 227 48
-56 21 21 102 51 51
-55 34 21 102 51 51
-55 21 21 102 51 51
-50 29 18 50 50 50
-44 34 14 102 51 51
-51 34 13 102 51 51
-38 20 15 255 255 254
-39 20 15 255 255 254
-40 19 13 0 0 0
-48 17 13 42 22 4
-41 19 13 42 22 4
-39 19 13 0 0 0
-38 19 13 42 22 4
-48 16 13 50 50 50
-33 15 13 42 22 4
-45 19 13 50 50 50
-44 19 13 42 22 4
-43 19 13 50 50 50
-56 34 20 102 51 51
-56 21 20 102 51 51
-55 34 20 102 51 51
-55 21 20 102 51 51
-50 34 13 102 51 51
-49 34 13 102 51 51
-48 34 13 102 51 51
-47 34 13 102 51 51
-46 34 13 102 51 51
-45 34 13 102 51 51
-44 34 13 102 51 51
-43 34 13 102 51 51
-42 34 13 102 51 51
-41 34 13 102 51 51
-40 34 13 102 51 51
-39 34 13 102 51 51
-54 34 20 102 51 51
-54 21 20 102 51 51
-53 34 20 102 51 51
-28 21 12 102 51 51
-30 21 14 102 51 51
-53 21 20 102 51 51
-52 34 20 102 51 51
-52 21 20 102 51 51
-29 21 12 102 51 51
-30 21 13 102 51 51
-51 34 20 102 51 51
-26 33 17 42 22 4
-21 26 17 102 51 51
-30 21 12 102 51 51
-25 30 16 255 227 49
-51 21 20 102 51 51
-50 34 20 102 51 51
-50 21 20 102 51 51
-31 21 12 102 51 51
-41 18 13 0 204 0
-50 24 18 42 22 4
-43 34 14 102 51 51
-38 34 13 102 51 51
-32 21 12 102 51 51
-38 18 13 0 204 0
-28 34 15 102 51 51
-32 34 15 102 51 51
-31 21 14 255 255 255
-33 21 12 102 51 51
-57 26 18 0 204 0
-32 21 14 255 255 255
-28 33 15 42 22 4
-32 21 15 102 51 51
-34 21 12 102 51 51
-57 28 19 255 255 255
-42 19 13 50 50 50
-38 15 13 42 22 4
-39 15 13 50 50 50
-35 21 12 102 51 51
-57 27 19 255 255 255
-40 15 13 50 50 50
-41 15 13 42 22 4
-48 15 13 50 50 50
-36 21 12 102 51 51
-57 22 17 42 22 4
-42 14 13 42 22 4
-48 18 13 0 0 153
-48 14 13 42 22 4
-37 21 12 102 51 51
-57 27 17 42 22 4
-42 13 13 50 50 50
-48 18 12 42 22 4
-48 13 13 50 50 50
-38 21 12 102 51 51
-57 23 17 42 22 4
-56 34 19 102 51 51
-57 29 18 0 204 0
-57 29 17 42 22 4
-39 21 12 102 51 51
-57 26 17 42 22 4
-57 28 17 42 22 4
-56 21 19 102 51 51
-55 34 19 50 50 50
-40 21 12 102 51 51
-48 31 18 255 255 254
-55 21 19 50 50 50
-54 34 19 50 50 50
-54 21 19 50 50 50
-41 21 12 102 51 51
-49 31 18 255 255 254
-53 34 19 50 50 50
-53 21 19 50 50 50
-52 34 19 50 50 50
-42 21 12 102 51 51
-47 31 17 255 255 254
-43 21 12 102 51 51
-47 31 16 255 255 254
-44 21 12 102 51 51
-48 31 17 255 255 254
-45 21 12 102 51 51
-47 24 17 255 255 254
-46 21 12 102 51 51
-48 24 18 255 255 254
-47 21 12 102 51 51
-49 24 18 255 255 254
-48 21 12 102 51 51
-47 24 16 255 255 254
-49 21 12 102 51 51
-48 24 17 255 255 254
-50 21 12 102 51 51
-32 28 15 0 0 153
-51 21 12 102 51 51
-48 25 15 0 0 153
-52 21 12 102 51 51
-26 26 17 50 50 50
-53 21 12 102 51 51
-26 25 17 42 22 4
-54 21 12 102 51 51
-57 24 18 0 0 153
-57 33 14 102 51 51
-57 32 14 102 51 51
-57 31 14 102 51 51
-57 30 14 102 51 51
-57 29 14 102 51 51
-57 28 14 102 51 51
-57 27 14 102 51 51
-57 26 14 102 51 51
-57 25 14 102 51 51
-57 24 14 102 51 51
-57 23 14 102 51 51
-57 22 14 102 51 51
-52 21 19 50 50 50
-51 34 19 50 50 50
-51 21 19 50 50 50
-50 34 19 102 51 51
-50 21 19 102 51 51
-50 31 18 42 22 4
-42 34 14 102 51 51
-33 29 15 255 145 237
-37 34 13 102 51 51
-55 31 17 42 22 4
-31 21 13 0 225 255
-32 21 13 255 255 255
-28 32 15 42 22 4
-21 27 17 102 51 51
-26 28 15 42 22 4
-21 27 15 102 51 51
-28 31 15 42 22 4
-20 28 18 42 22 4
-42 12 13 50 50 50
-47 18 13 0 0 153
-36 19 13 50 50 50
-48 12 13 50 50 50
-42 11 13 42 22 4
-35 19 13 42 22 4
-36 34 13 102 51 51
-35 34 13 102 51 51
-34 34 13 102 51 51
-33 34 13 102 51 51
-32 34 13 102 51 51
-54 34 12 102 51 51
-53 34 12 102 51 51
-52 34 12 102 51 51
-48 11 13 42 22 4
-42 10 13 50 50 50
-51 34 12 102 51 51
-50 34 12 102 51 51
-37 19 13 50 50 50
-48 10 13 50 50 50
-26 27 15 42 22 4
-49 34 12 102 51 51
-48 34 12 102 51 51
-47 34 12 102 51 51
-42 9 13 50 50 50
-48 9 13 50 50 50
-28 21 13 102 51 51
-52 31 17 42 22 4
-56 34 18 102 51 51
-57 28 18 255 255 255
-29 21 13 102 51 51
-54 31 17 42 22 4
-57 33 19 0 0 153
-57 33 17 42 22 4
-29 34 16 102 51 51
-27 28 16 255 145 236
-57 32 17 42 22 4
-57 31 17 42 22 4
-22 30 15 102 51 51
-53 31 17 42 22 4
-57 30 17 42 22 4
-56 21 18 102 51 51
-26 29 15 42 22 4
-27 22 16 0 204 0
-55 34 18 102 51 51
-57 27 18 0 255 205
-33 21 13 102 51 51
-57 24 17 42 22 4
-37 33 17 255 255 255
-32 34 16 255 255 254
-34 21 13 102 51 51
-31 34 16 102 51 51
-55 21 18 102 51 51
-54 34 18 102 51 51
-35 21 13 0 225 255
-32 21 16 255 255 254
-38 33 17 255 255 255
-54 29 18 255 102 0
-36 21 13 255 255 255
-31 21 16 102 51 51
-54 28 18 221 0 0
-54 27 18 221 0 0
-37 21 13 102 51 51
-25 29 16 42 22 4
-54 26 18 255 102 0
-49 29 15 0 0 153
-22 25 16 102 51 51
-38 21 13 102 51 51
-25 31 16 255 227 49
-54 21 18 102 51 51
-21 29 16 102 51 51
-39 20 13 42 22 4
-39 21 13 102 51 51
-25 23 16 255 227 49
-53 34 18 102 51 51
-21 28 16 102 51 51
-40 20 13 42 22 4
-40 21 13 102 51 51
-25 32 16 255 227 49
-39 33 17 255 255 255
-53 29 18 255 102 0
-21 27 16 102 51 51
-41 21 13 102 51 51
-25 28 16 42 22 4
-53 28 18 221 0 0
-53 27 18 221 0 0
-42 21 13 102 51 51
-25 27 16 42 22 4
-43 21 13 0 225 255
-25 26 16 42 22 4
-44 21 13 255 255 255
-25 25 16 42 22 4
-45 21 13 102 51 51
-25 24 16 255 227 49
-46 21 13 102 51 51
-26 22 17 42 22 4
-47 21 13 0 225 255
-26 22 16 42 22 4
-48 21 13 255 255 255
-26 33 16 42 22 4
-49 21 13 102 51 51
-38 16 13 0 204 0
-50 21 13 102 51 51
-26 29 16 42 22 4
-51 21 13 0 225 255
-26 30 16 42 22 4
-52 21 13 255 255 255
-26 31 16 0 0 0
-53 21 13 102 51 51
-24 31 16 42 22 4
-54 21 13 102 51 51
-46 21 17 255 255 254
-55 21 13 102 51 51
-55 34 13 102 51 51
-58 22 18 102 51 51
-58 32 21 102 51 51
-58 31 21 102 51 51
-58 30 21 102 51 51
-58 29 21 102 51 51
-58 28 21 102 51 51
-58 27 21 102 51 51
-58 26 21 102 51 51
-58 25 21 102 51 51
-58 24 21 102 51 51
-58 23 21 102 51 51
-58 22 21 102 51 51
-46 34 12 102 51 51
-45 34 12 102 51 51
-44 34 12 102 51 51
-43 34 12 102 51 51
-42 34 12 102 51 51
-41 34 12 102 51 51
-40 34 12 102 51 51
-39 34 12 102 51 51
-38 34 12 102 51 51
-37 34 12 102 51 51
-36 34 12 102 51 51
-35 34 12 102 51 51
-22 26 15 102 51 51
-34 34 12 102 51 51
-28 21 14 102 51 51
-46 21 16 255 255 254
-29 21 14 102 51 51
-47 21 17 255 255 254
-26 30 15 42 22 4
-48 21 18 255 255 254
-22 29 15 102 51 51
-46 34 17 255 255 254
-21 28 15 102 51 51
-27 21 17 255 255 254
-30 34 16 102 51 51
-32 33 15 0 0 0
-57 25 17 42 22 4
-32 32 15 0 0 0
-56 21 14 102 51 51
-32 31 15 102 51 51
-32 24 15 102 51 51
-26 32 16 0 0 0
-56 21 13 102 51 51
-32 22 15 0 0 0
-55 21 12 102 51 51
-46 34 16 255 255 254
-33 21 14 102 51 51
-33 22 14 255 227 49
-33 23 14 255 227 49
-33 24 14 42 22 4
-33 25 14 42 22 4
-33 26 14 42 22 4
-33 27 14 42 22 4
-33 28 14 42 22 4
-33 29 14 42 22 4
-33 30 14 42 22 4
-33 31 14 42 22 4
-33 32 14 255 227 49
-33 33 14 255 227 49
-47 34 17 255 255 254
-34 21 14 102 51 51
-34 22 14 42 22 4
-34 23 14 42 22 4
-34 24 14 42 22 4
-34 25 14 42 22 4
-34 26 14 42 22 4
-34 27 14 42 22 4
-34 28 14 42 22 4
-34 29 14 42 22 4
-34 30 14 42 22 4
-34 31 14 42 22 4
-34 32 14 255 227 49
-34 33 14 255 227 49
-48 34 18 255 255 254
-35 21 14 255 255 255
-35 22 14 42 22 4
-35 23 14 42 22 4
-35 24 14 255 227 48
-35 25 14 255 227 48
-35 26 14 42 22 4
-35 27 14 42 22 4
-35 28 14 42 22 4
-35 29 14 42 22 4
-35 30 14 42 22 4
-35 31 14 42 22 4
-35 32 14 42 22 4
-35 33 14 42 22 4
-34 19 13 0 0 153
-36 21 14 255 255 255
-36 22 14 42 22 4
-36 23 14 42 22 4
-36 24 14 255 227 48
-36 25 14 255 227 48
-36 26 14 42 22 4
-36 27 14 42 22 4
-36 28 14 42 22 4
-36 29 14 42 22 4
-36 30 14 42 22 4
-36 31 14 42 22 4
-36 32 14 42 22 4
-36 33 14 42 22 4
-33 19 13 0 0 153
-37 21 14 102 51 51
-37 22 14 42 22 4
-37 23 14 42 22 4
-37 24 14 255 227 48
-37 25 14 255 227 48
-37 26 14 42 22 4
-37 27 14 42 22 4
-37 28 14 255 227 48
-37 29 14 42 22 4
-37 30 14 42 22 4
-37 31 14 42 22 4
-37 32 14 42 22 4
-37 33 14 42 22 4
-31 33 14 42 22 4
-38 20 14 42 22 4
-38 21 14 102 51 51
-38 22 14 42 22 4
-38 23 14 42 22 4
-38 24 14 255 227 48
-38 25 14 255 227 48
-38 26 14 42 22 4
-38 27 14 42 22 4
-38 28 14 255 227 48
-38 29 14 42 22 4
-38 30 14 42 22 4
-38 31 14 42 22 4
-38 32 14 42 22 4
-38 33 14 42 22 4
-32 33 14 42 22 4
-39 20 14 0 0 0
-39 21 14 255 227 49
-39 22 14 42 22 4
-39 23 14 42 22 4
-39 24 14 42 22 4
-39 25 14 42 22 4
-39 26 14 42 22 4
-39 27 14 42 22 4
-39 28 14 42 22 4
-39 29 14 42 22 4
-39 30 14 42 22 4
-39 31 14 42 22 4
-39 32 14 42 22 4
-39 33 14 42 22 4
-31 32 14 42 22 4
-40 20 14 0 0 0
-40 21 14 255 227 49
-40 22 14 42 22 4
-40 23 14 42 22 4
-40 24 14 42 22 4
-40 25 14 42 22 4
-40 26 14 42 22 4
-40 27 14 42 22 4
-40 28 14 42 22 4
-40 29 14 42 22 4
-40 30 14 42 22 4
-40 31 14 42 22 4
-40 32 14 42 22 4
-40 33 14 42 22 4
-32 32 14 42 22 4
-41 20 14 42 22 4
-41 21 14 102 51 51
-41 22 14 42 22 4
-41 23 14 42 22 4
-41 24 14 255 227 48
-41 25 14 255 227 48
-41 26 14 42 22 4
-41 27 14 42 22 4
-41 28 14 255 227 48
-41 29 14 42 22 4
-41 30 14 42 22 4
-41 31 14 42 22 4
-41 32 14 42 22 4
-41 33 14 42 22 4
-31 31 14 42 22 4
-42 21 14 102 51 51
-42 22 14 42 22 4
-42 23 14 42 22 4
-42 24 14 255 227 48
-42 25 14 255 227 48
-42 26 14 42 22 4
-42 27 14 42 22 4
-42 28 14 255 227 48
-42 29 14 42 22 4
-42 30 14 42 22 4
-42 31 14 42 22 4
-42 32 14 42 22 4
-42 33 14 42 22 4
-32 31 14 42 22 4
-43 21 14 255 255 255
-43 22 14 42 22 4
-43 23 14 42 22 4
-43 24 14 255 227 48
-43 25 14 255 227 48
-43 26 14 42 22 4
-43 27 14 42 22 4
-43 28 14 42 22 4
-43 29 14 42 22 4
-43 30 14 42 22 4
-43 31 14 42 22 4
-43 32 14 42 22 4
-43 33 14 42 22 4
-30 33 15 255 227 49
-44 21 14 255 255 255
-44 22 14 42 22 4
-44 23 14 42 22 4
-44 24 14 255 227 48
-44 25 14 255 227 48
-44 26 14 42 22 4
-44 27 14 42 22 4
-44 28 14 42 22 4
-44 29 14 42 22 4
-44 30 14 42 22 4
-44 31 14 42 22 4
-44 32 14 42 22 4
-44 33 14 42 22 4
-32 30 14 42 22 4
-45 21 14 102 51 51
-45 22 14 42 22 4
-45 23 14 42 22 4
-45 24 14 42 22 4
-45 25 14 42 22 4
-45 26 14 42 22 4
-45 27 14 42 22 4
-45 28 14 42 22 4
-45 29 14 42 22 4
-45 30 14 42 22 4
-45 31 14 42 22 4
-45 32 14 42 22 4
-45 33 14 42 22 4
-30 32 15 255 227 49
-46 21 14 102 51 51
-46 22 14 255 227 49
-46 23 14 255 227 49
-46 24 14 42 22 4
-46 25 14 42 22 4
-46 26 14 42 22 4
-46 27 14 42 22 4
-46 28 14 42 22 4
-46 29 14 42 22 4
-46 30 14 42 22 4
-46 31 14 42 22 4
-46 32 14 255 227 49
-46 33 14 255 227 49
-32 29 14 42 22 4
-47 21 14 255 255 255
-47 25 14 255 227 49
-47 26 14 255 227 49
-47 27 14 255 227 49
-47 28 14 255 227 49
-47 29 14 255 227 49
-47 30 14 255 227 49
-30 31 15 42 22 4
-48 21 14 255 255 255
-48 25 14 255 227 49
-48 26 14 255 227 49
-48 27 14 255 227 49
-48 28 14 255 227 49
-48 29 14 255 227 49
-48 30 14 255 227 49
-32 28 14 42 22 4
-49 21 14 102 51 51
-49 25 14 255 227 49
-49 26 14 255 227 49
-49 27 14 255 227 49
-49 28 14 255 227 49
-49 29 14 255 227 49
-49 30 14 255 227 49
-31 22 14 42 22 4
-50 21 14 102 51 51
-32 22 14 42 22 4
-51 21 14 255 255 255
-30 30 15 42 22 4
-52 21 14 255 255 255
-32 27 14 42 22 4
-53 21 14 102 51 51
-31 23 14 42 22 4
-54 21 14 102 51 51
-32 23 14 42 22 4
-55 21 14 102 51 51
-55 34 14 102 51 51
-58 33 20 102 51 51
-58 32 20 50 50 50
-58 31 20 102 51 51
-58 30 20 50 50 50
-58 29 20 102 51 51
-58 28 20 50 50 50
-58 27 20 50 50 50
-58 26 20 102 51 51
-58 25 20 50 50 50
-58 24 20 102 51 51
-58 23 20 50 50 50
-58 22 20 102 51 51
-33 34 12 102 51 51
-32 34 12 102 51 51
-40 33 15 255 255 255
-32 26 14 42 22 4
-31 24 14 42 22 4
-32 24 14 42 22 4
-31 25 14 42 22 4
-32 25 14 42 22 4
-42 33 15 255 255 255
-43 33 15 255 255 255
-29 21 16 102 51 51
-30 21 16 102 51 51
-28 30 15 42 22 4
-29 34 15 102 51 51
-30 34 15 102 51 51
-31 34 15 102 51 51
-29 33 15 42 22 4
-27 34 17 255 255 254
-31 30 14 42 22 4
-29 32 15 42 22 4
-27 33 17 255 255 254
-31 29 14 42 22 4
-29 31 15 42 22 4
-27 33 12 102 51 51
-31 28 14 42 22 4
-29 30 15 42 22 4
-28 21 15 102 51 51
-26 23 16 0 0 0
-29 29 15 42 22 4
-26 30 17 42 22 4
-53 32 17 42 22 4
-29 28 15 42 22 4
-26 29 17 50 50 50
-26 28 17 50 50 50
-29 27 15 42 22 4
-40 32 15 255 255 255
-26 27 17 50 50 50
-29 26 15 42 22 4
-41 32 15 153 0 153
-27 22 17 255 255 254
-20 27 18 42 22 4
-29 25 15 42 22 4
-42 32 15 255 255 255
-31 31 16 42 22 4
-43 32 15 153 0 153
-31 27 14 42 22 4
-29 23 15 42 22 4
-56 33 12 102 51 51
-31 26 14 42 22 4
-29 22 15 42 22 4
-56 32 12 102 51 51
-41 33 15 255 255 255
-29 21 15 102 51 51
-30 21 15 102 51 51
-26 26 15 42 22 4
-31 21 15 102 51 51
-30 25 15 42 22 4
-30 24 15 42 22 4
-25 22 17 102 51 51
-24 32 17 102 51 51
-24 23 17 102 51 51
-23 31 17 102 51 51
-23 30 17 0 204 0
-23 25 17 0 204 0
-23 24 17 102 51 51
-22 30 17 102 51 51
-22 29 17 255 102 0
-22 28 17 221 0 0
-22 25 15 102 51 51
-22 27 17 221 0 0
-22 26 17 255 102 0
-22 25 17 102 51 51
-21 29 17 102 51 51
-49 25 15 0 0 153
-20 28 17 102 51 51
-20 27 17 102 51 51
-19 28 17 42 22 4
-19 27 17 42 22 4
-26 34 16 102 51 51
-31 27 16 50 50 50
-25 33 15 102 51 51
-26 34 15 102 51 51
-26 25 15 42 22 4
-23 24 15 102 51 51
-26 24 15 42 22 4
-24 23 15 102 51 51
-26 23 15 42 22 4
-25 22 15 102 51 51
-26 22 15 42 22 4
-26 34 14 102 51 51
-25 33 14 102 51 51
-24 32 14 102 51 51
-23 31 14 102 51 51
-23 30 14 102 51 51
-33 21 15 102 51 51
-33 34 15 102 51 51
-34 21 15 102 51 51
-34 34 15 102 51 51
-35 21 15 102 51 51
-35 24 15 255 102 0
-35 25 15 255 102 0
-57 32 18 67 67 255
-35 34 15 102 51 51
-36 21 15 102 51 51
-36 24 15 221 0 0
-36 25 15 221 0 0
-26 31 15 42 22 4
-31 29 16 50 50 50
-36 34 15 102 51 51
-37 21 15 102 51 51
-37 24 15 221 0 0
-37 25 15 221 0 0
-37 28 15 221 0 0
-37 29 15 0 0 153
-57 21 21 102 51 51
-37 34 15 102 51 51
-38 21 15 102 51 51
-38 24 15 255 102 0
-38 25 15 255 102 0
-38 28 15 255 102 0
-57 21 20 102 51 51
-38 34 15 102 51 51
-57 21 19 102 51 51
-39 34 15 102 51 51
-57 34 15 102 51 51
-57 21 18 102 51 51
-40 34 15 102 51 51
-41 21 15 102 51 51
-41 24 15 255 102 0
-41 25 15 255 102 0
-41 28 15 255 102 0
-56 34 14 102 51 51
-57 21 17 102 51 51
-41 34 15 102 51 51
-42 21 15 102 51 51
-42 24 15 221 0 0
-42 25 15 221 0 0
-42 28 15 221 0 0
-42 29 15 0 0 153
-56 34 13 102 51 51
-57 21 16 102 51 51
-42 34 15 102 51 51
-43 21 15 102 51 51
-43 24 15 221 0 0
-43 25 15 221 0 0
-46 34 14 102 51 51
-43 29 15 0 0 153
-55 34 12 102 51 51
-57 21 15 102 51 51
-43 34 15 102 51 51
-44 21 15 102 51 51
-44 24 15 255 102 0
-44 25 15 255 102 0
-44 34 15 102 51 51
-45 21 15 102 51 51
-45 34 15 102 51 51
-46 21 15 102 51 51
-46 25 15 0 255 134
-46 26 15 0 255 133
-46 27 15 0 255 133
-46 28 15 0 255 133
-46 29 15 0 255 133
-46 30 15 0 255 135
-46 34 15 102 51 51
-47 21 15 102 51 51
-47 22 15 0 0 0
-47 23 15 0 0 0
-47 24 15 102 51 51
-47 31 15 102 51 51
-47 32 15 0 0 0
-47 33 15 0 0 0
-47 34 15 102 51 51
-48 21 15 102 51 51
-48 22 15 42 22 4
-48 23 15 42 22 4
-48 24 15 102 51 51
-48 30 15 67 67 255
-48 31 15 102 51 51
-48 32 15 42 22 4
-48 33 15 42 22 4
-48 34 15 102 51 51
-49 21 15 102 51 51
-49 24 15 102 51 51
-53 33 18 221 0 0
-49 30 15 0 0 153
-49 31 15 102 51 51
-49 34 15 102 51 51
-50 21 15 102 51 51
-50 25 15 102 51 51
-50 26 15 102 51 51
-50 27 15 102 51 51
-50 28 15 102 51 51
-50 29 15 102 51 51
-50 30 15 102 51 51
-50 34 15 102 51 51
-51 21 15 102 51 51
-51 34 15 102 51 51
-52 21 15 102 51 51
-52 34 15 102 51 51
-53 21 15 102 51 51
-53 34 15 102 51 51
-54 21 15 102 51 51
-54 34 15 102 51 51
-55 21 15 102 51 51
-55 34 15 102 51 51
-56 21 15 102 51 51
-56 34 15 102 51 51
-42 8 13 42 22 4
-48 8 13 42 22 4
-42 7 13 50 50 50
-48 7 13 50 50 50
-42 6 13 50 50 50
-48 6 13 50 50 50
-42 5 13 42 22 4
-48 5 13 42 22 4
-42 4 13 50 50 50
-48 4 13 50 50 50
-42 3 13 50 50 50
-48 3 13 50 50 50
-19 28 18 42 22 4
-22 29 14 102 51 51
-22 28 14 102 51 51
-28 29 15 42 22 4
-19 27 18 42 22 4
-22 27 14 102 51 51
-22 26 14 102 51 51
-28 28 15 42 22 4
-18 28 18 42 22 4
-23 25 14 102 51 51
-23 24 14 102 51 51
-28 27 15 42 22 4
-18 27 18 42 22 4
-24 23 14 102 51 51
-25 22 14 102 51 51
-28 26 15 42 22 4
-26 34 17 102 51 51
-26 27 16 42 22 4
-26 33 13 102 51 51
-28 25 15 42 22 4
-26 21 17 102 51 51
-25 32 13 102 51 51
-24 31 13 102 51 51
-28 24 15 42 22 4
-25 33 17 102 51 51
-24 30 13 102 51 51
-24 29 13 102 51 51
-28 23 15 42 22 4
-30 22 15 42 22 4
-24 28 13 102 51 51
-24 27 13 102 51 51
-28 22 15 42 22 4
-30 23 15 42 22 4
-24 26 13 102 51 51
-24 25 13 102 51 51
-28 34 14 102 51 51
-29 34 14 102 51 51
-30 34 14 102 51 51
-31 34 14 102 51 51
-28 34 13 102 51 51
-29 34 13 102 51 51
-30 34 13 102 51 51
-31 34 13 102 51 51
-28 34 12 102 51 51
-29 34 12 102 51 51
-30 34 12 102 51 51
-31 34 12 102 51 51
-31 28 16 50 50 50
-28 21 16 102 51 51
-28 34 16 102 51 51
-29 24 15 42 22 4
-23 31 15 102 51 51
-26 33 15 42 22 4
-24 32 15 102 51 51
-26 32 15 42 22 4
-31 30 16 50 50 50
-24 24 13 102 51 51
-25 23 13 102 51 51
-26 22 13 102 51 51
-26 24 16 0 0 0
-26 32 12 102 51 51
-26 31 12 102 51 51
-26 30 12 102 51 51
-26 29 12 102 51 51
-26 28 12 102 51 51
-26 27 12 102 51 51
-26 26 12 102 51 51
-26 25 12 102 51 51
-26 24 12 102 51 51
-26 23 12 102 51 51
-26 26 16 42 22 4
-21 28 17 102 51 51
-41 34 14 102 51 51
-57 34 21 102 51 51
-57 34 20 102 51 51
-57 34 19 102 51 51
-34 34 14 102 51 51
-33 34 14 102 51 51
-40 34 14 102 51 51
-39 34 14 102 51 51
-38 34 14 102 51 51
-54 34 13 102 51 51
-50 25 18 50 50 50
-50 26 18 50 50 50
-37 34 14 102 51 51
-47 21 16 102 51 51
-47 34 16 102 51 51
-48 21 16 102 51 51
-48 22 16 0 0 0
-48 23 16 0 0 0
-48 24 16 102 51 51
-48 31 16 102 51 51
-48 32 16 0 0 0
-48 33 16 0 0 0
-48 34 16 102 51 51
-49 21 16 102 51 51
-49 22 16 42 22 4
-49 23 16 42 22 4
-49 24 16 102 51 51
-49 31 16 102 51 51
-49 32 16 42 22 4
-49 33 16 42 22 4
-49 34 16 102 51 51
-50 21 16 102 51 51
-50 25 16 102 51 51
-50 26 16 102 51 51
-50 27 16 102 51 51
-50 28 16 102 51 51
-50 29 16 102 51 51
-50 30 16 102 51 51
-50 34 16 102 51 51
-51 21 16 102 51 51
-51 34 16 102 51 51
-52 21 16 102 51 51
-52 34 16 102 51 51
-53 21 16 102 51 51
-53 34 16 102 51 51
-54 21 16 102 51 51
-54 34 16 102 51 51
-55 21 16 102 51 51
-55 34 16 102 51 51
-56 21 16 102 51 51
-56 34 16 102 51 51
-42 2 13 42 22 4
-48 2 13 42 22 4
-33 19 12 42 22 4
-34 19 12 42 22 4
-35 19 12 42 22 4
-36 19 12 42 22 4
-37 19 12 42 22 4
-38 19 12 42 22 4
-39 19 12 42 22 4
-40 19 12 42 22 4
-41 19 12 42 22 4
-42 19 12 42 22 4
-26 21 16 102 51 51
-25 33 16 102 51 51
-33 21 16 255 255 254
-33 34 16 255 255 254
-30 29 16 255 102 0
-30 28 16 221 0 0
-30 27 16 221 0 0
-30 26 16 255 102 0
-30 29 15 255 227 49
-30 28 15 255 227 49
-30 27 15 255 227 49
-30 26 15 255 227 49
-25 22 16 102 51 51
-24 32 16 102 51 51
-32 23 15 0 0 0
-24 30 16 42 22 4
-24 29 16 42 22 4
-24 28 16 42 22 4
-24 27 16 42 22 4
-24 26 16 42 22 4
-24 25 16 42 22 4
-24 24 16 42 22 4
-24 23 16 102 51 51
-23 31 16 102 51 51
-23 30 16 42 22 4
-23 29 16 42 22 4
-23 28 16 42 22 4
-53 34 13 102 51 51
-53 26 18 255 102 0
-36 34 14 102 51 51
-57 34 18 102 51 51
-57 34 17 102 51 51
-57 34 16 102 51 51
-48 34 14 102 51 51
-48 21 17 102 51 51
-48 34 17 102 51 51
-49 21 17 102 51 51
-49 22 17 0 0 0
-49 23 17 0 0 0
-49 24 17 102 51 51
-49 25 17 102 51 51
-49 26 17 102 51 51
-49 27 17 102 51 51
-49 28 17 102 51 51
-49 29 17 102 51 51
-48 29 17 102 51 51
-49 31 17 102 51 51
-49 32 17 0 0 0
-49 33 17 0 0 0
-49 34 17 102 51 51
-50 21 17 102 51 51
-50 22 17 255 227 49
-50 23 17 255 227 49
-50 24 17 42 22 4
-50 25 17 42 22 4
-50 26 17 42 22 4
-50 27 17 42 22 4
-50 28 17 42 22 4
-50 29 17 42 22 4
-50 30 17 42 22 4
-50 31 17 42 22 4
-50 32 17 255 227 49
-50 33 17 255 227 49
-50 34 17 102 51 51
-51 21 17 102 51 51
-51 22 17 42 22 4
-51 23 17 42 22 4
-51 24 17 42 22 4
-51 25 17 42 22 4
-51 26 17 42 22 4
-51 27 17 42 22 4
-51 28 17 42 22 4
-51 29 17 42 22 4
-51 30 17 42 22 4
-51 31 17 42 22 4
-51 32 17 42 22 4
-51 33 17 42 22 4
-51 34 17 102 51 51
-52 21 17 102 51 51
-52 22 17 42 22 4
-52 23 17 42 22 4
-52 24 17 42 22 4
-52 25 17 42 22 4
-52 26 17 42 22 4
-52 27 17 42 22 4
-52 28 17 42 22 4
-52 29 17 42 22 4
-52 30 17 42 22 4
-37 33 16 255 255 255
-38 33 16 255 255 255
-48 28 17 102 51 51
-52 34 17 102 51 51
-53 21 17 102 51 51
-53 22 17 42 22 4
-53 23 17 42 22 4
-53 24 17 42 22 4
-53 25 17 42 22 4
-53 26 17 255 227 48
-53 27 17 255 227 48
-53 28 17 255 227 48
-53 29 17 255 227 48
-53 30 17 42 22 4
-39 33 16 255 255 255
-37 33 15 255 255 255
-48 27 17 102 51 51
-53 34 17 102 51 51
-54 21 17 102 51 51
-54 22 17 42 22 4
-54 23 17 42 22 4
-54 24 17 42 22 4
-54 25 17 42 22 4
-54 26 17 255 227 48
-54 27 17 255 227 48
-54 28 17 255 227 48
-54 29 17 255 227 48
-54 30 17 42 22 4
-38 33 15 255 255 255
-39 33 15 153 51 205
-48 26 17 102 51 51
-54 34 17 102 51 51
-55 21 17 102 51 51
-55 22 17 42 22 4
-55 23 17 42 22 4
-55 24 17 42 22 4
-55 25 17 42 22 4
-55 26 17 42 22 4
-55 27 17 42 22 4
-55 28 17 42 22 4
-55 29 17 42 22 4
-55 30 17 42 22 4
-57 23 18 0 0 153
-48 30 17 102 51 51
-27 33 16 0 204 0
-55 34 17 102 51 51
-56 21 17 102 51 51
-56 22 17 42 22 4
-56 23 17 42 22 4
-56 24 17 42 22 4
-56 25 17 42 22 4
-56 26 17 42 22 4
-56 27 17 42 22 4
-56 28 17 42 22 4
-56 29 17 42 22 4
-56 30 17 42 22 4
-56 31 17 42 22 4
-56 32 17 42 22 4
-56 33 17 42 22 4
-56 34 17 102 51 51
-43 19 12 42 22 4
-44 19 12 42 22 4
-45 19 12 42 22 4
-46 19 12 42 22 4
-47 19 12 42 22 4
-33 18 12 42 22 4
-34 18 12 42 22 4
-35 18 12 42 22 4
-36 18 12 42 22 4
-37 18 12 42 22 4
-38 18 12 42 22 4
-39 18 12 255 227 49
-23 27 16 42 22 4
-53 21 18 102 51 51
-52 34 18 102 51 51
-49 30 17 102 51 51
-23 26 16 42 22 4
-52 21 18 102 51 51
-52 34 13 102 51 51
-23 25 16 42 22 4
-35 34 14 102 51 51
-23 24 16 102 51 51
-22 30 16 102 51 51
-47 34 14 102 51 51
-22 29 16 255 227 48
-49 21 18 102 51 51
-49 34 18 102 51 51
-50 21 18 102 51 51
-50 28 18 255 0 255
-50 34 14 102 51 51
-51 34 14 102 51 51
-54 34 14 102 51 51
-49 34 14 102 51 51
-53 34 14 102 51 51
-52 34 14 102 51 51
-50 27 18 50 50 50
-50 34 18 102 51 51
-51 21 18 102 51 51
-51 34 18 102 51 51
-27 24 15 255 227 49
-27 23 15 255 227 49
-27 25 15 42 22 4
-27 22 15 42 22 4
-27 26 15 42 22 4
-27 27 15 42 22 4
-27 28 15 42 22 4
-27 29 15 42 22 4
-27 30 15 42 22 4
-27 31 15 255 227 49
-27 32 15 255 227 49
-27 33 15 42 22 4
-27 34 16 102 51 51
-27 34 15 102 51 51
-27 34 14 102 51 51
-27 34 13 102 51 51
-27 22 12 102 51 51
-27 21 15 102 51 51
-27 21 14 102 51 51
-27 21 16 102 51 51
-27 21 13 102 51 51
-26 25 16 42 22 4
-15 28 20 42 22 4
-15 27 20 42 22 4
-14 28 20 42 22 4
-14 27 20 42 22 4
-13 28 20 42 22 4
-13 27 20 42 22 4
-18 28 19 42 22 4
-18 27 19 42 22 4
-17 28 19 42 22 4
-17 27 19 42 22 4
-16 28 19 42 22 4
-16 27 19 42 22 4
-15 28 19 42 22 4
-15 27 19 42 22 4
-26 28 16 42 22 4
-26 21 14 102 51 51
-26 21 15 102 51 51
-20 27 16 102 51 51
-20 28 16 102 51 51
-21 26 16 102 51 51
-57 33 18 0 0 153
-56 33 18 0 0 153
-33 19 14 0 0 153
-48 2 12 42 22 4
-47 2 12 42 22 4
-46 2 12 42 22 4
-45 2 12 42 22 4
-44 2 12 42 22 4
-43 2 12 42 22 4
-42 2 12 42 22 4
-48 3 12 42 22 4
-47 3 12 42 22 4
-46 3 12 42 22 4
-45 3 12 42 22 4
-44 3 12 42 22 4
-43 3 12 42 22 4
-42 3 12 42 22 4
-48 4 12 42 22 4
-47 4 12 42 22 4
-46 4 12 42 22 4
-45 4 12 42 22 4
-44 4 12 42 22 4
-43 4 12 42 22 4
-42 4 12 42 22 4
-48 5 12 42 22 4
-47 5 12 42 22 4
-46 5 12 42 22 4
-45 5 12 42 22 4
-44 5 12 42 22 4
-43 5 12 42 22 4
-42 5 12 42 22 4
-48 6 12 42 22 4
-47 6 12 42 22 4
-46 6 12 42 22 4
-45 6 12 42 22 4
-44 6 12 42 22 4
-43 6 12 42 22 4
-42 6 12 42 22 4
-48 7 12 42 22 4
-47 7 12 42 22 4
-46 7 12 42 22 4
-45 7 12 42 22 4
-44 7 12 42 22 4
-43 7 12 42 22 4
-42 7 12 42 22 4
-48 8 12 42 22 4
-47 8 12 42 22 4
-46 8 12 42 22 4
-45 8 12 42 22 4
-44 8 12 42 22 4
-43 8 12 42 22 4
-42 8 12 42 22 4
-48 9 12 42 22 4
-47 9 12 42 22 4
-46 9 12 42 22 4
-45 9 12 42 22 4
-44 9 12 42 22 4
-43 9 12 42 22 4
-42 9 12 42 22 4
-48 10 12 42 22 4
-47 10 12 42 22 4
-46 10 12 42 22 4
-45 10 12 42 22 4
-44 10 12 42 22 4
-43 10 12 42 22 4
-42 10 12 42 22 4
-48 11 12 42 22 4
-47 11 12 42 22 4
-46 11 12 42 22 4
-45 11 12 42 22 4
-44 11 12 42 22 4
-43 11 12 42 22 4
-42 11 12 42 22 4
-48 12 12 42 22 4
-47 12 12 42 22 4
-46 12 12 42 22 4
-45 12 12 42 22 4
-44 12 12 42 22 4
-43 12 12 42 22 4
-42 12 12 42 22 4
-48 13 12 42 22 4
-47 13 12 42 22 4
-46 13 12 42 22 4
-45 13 12 42 22 4
-44 13 12 42 22 4
-43 13 12 42 22 4
-42 13 12 42 22 4
-48 14 12 42 22 4
-47 14 12 42 22 4
-46 14 12 42 22 4
-45 14 12 42 22 4
-44 14 12 42 22 4
-43 14 12 42 22 4
-42 14 12 42 22 4
-48 15 12 42 22 4
-47 15 12 42 22 4
-46 15 12 42 22 4
-45 15 12 42 22 4
-44 15 12 42 22 4
-43 15 12 42 22 4
-42 15 12 42 22 4
-41 15 12 42 22 4
-40 15 12 42 22 4
-39 15 12 42 22 4
-38 15 12 42 22 4
-46 19 13 50 50 50
-36 15 12 42 22 4
-35 15 12 42 22 4
-34 15 12 42 22 4
-33 15 12 42 22 4
-48 16 12 42 22 4
-47 16 12 42 22 4
-46 16 12 42 22 4
-45 16 12 255 227 49
-44 16 12 255 227 49
-43 16 12 255 227 49
-42 16 12 255 227 49
-41 16 12 255 227 49
-40 16 12 255 227 49
-39 16 12 255 227 49
-38 16 12 42 22 4
-37 16 12 42 22 4
-36 16 12 42 22 4
-35 16 12 42 22 4
-34 16 12 42 22 4
-33 16 12 42 22 4
-48 17 12 42 22 4
-47 17 12 42 22 4
-46 17 12 42 22 4
-45 17 12 255 227 49
-44 17 12 255 227 49
-43 17 12 255 227 49
-42 17 12 255 227 49
-41 17 12 255 227 49
-40 17 12 255 227 49
-39 17 12 255 227 49
-38 17 12 42 22 4
-37 17 12 42 22 4
-36 17 12 42 22 4
-35 17 12 42 22 4
-34 17 12 42 22 4
-33 17 12 42 22 4
-40 20 15 255 255 254
-47 18 12 42 22 4
-46 18 12 42 22 4
-45 18 12 42 22 4
-44 18 12 42 22 4
-43 18 12 42 22 4
-42 18 12 42 22 4
-41 18 12 42 22 4
-40 18 12 255 227 49
-58 22 15 102 51 51
-58 23 15 102 51 51
-58 24 15 102 51 51
-58 25 15 102 51 51
-58 26 15 102 51 51
-58 27 15 102 51 51
-58 28 15 102 51 51
-58 29 15 102 51 51
-58 30 15 102 51 51
-58 31 15 102 51 51
-58 32 15 102 51 51
-58 33 15 102 51 51
-58 22 16 102 51 51
-58 23 16 102 51 51
-58 24 16 102 51 51
-58 25 16 102 51 51
-58 26 16 102 51 51
-58 27 16 102 51 51
-58 28 16 102 51 51
-58 29 16 102 51 51
-58 30 16 102 51 51
-58 31 16 102 51 51
-58 32 16 102 51 51
-58 33 16 102 51 51
-58 22 17 102 51 51
-58 23 17 102 51 51
-58 24 17 102 51 51
-58 25 17 102 51 51
-58 26 17 102 51 51
-58 27 17 102 51 51
-58 28 17 102 51 51
-58 29 17 102 51 51
-58 30 17 102 51 51
-58 31 17 102 51 51
-58 32 17 102 51 51
-58 33 17 102 51 51
-58 33 21 102 51 51
-58 23 18 102 51 51
-58 24 18 102 51 51
-58 25 18 102 51 51
-58 26 18 102 51 51
-58 27 18 102 51 51
-58 28 18 102 51 51
-58 29 18 102 51 51
-58 30 18 102 51 51
-58 31 18 102 51 51
-58 32 18 102 51 51
-58 33 18 102 51 51
-58 22 19 102 51 51
-58 23 19 50 50 50
-58 24 19 102 51 51
-58 25 19 50 50 50
-58 26 19 102 51 51
-58 27 19 50 50 50
-58 28 19 50 50 50
-58 29 19 102 51 51
-58 30 19 50 50 50
-58 31 19 102 51 51
-58 32 19 50 50 50
-58 33 19 102 51 51
-57 22 13 102 51 51
-57 23 13 102 51 51
-57 24 13 102 51 51
-57 25 13 102 51 51
-57 26 13 102 51 51
-57 27 13 102 51 51
-57 28 13 102 51 51
-57 29 13 102 51 51
-57 30 13 102 51 51
-57 31 13 102 51 51
-57 32 13 102 51 51
-57 33 13 102 51 51
-56 22 12 102 51 51
-56 23 12 102 51 51
-56 24 12 102 51 51
-56 25 12 102 51 51
-56 26 12 102 51 51
-56 27 12 102 51 51
-56 28 12 102 51 51
-56 29 12 102 51 51
-56 30 12 102 51 51
-56 31 12 102 51 51
-31 22 15 255 227 49
-31 23 15 255 227 49
-31 24 15 42 22 4
-31 25 15 42 22 4
-31 26 15 42 22 4
-31 27 15 42 22 4
-31 28 15 42 22 4
-31 29 15 42 22 4
-31 30 15 42 22 4
-31 31 15 42 22 4
-31 32 15 255 227 49
-31 33 15 255 227 49
-31 24 16 42 22 4
-31 25 16 50 50 50
-31 26 16 50 50 50
-55 32 17 42 22 4
-54 32 17 42 22 4
-52 33 18 255 102 0
-52 32 17 42 22 4
-55 33 17 255 227 48
-54 33 17 255 227 48
-53 33 17 255 227 48
-52 33 17 255 227 48
-55 33 18 255 102 0
-54 33 18 221 0 0
-33 27 15 0 204 0
-48 25 17 102 51 51
-36 29 15 67 67 255
-48 26 15 0 0 153
-49 26 15 0 0 153
-49 27 15 0 0 153
-49 28 15 0 0 153
-43 18 13 0 204 0
-45 18 13 0 204 0
