ply
format ascii 1.0
comment : MagicaVoxel @ Ephtracy
element vertex 1310
property float x
property float y
property float z
property uchar red
property uchar green
property uchar blue
end_header
-44 18 13 67 67 255
-32 34 14 102 51 51
-50 30 18 50 50 50
-45 34 14 102 51 51
-43 28 15 67 67 255
-57 33 21 102 51 51
-57 32 21 102 51 51
-57 31 21 102 51 51
-57 30 21 102 51 51
-57 29 21 102 51 51
-57 28 21 102 51 51
-57 27 21 102 51 51
-57 26 21 102 51 51
-57 25 21 102 51 51
-57 24 21 102 51 51
-57 23 21 102 51 51
-57 22 21 102 51 51
-56 34 21 102 51 51
-38 18 13 102 51 51
-46 18 12 42 22 4
-56 21 21 102 51 51
-55 34 21 102 51 51
-55 21 21 102 51 51
-50 29 18 50 50 50
-44 34 14 102 51 51
-51 34 13 102 51 51
-57 33 20 102 51 51
-57 32 20 50 50 50
-57 31 20 102 51 51
-57 30 20 50 50 50
-57 29 20 102 51 51
-57 28 20 50 50 50
-57 27 20 50 50 50
-57 26 20 102 51 51
-57 25 20 50 50 50
-57 24 20 102 51 51
-57 23 20 50 50 50
-57 22 20 102 51 51
-56 34 20 102 51 51
-56 21 20 102 51 51
-55 34 20 102 51 51
-55 21 20 102 51 51
-50 34 13 102 51 51
-49 34 13 102 51 51
-48 34 13 102 51 51
-47 34 13 102 51 51
-46 34 13 102 51 51
-45 34 13 102 51 51
-44 34 13 102 51 51
-43 34 13 102 51 51
-42 34 13 102 51 51
-41 34 13 102 51 51
-40 34 13 102 51 51
-39 34 13 102 51 51
-54 34 20 102 51 51
-54 21 20 102 51 51
-53 34 20 102 51 51
-28 21 12 102 51 51
-14 18 13 102 51 51
-53 21 20 102 51 51
-52 34 20 102 51 51
-52 21 20 102 51 51
-29 21 12 102 51 51
-14 15 13 102 51 51
-51 34 20 102 51 51
-41 18 13 102 51 51
-30 18 13 50 50 50
-30 21 12 102 51 51
-15 15 13 50 50 50
-51 21 20 102 51 51
-50 34 20 102 51 51
-50 21 20 102 51 51
-31 21 12 102 51 51
-16 15 13 50 50 50
-50 24 18 42 22 4
-43 34 14 102 51 51
-38 34 13 102 51 51
-32 21 12 102 51 51
-15 18 13 50 50 50
-28 34 15 102 51 51
-32 34 15 102 51 51
-31 21 14 255 255 255
-33 21 12 102 51 51
-16 18 13 50 50 50
-32 21 14 255 255 255
-28 33 15 42 22 4
-32 21 15 102 51 51
-34 21 12 102 51 51
-14 18 12 42 22 4
-57 33 19 102 51 51
-57 32 19 50 50 50
-57 31 19 102 51 51
-35 21 12 102 51 51
-14 17 12 42 22 4
-57 30 19 50 50 50
-57 29 19 102 51 51
-57 28 19 50 50 50
-36 21 12 102 51 51
-14 16 12 42 22 4
-57 27 19 50 50 50
-57 26 19 102 51 51
-57 25 19 50 50 50
-37 21 12 102 51 51
-14 15 12 42 22 4
-57 24 19 102 51 51
-57 23 19 50 50 50
-57 22 19 102 51 51
-38 21 12 102 51 51
-15 18 12 42 22 4
-56 34 19 102 51 51
-56 33 19 0 0 153
-56 28 19 255 255 255
-39 21 12 102 51 51
-15 17 12 42 22 4
-56 27 19 255 255 255
-56 21 19 102 51 51
-55 34 19 50 50 50
-40 21 12 102 51 51
-15 16 12 42 22 4
-55 21 19 50 50 50
-54 34 19 50 50 50
-54 21 19 50 50 50
-41 21 12 102 51 51
-15 15 12 42 22 4
-53 34 19 50 50 50
-53 21 19 50 50 50
-52 34 19 50 50 50
-42 21 12 102 51 51
-16 15 12 42 22 4
-43 21 12 102 51 51
-16 16 12 42 22 4
-44 21 12 102 51 51
-16 17 12 42 22 4
-45 21 12 102 51 51
-16 18 12 42 22 4
-46 21 12 102 51 51
-46 16 13 0 0 153
-47 21 12 102 51 51
-46 17 13 67 67 255
-48 21 12 102 51 51
-17 16 12 42 22 4
-49 21 12 102 51 51
-18 16 12 42 22 4
-50 21 12 102 51 51
-19 16 12 42 22 4
-51 21 12 102 51 51
-46 16 12 42 22 4
-52 21 12 102 51 51
-20 16 12 42 22 4
-53 21 12 102 51 51
-45 16 12 42 22 4
-54 21 12 102 51 51
-21 16 12 42 22 4
-55 22 12 102 51 51
-55 23 12 102 51 51
-55 24 12 102 51 51
-55 25 12 102 51 51
-55 26 12 102 51 51
-55 27 12 102 51 51
-55 28 12 102 51 51
-55 29 12 102 51 51
-55 30 12 102 51 51
-55 31 12 102 51 51
-55 32 12 102 51 51
-55 33 12 102 51 51
-52 21 19 50 50 50
-51 34 19 50 50 50
-51 21 19 50 50 50
-50 34 19 102 51 51
-50 21 19 102 51 51
-50 31 18 42 22 4
-42 34 14 102 51 51
-29 18 13 102 51 51
-37 34 13 102 51 51
-37 18 13 50 50 50
-31 21 13 0 225 255
-32 21 13 255 255 255
-28 32 15 42 22 4
-21 27 17 102 51 51
-26 28 15 42 22 4
-21 27 15 102 51 51
-28 31 15 42 22 4
-20 28 18 42 22 4
-57 33 18 102 51 51
-57 32 18 102 51 51
-57 31 18 102 51 51
-57 30 18 102 51 51
-57 29 18 102 51 51
-57 28 18 102 51 51
-36 34 13 102 51 51
-35 34 13 102 51 51
-34 34 13 102 51 51
-33 34 13 102 51 51
-32 34 13 102 51 51
-54 34 12 102 51 51
-53 34 12 102 51 51
-52 34 12 102 51 51
-57 27 18 102 51 51
-57 26 18 102 51 51
-51 34 12 102 51 51
-50 34 12 102 51 51
-57 25 18 102 51 51
-57 24 18 102 51 51
-26 27 15 42 22 4
-49 34 12 102 51 51
-48 34 12 102 51 51
-47 34 12 102 51 51
-57 23 18 102 51 51
-57 22 18 102 51 51
-28 21 13 102 51 51
-44 16 12 42 22 4
-56 34 18 102 51 51
-56 33 18 0 0 153
-29 21 13 102 51 51
-22 16 12 42 22 4
-56 32 18 67 67 255
-56 29 18 0 204 0
-29 34 16 102 51 51
-43 16 12 42 22 4
-56 28 18 255 255 255
-56 27 18 0 255 205
-22 30 15 102 51 51
-23 16 12 42 22 4
-56 26 18 0 204 0
-56 21 18 102 51 51
-26 29 15 42 22 4
-42 16 12 42 22 4
-55 34 18 102 51 51
-55 33 18 0 0 153
-33 21 13 102 51 51
-24 16 12 42 22 4
-55 32 18 255 102 0
-28 18 13 50 50 50
-34 21 13 102 51 51
-41 16 12 42 22 4
-55 21 18 102 51 51
-54 34 18 102 51 51
-35 21 13 0 225 255
-25 16 12 42 22 4
-54 32 18 221 0 0
-54 29 18 255 102 0
-36 21 13 255 255 255
-40 16 12 42 22 4
-54 28 18 221 0 0
-54 27 18 221 0 0
-37 21 13 102 51 51
-26 16 12 42 22 4
-54 26 18 255 102 0
-27 18 13 50 50 50
-38 19 13 42 22 4
-38 21 13 102 51 51
-39 16 12 42 22 4
-54 21 18 102 51 51
-39 19 13 0 0 0
-39 20 13 42 22 4
-39 21 13 102 51 51
-27 16 12 42 22 4
-53 34 18 102 51 51
-40 19 13 0 0 0
-40 20 13 42 22 4
-40 21 13 102 51 51
-38 16 12 42 22 4
-53 32 18 221 0 0
-53 29 18 255 102 0
-41 19 13 42 22 4
-41 21 13 102 51 51
-28 16 12 42 22 4
-53 28 18 221 0 0
-53 27 18 221 0 0
-42 21 13 102 51 51
-37 16 12 42 22 4
-43 21 13 0 225 255
-29 16 12 42 22 4
-44 21 13 255 255 255
-36 16 12 42 22 4
-45 21 13 102 51 51
-30 16 12 42 22 4
-46 21 13 102 51 51
-35 16 12 42 22 4
-47 21 13 0 225 255
-31 16 12 42 22 4
-48 21 13 255 255 255
-34 16 12 42 22 4
-49 21 13 102 51 51
-32 16 12 42 22 4
-50 21 13 102 51 51
-33 16 12 42 22 4
-51 21 13 0 225 255
-25 15 13 50 50 50
-52 21 13 255 255 255
-24 15 13 50 50 50
-53 21 13 102 51 51
-23 15 13 102 51 51
-54 21 13 102 51 51
-22 15 13 50 50 50
-55 21 13 102 51 51
-55 34 13 102 51 51
-56 22 13 102 51 51
-56 23 13 102 51 51
-56 24 13 102 51 51
-56 25 13 102 51 51
-56 26 13 102 51 51
-56 27 13 102 51 51
-56 28 13 102 51 51
-56 29 13 102 51 51
-56 30 13 102 51 51
-56 31 13 102 51 51
-56 32 13 102 51 51
-56 33 13 102 51 51
-46 34 12 102 51 51
-45 34 12 102 51 51
-44 34 12 102 51 51
-43 34 12 102 51 51
-42 34 12 102 51 51
-41 34 12 102 51 51
-40 34 12 102 51 51
-39 34 12 102 51 51
-38 34 12 102 51 51
-37 34 12 102 51 51
-36 34 12 102 51 51
-35 34 12 102 51 51
-22 26 15 102 51 51
-34 34 12 102 51 51
-28 21 14 102 51 51
-21 15 13 50 50 50
-29 21 14 102 51 51
-20 15 13 102 51 51
-26 30 15 42 22 4
-19 15 13 50 50 50
-22 29 15 102 51 51
-18 15 13 50 50 50
-21 28 15 102 51 51
-34 28 15 255 145 237
-30 34 16 102 51 51
-30 31 16 42 22 4
-29 30 16 255 102 0
-30 30 16 50 50 50
-29 29 16 221 0 0
-30 29 16 50 50 50
-30 28 16 50 50 50
-30 27 16 50 50 50
-29 26 16 221 0 0
-30 26 16 50 50 50
-29 25 16 255 102 0
-17 15 13 102 51 51
-33 21 14 102 51 51
-33 22 14 42 22 4
-33 23 14 42 22 4
-33 24 14 42 22 4
-33 25 14 42 22 4
-33 26 14 42 22 4
-33 27 14 42 22 4
-33 28 14 42 22 4
-33 29 14 42 22 4
-33 30 14 42 22 4
-33 31 14 42 22 4
-33 32 14 42 22 4
-33 33 14 42 22 4
-25 15 12 42 22 4
-34 21 14 102 51 51
-34 22 14 42 22 4
-34 23 14 42 22 4
-34 24 14 42 22 4
-34 25 14 42 22 4
-34 26 14 42 22 4
-34 27 14 42 22 4
-34 28 14 42 22 4
-34 29 14 42 22 4
-34 30 14 42 22 4
-34 31 14 42 22 4
-34 32 14 42 22 4
-34 33 14 42 22 4
-24 15 12 42 22 4
-35 21 14 255 255 255
-35 22 14 42 22 4
-35 23 14 42 22 4
-35 24 14 42 22 4
-35 25 14 42 22 4
-35 26 14 42 22 4
-35 27 14 42 22 4
-35 28 14 42 22 4
-35 29 14 42 22 4
-35 30 14 42 22 4
-35 31 14 42 22 4
-35 32 14 42 22 4
-35 33 14 42 22 4
-23 15 12 42 22 4
-36 21 14 255 255 255
-36 22 14 42 22 4
-36 23 14 42 22 4
-36 24 14 42 22 4
-36 25 14 42 22 4
-36 26 14 42 22 4
-36 27 14 42 22 4
-36 28 14 42 22 4
-36 29 14 42 22 4
-36 30 14 42 22 4
-36 31 14 42 22 4
-36 32 14 42 22 4
-36 33 14 42 22 4
-22 15 12 42 22 4
-37 21 14 102 51 51
-37 22 14 42 22 4
-37 23 14 42 22 4
-37 24 14 42 22 4
-37 25 14 42 22 4
-37 26 14 42 22 4
-37 27 14 42 22 4
-37 28 14 42 22 4
-37 29 14 42 22 4
-37 30 14 42 22 4
-37 31 14 42 22 4
-37 32 14 42 22 4
-37 33 14 42 22 4
-21 15 12 42 22 4
-38 20 14 42 22 4
-38 21 14 102 51 51
-38 22 14 42 22 4
-38 23 14 42 22 4
-38 24 14 42 22 4
-38 25 14 42 22 4
-38 26 14 42 22 4
-38 27 14 42 22 4
-38 28 14 42 22 4
-38 29 14 42 22 4
-38 30 14 42 22 4
-38 31 14 42 22 4
-38 32 14 42 22 4
-38 33 14 42 22 4
-20 15 12 42 22 4
-39 20 14 0 0 0
-39 21 14 42 22 4
-39 22 14 42 22 4
-39 23 14 42 22 4
-39 24 14 42 22 4
-39 25 14 42 22 4
-39 26 14 42 22 4
-39 27 14 42 22 4
-39 28 14 42 22 4
-39 29 14 42 22 4
-39 30 14 42 22 4
-39 31 14 42 22 4
-39 32 14 42 22 4
-39 33 14 42 22 4
-19 15 12 42 22 4
-40 20 14 0 0 0
-40 21 14 42 22 4
-40 22 14 42 22 4
-40 23 14 42 22 4
-40 24 14 42 22 4
-40 25 14 42 22 4
-40 26 14 42 22 4
-40 27 14 42 22 4
-40 28 14 42 22 4
-40 29 14 42 22 4
-40 30 14 42 22 4
-40 31 14 42 22 4
-40 32 14 42 22 4
-40 33 14 42 22 4
-18 15 12 42 22 4
-41 20 14 42 22 4
-41 21 14 102 51 51
-41 22 14 42 22 4
-41 23 14 42 22 4
-41 24 14 42 22 4
-41 25 14 42 22 4
-41 26 14 42 22 4
-41 27 14 42 22 4
-41 28 14 42 22 4
-41 29 14 42 22 4
-41 30 14 42 22 4
-41 31 14 42 22 4
-41 32 14 42 22 4
-41 33 14 42 22 4
-17 15 12 42 22 4
-42 21 14 102 51 51
-42 22 14 42 22 4
-42 23 14 42 22 4
-42 24 14 42 22 4
-42 25 14 42 22 4
-42 26 14 42 22 4
-42 27 14 42 22 4
-42 28 14 42 22 4
-42 29 14 42 22 4
-42 30 14 42 22 4
-42 31 14 42 22 4
-42 32 14 42 22 4
-42 33 14 42 22 4
-31 15 13 50 50 50
-43 21 14 255 255 255
-43 22 14 42 22 4
-43 23 14 42 22 4
-43 24 14 42 22 4
-43 25 14 42 22 4
-43 26 14 42 22 4
-43 27 14 42 22 4
-43 28 14 42 22 4
-43 29 14 42 22 4
-43 30 14 42 22 4
-43 31 14 42 22 4
-43 32 14 42 22 4
-43 33 14 42 22 4
-30 15 13 50 50 50
-44 21 14 255 255 255
-44 22 14 42 22 4
-44 23 14 42 22 4
-44 24 14 42 22 4
-44 25 14 42 22 4
-44 26 14 42 22 4
-44 27 14 42 22 4
-44 28 14 42 22 4
-44 29 14 42 22 4
-44 30 14 42 22 4
-44 31 14 42 22 4
-44 32 14 42 22 4
-44 33 14 42 22 4
-29 15 13 102 51 51
-45 21 14 102 51 51
-45 22 14 42 22 4
-45 23 14 42 22 4
-45 24 14 42 22 4
-45 25 14 42 22 4
-45 26 14 42 22 4
-45 27 14 42 22 4
-45 28 14 42 22 4
-45 29 14 42 22 4
-45 30 14 42 22 4
-45 31 14 42 22 4
-45 32 14 42 22 4
-45 33 14 42 22 4
-28 15 13 50 50 50
-46 21 14 102 51 51
-46 22 14 42 22 4
-46 23 14 42 22 4
-46 24 14 42 22 4
-46 25 14 42 22 4
-46 26 14 42 22 4
-46 27 14 42 22 4
-46 28 14 42 22 4
-46 29 14 42 22 4
-46 30 14 42 22 4
-46 31 14 42 22 4
-46 32 14 42 22 4
-46 33 14 42 22 4
-27 15 13 50 50 50
-47 21 14 255 255 255
-47 25 14 42 22 4
-47 26 14 42 22 4
-47 27 14 42 22 4
-47 28 14 42 22 4
-47 29 14 42 22 4
-47 30 14 42 22 4
-26 15 13 102 51 51
-48 21 14 255 255 255
-48 25 14 42 22 4
-48 26 14 42 22 4
-48 27 14 42 22 4
-48 28 14 42 22 4
-48 29 14 42 22 4
-48 30 14 42 22 4
-32 15 13 102 51 51
-49 21 14 102 51 51
-49 25 14 42 22 4
-49 26 14 42 22 4
-49 27 14 42 22 4
-49 28 14 42 22 4
-49 29 14 42 22 4
-49 30 14 42 22 4
-33 15 13 50 50 50
-50 21 14 102 51 51
-34 15 13 50 50 50
-51 21 14 255 255 255
-35 15 13 102 51 51
-52 21 14 255 255 255
-44 15 13 102 51 51
-53 21 14 102 51 51
-44 15 12 42 22 4
-54 21 14 102 51 51
-43 15 12 42 22 4
-55 21 14 102 51 51
-55 34 14 102 51 51
-56 22 14 102 51 51
-56 23 14 102 51 51
-56 24 14 102 51 51
-56 25 14 102 51 51
-56 26 14 102 51 51
-56 27 14 102 51 51
-56 28 14 102 51 51
-56 29 14 102 51 51
-56 30 14 102 51 51
-56 31 14 102 51 51
-56 32 14 102 51 51
-56 33 14 102 51 51
-33 34 12 102 51 51
-32 34 12 102 51 51
-42 15 12 42 22 4
-41 15 12 42 22 4
-40 15 12 42 22 4
-39 15 12 42 22 4
-38 15 12 42 22 4
-37 15 12 42 22 4
-36 15 12 42 22 4
-35 15 12 42 22 4
-34 15 12 42 22 4
-33 15 12 42 22 4
-28 30 15 42 22 4
-32 15 12 42 22 4
-31 15 12 42 22 4
-30 15 12 42 22 4
-29 15 12 42 22 4
-28 15 12 42 22 4
-27 15 12 42 22 4
-26 15 12 42 22 4
-36 15 13 50 50 50
-45 15 12 42 22 4
-46 15 13 0 0 153
-45 15 13 0 0 153
-43 15 13 67 67 255
-40 15 13 50 50 50
-28 21 15 102 51 51
-39 15 13 50 50 50
-46 15 14 0 0 153
-38 15 13 102 51 51
-41 15 13 102 51 51
-42 15 13 50 50 50
-37 15 13 50 50 50
-46 15 12 42 22 4
-40 18 12 42 22 4
-40 17 12 42 22 4
-41 17 12 42 22 4
-39 18 12 42 22 4
-39 17 12 42 22 4
-41 18 12 42 22 4
-20 27 18 42 22 4
-38 18 12 42 22 4
-38 17 12 42 22 4
-42 17 12 42 22 4
-37 18 12 42 22 4
-37 17 12 42 22 4
-42 18 12 42 22 4
-36 18 12 42 22 4
-36 17 12 42 22 4
-43 17 12 42 22 4
-35 18 12 42 22 4
-35 17 12 42 22 4
-43 18 12 42 22 4
-34 18 12 42 22 4
-26 26 15 42 22 4
-34 17 12 42 22 4
-44 17 12 42 22 4
-33 18 12 42 22 4
-33 17 12 42 22 4
-44 18 12 42 22 4
-32 18 12 42 22 4
-32 17 12 42 22 4
-46 18 13 102 51 51
-31 18 12 42 22 4
-31 17 12 42 22 4
-35 18 13 102 51 51
-30 18 12 42 22 4
-30 17 12 42 22 4
-22 25 15 102 51 51
-17 18 13 102 51 51
-29 18 12 42 22 4
-29 17 12 42 22 4
-18 18 13 50 50 50
-28 18 12 42 22 4
-28 17 12 42 22 4
-34 18 13 50 50 50
-27 18 12 42 22 4
-27 17 12 42 22 4
-19 18 13 50 50 50
-26 18 12 42 22 4
-26 17 12 42 22 4
-20 18 13 102 51 51
-26 25 15 42 22 4
-23 24 15 102 51 51
-26 24 15 42 22 4
-24 23 15 102 51 51
-26 23 15 42 22 4
-25 22 15 102 51 51
-26 22 15 42 22 4
-26 34 14 102 51 51
-25 33 14 102 51 51
-24 32 14 102 51 51
-23 31 14 102 51 51
-23 30 14 102 51 51
-33 21 15 102 51 51
-33 34 15 102 51 51
-34 21 15 102 51 51
-34 34 15 102 51 51
-35 21 15 102 51 51
-35 24 15 255 102 0
-35 25 15 255 102 0
-27 28 16 255 145 236
-35 34 15 102 51 51
-36 21 15 102 51 51
-36 24 15 221 0 0
-36 25 15 221 0 0
-26 31 15 42 22 4
-36 33 15 255 255 255
-36 34 15 102 51 51
-37 21 15 102 51 51
-37 24 15 221 0 0
-37 25 15 221 0 0
-37 28 15 221 0 0
-37 29 15 0 0 153
-37 33 15 255 255 255
-37 34 15 102 51 51
-38 21 15 102 51 51
-38 24 15 255 102 0
-38 25 15 255 102 0
-38 28 15 255 102 0
-38 33 15 153 51 205
-38 34 15 102 51 51
-39 33 15 67 67 255
-39 34 15 102 51 51
-40 32 15 153 0 153
-40 33 15 255 255 255
-40 34 15 102 51 51
-41 21 15 102 51 51
-41 24 15 255 102 0
-41 25 15 255 102 0
-41 28 15 255 102 0
-41 32 15 255 255 255
-41 33 15 255 255 255
-41 34 15 102 51 51
-42 21 15 102 51 51
-42 24 15 221 0 0
-42 25 15 221 0 0
-42 28 15 221 0 0
-42 29 15 0 0 153
-42 32 15 153 0 153
-42 33 15 255 255 255
-42 34 15 102 51 51
-43 21 15 102 51 51
-43 24 15 221 0 0
-43 25 15 221 0 0
-46 34 14 102 51 51
-43 29 15 0 0 153
-43 32 15 255 255 255
-43 33 15 255 255 255
-43 34 15 102 51 51
-44 21 15 102 51 51
-44 24 15 255 102 0
-44 25 15 255 102 0
-44 34 15 102 51 51
-45 21 15 102 51 51
-45 34 15 102 51 51
-46 21 15 102 51 51
-46 25 15 0 255 134
-46 26 15 0 255 133
-46 27 15 0 255 133
-46 28 15 0 255 133
-46 29 15 0 255 133
-46 30 15 0 255 135
-46 34 15 102 51 51
-47 21 15 102 51 51
-47 22 15 0 0 0
-47 23 15 0 0 0
-47 24 15 102 51 51
-47 31 15 102 51 51
-47 32 15 0 0 0
-47 33 15 0 0 0
-47 34 15 102 51 51
-48 21 15 102 51 51
-48 22 15 42 22 4
-48 23 15 42 22 4
-48 24 15 102 51 51
-48 30 15 67 67 255
-48 31 15 102 51 51
-48 32 15 42 22 4
-48 33 15 42 22 4
-48 34 15 102 51 51
-49 21 15 102 51 51
-49 24 15 102 51 51
-49 29 15 0 0 153
-49 30 15 0 0 153
-49 31 15 102 51 51
-49 34 15 102 51 51
-50 21 15 102 51 51
-50 25 15 102 51 51
-50 26 15 102 51 51
-50 27 15 102 51 51
-50 28 15 102 51 51
-50 29 15 102 51 51
-50 30 15 102 51 51
-50 34 15 102 51 51
-51 21 15 102 51 51
-51 34 15 102 51 51
-52 21 15 102 51 51
-52 34 15 102 51 51
-53 21 15 102 51 51
-53 34 15 102 51 51
-54 21 15 102 51 51
-54 34 15 102 51 51
-55 21 15 102 51 51
-55 34 15 102 51 51
-56 21 15 102 51 51
-56 34 15 102 51 51
-57 22 15 102 51 51
-57 23 15 102 51 51
-57 24 15 102 51 51
-57 25 15 102 51 51
-57 26 15 102 51 51
-57 27 15 102 51 51
-57 28 15 102 51 51
-57 29 15 102 51 51
-57 30 15 102 51 51
-57 31 15 102 51 51
-57 32 15 102 51 51
-57 33 15 102 51 51
-19 28 18 42 22 4
-22 29 14 102 51 51
-22 28 14 102 51 51
-28 29 15 42 22 4
-19 27 18 42 22 4
-22 27 14 102 51 51
-22 26 14 102 51 51
-28 28 15 42 22 4
-18 28 18 42 22 4
-23 25 14 102 51 51
-23 24 14 102 51 51
-28 27 15 42 22 4
-18 27 18 42 22 4
-24 23 14 102 51 51
-25 22 14 102 51 51
-28 26 15 42 22 4
-26 34 17 102 51 51
-26 34 13 102 51 51
-26 33 13 102 51 51
-28 25 15 42 22 4
-26 21 17 102 51 51
-25 32 13 102 51 51
-24 31 13 102 51 51
-28 24 15 42 22 4
-25 33 17 102 51 51
-24 30 13 102 51 51
-24 29 13 102 51 51
-28 23 15 42 22 4
-25 30 17 42 22 4
-24 28 13 102 51 51
-24 27 13 102 51 51
-28 22 15 42 22 4
-25 29 17 50 50 50
-24 26 13 102 51 51
-24 25 13 102 51 51
-28 34 14 102 51 51
-29 34 14 102 51 51
-30 34 14 102 51 51
-31 34 14 102 51 51
-28 34 13 102 51 51
-29 34 13 102 51 51
-30 34 13 102 51 51
-31 34 13 102 51 51
-28 34 12 102 51 51
-29 34 12 102 51 51
-30 34 12 102 51 51
-31 34 12 102 51 51
-25 18 12 42 22 4
-28 21 16 102 51 51
-28 34 16 102 51 51
-25 28 17 50 50 50
-23 31 15 102 51 51
-26 33 15 42 22 4
-24 32 15 102 51 51
-26 32 15 42 22 4
-25 27 17 50 50 50
-24 24 13 102 51 51
-25 23 13 102 51 51
-26 22 13 102 51 51
-26 33 12 102 51 51
-26 32 12 102 51 51
-26 31 12 102 51 51
-26 30 12 102 51 51
-26 29 12 102 51 51
-26 28 12 102 51 51
-26 27 12 102 51 51
-26 26 12 102 51 51
-26 25 12 102 51 51
-26 24 12 102 51 51
-26 23 12 102 51 51
-26 22 12 102 51 51
-21 28 17 102 51 51
-41 34 14 102 51 51
-36 33 16 255 255 255
-37 33 16 255 255 255
-38 33 16 255 255 255
-34 34 14 102 51 51
-33 34 14 102 51 51
-40 34 14 102 51 51
-39 34 14 102 51 51
-38 34 14 102 51 51
-54 34 13 102 51 51
-50 25 18 50 50 50
-50 26 18 50 50 50
-37 34 14 102 51 51
-47 21 16 102 51 51
-47 34 16 102 51 51
-48 21 16 102 51 51
-48 22 16 0 0 0
-48 23 16 0 0 0
-48 24 16 102 51 51
-48 31 16 102 51 51
-48 32 16 0 0 0
-48 33 16 0 0 0
-48 34 16 102 51 51
-49 21 16 102 51 51
-49 22 16 42 22 4
-49 23 16 42 22 4
-49 24 16 102 51 51
-49 31 16 102 51 51
-49 32 16 42 22 4
-49 33 16 42 22 4
-49 34 16 102 51 51
-50 21 16 102 51 51
-50 25 16 102 51 51
-50 26 16 102 51 51
-50 27 16 102 51 51
-50 28 16 102 51 51
-50 29 16 102 51 51
-50 30 16 102 51 51
-50 34 16 102 51 51
-51 21 16 102 51 51
-51 34 16 102 51 51
-52 21 16 102 51 51
-52 34 16 102 51 51
-53 21 16 102 51 51
-53 34 16 102 51 51
-54 21 16 102 51 51
-54 34 16 102 51 51
-55 21 16 102 51 51
-55 34 16 102 51 51
-56 21 16 102 51 51
-56 34 16 102 51 51
-57 22 16 102 51 51
-57 23 16 102 51 51
-57 24 16 102 51 51
-57 25 16 102 51 51
-57 26 16 102 51 51
-57 27 16 102 51 51
-57 28 16 102 51 51
-57 29 16 102 51 51
-57 30 16 102 51 51
-57 31 16 102 51 51
-57 32 16 102 51 51
-57 33 16 102 51 51
-25 17 12 42 22 4
-33 18 13 50 50 50
-24 18 12 42 22 4
-24 17 12 42 22 4
-36 18 13 50 50 50
-23 18 12 42 22 4
-23 17 12 42 22 4
-22 18 12 42 22 4
-22 17 12 42 22 4
-21 18 12 42 22 4
-21 17 12 42 22 4
-43 18 13 0 0 153
-20 18 12 42 22 4
-20 17 12 42 22 4
-45 18 13 0 0 153
-19 18 12 42 22 4
-19 17 12 42 22 4
-45 17 12 42 22 4
-18 18 12 42 22 4
-18 17 12 42 22 4
-21 18 13 50 50 50
-17 18 12 42 22 4
-17 17 12 42 22 4
-22 18 13 50 50 50
-32 18 13 102 51 51
-45 18 12 42 22 4
-23 18 13 102 51 51
-53 34 13 102 51 51
-53 26 18 255 102 0
-36 34 14 102 51 51
-36 33 17 255 255 255
-37 33 17 255 255 255
-38 33 17 255 255 255
-48 34 14 102 51 51
-48 21 17 102 51 51
-48 34 17 102 51 51
-49 21 17 102 51 51
-49 22 17 0 0 0
-49 23 17 0 0 0
-49 24 17 102 51 51
-49 25 17 102 51 51
-49 26 17 102 51 51
-49 27 17 102 51 51
-49 28 17 102 51 51
-49 29 17 102 51 51
-49 30 17 102 51 51
-49 31 17 102 51 51
-49 32 17 0 0 0
-49 33 17 0 0 0
-49 34 17 102 51 51
-50 21 17 102 51 51
-50 22 17 42 22 4
-50 23 17 42 22 4
-50 24 17 42 22 4
-50 25 17 42 22 4
-50 26 17 42 22 4
-50 27 17 42 22 4
-50 28 17 42 22 4
-50 29 17 42 22 4
-50 30 17 42 22 4
-50 31 17 42 22 4
-50 32 17 42 22 4
-50 33 17 42 22 4
-50 34 17 102 51 51
-51 21 17 102 51 51
-51 22 17 42 22 4
-51 23 17 42 22 4
-51 24 17 42 22 4
-51 25 17 42 22 4
-51 26 17 42 22 4
-51 27 17 42 22 4
-51 28 17 42 22 4
-51 29 17 42 22 4
-51 30 17 42 22 4
-51 31 17 42 22 4
-51 32 17 42 22 4
-51 33 17 42 22 4
-51 34 17 102 51 51
-52 21 17 102 51 51
-52 22 17 42 22 4
-52 23 17 42 22 4
-52 24 17 42 22 4
-52 25 17 42 22 4
-52 26 17 42 22 4
-52 27 17 42 22 4
-52 28 17 42 22 4
-52 29 17 42 22 4
-52 30 17 42 22 4
-52 31 17 42 22 4
-52 32 17 42 22 4
-52 33 17 42 22 4
-52 34 17 102 51 51
-53 21 17 102 51 51
-53 22 17 42 22 4
-53 23 17 42 22 4
-53 24 17 42 22 4
-53 25 17 42 22 4
-53 26 17 42 22 4
-53 27 17 42 22 4
-53 28 17 42 22 4
-53 29 17 42 22 4
-53 30 17 42 22 4
-53 31 17 42 22 4
-53 32 17 42 22 4
-53 33 17 42 22 4
-53 34 17 102 51 51
-54 21 17 102 51 51
-54 22 17 42 22 4
-54 23 17 42 22 4
-54 24 17 42 22 4
-54 25 17 42 22 4
-54 26 17 42 22 4
-54 27 17 42 22 4
-54 28 17 42 22 4
-54 29 17 42 22 4
-54 30 17 42 22 4
-54 31 17 42 22 4
-54 32 17 42 22 4
-54 33 17 42 22 4
-54 34 17 102 51 51
-55 21 17 102 51 51
-55 22 17 42 22 4
-55 23 17 42 22 4
-55 24 17 42 22 4
-55 25 17 42 22 4
-55 26 17 42 22 4
-55 27 17 42 22 4
-55 28 17 42 22 4
-55 29 17 42 22 4
-55 30 17 42 22 4
-55 31 17 42 22 4
-55 32 17 42 22 4
-55 33 17 42 22 4
-55 34 17 102 51 51
-56 21 17 102 51 51
-56 22 17 42 22 4
-56 23 17 42 22 4
-56 24 17 42 22 4
-56 25 17 42 22 4
-56 26 17 42 22 4
-56 27 17 42 22 4
-56 28 17 42 22 4
-56 29 17 42 22 4
-56 30 17 42 22 4
-56 31 17 42 22 4
-56 32 17 42 22 4
-56 33 17 42 22 4
-56 34 17 102 51 51
-57 22 17 102 51 51
-57 23 17 102 51 51
-57 24 17 102 51 51
-57 25 17 102 51 51
-57 26 17 102 51 51
-57 27 17 102 51 51
-57 28 17 102 51 51
-57 29 17 102 51 51
-57 30 17 102 51 51
-57 31 17 102 51 51
-57 32 17 102 51 51
-57 33 17 102 51 51
-24 18 13 50 50 50
-53 21 18 102 51 51
-52 34 18 102 51 51
-52 32 18 255 102 0
-42 18 13 50 50 50
-52 21 18 102 51 51
-52 34 13 102 51 51
-46 17 12 42 22 4
-35 34 14 102 51 51
-26 18 13 102 51 51
-25 18 13 50 50 50
-47 34 14 102 51 51
-31 18 13 50 50 50
-49 21 18 102 51 51
-49 34 18 102 51 51
-50 21 18 102 51 51
-50 28 18 255 0 255
-50 34 14 102 51 51
-51 34 14 102 51 51
-54 34 14 102 51 51
-49 34 14 102 51 51
-53 34 14 102 51 51
-52 34 14 102 51 51
-50 27 18 50 50 50
-50 34 18 102 51 51
-51 21 18 102 51 51
-51 34 18 102 51 51
-27 24 15 42 22 4
-27 23 15 42 22 4
-27 25 15 42 22 4
-27 22 15 42 22 4
-27 26 15 42 22 4
-27 27 15 42 22 4
-27 28 15 42 22 4
-27 29 15 42 22 4
-27 30 15 42 22 4
-27 31 15 42 22 4
-27 32 15 42 22 4
-27 33 15 42 22 4
-27 34 16 102 51 51
-27 34 15 102 51 51
-27 34 14 102 51 51
-27 34 13 102 51 51
-27 34 12 102 51 51
-27 21 15 102 51 51
-27 21 14 102 51 51
-27 21 16 102 51 51
-27 21 13 102 51 51
-27 21 12 102 51 51
-15 28 20 42 22 4
-15 27 20 42 22 4
-14 28 20 42 22 4
-14 27 20 42 22 4
-13 28 20 42 22 4
-13 27 20 42 22 4
-18 28 19 42 22 4
-18 27 19 42 22 4
-17 28 19 42 22 4
-17 27 19 42 22 4
-16 28 19 42 22 4
-16 27 19 42 22 4
-15 28 19 42 22 4
-15 27 19 42 22 4
-26 21 13 102 51 51
-26 21 14 102 51 51
-26 21 15 102 51 51
-20 27 16 102 51 51
-20 28 16 102 51 51
-21 26 16 102 51 51
-21 27 16 42 22 4
-21 28 16 42 22 4
-21 29 16 102 51 51
-22 25 16 102 51 51
-22 26 16 42 22 4
-22 27 16 42 22 4
-22 28 16 42 22 4
-22 29 16 42 22 4
-22 30 16 102 51 51
-23 24 16 102 51 51
-23 25 16 42 22 4
-23 26 16 42 22 4
-23 27 16 42 22 4
-23 28 16 42 22 4
-23 29 16 42 22 4
-23 30 16 42 22 4
-23 31 16 102 51 51
-24 23 16 102 51 51
-24 24 16 42 22 4
-24 25 16 42 22 4
-24 26 16 42 22 4
-24 27 16 42 22 4
-24 28 16 42 22 4
-24 29 16 42 22 4
-24 30 16 42 22 4
-24 31 16 42 22 4
-24 32 16 102 51 51
-25 22 16 102 51 51
-25 23 16 0 0 0
-25 24 16 0 0 0
-25 25 16 42 22 4
-25 26 16 42 22 4
-25 27 16 42 22 4
-25 28 16 42 22 4
-25 29 16 42 22 4
-25 30 16 42 22 4
-25 31 16 0 0 0
-25 32 16 0 0 0
-25 33 16 102 51 51
-26 21 16 102 51 51
-26 22 16 0 204 0
-26 34 15 102 51 51
-25 33 15 102 51 51
-26 33 16 0 204 0
-26 34 16 102 51 51
-19 27 17 42 22 4
-19 28 17 42 22 4
-20 27 17 102 51 51
-20 28 17 102 51 51
-21 26 17 102 51 51
-21 29 17 102 51 51
-22 25 17 102 51 51
-22 26 17 255 102 0
-22 27 17 221 0 0
-22 28 17 221 0 0
-22 29 17 255 102 0
-22 30 17 102 51 51
-23 24 17 102 51 51
-23 25 17 0 204 0
-23 30 17 0 204 0
-23 31 17 102 51 51
-24 23 17 102 51 51
-24 32 17 102 51 51
-25 22 17 102 51 51
-25 25 17 42 22 4
-25 26 17 50 50 50
-31 21 15 102 51 51
-30 21 15 102 51 51
-29 21 15 102 51 51
-31 22 15 0 0 0
-30 22 15 42 22 4
-29 22 15 42 22 4
-31 23 15 0 0 0
-30 23 15 42 22 4
-29 23 15 42 22 4
-31 24 15 102 51 51
-30 24 15 42 22 4
-29 24 15 42 22 4
-30 25 15 42 22 4
-29 25 15 42 22 4
-31 26 15 255 102 0
-30 26 15 42 22 4
-29 26 15 42 22 4
-31 27 15 221 0 0
-30 27 15 42 22 4
-29 27 15 42 22 4
-31 28 15 221 0 0
-30 28 15 42 22 4
-29 28 15 42 22 4
-31 29 15 255 102 0
-30 29 15 42 22 4
-29 29 15 42 22 4
-30 30 15 42 22 4
-29 30 15 42 22 4
-31 31 15 102 51 51
-30 31 15 42 22 4
-29 31 15 42 22 4
-31 32 15 0 0 0
-30 32 15 42 22 4
-29 32 15 42 22 4
-31 33 15 0 0 0
-30 33 15 42 22 4
-29 33 15 42 22 4
-31 34 15 102 51 51
-30 34 15 102 51 51
-29 34 15 102 51 51
-30 21 16 102 51 51
-29 21 16 102 51 51
-30 24 16 42 22 4
-30 25 16 50 50 50
-32 25 14 42 22 4
-31 25 14 42 22 4
-32 24 14 42 22 4
-31 24 14 42 22 4
-32 26 14 42 22 4
-31 26 14 42 22 4
-32 23 14 42 22 4
-31 23 14 42 22 4
-32 27 14 42 22 4
-31 27 14 42 22 4
-32 22 14 42 22 4
-31 22 14 42 22 4
-32 28 14 42 22 4
-31 28 14 42 22 4
-32 29 14 42 22 4
-31 29 14 42 22 4
-32 30 14 42 22 4
-31 30 14 42 22 4
-32 31 14 42 22 4
-31 31 14 42 22 4
-32 32 14 42 22 4
-31 32 14 42 22 4
-32 33 14 42 22 4
-31 33 14 42 22 4
