ply
format ascii 1.0
comment : MagicaVoxel @ Ephtracy
element vertex 1206
property float x
property float y
property float z
property uchar red
property uchar green
property uchar blue
end_header
-42 33 14 42 22 4
-47 30 15 0 0 153
-48 30 15 0 0 153
-47 29 15 67 67 255
-50 24 18 102 51 51
-49 30 17 102 51 51
-49 25 17 102 51 51
-46 29 15 0 255 133
-46 26 15 0 255 133
-48 31 16 102 51 51
-49 31 16 102 51 51
-47 31 15 102 51 51
-48 31 15 102 51 51
-49 31 15 102 51 51
-50 22 17 42 22 4
-41 33 14 42 22 4
-40 33 14 42 22 4
-55 22 12 102 51 51
-39 33 14 42 22 4
-38 33 14 42 22 4
-57 22 20 102 51 51
-57 22 19 102 51 51
-57 22 18 102 51 51
-57 22 17 102 51 51
-57 22 15 102 51 51
-57 22 16 102 51 51
-56 22 13 102 51 51
-56 22 14 102 51 51
-57 33 19 102 51 51
-57 32 19 50 50 50
-57 33 20 102 51 51
-33 33 14 42 22 4
-37 33 14 42 22 4
-34 33 14 42 22 4
-36 33 14 42 22 4
-57 32 20 102 51 51
-55 33 12 102 51 51
-55 32 12 102 51 51
-57 33 18 102 51 51
-57 33 17 102 51 51
-57 33 15 102 51 51
-57 33 16 102 51 51
-56 33 13 102 51 51
-56 33 14 102 51 51
-57 32 18 102 51 51
-57 32 17 102 51 51
-35 33 14 42 22 4
-57 32 15 102 51 51
-32 33 15 42 22 4
-27 33 15 42 22 4
-31 33 15 42 22 4
-28 33 15 42 22 4
-30 33 15 42 22 4
-29 33 15 42 22 4
-27 22 15 42 22 4
-57 32 16 102 51 51
-56 32 14 102 51 51
-56 32 13 102 51 51
-56 33 17 42 22 4
-55 33 17 42 22 4
-50 33 17 42 22 4
-54 33 17 42 22 4
-51 33 17 42 22 4
-53 33 17 42 22 4
-52 33 17 42 22 4
-56 32 17 42 22 4
-55 32 17 42 22 4
-50 32 17 42 22 4
-54 32 17 42 22 4
-51 32 17 42 22 4
-53 32 17 42 22 4
-52 32 17 42 22 4
-46 33 14 42 22 4
-45 33 14 42 22 4
-44 33 14 42 22 4
-43 33 14 42 22 4
-49 21 19 102 51 51
-50 21 19 50 50 50
-51 21 19 50 50 50
-52 21 19 50 50 50
-53 21 19 50 50 50
-54 21 19 50 50 50
-55 21 19 50 50 50
-56 21 19 102 51 51
-49 21 18 102 51 51
-50 21 18 102 51 51
-51 21 18 102 51 51
-52 21 18 102 51 51
-53 21 18 102 51 51
-54 21 18 102 51 51
-55 21 18 102 51 51
-56 21 18 102 51 51
-48 21 17 102 51 51
-49 21 17 102 51 51
-50 21 17 102 51 51
-51 21 17 102 51 51
-52 21 17 102 51 51
-53 21 17 102 51 51
-54 21 17 102 51 51
-55 21 17 102 51 51
-56 21 17 102 51 51
-27 21 16 102 51 51
-28 21 16 102 51 51
-29 21 16 102 51 51
-30 21 16 102 51 51
-55 23 12 102 51 51
-26 23 12 102 51 51
-55 24 12 102 51 51
-25 24 12 102 51 51
-55 25 12 102 51 51
-25 25 12 102 51 51
-55 26 12 102 51 51
-25 26 12 102 51 51
-55 27 12 102 51 51
-25 27 12 102 51 51
-55 28 12 102 51 51
-25 28 12 102 51 51
-55 29 12 102 51 51
-25 29 12 102 51 51
-55 30 12 102 51 51
-25 30 12 102 51 51
-55 31 12 102 51 51
-25 31 12 102 51 51
-54 29 18 255 102 0
-54 28 18 221 0 0
-54 27 18 221 0 0
-54 26 18 255 102 0
-23 28 16 67 67 255
-23 29 16 0 0 153
-26 32 12 102 51 51
-31 21 16 102 51 51
-47 21 16 102 51 51
-48 21 16 102 51 51
-49 21 16 102 51 51
-50 21 16 102 51 51
-51 21 16 102 51 51
-52 21 16 102 51 51
-53 21 16 102 51 51
-54 21 16 102 51 51
-55 21 16 102 51 51
-56 21 16 102 51 51
-27 21 15 102 51 51
-28 21 15 102 51 51
-30 32 16 0 204 0
-30 23 16 0 204 0
-29 21 15 102 51 51
-30 21 15 102 51 51
-31 21 15 102 51 51
-32 21 15 102 51 51
-33 21 15 102 51 51
-34 21 15 102 51 51
-35 21 15 102 51 51
-36 21 15 102 51 51
-37 21 15 102 51 51
-38 21 15 102 51 51
-40 20 14 0 0 0
-39 20 14 0 0 0
-41 21 15 102 51 51
-42 21 15 102 51 51
-43 21 15 102 51 51
-44 21 15 102 51 51
-45 21 15 102 51 51
-46 21 15 102 51 51
-47 21 15 102 51 51
-48 21 15 102 51 51
-49 21 15 102 51 51
-50 21 15 102 51 51
-51 21 15 102 51 51
-52 21 15 102 51 51
-53 21 15 102 51 51
-54 21 15 102 51 51
-55 21 15 102 51 51
-56 21 15 102 51 51
-27 21 14 102 51 51
-28 21 14 102 51 51
-29 21 14 102 51 51
-30 21 14 255 255 255
-31 21 14 255 255 255
-57 24 20 102 51 51
-57 23 20 102 51 51
-57 25 20 102 51 51
-57 26 20 102 51 51
-26 22 13 102 51 51
-56 23 13 102 51 51
-25 23 13 102 51 51
-56 24 13 102 51 51
-24 24 13 102 51 51
-56 25 13 102 51 51
-24 25 13 102 51 51
-56 26 13 102 51 51
-23 26 13 102 51 51
-56 27 13 102 51 51
-23 27 13 102 51 51
-56 28 13 102 51 51
-23 28 13 102 51 51
-56 29 13 102 51 51
-23 29 13 102 51 51
-56 30 13 102 51 51
-24 30 13 102 51 51
-56 31 13 102 51 51
-24 31 13 102 51 51
-27 27 16 255 102 0
-28 27 16 221 0 0
-56 30 18 0 204 0
-56 27 18 0 255 204
-32 21 14 102 51 51
-26 33 14 102 51 51
-26 33 13 102 51 51
-25 32 13 102 51 51
-33 21 14 102 51 51
-34 21 14 102 51 51
-35 21 14 255 255 255
-36 21 14 255 255 255
-37 21 14 102 51 51
-38 21 14 102 51 51
-39 21 14 102 51 51
-40 21 14 102 51 51
-41 21 14 102 51 51
-42 21 14 102 51 51
-43 21 14 255 255 255
-44 21 14 255 255 255
-45 21 14 102 51 51
-56 25 18 0 204 0
-35 32 14 42 22 4
-46 21 14 102 51 51
-47 21 14 255 255 255
-48 21 14 255 255 255
-49 21 14 102 51 51
-50 21 14 102 51 51
-51 21 14 255 255 255
-52 21 14 255 255 255
-53 21 14 102 51 51
-57 27 20 102 51 51
-57 28 20 102 51 51
-36 28 21 168 168 168
-54 21 14 102 51 51
-28 28 20 168 168 168
-57 31 19 102 51 51
-57 30 19 50 50 50
-57 29 19 102 51 51
-14 28 19 42 22 4
-15 28 19 42 22 4
-16 28 19 42 22 4
-28 28 19 168 168 168
-55 21 14 102 51 51
-36 28 22 168 168 168
-57 28 19 50 50 50
-14 27 19 42 22 4
-15 27 19 42 22 4
-16 27 19 42 22 4
-57 27 19 50 50 50
-57 26 19 102 51 51
-57 25 19 50 50 50
-57 24 19 102 51 51
-57 23 19 50 50 50
-56 21 14 102 51 51
-57 29 20 102 51 51
-57 30 20 102 51 51
-57 31 20 102 51 51
-36 28 20 168 168 168
-27 21 13 102 51 51
-28 28 21 168 168 168
-26 22 14 102 51 51
-56 23 14 102 51 51
-46 23 14 42 22 4
-45 23 14 42 22 4
-44 23 14 42 22 4
-43 23 14 42 22 4
-42 23 14 42 22 4
-41 23 14 42 22 4
-40 23 14 42 22 4
-39 23 14 42 22 4
-38 23 14 42 22 4
-37 23 14 42 22 4
-36 23 14 42 22 4
-35 23 14 42 22 4
-34 23 14 42 22 4
-33 23 14 42 22 4
-25 23 14 102 51 51
-56 24 14 102 51 51
-46 24 14 42 22 4
-45 24 14 42 22 4
-44 24 14 42 22 4
-43 24 14 42 22 4
-42 24 14 42 22 4
-41 24 14 42 22 4
-40 24 14 42 22 4
-39 24 14 42 22 4
-38 24 14 42 22 4
-37 24 14 42 22 4
-36 24 14 42 22 4
-35 24 14 42 22 4
-34 24 14 42 22 4
-33 24 14 42 22 4
-24 24 14 102 51 51
-56 25 14 102 51 51
-49 25 14 42 22 4
-48 25 14 42 22 4
-47 25 14 42 22 4
-46 25 14 42 22 4
-45 25 14 42 22 4
-44 25 14 42 22 4
-43 25 14 42 22 4
-42 25 14 42 22 4
-41 25 14 42 22 4
-40 25 14 42 22 4
-39 25 14 42 22 4
-38 25 14 42 22 4
-37 25 14 42 22 4
-36 25 14 42 22 4
-35 25 14 42 22 4
-34 25 14 42 22 4
-33 25 14 42 22 4
-23 25 14 102 51 51
-56 26 14 102 51 51
-49 26 14 42 22 4
-48 26 14 42 22 4
-47 26 14 42 22 4
-46 26 14 42 22 4
-45 26 14 42 22 4
-44 26 14 42 22 4
-43 26 14 42 22 4
-42 26 14 42 22 4
-41 26 14 42 22 4
-40 26 14 42 22 4
-39 26 14 42 22 4
-38 26 14 42 22 4
-37 26 14 42 22 4
-36 26 14 42 22 4
-35 26 14 42 22 4
-34 26 14 42 22 4
-33 26 14 42 22 4
-23 26 14 102 51 51
-56 27 14 102 51 51
-49 27 14 42 22 4
-48 27 14 42 22 4
-47 27 14 42 22 4
-46 27 14 42 22 4
-45 27 14 42 22 4
-44 27 14 42 22 4
-43 27 14 42 22 4
-42 27 14 42 22 4
-41 27 14 42 22 4
-40 27 14 42 22 4
-39 27 14 42 22 4
-38 27 14 42 22 4
-37 27 14 42 22 4
-36 27 14 42 22 4
-35 27 14 42 22 4
-34 27 14 42 22 4
-33 27 14 42 22 4
-22 27 14 102 51 51
-56 28 14 102 51 51
-49 28 14 42 22 4
-48 28 14 42 22 4
-47 28 14 42 22 4
-46 28 14 42 22 4
-45 28 14 42 22 4
-44 28 14 42 22 4
-43 28 14 42 22 4
-42 28 14 42 22 4
-41 28 14 42 22 4
-40 28 14 42 22 4
-39 28 14 42 22 4
-38 28 14 42 22 4
-37 28 14 42 22 4
-36 32 14 42 22 4
-35 28 14 42 22 4
-34 28 14 42 22 4
-33 28 14 42 22 4
-22 28 14 102 51 51
-56 29 14 102 51 51
-49 29 14 42 22 4
-48 29 14 42 22 4
-47 29 14 42 22 4
-46 29 14 42 22 4
-45 29 14 42 22 4
-44 29 14 42 22 4
-43 29 14 42 22 4
-42 29 14 42 22 4
-41 29 14 42 22 4
-40 29 14 42 22 4
-39 29 14 42 22 4
-38 29 14 42 22 4
-37 29 14 42 22 4
-35 31 14 42 22 4
-35 29 14 42 22 4
-34 29 14 42 22 4
-33 29 14 42 22 4
-23 29 14 102 51 51
-56 30 14 102 51 51
-49 30 14 42 22 4
-48 30 14 42 22 4
-47 30 14 42 22 4
-46 30 14 42 22 4
-45 30 14 42 22 4
-44 30 14 42 22 4
-43 30 14 42 22 4
-42 30 14 42 22 4
-41 30 14 42 22 4
-40 30 14 42 22 4
-39 30 14 42 22 4
-38 30 14 42 22 4
-37 30 14 42 22 4
-36 31 14 42 22 4
-28 28 24 168 168 168
-34 30 14 42 22 4
-33 30 14 42 22 4
-23 30 14 102 51 51
-56 31 14 102 51 51
-46 31 14 42 22 4
-45 31 14 42 22 4
-44 31 14 42 22 4
-43 31 14 42 22 4
-42 31 14 42 22 4
-41 31 14 42 22 4
-40 31 14 42 22 4
-39 31 14 42 22 4
-38 31 14 42 22 4
-37 31 14 42 22 4
-35 30 14 42 22 4
-28 28 23 168 168 168
-34 31 14 42 22 4
-33 31 14 42 22 4
-24 31 14 102 51 51
-26 33 15 102 51 51
-26 33 16 102 51 51
-33 33 15 0 0 0
-33 32 15 0 0 0
-33 31 15 102 51 51
-40 31 15 0 255 204
-36 26 15 255 102 0
-46 32 14 42 22 4
-45 32 14 42 22 4
-44 32 14 42 22 4
-43 32 14 42 22 4
-42 32 14 42 22 4
-41 32 14 42 22 4
-40 32 14 42 22 4
-39 32 14 42 22 4
-38 32 14 42 22 4
-37 32 14 42 22 4
-36 30 14 42 22 4
-46 15 13 0 0 153
-34 32 14 42 22 4
-33 32 14 42 22 4
-25 32 14 102 51 51
-28 21 13 102 51 51
-29 21 13 102 51 51
-30 21 13 0 225 255
-31 21 13 255 255 255
-32 21 13 102 51 51
-33 21 13 102 51 51
-34 21 13 102 51 51
-35 21 13 0 225 255
-36 21 13 255 255 255
-37 21 13 102 51 51
-38 21 13 102 51 51
-39 21 13 102 51 51
-40 21 13 102 51 51
-41 21 13 102 51 51
-42 21 13 102 51 51
-43 21 13 0 225 255
-44 21 13 255 255 255
-45 21 13 102 51 51
-46 21 13 102 51 51
-47 21 13 0 225 255
-48 21 13 255 255 255
-49 21 13 102 51 51
-50 21 13 102 51 51
-51 21 13 0 225 255
-50 31 18 102 51 51
-57 31 18 102 51 51
-50 30 18 50 50 50
-57 30 18 102 51 51
-50 29 18 50 50 50
-57 29 18 102 51 51
-16 28 18 42 22 4
-17 28 18 42 22 4
-18 28 18 42 22 4
-19 28 18 42 22 4
-28 28 18 168 168 168
-36 28 14 42 22 4
-36 28 23 168 168 168
-50 28 18 50 50 50
-57 28 18 102 51 51
-16 27 18 42 22 4
-17 27 18 42 22 4
-18 27 18 42 22 4
-19 27 18 42 22 4
-50 27 18 50 50 50
-57 27 18 102 51 51
-50 26 18 50 50 50
-57 26 18 102 51 51
-50 25 18 50 50 50
-57 25 18 102 51 51
-57 24 18 102 51 51
-57 23 18 102 51 51
-52 21 13 255 255 255
-53 21 13 102 51 51
-26 22 15 102 51 51
-57 23 15 102 51 51
-48 23 15 42 22 4
-47 23 15 0 0 0
-46 25 15 0 255 134
-32 23 15 42 22 4
-31 23 15 42 22 4
-30 23 15 42 22 4
-29 23 15 42 22 4
-28 23 15 42 22 4
-27 23 15 42 22 4
-26 23 15 42 22 4
-25 23 15 102 51 51
-57 24 15 102 51 51
-55 22 17 42 22 4
-54 22 17 42 22 4
-32 34 16 102 51 51
-32 24 15 42 22 4
-31 24 15 42 22 4
-30 24 15 42 22 4
-29 24 15 42 22 4
-28 24 15 42 22 4
-27 24 15 42 22 4
-26 24 15 42 22 4
-25 24 15 42 22 4
-24 24 15 102 51 51
-57 25 15 102 51 51
-50 25 15 102 51 51
-49 22 17 0 0 0
-48 22 16 0 0 0
-47 22 15 0 0 0
-32 21 16 102 51 51
-32 25 15 42 22 4
-31 25 15 42 22 4
-30 25 15 42 22 4
-29 25 15 42 22 4
-28 25 15 42 22 4
-27 25 15 42 22 4
-26 25 15 42 22 4
-25 25 15 42 22 4
-24 25 15 42 22 4
-23 25 15 102 51 51
-57 26 15 102 51 51
-50 26 15 102 51 51
-46 30 15 0 255 135
-32 26 15 42 22 4
-31 26 15 42 22 4
-30 26 15 42 22 4
-29 26 15 42 22 4
-28 26 15 42 22 4
-27 26 15 42 22 4
-26 26 15 42 22 4
-25 26 15 42 22 4
-24 26 15 42 22 4
-23 26 15 42 22 4
-22 26 15 102 51 51
-57 27 15 102 51 51
-50 27 15 102 51 51
-46 27 15 0 255 133
-32 27 15 42 22 4
-31 27 15 42 22 4
-30 27 15 42 22 4
-29 27 15 42 22 4
-28 27 15 42 22 4
-27 27 15 42 22 4
-26 27 15 42 22 4
-25 27 15 42 22 4
-24 27 15 42 22 4
-23 27 15 42 22 4
-21 27 15 102 51 51
-57 28 15 102 51 51
-50 28 15 102 51 51
-46 28 15 0 255 133
-36 28 27 168 168 168
-28 28 22 168 168 168
-32 28 15 42 22 4
-31 28 15 42 22 4
-30 28 15 42 22 4
-29 28 15 42 22 4
-28 28 15 42 22 4
-27 28 15 42 22 4
-26 28 15 42 22 4
-25 28 15 42 22 4
-24 28 15 42 22 4
-23 28 15 42 22 4
-21 28 15 102 51 51
-57 29 15 102 51 51
-50 29 15 102 51 51
-49 31 17 102 51 51
-32 29 15 42 22 4
-31 29 15 42 22 4
-30 29 15 42 22 4
-29 29 15 42 22 4
-28 29 15 42 22 4
-27 29 15 42 22 4
-26 29 15 42 22 4
-25 29 15 42 22 4
-24 29 15 42 22 4
-23 29 15 42 22 4
-22 29 15 102 51 51
-57 30 15 102 51 51
-50 30 15 102 51 51
-49 24 17 102 51 51
-48 24 16 102 51 51
-49 24 16 102 51 51
-33 24 15 102 51 51
-32 30 15 42 22 4
-31 30 15 42 22 4
-30 30 15 42 22 4
-29 30 15 42 22 4
-28 30 15 42 22 4
-27 30 15 42 22 4
-26 30 15 42 22 4
-25 30 15 42 22 4
-24 30 15 42 22 4
-23 30 15 102 51 51
-57 31 15 102 51 51
-47 33 15 0 0 0
-48 33 16 0 0 0
-33 23 15 0 0 0
-32 31 15 42 22 4
-31 31 15 42 22 4
-30 31 15 42 22 4
-29 31 15 42 22 4
-28 31 15 42 22 4
-27 31 15 42 22 4
-26 31 15 42 22 4
-25 31 15 42 22 4
-24 31 15 102 51 51
-43 26 15 255 102 0
-37 26 15 221 0 0
-42 26 15 221 0 0
-38 30 15 255 102 0
-39 30 15 221 0 0
-40 30 15 221 0 0
-41 30 15 255 102 0
-48 32 15 42 22 4
-47 32 15 0 0 0
-33 22 15 0 0 0
-32 32 15 42 22 4
-31 32 15 42 22 4
-30 32 15 42 22 4
-29 32 15 42 22 4
-28 32 15 42 22 4
-27 32 15 42 22 4
-26 32 15 42 22 4
-25 32 15 102 51 51
-54 21 13 102 51 51
-55 21 13 102 51 51
-56 21 13 102 51 51
-42 15 12 50 50 50
-28 21 12 102 51 51
-29 21 12 102 51 51
-30 21 12 102 51 51
-31 21 12 102 51 51
-32 21 12 102 51 51
-33 21 12 102 51 51
-34 21 12 102 51 51
-35 21 12 102 51 51
-36 21 12 102 51 51
-37 21 12 102 51 51
-38 21 12 102 51 51
-39 21 12 102 51 51
-40 21 12 102 51 51
-41 21 12 102 51 51
-42 21 12 102 51 51
-43 21 12 102 51 51
-44 21 12 102 51 51
-45 21 12 102 51 51
-46 21 12 102 51 51
-49 32 17 0 0 0
-36 28 15 168 168 167
-36 28 16 168 168 168
-36 28 17 168 168 168
-36 28 18 168 168 168
-36 28 19 168 168 168
-43 28 23 168 168 168
-43 28 22 168 168 168
-49 33 17 0 0 0
-50 31 17 42 22 4
-51 31 17 42 22 4
-52 31 17 42 22 4
-53 31 17 42 22 4
-54 31 17 42 22 4
-55 31 17 42 22 4
-26 22 16 102 51 51
-57 23 16 102 51 51
-49 23 16 42 22 4
-48 23 16 0 0 0
-25 23 16 102 51 51
-57 24 16 102 51 51
-53 22 17 42 22 4
-52 22 17 42 22 4
-24 24 16 102 51 51
-57 25 16 102 51 51
-50 25 16 102 51 51
-48 22 15 42 22 4
-49 22 16 42 22 4
-32 25 16 42 22 4
-24 25 16 0 204 0
-23 25 16 102 51 51
-57 26 16 102 51 51
-50 26 16 102 51 51
-32 26 16 50 50 50
-22 26 16 102 51 51
-57 27 16 102 51 51
-50 27 16 102 51 51
-32 27 16 50 50 50
-22 27 16 42 22 4
-21 27 16 102 51 51
-20 27 16 42 22 4
-57 28 16 102 51 51
-50 28 16 102 51 51
-36 28 26 168 168 168
-36 29 14 42 22 4
-32 28 16 50 50 50
-28 28 16 168 168 167
-22 28 16 42 22 4
-21 28 16 102 51 51
-20 28 16 42 22 4
-57 29 16 102 51 51
-50 29 16 102 51 51
-32 29 16 50 50 50
-22 29 16 102 51 51
-57 30 16 102 51 51
-50 30 16 102 51 51
-47 24 15 102 51 51
-48 24 15 102 51 51
-32 30 16 42 22 4
-24 30 16 0 204 0
-23 30 16 102 51 51
-57 31 16 102 51 51
-49 33 16 42 22 4
-48 33 15 42 22 4
-24 31 16 102 51 51
-43 28 19 168 168 168
-43 28 18 168 168 168
-43 28 17 168 168 168
-43 28 16 168 168 168
-43 28 15 168 168 167
-43 28 20 168 168 168
-43 28 21 168 168 168
-49 32 16 42 22 4
-48 32 16 0 0 0
-25 32 16 102 51 51
-47 21 12 102 51 51
-48 21 12 102 51 51
-49 21 12 102 51 51
-50 21 12 102 51 51
-51 21 12 102 51 51
-52 21 12 102 51 51
-53 21 12 102 51 51
-54 21 12 102 51 51
-56 31 17 42 22 4
-57 31 17 102 51 51
-49 24 15 102 51 51
-50 30 17 42 22 4
-51 30 17 42 22 4
-52 30 17 42 22 4
-53 30 17 42 22 4
-54 30 17 42 22 4
-55 30 17 42 22 4
-57 23 17 102 51 51
-56 23 17 42 22 4
-55 23 17 42 22 4
-54 23 17 42 22 4
-53 23 17 42 22 4
-52 23 17 42 22 4
-51 23 17 42 22 4
-50 23 17 42 22 4
-49 23 17 0 0 0
-57 24 17 102 51 51
-56 24 17 42 22 4
-55 24 17 42 22 4
-54 24 17 42 22 4
-53 24 17 42 22 4
-52 24 17 42 22 4
-51 24 17 42 22 4
-50 24 17 42 22 4
-51 22 17 42 22 4
-57 25 17 102 51 51
-56 25 17 42 22 4
-55 25 17 42 22 4
-54 25 17 42 22 4
-53 25 17 42 22 4
-52 25 17 42 22 4
-51 25 17 42 22 4
-50 25 17 42 22 4
-56 22 17 42 22 4
-57 26 17 102 51 51
-56 26 17 42 22 4
-55 26 17 42 22 4
-54 26 17 42 22 4
-53 26 17 42 22 4
-52 26 17 42 22 4
-51 26 17 42 22 4
-50 26 17 42 22 4
-49 26 17 102 51 51
-57 27 17 102 51 51
-56 27 17 42 22 4
-55 27 17 42 22 4
-54 27 17 42 22 4
-53 27 17 42 22 4
-52 27 17 42 22 4
-51 27 17 42 22 4
-50 27 17 42 22 4
-49 27 17 102 51 51
-21 27 17 42 22 4
-20 27 17 42 22 4
-19 27 17 42 22 4
-57 28 17 102 51 51
-56 28 17 42 22 4
-55 28 17 42 22 4
-54 28 17 42 22 4
-53 28 17 42 22 4
-52 28 17 42 22 4
-51 28 17 42 22 4
-50 28 17 42 22 4
-49 28 17 102 51 51
-36 28 25 168 168 168
-36 28 24 168 168 168
-28 28 17 168 168 168
-21 28 17 42 22 4
-20 28 17 42 22 4
-19 28 17 42 22 4
-57 29 17 102 51 51
-56 29 17 42 22 4
-55 29 17 42 22 4
-54 29 17 42 22 4
-53 29 17 42 22 4
-52 29 17 42 22 4
-51 29 17 42 22 4
-50 29 17 42 22 4
-49 29 17 102 51 51
-57 30 17 102 51 51
-56 30 17 42 22 4
-55 21 12 102 51 51
-50 34 19 102 51 51
-51 34 19 50 50 50
-52 34 19 50 50 50
-53 34 19 50 50 50
-54 34 19 50 50 50
-55 34 19 50 50 50
-56 34 19 102 51 51
-50 34 18 102 51 51
-51 34 18 102 51 51
-52 34 18 102 51 51
-53 34 18 102 51 51
-54 34 18 102 51 51
-55 34 18 102 51 51
-56 34 18 102 51 51
-50 34 17 102 51 51
-51 34 17 102 51 51
-52 34 17 102 51 51
-53 34 17 102 51 51
-54 34 17 102 51 51
-55 34 17 102 51 51
-56 34 17 102 51 51
-50 34 16 102 51 51
-51 34 16 102 51 51
-52 34 16 102 51 51
-53 34 16 102 51 51
-54 34 16 102 51 51
-55 34 16 102 51 51
-56 34 16 102 51 51
-50 34 15 102 51 51
-49 34 12 102 51 51
-48 34 12 102 51 51
-47 34 12 102 51 51
-46 34 12 102 51 51
-45 34 12 102 51 51
-44 34 12 102 51 51
-43 34 12 102 51 51
-42 34 12 102 51 51
-41 34 12 102 51 51
-40 34 12 102 51 51
-39 34 12 102 51 51
-38 34 12 102 51 51
-37 34 12 102 51 51
-34 34 12 102 51 51
-33 34 12 102 51 51
-32 34 12 102 51 51
-31 34 12 102 51 51
-30 34 12 102 51 51
-29 34 12 102 51 51
-28 34 12 102 51 51
-51 34 15 102 51 51
-52 34 15 102 51 51
-53 34 15 102 51 51
-54 34 15 102 51 51
-55 34 15 102 51 51
-56 34 15 102 51 51
-50 34 14 102 51 51
-51 34 14 102 51 51
-52 34 14 102 51 51
-53 34 14 102 51 51
-54 34 14 102 51 51
-55 34 14 102 51 51
-56 34 14 102 51 51
-50 34 13 102 51 51
-51 34 13 102 51 51
-52 34 13 102 51 51
-53 34 13 102 51 51
-54 34 13 102 51 51
-55 34 13 102 51 51
-56 34 13 102 51 51
-50 34 12 102 51 51
-51 34 12 102 51 51
-52 34 12 102 51 51
-53 34 12 102 51 51
-54 34 12 102 51 51
-55 34 12 102 51 51
-27 33 12 102 51 51
-49 34 13 102 51 51
-48 34 13 102 51 51
-47 34 13 102 51 51
-46 34 13 102 51 51
-45 34 13 102 51 51
-44 34 13 102 51 51
-43 34 13 102 51 51
-42 34 13 102 51 51
-41 34 13 102 51 51
-40 34 13 102 51 51
-39 34 13 102 51 51
-38 34 13 102 51 51
-37 34 13 102 51 51
-34 34 13 102 51 51
-33 34 13 102 51 51
-32 34 13 102 51 51
-31 34 13 102 51 51
-30 34 13 102 51 51
-29 34 13 102 51 51
-28 34 13 102 51 51
-27 34 13 102 51 51
-36 34 13 102 51 51
-35 34 13 102 51 51
-49 34 18 102 51 51
-35 34 12 102 51 51
-49 34 14 102 51 51
-48 34 14 102 51 51
-47 34 14 102 51 51
-46 34 14 102 51 51
-45 34 14 102 51 51
-44 34 14 102 51 51
-43 34 14 102 51 51
-42 34 14 102 51 51
-41 34 14 102 51 51
-40 34 14 102 51 51
-39 34 14 102 51 51
-38 34 14 102 51 51
-37 34 14 102 51 51
-36 34 14 102 51 51
-35 34 14 102 51 51
-34 34 14 102 51 51
-33 34 14 102 51 51
-32 34 14 102 51 51
-31 34 14 102 51 51
-30 34 14 102 51 51
-29 34 14 102 51 51
-28 34 14 102 51 51
-27 34 14 102 51 51
-36 34 12 102 51 51
-48 34 17 102 51 51
-49 34 17 102 51 51
-49 34 15 102 51 51
-48 34 15 102 51 51
-47 34 15 102 51 51
-46 34 15 102 51 51
-45 34 15 102 51 51
-44 34 15 102 51 51
-43 34 15 102 51 51
-42 34 15 102 51 51
-41 34 15 102 51 51
-40 34 15 102 51 51
-39 34 15 102 51 51
-38 34 15 102 51 51
-37 34 15 102 51 51
-36 34 15 102 51 51
-35 34 15 102 51 51
-34 34 15 102 51 51
-33 34 15 102 51 51
-32 34 15 102 51 51
-31 34 15 102 51 51
-30 34 15 102 51 51
-29 34 15 102 51 51
-28 34 15 102 51 51
-27 34 15 102 51 51
-49 34 16 102 51 51
-48 34 16 102 51 51
-47 34 16 102 51 51
-31 34 16 102 51 51
-30 34 16 102 51 51
-29 34 16 102 51 51
-28 34 16 102 51 51
-27 34 16 102 51 51
-37 22 14 42 22 4
-38 22 14 42 22 4
-36 22 14 42 22 4
-39 22 14 42 22 4
-35 22 14 42 22 4
-40 22 14 42 22 4
-34 22 14 42 22 4
-41 22 14 42 22 4
-33 22 14 42 22 4
-42 22 14 42 22 4
-43 22 14 42 22 4
-44 22 14 42 22 4
-45 22 14 42 22 4
-46 22 14 42 22 4
-31 22 15 42 22 4
-32 22 15 42 22 4
-30 22 15 42 22 4
-29 22 15 42 22 4
-28 22 15 42 22 4
-39 20 13 42 22 4
-40 20 13 42 22 4
-39 19 12 42 22 4
-40 19 12 42 22 4
-40 19 13 0 0 0
-41 19 13 42 22 4
-41 20 14 42 22 4
-39 19 13 0 0 0
-38 19 13 42 22 4
-38 20 14 42 22 4
-39 18 12 0 0 0
-40 18 12 0 0 0
-46 15 11 42 22 4
-45 15 11 42 22 4
-44 15 11 42 22 4
-43 15 11 42 22 4
-42 15 11 42 22 4
-41 15 11 42 22 4
-40 15 11 42 22 4
-39 15 11 42 22 4
-38 15 11 42 22 4
-27 22 12 102 51 51
-43 15 12 50 50 50
-35 15 11 42 22 4
-40 15 12 50 50 50
-39 15 12 50 50 50
-42 18 12 0 0 153
-46 16 11 42 22 4
-45 16 11 42 22 4
-44 16 11 42 22 4
-43 16 11 42 22 4
-42 16 11 42 22 4
-41 16 11 42 22 4
-40 16 11 42 22 4
-39 16 11 42 22 4
-38 16 11 42 22 4
-37 16 11 42 22 4
-36 16 11 42 22 4
-35 16 11 42 22 4
-42 18 11 42 22 4
-41 15 12 42 22 4
-38 15 12 42 22 4
-46 17 11 42 22 4
-45 17 11 42 22 4
-44 17 11 42 22 4
-43 17 11 42 22 4
-42 17 11 42 22 4
-41 17 11 42 22 4
-40 17 11 42 22 4
-39 17 11 42 22 4
-38 17 11 42 22 4
-37 17 11 42 22 4
-36 17 11 42 22 4
-35 17 11 42 22 4
-35 15 12 42 22 4
-36 15 12 50 50 50
-37 15 12 50 50 50
-46 18 11 42 22 4
-45 18 11 42 22 4
-44 18 11 42 22 4
-43 18 11 42 22 4
-44 15 12 42 22 4
-41 18 11 42 22 4
-40 18 11 42 22 4
-39 18 11 42 22 4
-37 18 11 42 22 4
-36 18 11 42 22 4
-35 18 11 42 22 4
-37 15 11 42 22 4
-36 15 11 42 22 4
-35 18 12 42 22 4
-46 15 12 0 0 153
-45 15 12 0 0 153
-46 16 12 0 0 153
-46 17 12 67 67 255
-45 18 12 0 0 153
-44 18 12 67 67 255
-43 18 12 0 0 153
-46 18 12 42 22 4
-41 18 12 42 22 4
-38 18 12 42 22 4
-37 18 12 50 50 50
-36 18 12 50 50 50
-34 15 11 42 22 4
-33 15 11 42 22 4
-32 15 11 42 22 4
-34 16 11 42 22 4
-33 16 11 42 22 4
-32 16 11 42 22 4
-34 17 11 42 22 4
-33 17 11 42 22 4
-32 17 11 42 22 4
-34 18 11 42 22 4
-33 18 11 42 22 4
-32 18 11 42 22 4
-34 15 12 50 50 50
-33 15 12 50 50 50
-32 15 12 42 22 4
-34 18 12 50 50 50
-33 18 12 50 50 50
-32 18 12 42 22 4
-31 15 11 42 22 4
-30 15 11 42 22 4
-29 15 11 42 22 4
-31 16 11 42 22 4
-30 16 11 42 22 4
-29 16 11 42 22 4
-31 17 11 42 22 4
-30 17 11 42 22 4
-29 17 11 42 22 4
-31 18 11 42 22 4
-30 18 11 42 22 4
-29 18 11 42 22 4
-31 15 12 50 50 50
-30 15 12 50 50 50
-29 15 12 42 22 4
-31 18 12 50 50 50
-30 18 12 50 50 50
-29 18 12 42 22 4
-28 15 11 42 22 4
-27 15 11 42 22 4
-26 15 11 42 22 4
-28 16 11 42 22 4
-27 16 11 42 22 4
-26 16 11 42 22 4
-28 17 11 42 22 4
-27 17 11 42 22 4
-26 17 11 42 22 4
-28 18 11 42 22 4
-27 18 11 42 22 4
-26 18 11 42 22 4
-28 15 12 50 50 50
-27 15 12 50 50 50
-26 15 12 42 22 4
-28 18 12 50 50 50
-27 18 12 50 50 50
-26 18 12 42 22 4
-25 15 11 42 22 4
-24 15 11 42 22 4
-23 15 11 42 22 4
-25 16 11 42 22 4
-24 16 11 42 22 4
-23 16 11 42 22 4
-25 17 11 42 22 4
-24 17 11 42 22 4
-23 17 11 42 22 4
-25 18 11 42 22 4
-24 18 11 42 22 4
-23 18 11 42 22 4
-25 15 12 50 50 50
-24 15 12 50 50 50
-23 15 12 42 22 4
-25 18 12 50 50 50
-24 18 12 50 50 50
-23 18 12 42 22 4
-22 15 11 42 22 4
-21 15 11 42 22 4
-20 15 11 42 22 4
-22 16 11 42 22 4
-21 16 11 42 22 4
-20 16 11 42 22 4
-22 17 11 42 22 4
-21 17 11 42 22 4
-20 17 11 42 22 4
-22 18 11 42 22 4
-21 18 11 42 22 4
-20 18 11 42 22 4
-22 15 12 50 50 50
-21 15 12 50 50 50
-20 15 12 42 22 4
-22 18 12 50 50 50
-21 18 12 50 50 50
-20 18 12 42 22 4
-19 15 11 42 22 4
-18 15 11 42 22 4
-17 15 11 42 22 4
-19 16 11 42 22 4
-18 16 11 42 22 4
-17 16 11 42 22 4
-19 17 11 42 22 4
-18 17 11 42 22 4
-17 17 11 42 22 4
-19 18 11 42 22 4
-18 18 11 42 22 4
-17 18 11 42 22 4
-19 15 12 50 50 50
-18 15 12 50 50 50
-17 15 12 42 22 4
-19 18 12 50 50 50
-18 18 12 50 50 50
-17 18 12 42 22 4
-56 28 18 255 255 255
