ply
format ascii 1.0
comment : MagicaVoxel @ Ephtracy
element vertex 1169
property float x
property float y
property float z
property uchar red
property uchar green
property uchar blue
end_header
-28 27 16 221 0 0
-41 28 15 255 102 0
-42 28 15 255 102 0
-29 27 16 255 102 0
-41 27 15 221 0 0
-28 26 16 221 0 0
-40 24 14 42 22 4
-29 26 16 255 102 0
-56 26 13 102 51 51
-38 27 14 42 22 4
-39 28 14 42 22 4
-41 24 14 42 22 4
-40 29 14 42 22 4
-55 27 12 102 51 51
-39 26 14 42 22 4
-42 27 15 221 0 0
-41 26 15 221 0 0
-55 22 12 102 51 51
-55 26 12 102 51 51
-40 25 14 42 22 4
-42 26 15 221 0 0
-41 25 15 255 102 0
-42 25 15 255 102 0
-39 27 14 42 22 4
-57 22 15 102 51 51
-39 20 15 255 255 254
-56 22 13 102 51 51
-56 22 14 102 51 51
-40 28 14 42 22 4
-40 20 15 255 255 254
-40 26 14 42 22 4
-46 24 14 42 22 4
-41 20 15 255 255 254
-38 20 15 255 255 254
-46 28 16 255 255 254
-46 25 16 255 255 254
-46 25 15 0 255 133
-46 28 15 0 255 133
-48 22 16 0 0 0
-48 23 16 0 0 0
-49 22 17 0 0 0
-27 31 16 102 51 51
-27 31 15 102 51 51
-19 26 18 42 22 4
-49 23 17 0 0 0
-47 30 15 0 0 0
-19 27 18 42 22 4
-30 26 15 42 22 4
-30 27 15 42 22 4
-24 25 14 102 51 51
-24 28 14 102 51 51
-27 31 14 102 51 51
-18 26 18 42 22 4
-35 32 14 102 51 51
-47 31 15 0 0 0
-28 22 13 102 51 51
-27 30 12 102 51 51
-28 21 13 102 51 51
-25 25 16 0 0 153
-24 26 16 0 0 153
-24 26 15 42 22 4
-34 26 16 50 50 50
-32 27 15 42 22 4
-34 25 16 50 50 50
-31 26 15 42 22 4
-32 26 15 42 22 4
-26 29 13 102 51 51
-28 32 13 102 51 51
-29 32 13 102 51 51
-30 32 13 102 51 51
-31 32 13 102 51 51
-32 32 13 102 51 51
-33 32 13 102 51 51
-34 32 13 102 51 51
-35 32 13 102 51 51
-28 31 12 102 51 51
-41 28 14 255 227 48
-42 28 14 255 227 48
-41 27 14 255 227 48
-42 27 14 255 227 48
-41 26 14 255 227 48
-42 26 14 255 227 48
-41 25 14 255 227 48
-42 25 14 255 227 48
-40 27 14 42 22 4
-44 25 14 42 22 4
-46 29 14 42 22 4
-36 31 14 255 227 49
-45 30 14 42 22 4
-44 31 14 42 22 4
-36 23 14 255 227 49
-37 22 14 42 22 4
-48 30 16 0 0 0
-48 31 16 0 0 0
-49 30 17 0 0 0
-49 31 17 0 0 0
-48 30 15 42 22 4
-49 30 16 42 22 4
-49 31 16 42 22 4
-48 31 15 42 22 4
-47 30 14 42 22 4
-47 31 14 42 22 4
-48 24 18 255 255 254
-46 29 15 0 255 135
-46 29 16 255 255 254
-55 23 12 102 51 51
-39 31 15 67 67 255
-55 24 12 102 51 51
-27 23 16 0 204 0
-28 27 15 255 227 48
-26 24 16 0 204 0
-48 21 16 102 51 51
-55 21 13 102 51 51
-29 32 12 102 51 51
-30 32 12 102 51 51
-31 32 12 102 51 51
-32 32 12 102 51 51
-33 32 12 102 51 51
-34 32 12 102 51 51
-35 32 12 102 51 51
-26 30 16 102 51 51
-25 29 16 102 51 51
-24 28 16 102 51 51
-26 28 12 102 51 51
-34 30 15 255 227 49
-34 32 14 102 51 51
-56 21 13 102 51 51
-30 31 15 42 22 4
-31 31 15 42 22 4
-29 31 15 42 22 4
-57 25 15 102 51 51
-25 28 16 0 204 0
-26 29 16 0 204 0
-33 19 13 0 0 153
-34 19 13 0 0 153
-35 19 13 42 22 4
-36 19 13 50 50 50
-43 19 13 50 50 50
-48 15 13 50 50 50
-48 26 17 102 51 51
-48 25 17 102 51 51
-57 24 15 102 51 51
-47 29 16 102 51 51
-32 31 15 255 227 48
-56 25 14 102 51 51
-56 24 14 102 51 51
-44 23 14 42 22 4
-56 25 13 102 51 51
-56 24 13 102 51 51
-56 23 13 102 51 51
-48 29 17 102 51 51
-29 27 15 255 227 48
-36 21 15 102 51 51
-37 21 15 102 51 51
-38 21 15 102 51 51
-40 20 14 0 0 0
-39 20 14 0 0 0
-41 21 15 102 51 51
-42 21 15 102 51 51
-43 21 15 102 51 51
-44 21 15 102 51 51
-45 21 15 102 51 51
-46 21 15 102 51 51
-47 21 15 102 51 51
-48 21 15 102 51 51
-49 21 15 102 51 51
-51 21 16 102 51 51
-52 21 16 102 51 51
-53 21 16 102 51 51
-53 21 15 102 51 51
-54 21 15 102 51 51
-55 21 15 102 51 51
-56 21 15 102 51 51
-39 32 14 102 51 51
-40 32 14 102 51 51
-41 32 14 102 51 51
-28 31 15 42 22 4
-33 31 15 255 227 49
-43 24 14 42 22 4
-43 22 14 42 22 4
-45 27 14 42 22 4
-42 32 14 102 51 51
-43 32 14 102 51 51
-44 32 14 102 51 51
-45 32 14 102 51 51
-46 32 14 102 51 51
-47 32 14 102 51 51
-48 32 14 102 51 51
-28 26 15 255 227 48
-49 32 14 102 51 51
-43 31 14 42 22 4
-47 24 16 102 51 51
-48 24 17 102 51 51
-16 27 19 42 22 4
-24 27 15 42 22 4
-25 27 15 42 22 4
-29 32 15 102 51 51
-26 27 15 42 22 4
-27 27 15 42 22 4
-30 23 17 255 255 255
-28 32 15 102 51 51
-46 19 13 50 50 50
-30 31 16 67 67 255
-34 32 16 102 51 51
-23 26 16 102 51 51
-45 19 13 50 50 50
-40 15 13 50 50 50
-34 24 16 42 22 4
-27 30 13 102 51 51
-44 26 14 42 22 4
-34 24 15 42 22 4
-34 22 15 255 227 49
-36 21 14 255 255 255
-37 21 14 102 51 51
-38 21 14 102 51 51
-20 27 18 42 22 4
-28 28 15 42 22 4
-41 21 14 102 51 51
-42 21 14 102 51 51
-43 21 14 255 255 255
-44 21 14 255 255 255
-45 21 14 102 51 51
-36 32 13 102 51 51
-33 27 15 42 22 4
-46 21 14 102 51 51
-47 21 14 255 255 255
-48 21 14 255 255 255
-49 21 14 102 51 51
-50 21 14 102 51 51
-54 21 16 102 51 51
-55 21 16 102 51 51
-56 21 16 102 51 51
-48 14 13 42 22 4
-34 27 15 42 22 4
-25 26 15 42 22 4
-54 21 14 102 51 51
-26 26 15 42 22 4
-27 26 15 42 22 4
-29 23 17 255 255 255
-34 26 15 42 22 4
-42 13 13 50 50 50
-56 30 18 0 0 153
-34 23 15 255 227 49
-33 32 14 102 51 51
-55 21 14 102 51 51
-43 14 13 0 204 0
-57 27 18 102 51 51
-33 21 16 102 51 51
-32 32 14 102 51 51
-34 29 16 42 22 4
-49 24 18 102 51 51
-56 28 14 102 51 51
-43 25 14 42 22 4
-45 29 14 42 22 4
-36 30 14 255 227 49
-56 21 14 102 51 51
-31 27 15 42 22 4
-33 17 13 0 0 153
-48 17 13 42 22 4
-33 16 13 67 67 255
-37 32 13 102 51 51
-35 16 13 0 204 0
-38 32 13 102 51 51
-56 23 14 102 51 51
-46 23 14 255 227 49
-33 32 16 102 51 51
-35 24 14 42 22 4
-35 23 14 42 22 4
-35 22 14 42 22 4
-47 22 14 42 22 4
-47 23 14 42 22 4
-47 24 17 255 255 254
-50 21 16 102 51 51
-54 21 12 102 51 51
-53 21 13 102 51 51
-46 31 14 255 227 49
-39 32 13 102 51 51
-40 32 13 102 51 51
-41 32 13 102 51 51
-42 32 13 102 51 51
-55 21 12 102 51 51
-53 21 14 102 51 51
-52 21 14 255 255 255
-51 21 14 255 255 255
-29 26 15 255 227 48
-45 22 14 42 22 4
-52 21 15 102 51 51
-51 21 15 102 51 51
-50 21 15 102 51 51
-54 21 13 102 51 51
-57 26 18 102 51 51
-51 32 18 102 51 51
-43 32 13 102 51 51
-44 32 13 102 51 51
-45 32 13 102 51 51
-52 32 18 102 51 51
-57 27 16 102 51 51
-48 25 14 255 227 49
-47 25 14 255 227 49
-46 25 14 42 22 4
-53 32 18 102 51 51
-54 32 18 102 51 51
-55 32 18 102 51 51
-45 25 14 42 22 4
-45 31 14 42 22 4
-56 32 18 102 51 51
-57 23 18 102 51 51
-57 24 18 102 51 51
-57 25 18 102 51 51
-49 26 15 102 51 51
-49 26 17 42 22 4
-46 32 13 102 51 51
-47 32 13 102 51 51
-48 32 13 102 51 51
-37 31 14 255 227 48
-49 32 13 102 51 51
-55 32 12 102 51 51
-54 32 12 102 51 51
-53 32 12 102 51 51
-54 32 16 102 51 51
-36 21 12 102 51 51
-37 21 12 102 51 51
-38 21 12 102 51 51
-39 21 12 102 51 51
-52 32 12 102 51 51
-40 21 12 102 51 51
-41 21 12 102 51 51
-42 21 12 102 51 51
-43 21 12 102 51 51
-44 21 12 102 51 51
-45 21 12 102 51 51
-46 21 12 102 51 51
-51 32 12 102 51 51
-36 16 13 0 0 153
-48 16 13 50 50 50
-30 32 15 102 51 51
-23 27 16 102 51 51
-32 32 16 102 51 51
-42 14 13 42 22 4
-41 15 13 42 22 4
-34 25 15 42 22 4
-33 26 15 42 22 4
-45 24 14 42 22 4
-29 28 15 42 22 4
-44 19 13 42 22 4
-29 31 16 0 0 153
-29 30 16 0 0 153
-28 31 16 0 0 153
-18 27 18 42 22 4
-18 26 19 42 22 4
-31 32 14 102 51 51
-17 26 19 42 22 4
-30 32 14 102 51 51
-33 15 13 42 22 4
-34 28 16 50 50 50
-24 27 16 67 67 255
-29 32 14 102 51 51
-28 32 14 102 51 51
-34 15 13 0 0 153
-35 15 13 67 67 255
-24 27 14 102 51 51
-48 28 17 102 51 51
-23 27 15 102 51 51
-47 19 13 42 22 4
-33 18 13 0 0 153
-31 32 16 102 51 51
-36 15 13 0 0 153
-37 15 13 0 0 153
-38 15 13 42 22 4
-39 15 13 50 50 50
-30 32 16 102 51 51
-34 18 13 67 67 255
-46 18 13 67 67 255
-47 18 13 67 67 255
-29 32 16 102 51 51
-28 32 16 102 51 51
-39 19 13 0 0 0
-26 30 15 102 51 51
-27 30 15 42 22 4
-28 30 15 42 22 4
-29 30 15 42 22 4
-30 30 15 42 22 4
-31 30 15 42 22 4
-32 30 15 255 227 48
-33 30 15 255 227 49
-25 29 15 102 51 51
-26 29 15 42 22 4
-27 29 15 42 22 4
-28 29 15 42 22 4
-29 29 15 42 22 4
-30 29 15 42 22 4
-31 29 15 42 22 4
-32 29 15 42 22 4
-33 29 15 42 22 4
-24 28 15 102 51 51
-25 28 15 42 22 4
-26 28 15 42 22 4
-27 28 15 42 22 4
-28 31 13 102 51 51
-47 28 17 102 51 51
-30 28 15 42 22 4
-31 28 15 42 22 4
-32 28 15 42 22 4
-33 28 15 42 22 4
-34 21 16 102 51 51
-26 30 14 102 51 51
-48 21 18 102 51 51
-44 30 14 42 22 4
-53 26 18 221 0 0
-57 23 19 50 50 50
-35 25 14 42 22 4
-57 24 19 102 51 51
-57 25 19 50 50 50
-49 32 18 102 51 51
-36 24 14 42 22 4
-37 23 14 42 22 4
-57 25 20 102 51 51
-50 32 12 102 51 51
-39 22 14 42 22 4
-57 23 20 102 51 51
-40 19 13 0 0 0
-37 19 13 50 50 50
-35 21 16 255 255 254
-56 32 13 102 51 51
-55 32 13 102 51 51
-57 24 20 102 51 51
-54 32 13 102 51 51
-53 32 13 102 51 51
-52 32 13 102 51 51
-51 32 13 102 51 51
-50 32 13 102 51 51
-55 25 12 102 51 51
-38 20 14 42 22 4
-41 20 14 42 22 4
-40 20 13 42 22 4
-39 20 13 42 22 4
-56 32 14 102 51 51
-55 32 14 102 51 51
-54 32 14 102 51 51
-53 32 14 102 51 51
-52 32 14 102 51 51
-46 22 14 255 227 49
-56 25 18 0 204 0
-56 21 18 102 51 51
-55 21 18 102 51 51
-54 21 18 102 51 51
-51 32 14 102 51 51
-50 32 14 102 51 51
-56 32 15 102 51 51
-36 21 16 255 255 254
-47 27 17 102 51 51
-53 21 18 102 51 51
-55 32 15 102 51 51
-54 32 15 102 51 51
-52 21 18 102 51 51
-36 21 13 255 255 255
-37 21 13 102 51 51
-38 21 13 102 51 51
-39 21 13 102 51 51
-40 21 13 102 51 51
-41 21 13 102 51 51
-42 21 13 102 51 51
-43 21 13 0 225 255
-44 21 13 255 255 255
-45 21 13 102 51 51
-46 21 13 102 51 51
-47 21 13 0 225 255
-48 21 13 255 255 255
-49 21 13 102 51 51
-50 21 13 102 51 51
-51 21 13 0 225 255
-53 32 15 102 51 51
-47 26 17 102 51 51
-51 21 18 102 51 51
-47 25 17 102 51 51
-50 21 18 102 51 51
-49 21 18 102 51 51
-56 21 19 102 51 51
-54 32 19 50 50 50
-52 32 15 102 51 51
-55 21 19 50 50 50
-51 32 15 102 51 51
-54 21 19 50 50 50
-53 21 19 50 50 50
-52 21 19 50 50 50
-51 21 19 50 50 50
-50 21 19 50 50 50
-37 32 12 102 51 51
-49 21 19 102 51 51
-57 22 18 102 51 51
-57 22 19 102 51 51
-57 22 20 102 51 51
-36 32 15 102 51 51
-53 27 18 221 0 0
-38 22 14 42 22 4
-43 23 14 42 22 4
-42 22 14 42 22 4
-35 28 14 42 22 4
-52 21 13 255 255 255
-55 32 19 50 50 50
-38 32 12 102 51 51
-57 23 15 102 51 51
-48 24 16 102 51 51
-46 27 16 255 255 254
-47 22 15 0 0 0
-39 32 12 102 51 51
-40 32 12 102 51 51
-41 32 12 102 51 51
-42 32 12 102 51 51
-43 32 12 102 51 51
-44 32 12 102 51 51
-45 32 12 102 51 51
-46 32 12 102 51 51
-37 32 15 102 51 51
-53 28 18 255 102 0
-49 27 15 102 51 51
-53 22 18 0 0 153
-47 32 12 102 51 51
-48 32 12 102 51 51
-49 32 12 102 51 51
-50 32 15 102 51 51
-54 22 18 0 0 153
-56 31 17 42 22 4
-55 31 17 42 22 4
-57 23 16 102 51 51
-57 30 17 102 51 51
-38 32 15 102 51 51
-46 21 16 102 51 51
-57 31 17 102 51 51
-47 23 15 0 0 0
-46 26 16 255 255 254
-54 31 17 42 22 4
-51 31 17 42 22 4
-49 28 15 102 51 51
-53 31 17 42 22 4
-47 32 16 102 51 51
-52 31 17 42 22 4
-56 30 17 42 22 4
-49 29 17 102 51 51
-50 32 18 102 51 51
-45 28 14 42 22 4
-44 27 14 42 22 4
-49 28 16 102 51 51
-47 29 17 255 255 254
-39 32 15 102 51 51
-43 26 14 42 22 4
-36 29 14 42 22 4
-44 29 14 42 22 4
-47 24 15 102 51 51
-48 24 15 102 51 51
-47 21 12 102 51 51
-48 21 12 102 51 51
-49 21 12 102 51 51
-50 21 12 102 51 51
-51 21 12 102 51 51
-37 30 14 255 227 48
-40 32 15 102 51 51
-41 32 15 102 51 51
-48 32 18 102 51 51
-57 28 18 102 51 51
-52 29 17 42 22 4
-53 29 17 42 22 4
-54 29 17 42 22 4
-57 26 17 102 51 51
-42 32 15 102 51 51
-43 32 15 102 51 51
-48 32 17 102 51 51
-55 29 17 42 22 4
-49 32 17 102 51 51
-53 26 17 255 227 48
-52 26 17 42 22 4
-49 28 17 42 22 4
-57 29 18 102 51 51
-48 22 15 42 22 4
-57 27 17 102 51 51
-56 27 17 42 22 4
-52 27 17 42 22 4
-57 24 16 102 51 51
-56 32 19 102 51 51
-53 21 12 102 51 51
-52 21 12 102 51 51
-56 28 13 102 51 51
-57 26 15 102 51 51
-40 22 14 42 22 4
-38 31 14 42 22 4
-39 21 14 255 227 49
-43 30 14 42 22 4
-35 26 14 42 22 4
-48 18 13 0 0 153
-23 26 15 102 51 51
-36 25 14 42 22 4
-37 24 14 42 22 4
-38 23 14 42 22 4
-49 27 17 42 22 4
-40 31 16 67 67 255
-40 31 15 67 67 255
-41 31 17 255 255 255
-42 31 17 255 255 255
-43 31 17 255 255 255
-41 31 16 255 255 255
-43 31 16 255 255 255
-49 32 16 102 51 51
-42 23 14 42 22 4
-41 22 14 42 22 4
-35 27 14 42 22 4
-36 28 14 42 22 4
-44 28 14 42 22 4
-46 24 15 0 255 134
-47 32 17 102 51 51
-38 32 14 102 51 51
-37 32 14 102 51 51
-36 32 14 102 51 51
-43 27 14 42 22 4
-37 29 14 42 22 4
-43 29 14 42 22 4
-56 29 17 42 22 4
-57 29 17 102 51 51
-57 27 19 50 50 50
-57 26 19 50 50 50
-52 28 17 42 22 4
-57 28 17 102 51 51
-56 28 17 42 22 4
-38 30 14 42 22 4
-57 23 17 102 51 51
-56 23 17 42 22 4
-55 23 17 42 22 4
-54 23 17 42 22 4
-53 23 17 42 22 4
-44 32 15 102 51 51
-45 32 15 102 51 51
-46 32 15 102 51 51
-52 23 17 42 22 4
-57 30 20 102 51 51
-57 31 18 102 51 51
-49 27 16 102 51 51
-51 28 17 42 22 4
-57 30 18 102 51 51
-57 24 17 102 51 51
-56 24 17 42 22 4
-53 24 17 42 22 4
-52 24 17 42 22 4
-47 32 15 102 51 51
-48 32 15 102 51 51
-49 32 15 102 51 51
-57 29 19 102 51 51
-56 27 18 255 255 255
-51 22 17 42 22 4
-57 25 17 102 51 51
-50 32 17 102 51 51
-51 32 17 102 51 51
-52 32 17 102 51 51
-42 31 16 255 255 255
-41 31 15 255 255 255
-36 32 12 102 51 51
-53 32 17 102 51 51
-54 32 17 102 51 51
-55 32 17 102 51 51
-56 32 17 102 51 51
-42 31 15 255 255 255
-43 31 15 153 51 205
-48 23 15 42 22 4
-53 25 17 255 227 48
-54 22 17 42 22 4
-49 23 16 42 22 4
-57 30 16 102 51 51
-49 25 16 102 51 51
-56 27 13 102 51 51
-56 26 14 102 51 51
-56 27 14 102 51 51
-55 28 12 102 51 51
-55 22 17 42 22 4
-49 22 16 42 22 4
-46 26 15 0 255 133
-39 31 14 42 22 4
-42 30 14 42 22 4
-57 29 15 102 51 51
-57 28 16 102 51 51
-57 28 15 102 51 51
-52 25 17 42 22 4
-36 26 14 42 22 4
-37 25 14 42 22 4
-38 24 14 42 22 4
-46 24 16 255 255 254
-39 23 14 42 22 4
-41 23 14 42 22 4
-36 22 14 255 227 49
-36 27 14 42 22 4
-37 28 14 42 22 4
-57 29 20 102 51 51
-56 22 17 42 22 4
-43 28 14 42 22 4
-38 29 14 42 22 4
-52 22 17 42 22 4
-53 22 17 42 22 4
-49 24 17 102 51 51
-42 29 14 42 22 4
-55 30 17 42 22 4
-49 21 16 102 51 51
-48 29 16 102 51 51
-56 32 16 102 51 51
-47 21 17 102 51 51
-54 30 17 42 22 4
-49 25 15 102 51 51
-48 26 14 255 227 49
-47 26 14 255 227 49
-46 26 14 42 22 4
-57 31 19 102 51 51
-53 30 17 42 22 4
-52 30 17 42 22 4
-45 23 14 42 22 4
-44 24 14 42 22 4
-54 25 17 42 22 4
-55 25 17 42 22 4
-56 25 17 42 22 4
-48 29 18 255 255 254
-35 32 16 255 255 254
-54 24 17 42 22 4
-33 25 15 42 22 4
-35 22 15 0 0 0
-46 30 14 255 227 49
-55 24 17 42 22 4
-57 26 16 102 51 51
-48 27 14 255 227 49
-47 27 14 255 227 49
-46 27 14 42 22 4
-25 24 15 102 51 51
-53 27 17 255 227 48
-54 27 17 42 22 4
-44 22 14 42 22 4
-45 26 14 42 22 4
-56 21 17 102 51 51
-55 21 17 102 51 51
-54 21 17 102 51 51
-53 21 17 102 51 51
-52 21 17 102 51 51
-51 21 17 102 51 51
-50 21 17 102 51 51
-49 21 17 102 51 51
-48 21 17 102 51 51
-55 27 17 42 22 4
-39 30 14 42 22 4
-50 31 17 255 227 49
-57 30 19 50 50 50
-50 23 17 255 227 49
-50 22 17 255 227 49
-54 26 17 42 22 4
-57 22 17 102 51 51
-57 27 15 102 51 51
-57 29 16 102 51 51
-46 27 15 0 255 133
-41 30 14 42 22 4
-34 28 15 42 22 4
-56 29 14 102 51 51
-24 25 15 102 51 51
-55 26 17 42 22 4
-51 23 17 42 22 4
-56 26 17 42 22 4
-55 28 17 42 22 4
-25 25 15 42 22 4
-54 28 17 42 22 4
-53 28 17 255 227 48
-49 25 17 42 22 4
-48 32 16 102 51 51
-26 25 15 42 22 4
-27 25 15 42 22 4
-26 24 15 42 22 4
-50 32 16 102 51 51
-37 26 14 42 22 4
-28 25 15 42 22 4
-56 31 18 0 0 153
-40 21 14 255 227 49
-24 25 16 102 51 51
-27 24 15 42 22 4
-46 28 14 42 22 4
-47 28 14 255 227 49
-48 28 14 255 227 49
-57 25 16 102 51 51
-55 31 18 67 67 255
-56 26 18 0 255 205
-28 24 15 42 22 4
-38 25 14 42 22 4
-42 31 14 42 22 4
-47 28 15 0 0 153
-48 28 15 0 0 153
-53 25 18 255 102 0
-29 25 15 42 22 4
-30 25 15 42 22 4
-47 29 15 102 51 51
-48 29 15 102 51 51
-57 22 16 102 51 51
-41 31 14 42 22 4
-40 31 14 42 22 4
-29 24 15 42 22 4
-30 24 15 42 22 4
-39 24 14 42 22 4
-40 23 14 42 22 4
-37 27 14 42 22 4
-38 28 14 42 22 4
-31 24 15 42 22 4
-42 24 14 42 22 4
-32 24 15 42 22 4
-39 29 14 42 22 4
-55 31 12 102 51 51
-55 30 12 102 51 51
-41 29 14 42 22 4
-57 26 20 102 51 51
-57 31 15 102 51 51
-31 25 15 42 22 4
-56 31 13 102 51 51
-56 31 14 102 51 51
-40 30 14 42 22 4
-57 27 20 102 51 51
-51 32 19 50 50 50
-57 30 15 102 51 51
-38 26 14 42 22 4
-51 24 17 42 22 4
-39 25 14 42 22 4
-56 29 13 102 51 51
-33 24 15 42 22 4
-55 29 12 102 51 51
-32 25 15 42 22 4
-56 30 14 102 51 51
-56 30 13 102 51 51
-50 24 17 42 22 4
-28 22 16 0 0 153
-29 22 16 255 255 255
-29 23 16 255 255 255
-30 23 16 255 255 255
-35 31 15 0 0 0
-33 21 14 102 51 51
-32 21 13 255 255 255
-33 21 13 102 51 51
-30 22 16 153 0 153
-36 32 16 255 255 254
-34 29 15 42 22 4
-31 21 14 255 255 255
-31 21 13 0 225 255
-28 22 15 42 22 4
-28 21 16 102 51 51
-29 21 16 102 51 51
-30 21 16 102 51 51
-31 21 16 102 51 51
-27 23 12 102 51 51
-27 23 13 102 51 51
-48 27 17 102 51 51
-32 21 16 102 51 51
-28 21 15 102 51 51
-29 21 15 102 51 51
-34 31 15 255 227 49
-30 21 15 102 51 51
-31 21 15 102 51 51
-32 21 15 102 51 51
-33 21 15 102 51 51
-34 21 15 102 51 51
-35 21 15 102 51 51
-28 21 14 102 51 51
-29 21 14 102 51 51
-30 21 14 102 51 51
-29 21 12 102 51 51
-25 28 13 102 51 51
-31 32 15 102 51 51
-25 25 13 102 51 51
-32 32 15 102 51 51
-21 27 18 42 22 4
-33 32 15 102 51 51
-30 21 12 102 51 51
-31 21 12 102 51 51
-34 21 14 102 51 51
-35 21 14 255 255 255
-34 32 15 102 51 51
-26 29 12 102 51 51
-27 22 14 102 51 51
-51 25 17 42 22 4
-35 30 15 0 0 0
-26 23 14 102 51 51
-35 32 15 102 51 51
-50 25 17 42 22 4
-35 29 15 102 51 51
-25 24 14 102 51 51
-51 26 17 42 22 4
-26 23 15 102 51 51
-24 26 14 102 51 51
-32 21 12 102 51 51
-33 21 12 102 51 51
-34 21 12 102 51 51
-35 21 12 102 51 51
-35 31 14 42 22 4
-17 27 19 42 22 4
-27 22 16 102 51 51
-35 24 15 102 51 51
-35 23 15 0 0 0
-38 19 13 42 22 4
-41 19 13 42 22 4
-42 19 13 50 50 50
-28 22 12 102 51 51
-32 21 14 255 255 255
-29 22 15 42 22 4
-30 22 15 42 22 4
-31 22 15 42 22 4
-33 22 15 42 22 4
-32 22 15 42 22 4
-35 30 14 42 22 4
-29 21 13 102 51 51
-30 21 13 102 51 51
-34 21 13 102 51 51
-35 21 13 0 225 255
-50 32 19 50 50 50
-26 23 16 102 51 51
-35 29 14 42 22 4
-25 24 16 102 51 51
-27 22 15 102 51 51
-33 23 15 42 22 4
-32 23 15 42 22 4
-31 23 15 42 22 4
-30 23 15 42 22 4
-29 23 15 42 22 4
-28 23 15 42 22 4
-27 23 15 42 22 4
-49 27 18 50 50 50
-46 32 16 102 51 51
-50 27 17 42 22 4
-52 32 19 50 50 50
-56 28 18 0 204 0
-51 27 17 42 22 4
-49 32 19 102 51 51
-49 26 18 50 50 50
-49 25 18 50 50 50
-53 32 19 50 50 50
-50 26 17 42 22 4
-47 21 16 102 51 51
-50 30 17 255 227 49
-57 28 19 50 50 50
-51 30 17 42 22 4
-50 29 17 42 22 4
-51 32 16 102 51 51
-51 29 17 42 22 4
-52 32 16 102 51 51
-53 32 16 102 51 51
-57 31 16 102 51 51
-55 32 16 102 51 51
-50 28 17 42 22 4
-49 29 18 102 51 51
-57 28 20 102 51 51
-49 28 18 50 50 50
-57 31 20 102 51 51
-49 26 16 102 51 51
-47 11 14 0 0 153
-47 12 14 0 0 153
-33 19 14 0 0 153
-48 2 12 42 22 4
-47 2 12 42 22 4
-46 2 12 42 22 4
-45 2 12 42 22 4
-44 2 12 42 22 4
-43 2 12 42 22 4
-42 2 12 42 22 4
-48 3 12 42 22 4
-47 3 12 42 22 4
-46 3 12 42 22 4
-45 3 12 42 22 4
-44 3 12 42 22 4
-43 3 12 42 22 4
-42 3 12 42 22 4
-48 4 12 42 22 4
-47 4 12 42 22 4
-46 4 12 42 22 4
-45 4 12 42 22 4
-44 4 12 42 22 4
-43 4 12 42 22 4
-42 4 12 42 22 4
-48 5 12 42 22 4
-47 5 12 42 22 4
-46 5 12 42 22 4
-45 5 12 42 22 4
-44 5 12 42 22 4
-43 5 12 42 22 4
-42 5 12 42 22 4
-48 6 12 42 22 4
-47 6 12 42 22 4
-46 6 12 42 22 4
-45 6 12 42 22 4
-44 6 12 42 22 4
-43 6 12 42 22 4
-42 6 12 42 22 4
-48 7 12 42 22 4
-47 7 12 42 22 4
-46 7 12 42 22 4
-45 7 12 42 22 4
-44 7 12 42 22 4
-43 7 12 42 22 4
-42 7 12 42 22 4
-48 8 12 42 22 4
-47 8 12 42 22 4
-46 8 12 42 22 4
-45 8 12 42 22 4
-44 8 12 42 22 4
-43 8 12 42 22 4
-42 8 12 42 22 4
-48 9 12 42 22 4
-47 9 12 42 22 4
-46 9 12 42 22 4
-45 9 12 42 22 4
-44 9 12 42 22 4
-43 9 12 42 22 4
-42 9 12 42 22 4
-48 10 12 42 22 4
-47 10 12 42 22 4
-46 10 12 42 22 4
-45 10 12 42 22 4
-44 10 12 42 22 4
-43 10 12 42 22 4
-42 10 12 42 22 4
-48 11 12 42 22 4
-47 11 12 42 22 4
-46 11 12 42 22 4
-45 11 12 42 22 4
-44 11 12 42 22 4
-43 11 12 42 22 4
-42 11 12 42 22 4
-48 12 12 42 22 4
-47 12 12 42 22 4
-46 12 12 42 22 4
-45 12 12 42 22 4
-44 12 12 42 22 4
-43 12 12 42 22 4
-42 12 12 42 22 4
-48 13 12 42 22 4
-47 13 12 42 22 4
-46 13 12 42 22 4
-45 13 12 42 22 4
-44 13 12 42 22 4
-43 13 12 42 22 4
-42 13 12 42 22 4
-48 14 12 42 22 4
-47 14 12 42 22 4
-46 14 12 42 22 4
-45 14 12 42 22 4
-44 14 12 42 22 4
-43 14 12 42 22 4
-42 14 12 42 22 4
-48 15 12 42 22 4
-47 15 12 42 22 4
-46 15 12 42 22 4
-45 15 12 42 22 4
-44 15 12 42 22 4
-43 15 12 42 22 4
-42 15 12 42 22 4
-41 15 12 42 22 4
-40 15 12 42 22 4
-39 15 12 42 22 4
-38 15 12 42 22 4
-37 15 12 42 22 4
-36 15 12 42 22 4
-35 15 12 42 22 4
-34 15 12 42 22 4
-33 15 12 42 22 4
-48 16 12 42 22 4
-47 16 12 42 22 4
-46 16 12 42 22 4
-45 16 12 42 22 4
-44 16 12 42 22 4
-43 16 12 42 22 4
-42 16 12 42 22 4
-41 16 12 42 22 4
-40 16 12 42 22 4
-39 16 12 42 22 4
-38 16 12 42 22 4
-37 16 12 42 22 4
-36 16 12 42 22 4
-35 16 12 42 22 4
-34 16 12 42 22 4
-33 16 12 42 22 4
-48 17 12 42 22 4
-47 17 12 42 22 4
-46 17 12 42 22 4
-45 17 12 42 22 4
-44 17 12 42 22 4
-43 17 12 42 22 4
-42 17 12 42 22 4
-41 17 12 42 22 4
-40 17 12 42 22 4
-39 17 12 42 22 4
-38 17 12 42 22 4
-37 17 12 42 22 4
-36 17 12 42 22 4
-35 17 12 42 22 4
-34 17 12 42 22 4
-33 17 12 42 22 4
-48 18 12 42 22 4
-47 18 12 42 22 4
-46 18 12 42 22 4
-45 18 12 42 22 4
-44 18 12 42 22 4
-43 18 12 42 22 4
-42 18 12 42 22 4
-41 18 12 42 22 4
-40 18 12 255 227 49
-39 18 12 255 227 49
-38 18 12 42 22 4
-37 18 12 42 22 4
-36 18 12 42 22 4
-35 18 12 42 22 4
-34 18 12 42 22 4
-33 18 12 42 22 4
-47 19 12 42 22 4
-46 19 12 42 22 4
-45 19 12 42 22 4
-44 19 12 42 22 4
-43 19 12 42 22 4
-42 19 12 42 22 4
-41 19 12 42 22 4
-40 19 12 42 22 4
-39 19 12 42 22 4
-38 19 12 42 22 4
-37 19 12 42 22 4
-36 19 12 42 22 4
-35 19 12 42 22 4
-34 19 12 42 22 4
-33 19 12 42 22 4
-48 2 13 42 22 4
-42 2 13 42 22 4
-48 3 13 50 50 50
-42 3 13 50 50 50
-48 4 13 50 50 50
-42 4 13 50 50 50
-48 5 13 42 22 4
-42 5 13 42 22 4
-48 6 13 50 50 50
-42 6 13 50 50 50
-48 7 13 50 50 50
-42 7 13 50 50 50
-48 8 13 42 22 4
-42 8 13 42 22 4
-48 9 13 50 50 50
-42 9 13 50 50 50
-48 10 13 50 50 50
-47 10 13 0 0 153
-42 10 13 50 50 50
-48 11 13 42 22 4
-47 11 13 0 0 153
-42 11 13 42 22 4
-48 12 13 50 50 50
-47 12 13 0 0 153
-46 12 13 0 0 153
-42 12 13 50 50 50
-48 13 13 50 50 50
-43 13 13 67 67 255
-18 27 19 42 22 4
-16 26 19 42 22 4
-22 26 16 42 22 4
-22 27 16 42 22 4
-23 26 17 42 22 4
-22 26 17 42 22 4
-21 26 17 42 22 4
-23 27 17 42 22 4
-22 27 17 42 22 4
-21 27 17 42 22 4
-21 26 18 42 22 4
-20 26 18 42 22 4
-25 29 14 102 51 51
-24 27 13 102 51 51
-24 26 13 102 51 51
-26 24 13 102 51 51
-26 24 12 102 51 51
-26 25 12 102 51 51
-26 26 12 102 51 51
-26 27 12 102 51 51
-34 27 16 50 50 50
-33 27 16 255 145 236
