ply
format ascii 1.0
comment : MagicaVoxel @ Ephtracy
element vertex 1206
property float x
property float y
property float z
property uchar red
property uchar green
property uchar blue
end_header
-28 18 11 42 22 4
-33 15 12 0 0 153
-34 15 12 0 0 153
-33 14 12 67 67 255
-36 9 15 102 51 51
-35 15 14 102 51 51
-35 10 14 102 51 51
-32 14 12 0 255 133
-32 11 12 0 255 133
-34 16 13 102 51 51
-35 16 13 102 51 51
-33 16 12 102 51 51
-34 16 12 102 51 51
-35 16 12 102 51 51
-36 7 14 42 22 4
-27 18 11 42 22 4
-26 18 11 42 22 4
-41 7 9 102 51 51
-25 18 11 42 22 4
-24 18 11 42 22 4
-43 7 17 102 51 51
-43 7 16 102 51 51
-43 7 15 102 51 51
-43 7 14 102 51 51
-43 7 12 102 51 51
-43 7 13 102 51 51
-42 7 10 102 51 51
-42 7 11 102 51 51
-43 18 16 102 51 51
-43 17 16 50 50 50
-43 18 17 102 51 51
-19 18 11 42 22 4
-23 18 11 42 22 4
-20 18 11 42 22 4
-22 18 11 42 22 4
-43 17 17 102 51 51
-41 18 9 102 51 51
-41 17 9 102 51 51
-43 18 15 102 51 51
-43 18 14 102 51 51
-43 18 12 102 51 51
-43 18 13 102 51 51
-42 18 10 102 51 51
-42 18 11 102 51 51
-43 17 15 102 51 51
-43 17 14 102 51 51
-21 18 11 42 22 4
-43 17 12 102 51 51
-18 18 12 42 22 4
-13 18 12 42 22 4
-17 18 12 42 22 4
-14 18 12 42 22 4
-16 18 12 42 22 4
-15 18 12 42 22 4
-13 7 12 42 22 4
-43 17 13 102 51 51
-42 17 11 102 51 51
-42 17 10 102 51 51
-42 18 14 42 22 4
-41 18 14 42 22 4
-36 18 14 42 22 4
-40 18 14 42 22 4
-37 18 14 42 22 4
-39 18 14 42 22 4
-38 18 14 42 22 4
-42 17 14 42 22 4
-41 17 14 42 22 4
-36 17 14 42 22 4
-40 17 14 42 22 4
-37 17 14 42 22 4
-39 17 14 42 22 4
-38 17 14 42 22 4
-32 18 11 42 22 4
-31 18 11 42 22 4
-30 18 11 42 22 4
-29 18 11 42 22 4
-35 6 16 102 51 51
-36 6 16 50 50 50
-37 6 16 50 50 50
-38 6 16 50 50 50
-39 6 16 50 50 50
-40 6 16 50 50 50
-41 6 16 50 50 50
-42 6 16 102 51 51
-35 6 15 102 51 51
-36 6 15 102 51 51
-37 6 15 102 51 51
-38 6 15 102 51 51
-39 6 15 102 51 51
-40 6 15 102 51 51
-41 6 15 102 51 51
-42 6 15 102 51 51
-34 6 14 102 51 51
-35 6 14 102 51 51
-36 6 14 102 51 51
-37 6 14 102 51 51
-38 6 14 102 51 51
-39 6 14 102 51 51
-40 6 14 102 51 51
-41 6 14 102 51 51
-42 6 14 102 51 51
-13 6 13 102 51 51
-14 6 13 102 51 51
-15 6 13 102 51 51
-16 6 13 102 51 51
-41 8 9 102 51 51
-12 8 9 102 51 51
-41 9 9 102 51 51
-11 9 9 102 51 51
-41 10 9 102 51 51
-11 10 9 102 51 51
-41 11 9 102 51 51
-11 11 9 102 51 51
-41 12 9 102 51 51
-11 12 9 102 51 51
-41 13 9 102 51 51
-11 13 9 102 51 51
-41 14 9 102 51 51
-11 14 9 102 51 51
-41 15 9 102 51 51
-11 15 9 102 51 51
-41 16 9 102 51 51
-11 16 9 102 51 51
-40 14 15 255 102 0
-40 13 15 221 0 0
-40 12 15 221 0 0
-40 11 15 255 102 0
-9 13 13 67 67 255
-9 14 13 0 0 153
-12 17 9 102 51 51
-17 6 13 102 51 51
-33 6 13 102 51 51
-34 6 13 102 51 51
-35 6 13 102 51 51
-36 6 13 102 51 51
-37 6 13 102 51 51
-38 6 13 102 51 51
-39 6 13 102 51 51
-40 6 13 102 51 51
-41 6 13 102 51 51
-42 6 13 102 51 51
-13 6 12 102 51 51
-14 6 12 102 51 51
-16 17 13 0 204 0
-16 8 13 0 204 0
-15 6 12 102 51 51
-16 6 12 102 51 51
-17 6 12 102 51 51
-18 6 12 102 51 51
-19 6 12 102 51 51
-20 6 12 102 51 51
-21 6 12 102 51 51
-22 6 12 102 51 51
-23 6 12 102 51 51
-24 6 12 102 51 51
-26 5 11 0 0 0
-25 5 11 0 0 0
-27 6 12 102 51 51
-28 6 12 102 51 51
-29 6 12 102 51 51
-30 6 12 102 51 51
-31 6 12 102 51 51
-32 6 12 102 51 51
-33 6 12 102 51 51
-34 6 12 102 51 51
-35 6 12 102 51 51
-36 6 12 102 51 51
-37 6 12 102 51 51
-38 6 12 102 51 51
-39 6 12 102 51 51
-40 6 12 102 51 51
-41 6 12 102 51 51
-42 6 12 102 51 51
-13 6 11 102 51 51
-14 6 11 102 51 51
-15 6 11 102 51 51
-16 6 11 255 255 255
-17 6 11 255 255 255
-43 9 17 102 51 51
-43 8 17 102 51 51
-43 10 17 102 51 51
-43 11 17 102 51 51
-12 7 10 102 51 51
-42 8 10 102 51 51
-11 8 10 102 51 51
-42 9 10 102 51 51
-10 9 10 102 51 51
-42 10 10 102 51 51
-10 10 10 102 51 51
-42 11 10 102 51 51
-9 11 10 102 51 51
-42 12 10 102 51 51
-9 12 10 102 51 51
-42 13 10 102 51 51
-9 13 10 102 51 51
-42 14 10 102 51 51
-9 14 10 102 51 51
-42 15 10 102 51 51
-10 15 10 102 51 51
-42 16 10 102 51 51
-10 16 10 102 51 51
-13 12 13 255 102 0
-14 12 13 221 0 0
-42 15 15 0 204 0
-42 12 15 0 255 204
-18 6 11 102 51 51
-12 18 11 102 51 51
-12 18 10 102 51 51
-11 17 10 102 51 51
-19 6 11 102 51 51
-20 6 11 102 51 51
-21 6 11 255 255 255
-22 6 11 255 255 255
-23 6 11 102 51 51
-24 6 11 102 51 51
-25 6 11 102 51 51
-26 6 11 102 51 51
-27 6 11 102 51 51
-28 6 11 102 51 51
-29 6 11 255 255 255
-30 6 11 255 255 255
-31 6 11 102 51 51
-42 10 15 0 204 0
-21 17 11 42 22 4
-32 6 11 102 51 51
-33 6 11 255 255 255
-34 6 11 255 255 255
-35 6 11 102 51 51
-36 6 11 102 51 51
-37 6 11 255 255 255
-38 6 11 255 255 255
-39 6 11 102 51 51
-43 12 17 102 51 51
-43 13 17 102 51 51
-22 13 18 168 168 168
-40 6 11 102 51 51
-14 13 17 168 168 168
-43 16 16 102 51 51
-43 15 16 50 50 50
-43 14 16 102 51 51
0 13 16 42 22 4
-1 13 16 42 22 4
-2 13 16 42 22 4
-14 13 16 168 168 168
-41 6 11 102 51 51
-22 13 19 168 168 168
-43 13 16 50 50 50
0 12 16 42 22 4
-1 12 16 42 22 4
-2 12 16 42 22 4
-43 12 16 50 50 50
-43 11 16 102 51 51
-43 10 16 50 50 50
-43 9 16 102 51 51
-43 8 16 50 50 50
-42 6 11 102 51 51
-43 14 17 102 51 51
-43 15 17 102 51 51
-43 16 17 102 51 51
-22 13 17 168 168 168
-13 6 10 102 51 51
-14 13 18 168 168 168
-12 7 11 102 51 51
-42 8 11 102 51 51
-32 8 11 42 22 4
-31 8 11 42 22 4
-30 8 11 42 22 4
-29 8 11 42 22 4
-28 8 11 42 22 4
-27 8 11 42 22 4
-26 8 11 42 22 4
-25 8 11 42 22 4
-24 8 11 42 22 4
-23 8 11 42 22 4
-22 8 11 42 22 4
-21 8 11 42 22 4
-20 8 11 42 22 4
-19 8 11 42 22 4
-11 8 11 102 51 51
-42 9 11 102 51 51
-32 9 11 42 22 4
-31 9 11 42 22 4
-30 9 11 42 22 4
-29 9 11 42 22 4
-28 9 11 42 22 4
-27 9 11 42 22 4
-26 9 11 42 22 4
-25 9 11 42 22 4
-24 9 11 42 22 4
-23 9 11 42 22 4
-22 9 11 42 22 4
-21 9 11 42 22 4
-20 9 11 42 22 4
-19 9 11 42 22 4
-10 9 11 102 51 51
-42 10 11 102 51 51
-35 10 11 42 22 4
-34 10 11 42 22 4
-33 10 11 42 22 4
-32 10 11 42 22 4
-31 10 11 42 22 4
-30 10 11 42 22 4
-29 10 11 42 22 4
-28 10 11 42 22 4
-27 10 11 42 22 4
-26 10 11 42 22 4
-25 10 11 42 22 4
-24 10 11 42 22 4
-23 10 11 42 22 4
-22 10 11 42 22 4
-21 10 11 42 22 4
-20 10 11 42 22 4
-19 10 11 42 22 4
-9 10 11 102 51 51
-42 11 11 102 51 51
-35 11 11 42 22 4
-34 11 11 42 22 4
-33 11 11 42 22 4
-32 11 11 42 22 4
-31 11 11 42 22 4
-30 11 11 42 22 4
-29 11 11 42 22 4
-28 11 11 42 22 4
-27 11 11 42 22 4
-26 11 11 42 22 4
-25 11 11 42 22 4
-24 11 11 42 22 4
-23 11 11 42 22 4
-22 11 11 42 22 4
-21 11 11 42 22 4
-20 11 11 42 22 4
-19 11 11 42 22 4
-9 11 11 102 51 51
-42 12 11 102 51 51
-35 12 11 42 22 4
-34 12 11 42 22 4
-33 12 11 42 22 4
-32 12 11 42 22 4
-31 12 11 42 22 4
-30 12 11 42 22 4
-29 12 11 42 22 4
-28 12 11 42 22 4
-27 12 11 42 22 4
-26 12 11 42 22 4
-25 12 11 42 22 4
-24 12 11 42 22 4
-23 12 11 42 22 4
-22 12 11 42 22 4
-21 12 11 42 22 4
-20 12 11 42 22 4
-19 12 11 42 22 4
-8 12 11 102 51 51
-42 13 11 102 51 51
-35 13 11 42 22 4
-34 13 11 42 22 4
-33 13 11 42 22 4
-32 13 11 42 22 4
-31 13 11 42 22 4
-30 13 11 42 22 4
-29 13 11 42 22 4
-28 13 11 42 22 4
-27 13 11 42 22 4
-26 13 11 42 22 4
-25 13 11 42 22 4
-24 13 11 42 22 4
-23 13 11 42 22 4
-22 17 11 42 22 4
-21 13 11 42 22 4
-20 13 11 42 22 4
-19 13 11 42 22 4
-8 13 11 102 51 51
-42 14 11 102 51 51
-35 14 11 42 22 4
-34 14 11 42 22 4
-33 14 11 42 22 4
-32 14 11 42 22 4
-31 14 11 42 22 4
-30 14 11 42 22 4
-29 14 11 42 22 4
-28 14 11 42 22 4
-27 14 11 42 22 4
-26 14 11 42 22 4
-25 14 11 42 22 4
-24 14 11 42 22 4
-23 14 11 42 22 4
-21 16 11 42 22 4
-21 14 11 42 22 4
-20 14 11 42 22 4
-19 14 11 42 22 4
-9 14 11 102 51 51
-42 15 11 102 51 51
-35 15 11 42 22 4
-34 15 11 42 22 4
-33 15 11 42 22 4
-32 15 11 42 22 4
-31 15 11 42 22 4
-30 15 11 42 22 4
-29 15 11 42 22 4
-28 15 11 42 22 4
-27 15 11 42 22 4
-26 15 11 42 22 4
-25 15 11 42 22 4
-24 15 11 42 22 4
-23 15 11 42 22 4
-22 16 11 42 22 4
-14 13 21 168 168 168
-20 15 11 42 22 4
-19 15 11 42 22 4
-9 15 11 102 51 51
-42 16 11 102 51 51
-32 16 11 42 22 4
-31 16 11 42 22 4
-30 16 11 42 22 4
-29 16 11 42 22 4
-28 16 11 42 22 4
-27 16 11 42 22 4
-26 16 11 42 22 4
-25 16 11 42 22 4
-24 16 11 42 22 4
-23 16 11 42 22 4
-21 15 11 42 22 4
-14 13 20 168 168 168
-20 16 11 42 22 4
-19 16 11 42 22 4
-10 16 11 102 51 51
-12 18 12 102 51 51
-12 18 13 102 51 51
-19 18 12 0 0 0
-19 17 12 0 0 0
-19 16 12 102 51 51
-26 16 12 0 255 204
-22 11 12 255 102 0
-32 17 11 42 22 4
-31 17 11 42 22 4
-30 17 11 42 22 4
-29 17 11 42 22 4
-28 17 11 42 22 4
-27 17 11 42 22 4
-26 17 11 42 22 4
-25 17 11 42 22 4
-24 17 11 42 22 4
-23 17 11 42 22 4
-22 15 11 42 22 4
-32 0 10 0 0 153
-20 17 11 42 22 4
-19 17 11 42 22 4
-11 17 11 102 51 51
-14 6 10 102 51 51
-15 6 10 102 51 51
-16 6 10 0 225 255
-17 6 10 255 255 255
-18 6 10 102 51 51
-19 6 10 102 51 51
-20 6 10 102 51 51
-21 6 10 0 225 255
-22 6 10 255 255 255
-23 6 10 102 51 51
-24 6 10 102 51 51
-25 6 10 102 51 51
-26 6 10 102 51 51
-27 6 10 102 51 51
-28 6 10 102 51 51
-29 6 10 0 225 255
-30 6 10 255 255 255
-31 6 10 102 51 51
-32 6 10 102 51 51
-33 6 10 0 225 255
-34 6 10 255 255 255
-35 6 10 102 51 51
-36 6 10 102 51 51
-37 6 10 0 225 255
-36 16 15 102 51 51
-43 16 15 102 51 51
-36 15 15 50 50 50
-43 15 15 102 51 51
-36 14 15 50 50 50
-43 14 15 102 51 51
-2 13 15 42 22 4
-3 13 15 42 22 4
-4 13 15 42 22 4
-5 13 15 42 22 4
-14 13 15 168 168 168
-22 13 11 42 22 4
-22 13 20 168 168 168
-36 13 15 50 50 50
-43 13 15 102 51 51
-2 12 15 42 22 4
-3 12 15 42 22 4
-4 12 15 42 22 4
-5 12 15 42 22 4
-36 12 15 50 50 50
-43 12 15 102 51 51
-36 11 15 50 50 50
-43 11 15 102 51 51
-36 10 15 50 50 50
-43 10 15 102 51 51
-43 9 15 102 51 51
-43 8 15 102 51 51
-38 6 10 255 255 255
-39 6 10 102 51 51
-12 7 12 102 51 51
-43 8 12 102 51 51
-34 8 12 42 22 4
-33 8 12 0 0 0
-32 10 12 0 255 134
-18 8 12 42 22 4
-17 8 12 42 22 4
-16 8 12 42 22 4
-15 8 12 42 22 4
-14 8 12 42 22 4
-13 8 12 42 22 4
-12 8 12 42 22 4
-11 8 12 102 51 51
-43 9 12 102 51 51
-41 7 14 42 22 4
-40 7 14 42 22 4
-18 19 13 102 51 51
-18 9 12 42 22 4
-17 9 12 42 22 4
-16 9 12 42 22 4
-15 9 12 42 22 4
-14 9 12 42 22 4
-13 9 12 42 22 4
-12 9 12 42 22 4
-11 9 12 42 22 4
-10 9 12 102 51 51
-43 10 12 102 51 51
-36 10 12 102 51 51
-35 7 14 0 0 0
-34 7 13 0 0 0
-33 7 12 0 0 0
-18 6 13 102 51 51
-18 10 12 42 22 4
-17 10 12 42 22 4
-16 10 12 42 22 4
-15 10 12 42 22 4
-14 10 12 42 22 4
-13 10 12 42 22 4
-12 10 12 42 22 4
-11 10 12 42 22 4
-10 10 12 42 22 4
-9 10 12 102 51 51
-43 11 12 102 51 51
-36 11 12 102 51 51
-32 15 12 0 255 135
-18 11 12 42 22 4
-17 11 12 42 22 4
-16 11 12 42 22 4
-15 11 12 42 22 4
-14 11 12 42 22 4
-13 11 12 42 22 4
-12 11 12 42 22 4
-11 11 12 42 22 4
-10 11 12 42 22 4
-9 11 12 42 22 4
-8 11 12 102 51 51
-43 12 12 102 51 51
-36 12 12 102 51 51
-32 12 12 0 255 133
-18 12 12 42 22 4
-17 12 12 42 22 4
-16 12 12 42 22 4
-15 12 12 42 22 4
-14 12 12 42 22 4
-13 12 12 42 22 4
-12 12 12 42 22 4
-11 12 12 42 22 4
-10 12 12 42 22 4
-9 12 12 42 22 4
-7 12 12 102 51 51
-43 13 12 102 51 51
-36 13 12 102 51 51
-32 13 12 0 255 133
-22 13 24 168 168 168
-14 13 19 168 168 168
-18 13 12 42 22 4
-17 13 12 42 22 4
-16 13 12 42 22 4
-15 13 12 42 22 4
-14 13 12 42 22 4
-13 13 12 42 22 4
-12 13 12 42 22 4
-11 13 12 42 22 4
-10 13 12 42 22 4
-9 13 12 42 22 4
-7 13 12 102 51 51
-43 14 12 102 51 51
-36 14 12 102 51 51
-35 16 14 102 51 51
-18 14 12 42 22 4
-17 14 12 42 22 4
-16 14 12 42 22 4
-15 14 12 42 22 4
-14 14 12 42 22 4
-13 14 12 42 22 4
-12 14 12 42 22 4
-11 14 12 42 22 4
-10 14 12 42 22 4
-9 14 12 42 22 4
-8 14 12 102 51 51
-43 15 12 102 51 51
-36 15 12 102 51 51
-35 9 14 102 51 51
-34 9 13 102 51 51
-35 9 13 102 51 51
-19 9 12 102 51 51
-18 15 12 42 22 4
-17 15 12 42 22 4
-16 15 12 42 22 4
-15 15 12 42 22 4
-14 15 12 42 22 4
-13 15 12 42 22 4
-12 15 12 42 22 4
-11 15 12 42 22 4
-10 15 12 42 22 4
-9 15 12 102 51 51
-43 16 12 102 51 51
-33 18 12 0 0 0
-34 18 13 0 0 0
-19 8 12 0 0 0
-18 16 12 42 22 4
-17 16 12 42 22 4
-16 16 12 42 22 4
-15 16 12 42 22 4
-14 16 12 42 22 4
-13 16 12 42 22 4
-12 16 12 42 22 4
-11 16 12 42 22 4
-10 16 12 102 51 51
-29 11 12 255 102 0
-23 11 12 221 0 0
-28 11 12 221 0 0
-24 15 12 255 102 0
-25 15 12 221 0 0
-26 15 12 221 0 0
-27 15 12 255 102 0
-34 17 12 42 22 4
-33 17 12 0 0 0
-19 7 12 0 0 0
-18 17 12 42 22 4
-17 17 12 42 22 4
-16 17 12 42 22 4
-15 17 12 42 22 4
-14 17 12 42 22 4
-13 17 12 42 22 4
-12 17 12 42 22 4
-11 17 12 102 51 51
-40 6 10 102 51 51
-41 6 10 102 51 51
-42 6 10 102 51 51
-28 0 9 50 50 50
-14 6 9 102 51 51
-15 6 9 102 51 51
-16 6 9 102 51 51
-17 6 9 102 51 51
-18 6 9 102 51 51
-19 6 9 102 51 51
-20 6 9 102 51 51
-21 6 9 102 51 51
-22 6 9 102 51 51
-23 6 9 102 51 51
-24 6 9 102 51 51
-25 6 9 102 51 51
-26 6 9 102 51 51
-27 6 9 102 51 51
-28 6 9 102 51 51
-29 6 9 102 51 51
-30 6 9 102 51 51
-31 6 9 102 51 51
-32 6 9 102 51 51
-35 17 14 0 0 0
-22 13 12 168 168 167
-22 13 13 168 168 168
-22 13 14 168 168 168
-22 13 15 168 168 168
-22 13 16 168 168 168
-29 13 20 168 168 168
-29 13 19 168 168 168
-35 18 14 0 0 0
-36 16 14 42 22 4
-37 16 14 42 22 4
-38 16 14 42 22 4
-39 16 14 42 22 4
-40 16 14 42 22 4
-41 16 14 42 22 4
-12 7 13 102 51 51
-43 8 13 102 51 51
-35 8 13 42 22 4
-34 8 13 0 0 0
-11 8 13 102 51 51
-43 9 13 102 51 51
-39 7 14 42 22 4
-38 7 14 42 22 4
-10 9 13 102 51 51
-43 10 13 102 51 51
-36 10 13 102 51 51
-34 7 12 42 22 4
-35 7 13 42 22 4
-18 10 13 42 22 4
-10 10 13 0 204 0
-9 10 13 102 51 51
-43 11 13 102 51 51
-36 11 13 102 51 51
-18 11 13 50 50 50
-8 11 13 102 51 51
-43 12 13 102 51 51
-36 12 13 102 51 51
-18 12 13 50 50 50
-8 12 13 42 22 4
-7 12 13 102 51 51
-6 12 13 42 22 4
-43 13 13 102 51 51
-36 13 13 102 51 51
-22 13 23 168 168 168
-22 14 11 42 22 4
-18 13 13 50 50 50
-14 13 13 168 168 167
-8 13 13 42 22 4
-7 13 13 102 51 51
-6 13 13 42 22 4
-43 14 13 102 51 51
-36 14 13 102 51 51
-18 14 13 50 50 50
-8 14 13 102 51 51
-43 15 13 102 51 51
-36 15 13 102 51 51
-33 9 12 102 51 51
-34 9 12 102 51 51
-18 15 13 42 22 4
-10 15 13 0 204 0
-9 15 13 102 51 51
-43 16 13 102 51 51
-35 18 13 42 22 4
-34 18 12 42 22 4
-10 16 13 102 51 51
-29 13 16 168 168 168
-29 13 15 168 168 168
-29 13 14 168 168 168
-29 13 13 168 168 168
-29 13 12 168 168 167
-29 13 17 168 168 168
-29 13 18 168 168 168
-35 17 13 42 22 4
-34 17 13 0 0 0
-11 17 13 102 51 51
-33 6 9 102 51 51
-34 6 9 102 51 51
-35 6 9 102 51 51
-36 6 9 102 51 51
-37 6 9 102 51 51
-38 6 9 102 51 51
-39 6 9 102 51 51
-40 6 9 102 51 51
-42 16 14 42 22 4
-43 16 14 102 51 51
-35 9 12 102 51 51
-36 15 14 42 22 4
-37 15 14 42 22 4
-38 15 14 42 22 4
-39 15 14 42 22 4
-40 15 14 42 22 4
-41 15 14 42 22 4
-43 8 14 102 51 51
-42 8 14 42 22 4
-41 8 14 42 22 4
-40 8 14 42 22 4
-39 8 14 42 22 4
-38 8 14 42 22 4
-37 8 14 42 22 4
-36 8 14 42 22 4
-35 8 14 0 0 0
-43 9 14 102 51 51
-42 9 14 42 22 4
-41 9 14 42 22 4
-40 9 14 42 22 4
-39 9 14 42 22 4
-38 9 14 42 22 4
-37 9 14 42 22 4
-36 9 14 42 22 4
-37 7 14 42 22 4
-43 10 14 102 51 51
-42 10 14 42 22 4
-41 10 14 42 22 4
-40 10 14 42 22 4
-39 10 14 42 22 4
-38 10 14 42 22 4
-37 10 14 42 22 4
-36 10 14 42 22 4
-42 7 14 42 22 4
-43 11 14 102 51 51
-42 11 14 42 22 4
-41 11 14 42 22 4
-40 11 14 42 22 4
-39 11 14 42 22 4
-38 11 14 42 22 4
-37 11 14 42 22 4
-36 11 14 42 22 4
-35 11 14 102 51 51
-43 12 14 102 51 51
-42 12 14 42 22 4
-41 12 14 42 22 4
-40 12 14 42 22 4
-39 12 14 42 22 4
-38 12 14 42 22 4
-37 12 14 42 22 4
-36 12 14 42 22 4
-35 12 14 102 51 51
-7 12 14 42 22 4
-6 12 14 42 22 4
-5 12 14 42 22 4
-43 13 14 102 51 51
-42 13 14 42 22 4
-41 13 14 42 22 4
-40 13 14 42 22 4
-39 13 14 42 22 4
-38 13 14 42 22 4
-37 13 14 42 22 4
-36 13 14 42 22 4
-35 13 14 102 51 51
-22 13 22 168 168 168
-22 13 21 168 168 168
-14 13 14 168 168 168
-7 13 14 42 22 4
-6 13 14 42 22 4
-5 13 14 42 22 4
-43 14 14 102 51 51
-42 14 14 42 22 4
-41 14 14 42 22 4
-40 14 14 42 22 4
-39 14 14 42 22 4
-38 14 14 42 22 4
-37 14 14 42 22 4
-36 14 14 42 22 4
-35 14 14 102 51 51
-43 15 14 102 51 51
-42 15 14 42 22 4
-41 6 9 102 51 51
-36 19 16 102 51 51
-37 19 16 50 50 50
-38 19 16 50 50 50
-39 19 16 50 50 50
-40 19 16 50 50 50
-41 19 16 50 50 50
-42 19 16 102 51 51
-36 19 15 102 51 51
-37 19 15 102 51 51
-38 19 15 102 51 51
-39 19 15 102 51 51
-40 19 15 102 51 51
-41 19 15 102 51 51
-42 19 15 102 51 51
-36 19 14 102 51 51
-37 19 14 102 51 51
-38 19 14 102 51 51
-39 19 14 102 51 51
-40 19 14 102 51 51
-41 19 14 102 51 51
-42 19 14 102 51 51
-36 19 13 102 51 51
-37 19 13 102 51 51
-38 19 13 102 51 51
-39 19 13 102 51 51
-40 19 13 102 51 51
-41 19 13 102 51 51
-42 19 13 102 51 51
-36 19 12 102 51 51
-35 19 9 102 51 51
-34 19 9 102 51 51
-33 19 9 102 51 51
-32 19 9 102 51 51
-31 19 9 102 51 51
-30 19 9 102 51 51
-29 19 9 102 51 51
-28 19 9 102 51 51
-27 19 9 102 51 51
-26 19 9 102 51 51
-25 19 9 102 51 51
-24 19 9 102 51 51
-23 19 9 102 51 51
-20 19 9 102 51 51
-19 19 9 102 51 51
-18 19 9 102 51 51
-17 19 9 102 51 51
-16 19 9 102 51 51
-15 19 9 102 51 51
-14 19 9 102 51 51
-37 19 12 102 51 51
-38 19 12 102 51 51
-39 19 12 102 51 51
-40 19 12 102 51 51
-41 19 12 102 51 51
-42 19 12 102 51 51
-36 19 11 102 51 51
-37 19 11 102 51 51
-38 19 11 102 51 51
-39 19 11 102 51 51
-40 19 11 102 51 51
-41 19 11 102 51 51
-42 19 11 102 51 51
-36 19 10 102 51 51
-37 19 10 102 51 51
-38 19 10 102 51 51
-39 19 10 102 51 51
-40 19 10 102 51 51
-41 19 10 102 51 51
-42 19 10 102 51 51
-36 19 9 102 51 51
-37 19 9 102 51 51
-38 19 9 102 51 51
-39 19 9 102 51 51
-40 19 9 102 51 51
-41 19 9 102 51 51
-13 18 9 102 51 51
-35 19 10 102 51 51
-34 19 10 102 51 51
-33 19 10 102 51 51
-32 19 10 102 51 51
-31 19 10 102 51 51
-30 19 10 102 51 51
-29 19 10 102 51 51
-28 19 10 102 51 51
-27 19 10 102 51 51
-26 19 10 102 51 51
-25 19 10 102 51 51
-24 19 10 102 51 51
-23 19 10 102 51 51
-20 19 10 102 51 51
-19 19 10 102 51 51
-18 19 10 102 51 51
-17 19 10 102 51 51
-16 19 10 102 51 51
-15 19 10 102 51 51
-14 19 10 102 51 51
-13 19 10 102 51 51
-22 19 10 102 51 51
-21 19 10 102 51 51
-35 19 15 102 51 51
-21 19 9 102 51 51
-35 19 11 102 51 51
-34 19 11 102 51 51
-33 19 11 102 51 51
-32 19 11 102 51 51
-31 19 11 102 51 51
-30 19 11 102 51 51
-29 19 11 102 51 51
-28 19 11 102 51 51
-27 19 11 102 51 51
-26 19 11 102 51 51
-25 19 11 102 51 51
-24 19 11 102 51 51
-23 19 11 102 51 51
-22 19 11 102 51 51
-21 19 11 102 51 51
-20 19 11 102 51 51
-19 19 11 102 51 51
-18 19 11 102 51 51
-17 19 11 102 51 51
-16 19 11 102 51 51
-15 19 11 102 51 51
-14 19 11 102 51 51
-13 19 11 102 51 51
-22 19 9 102 51 51
-34 19 14 102 51 51
-35 19 14 102 51 51
-35 19 12 102 51 51
-34 19 12 102 51 51
-33 19 12 102 51 51
-32 19 12 102 51 51
-31 19 12 102 51 51
-30 19 12 102 51 51
-29 19 12 102 51 51
-28 19 12 102 51 51
-27 19 12 102 51 51
-26 19 12 102 51 51
-25 19 12 102 51 51
-24 19 12 102 51 51
-23 19 12 102 51 51
-22 19 12 102 51 51
-21 19 12 102 51 51
-20 19 12 102 51 51
-19 19 12 102 51 51
-18 19 12 102 51 51
-17 19 12 102 51 51
-16 19 12 102 51 51
-15 19 12 102 51 51
-14 19 12 102 51 51
-13 19 12 102 51 51
-35 19 13 102 51 51
-34 19 13 102 51 51
-33 19 13 102 51 51
-17 19 13 102 51 51
-16 19 13 102 51 51
-15 19 13 102 51 51
-14 19 13 102 51 51
-13 19 13 102 51 51
-23 7 11 42 22 4
-24 7 11 42 22 4
-22 7 11 42 22 4
-25 7 11 42 22 4
-21 7 11 42 22 4
-26 7 11 42 22 4
-20 7 11 42 22 4
-27 7 11 42 22 4
-19 7 11 42 22 4
-28 7 11 42 22 4
-29 7 11 42 22 4
-30 7 11 42 22 4
-31 7 11 42 22 4
-32 7 11 42 22 4
-17 7 12 42 22 4
-18 7 12 42 22 4
-16 7 12 42 22 4
-15 7 12 42 22 4
-14 7 12 42 22 4
-25 5 10 42 22 4
-26 5 10 42 22 4
-25 4 9 42 22 4
-26 4 9 42 22 4
-26 4 10 0 0 0
-27 4 10 42 22 4
-27 5 11 42 22 4
-25 4 10 0 0 0
-24 4 10 42 22 4
-24 5 11 42 22 4
-25 3 9 0 0 0
-26 3 9 0 0 0
-32 0 8 42 22 4
-31 0 8 42 22 4
-30 0 8 42 22 4
-29 0 8 42 22 4
-28 0 8 42 22 4
-27 0 8 42 22 4
-26 0 8 42 22 4
-25 0 8 42 22 4
-24 0 8 42 22 4
-13 7 9 102 51 51
-29 0 9 50 50 50
-21 0 8 42 22 4
-26 0 9 50 50 50
-25 0 9 50 50 50
-28 3 9 0 0 153
-32 1 8 42 22 4
-31 1 8 42 22 4
-30 1 8 42 22 4
-29 1 8 42 22 4
-28 1 8 42 22 4
-27 1 8 42 22 4
-26 1 8 42 22 4
-25 1 8 42 22 4
-24 1 8 42 22 4
-23 1 8 42 22 4
-22 1 8 42 22 4
-21 1 8 42 22 4
-28 3 8 42 22 4
-27 0 9 42 22 4
-24 0 9 42 22 4
-32 2 8 42 22 4
-31 2 8 42 22 4
-30 2 8 42 22 4
-29 2 8 42 22 4
-28 2 8 42 22 4
-27 2 8 42 22 4
-26 2 8 42 22 4
-25 2 8 42 22 4
-24 2 8 42 22 4
-23 2 8 42 22 4
-22 2 8 42 22 4
-21 2 8 42 22 4
-21 0 9 42 22 4
-22 0 9 50 50 50
-23 0 9 50 50 50
-32 3 8 42 22 4
-31 3 8 42 22 4
-30 3 8 42 22 4
-29 3 8 42 22 4
-30 0 9 42 22 4
-27 3 8 42 22 4
-26 3 8 42 22 4
-25 3 8 42 22 4
-23 3 8 42 22 4
-22 3 8 42 22 4
-21 3 8 42 22 4
-23 0 8 42 22 4
-22 0 8 42 22 4
-21 3 9 42 22 4
-32 0 9 0 0 153
-31 0 9 0 0 153
-32 1 9 0 0 153
-32 2 9 67 67 255
-31 3 9 0 0 153
-30 3 9 67 67 255
-29 3 9 0 0 153
-32 3 9 42 22 4
-27 3 9 42 22 4
-24 3 9 42 22 4
-23 3 9 50 50 50
-22 3 9 50 50 50
-20 0 8 42 22 4
-19 0 8 42 22 4
-18 0 8 42 22 4
-20 1 8 42 22 4
-19 1 8 42 22 4
-18 1 8 42 22 4
-20 2 8 42 22 4
-19 2 8 42 22 4
-18 2 8 42 22 4
-20 3 8 42 22 4
-19 3 8 42 22 4
-18 3 8 42 22 4
-20 0 9 50 50 50
-19 0 9 50 50 50
-18 0 9 42 22 4
-20 3 9 50 50 50
-19 3 9 50 50 50
-18 3 9 42 22 4
-17 0 8 42 22 4
-16 0 8 42 22 4
-15 0 8 42 22 4
-17 1 8 42 22 4
-16 1 8 42 22 4
-15 1 8 42 22 4
-17 2 8 42 22 4
-16 2 8 42 22 4
-15 2 8 42 22 4
-17 3 8 42 22 4
-16 3 8 42 22 4
-15 3 8 42 22 4
-17 0 9 50 50 50
-16 0 9 50 50 50
-15 0 9 42 22 4
-17 3 9 50 50 50
-16 3 9 50 50 50
-15 3 9 42 22 4
-14 0 8 42 22 4
-13 0 8 42 22 4
-12 0 8 42 22 4
-14 1 8 42 22 4
-13 1 8 42 22 4
-12 1 8 42 22 4
-14 2 8 42 22 4
-13 2 8 42 22 4
-12 2 8 42 22 4
-14 3 8 42 22 4
-13 3 8 42 22 4
-12 3 8 42 22 4
-14 0 9 50 50 50
-13 0 9 50 50 50
-12 0 9 42 22 4
-14 3 9 50 50 50
-13 3 9 50 50 50
-12 3 9 42 22 4
-11 0 8 42 22 4
-10 0 8 42 22 4
-9 0 8 42 22 4
-11 1 8 42 22 4
-10 1 8 42 22 4
-9 1 8 42 22 4
-11 2 8 42 22 4
-10 2 8 42 22 4
-9 2 8 42 22 4
-11 3 8 42 22 4
-10 3 8 42 22 4
-9 3 8 42 22 4
-11 0 9 50 50 50
-10 0 9 50 50 50
-9 0 9 42 22 4
-11 3 9 50 50 50
-10 3 9 50 50 50
-9 3 9 42 22 4
-8 0 8 42 22 4
-7 0 8 42 22 4
-6 0 8 42 22 4
-8 1 8 42 22 4
-7 1 8 42 22 4
-6 1 8 42 22 4
-8 2 8 42 22 4
-7 2 8 42 22 4
-6 2 8 42 22 4
-8 3 8 42 22 4
-7 3 8 42 22 4
-6 3 8 42 22 4
-8 0 9 50 50 50
-7 0 9 50 50 50
-6 0 9 42 22 4
-8 3 9 50 50 50
-7 3 9 50 50 50
-6 3 9 42 22 4
-5 0 8 42 22 4
-4 0 8 42 22 4
-3 0 8 42 22 4
-5 1 8 42 22 4
-4 1 8 42 22 4
-3 1 8 42 22 4
-5 2 8 42 22 4
-4 2 8 42 22 4
-3 2 8 42 22 4
-5 3 8 42 22 4
-4 3 8 42 22 4
-3 3 8 42 22 4
-5 0 9 50 50 50
-4 0 9 50 50 50
-3 0 9 42 22 4
-5 3 9 50 50 50
-4 3 9 50 50 50
-3 3 9 42 22 4
-42 13 15 255 255 255
