ply
format ascii 1.0
comment : MagicaVoxel @ Ephtracy
element vertex 1327
property float x
property float y
property float z
property uchar red
property uchar green
property uchar blue
end_header
-8 -7 1 67 67 255
9 3 11 168 168 168
-7 3 10 168 168 168
0 3 10 168 168 168
9 3 10 168 168 168
-21 8 9 102 51 51
-21 7 9 102 51 51
-21 6 9 102 51 51
-21 5 9 102 51 51
-21 4 9 102 51 51
-21 3 9 102 51 51
-21 2 9 102 51 51
-21 1 9 102 51 51
-21 0 9 102 51 51
-21 -1 9 102 51 51
-21 -2 9 102 51 51
-21 -3 9 102 51 51
-20 9 9 102 51 51
-2 -7 1 102 51 51
-10 -7 0 42 22 4
-20 -4 9 102 51 51
-19 9 9 102 51 51
-19 -4 9 102 51 51
-7 3 9 168 168 168
0 3 9 168 168 168
9 3 9 168 168 168
-21 8 8 102 51 51
-21 7 8 50 50 50
-21 6 8 102 51 51
-21 5 8 50 50 50
-21 4 8 102 51 51
-21 3 8 50 50 50
-21 2 8 50 50 50
-21 1 8 102 51 51
-21 0 8 50 50 50
-21 -1 8 102 51 51
-21 -2 8 50 50 50
-21 -3 8 102 51 51
-20 9 8 102 51 51
-20 -4 8 102 51 51
-19 9 8 102 51 51
-19 -4 8 102 51 51
9 -3 0 102 51 51
9 -2 0 102 51 51
9 -1 0 102 51 51
9 0 0 102 51 51
9 1 0 102 51 51
9 2 0 102 51 51
9 3 0 102 51 51
9 4 0 102 51 51
9 5 0 102 51 51
9 6 0 102 51 51
9 7 0 102 51 51
9 8 0 102 51 51
-18 9 8 102 51 51
-18 -4 8 102 51 51
-17 9 8 102 51 51
8 -4 0 102 51 51
22 -7 1 102 51 51
-17 -4 8 102 51 51
-16 9 8 102 51 51
-16 -4 8 102 51 51
7 -4 0 102 51 51
22 -10 1 102 51 51
-15 9 8 102 51 51
-5 -7 1 102 51 51
6 -7 1 50 50 50
6 -4 0 102 51 51
21 -10 1 50 50 50
-15 -4 8 102 51 51
-14 9 8 102 51 51
-14 -4 8 102 51 51
5 -4 0 102 51 51
20 -10 1 50 50 50
-7 3 8 168 168 168
0 3 8 168 168 168
9 3 8 168 168 168
4 -4 0 102 51 51
21 -7 1 50 50 50
20 3 8 42 22 4
20 2 8 42 22 4
21 3 8 42 22 4
3 -4 0 102 51 51
20 -7 1 50 50 50
21 2 8 42 22 4
22 3 8 42 22 4
22 2 8 42 22 4
2 -4 0 102 51 51
22 -7 0 42 22 4
-21 8 7 102 51 51
-21 7 7 50 50 50
-21 6 7 102 51 51
1 -4 0 102 51 51
22 -8 0 42 22 4
-21 5 7 50 50 50
-21 4 7 102 51 51
-21 3 7 50 50 50
0 -4 0 102 51 51
22 -9 0 42 22 4
-21 2 7 50 50 50
-21 1 7 102 51 51
-21 0 7 50 50 50
-1 -4 0 102 51 51
22 -10 0 42 22 4
-21 -1 7 102 51 51
-21 -2 7 50 50 50
-21 -3 7 102 51 51
-2 -4 0 102 51 51
21 -7 0 42 22 4
-20 9 7 102 51 51
-20 8 7 0 0 153
-20 3 7 255 255 255
-3 -4 0 102 51 51
21 -8 0 42 22 4
-20 2 7 255 255 255
-20 -4 7 102 51 51
-19 9 7 50 50 50
-4 -4 0 102 51 51
21 -9 0 42 22 4
-19 -4 7 50 50 50
-18 9 7 50 50 50
-18 -4 7 50 50 50
-5 -4 0 102 51 51
21 -10 0 42 22 4
-17 9 7 50 50 50
-17 -4 7 50 50 50
-16 9 7 50 50 50
-6 -4 0 102 51 51
20 -10 0 42 22 4
-7 -4 0 102 51 51
20 -9 0 42 22 4
-8 -4 0 102 51 51
20 -8 0 42 22 4
-9 -4 0 102 51 51
20 -7 0 42 22 4
-10 -4 0 102 51 51
-10 -9 1 0 0 153
-11 -4 0 102 51 51
-10 -8 1 67 67 255
-12 -4 0 102 51 51
19 -9 0 42 22 4
-13 -4 0 102 51 51
18 -9 0 42 22 4
-14 -4 0 102 51 51
17 -9 0 42 22 4
-15 -4 0 102 51 51
-10 -9 0 42 22 4
-16 -4 0 102 51 51
16 -9 0 42 22 4
-17 -4 0 102 51 51
-9 -9 0 42 22 4
-18 -4 0 102 51 51
15 -9 0 42 22 4
-19 -3 0 102 51 51
-19 -2 0 102 51 51
-19 -1 0 102 51 51
-19 0 0 102 51 51
-19 1 0 102 51 51
-19 2 0 102 51 51
-19 3 0 102 51 51
-19 4 0 102 51 51
-19 5 0 102 51 51
-19 6 0 102 51 51
-19 7 0 102 51 51
-19 8 0 102 51 51
-16 -4 7 50 50 50
-15 9 7 50 50 50
-15 -4 7 50 50 50
-14 9 7 102 51 51
-14 -4 7 102 51 51
-7 3 7 168 168 168
0 3 7 168 168 168
7 -7 1 102 51 51
9 3 7 168 168 168
-1 -7 1 50 50 50
17 3 7 42 22 4
17 2 7 42 22 4
18 3 7 42 22 4
18 2 7 42 22 4
19 3 7 42 22 4
19 2 7 42 22 4
20 3 7 42 22 4
20 2 7 42 22 4
-21 8 6 102 51 51
-21 7 6 102 51 51
-21 6 6 102 51 51
-21 5 6 102 51 51
-21 4 6 102 51 51
-21 3 6 102 51 51
11 -1 1 102 51 51
11 0 1 102 51 51
11 1 1 102 51 51
11 2 1 102 51 51
11 3 1 102 51 51
11 4 1 102 51 51
11 5 1 102 51 51
11 6 1 102 51 51
-21 2 6 102 51 51
-21 1 6 102 51 51
10 -2 1 102 51 51
10 7 1 102 51 51
-21 0 6 102 51 51
-21 -1 6 102 51 51
9 -4 1 102 51 51
9 -3 1 102 51 51
9 8 1 102 51 51
9 9 1 102 51 51
-21 -2 6 102 51 51
-21 -3 6 102 51 51
8 -4 1 102 51 51
-8 -9 0 42 22 4
-20 9 6 102 51 51
-20 8 6 0 0 153
7 -4 1 102 51 51
14 -9 0 42 22 4
-20 7 6 67 67 255
-20 4 6 0 204 0
6 -4 1 0 225 254
-7 -9 0 42 22 4
-20 3 6 255 255 255
-20 2 6 0 255 205
5 -4 1 255 255 255
13 -9 0 42 22 4
-20 1 6 0 204 0
-20 -4 6 102 51 51
4 -4 1 102 51 51
-6 -9 0 42 22 4
-19 9 6 102 51 51
-19 8 6 0 0 153
3 -4 1 102 51 51
12 -9 0 42 22 4
-19 7 6 255 102 0
8 -7 1 50 50 50
2 -4 1 102 51 51
-5 -9 0 42 22 4
-19 -4 6 102 51 51
-18 9 6 102 51 51
1 -4 1 0 225 254
11 -9 0 42 22 4
-18 7 6 221 0 0
-18 4 6 255 102 0
0 -4 1 255 255 255
-4 -9 0 42 22 4
-18 3 6 221 0 0
-18 2 6 221 0 0
-1 -4 1 102 51 51
10 -9 0 42 22 4
-18 1 6 255 102 0
9 -7 1 50 50 50
-2 -6 1 42 22 4
-2 -4 1 102 51 51
-3 -9 0 42 22 4
-18 -4 6 102 51 51
-3 -6 1 0 0 0
-3 -5 1 42 22 4
-3 -4 1 102 51 51
9 -9 0 42 22 4
-17 9 6 102 51 51
-4 -6 1 0 0 0
-4 -5 1 42 22 4
-4 -4 1 102 51 51
-2 -9 0 42 22 4
-17 7 6 221 0 0
-17 4 6 255 102 0
-5 -6 1 42 22 4
-5 -4 1 102 51 51
8 -9 0 42 22 4
-17 3 6 221 0 0
-17 2 6 221 0 0
-6 -4 1 102 51 51
-1 -9 0 42 22 4
-7 -4 1 0 225 254
7 -9 0 42 22 4
-8 -4 1 255 255 255
0 -9 0 42 22 4
-9 -4 1 102 51 51
6 -9 0 42 22 4
-10 -4 1 102 51 51
1 -9 0 42 22 4
-11 -4 1 0 225 254
5 -9 0 42 22 4
-12 -4 1 255 255 255
2 -9 0 42 22 4
-13 -4 1 102 51 51
4 -9 0 42 22 4
-14 -4 1 102 51 51
3 -9 0 42 22 4
-15 -4 1 0 225 254
11 -10 1 50 50 50
-16 -4 1 255 255 255
12 -10 1 50 50 50
-17 -4 1 102 51 51
13 -10 1 102 51 51
-18 -4 1 102 51 51
14 -10 1 50 50 50
-19 -4 1 102 51 51
-19 9 1 102 51 51
-20 -3 1 102 51 51
-20 -2 1 102 51 51
-20 -1 1 102 51 51
-20 0 1 102 51 51
-20 1 1 102 51 51
-20 2 1 102 51 51
-20 3 1 102 51 51
-20 4 1 102 51 51
-20 5 1 102 51 51
-20 6 1 102 51 51
-20 7 1 102 51 51
-20 8 1 102 51 51
13 1 2 102 51 51
13 2 2 102 51 51
13 3 2 102 51 51
13 4 2 102 51 51
12 -1 2 102 51 51
12 0 2 102 51 51
12 5 2 102 51 51
12 6 2 102 51 51
11 -2 2 102 51 51
11 7 2 102 51 51
10 -3 2 102 51 51
10 8 2 102 51 51
9 -4 2 102 51 51
9 9 2 102 51 51
8 -4 2 102 51 51
15 -10 1 50 50 50
7 -4 2 102 51 51
16 -10 1 102 51 51
6 -4 2 255 255 255
17 -10 1 50 50 50
5 -4 2 255 255 255
18 -10 1 50 50 50
4 -4 2 102 51 51
4 -3 2 42 22 4
4 -2 2 42 22 4
4 -1 2 42 22 4
4 0 2 42 22 4
4 1 2 42 22 4
4 2 2 42 22 4
4 3 2 42 22 4
4 4 2 42 22 4
4 5 2 42 22 4
4 6 2 42 22 4
4 7 2 42 22 4
4 8 2 42 22 4
19 -10 1 102 51 51
3 -4 2 102 51 51
3 -3 2 42 22 4
3 -2 2 42 22 4
3 -1 2 42 22 4
3 0 2 42 22 4
3 1 2 42 22 4
3 2 2 42 22 4
3 3 2 42 22 4
3 4 2 42 22 4
3 5 2 42 22 4
3 6 2 42 22 4
3 7 2 42 22 4
3 8 2 42 22 4
11 -10 0 42 22 4
2 -4 2 102 51 51
2 -3 2 42 22 4
2 -2 2 42 22 4
2 -1 2 42 22 4
2 0 2 42 22 4
2 1 2 42 22 4
2 2 2 42 22 4
2 3 2 42 22 4
2 4 2 42 22 4
2 5 2 42 22 4
2 6 2 42 22 4
2 7 2 42 22 4
2 8 2 42 22 4
12 -10 0 42 22 4
1 -4 2 255 255 255
1 -3 2 42 22 4
1 -2 2 42 22 4
1 -1 2 42 22 4
1 0 2 42 22 4
1 1 2 42 22 4
1 2 2 42 22 4
1 3 2 42 22 4
1 4 2 42 22 4
1 5 2 42 22 4
1 6 2 42 22 4
1 7 2 42 22 4
1 8 2 42 22 4
13 -10 0 42 22 4
0 -4 2 255 255 255
0 -3 2 42 22 4
0 -2 2 42 22 4
0 -1 2 42 22 4
0 0 2 42 22 4
0 1 2 42 22 4
0 2 2 42 22 4
0 3 2 42 22 4
0 4 2 42 22 4
0 5 2 42 22 4
0 6 2 42 22 4
0 7 2 42 22 4
0 8 2 42 22 4
14 -10 0 42 22 4
-1 -4 2 102 51 51
-1 -3 2 42 22 4
-1 -2 2 42 22 4
-1 -1 2 42 22 4
-1 0 2 42 22 4
-1 1 2 42 22 4
-1 2 2 42 22 4
-1 3 2 42 22 4
-1 4 2 42 22 4
-1 5 2 42 22 4
-1 6 2 42 22 4
-1 7 2 42 22 4
-1 8 2 42 22 4
15 -10 0 42 22 4
-2 -5 2 42 22 4
-2 -4 2 102 51 51
-2 -3 2 42 22 4
-2 -2 2 42 22 4
-2 -1 2 42 22 4
-2 0 2 42 22 4
-2 1 2 42 22 4
-2 2 2 42 22 4
-2 3 2 42 22 4
-2 4 2 42 22 4
-2 5 2 42 22 4
-2 6 2 42 22 4
-2 7 2 42 22 4
-2 8 2 42 22 4
16 -10 0 42 22 4
-3 -5 2 0 0 0
-3 -4 2 42 22 4
-3 -3 2 42 22 4
-3 -2 2 42 22 4
-3 -1 2 42 22 4
-3 0 2 42 22 4
-3 1 2 42 22 4
-3 2 2 42 22 4
-3 3 2 42 22 4
-3 4 2 42 22 4
-3 5 2 42 22 4
-3 6 2 42 22 4
-3 7 2 42 22 4
-3 8 2 42 22 4
17 -10 0 42 22 4
-4 -5 2 0 0 0
-4 -4 2 42 22 4
-4 -3 2 42 22 4
-4 -2 2 42 22 4
-4 -1 2 42 22 4
-4 0 2 42 22 4
-4 1 2 42 22 4
-4 2 2 42 22 4
-4 3 2 42 22 4
-4 4 2 42 22 4
-4 5 2 42 22 4
-4 6 2 42 22 4
-4 7 2 42 22 4
-4 8 2 42 22 4
18 -10 0 42 22 4
-5 -5 2 42 22 4
-5 -4 2 102 51 51
-5 -3 2 42 22 4
-5 -2 2 42 22 4
-5 -1 2 42 22 4
-5 0 2 42 22 4
-5 1 2 42 22 4
-5 2 2 42 22 4
-5 3 2 42 22 4
-5 4 2 42 22 4
-5 5 2 42 22 4
-5 6 2 42 22 4
-5 7 2 42 22 4
-5 8 2 42 22 4
19 -10 0 42 22 4
-6 -4 2 102 51 51
-6 -3 2 42 22 4
-6 -2 2 42 22 4
-6 -1 2 42 22 4
-6 0 2 42 22 4
-6 1 2 42 22 4
-6 2 2 42 22 4
-6 3 2 42 22 4
-6 4 2 42 22 4
-6 5 2 42 22 4
-6 6 2 42 22 4
-6 7 2 42 22 4
-6 8 2 42 22 4
5 -10 1 50 50 50
-7 -4 2 255 255 255
-7 -3 2 42 22 4
-7 -2 2 42 22 4
-7 -1 2 42 22 4
-7 0 2 42 22 4
-7 1 2 42 22 4
-7 2 2 42 22 4
-7 3 2 42 22 4
-7 4 2 42 22 4
-7 5 2 42 22 4
-7 6 2 42 22 4
-7 7 2 42 22 4
-7 8 2 42 22 4
6 -10 1 50 50 50
-8 -4 2 255 255 255
-8 -3 2 42 22 4
-8 -2 2 42 22 4
-8 -1 2 42 22 4
-8 0 2 42 22 4
-8 1 2 42 22 4
-8 2 2 42 22 4
-8 3 2 42 22 4
-8 4 2 42 22 4
-8 5 2 42 22 4
-8 6 2 42 22 4
-8 7 2 42 22 4
-8 8 2 42 22 4
7 -10 1 102 51 51
-9 -4 2 102 51 51
-9 -3 2 42 22 4
-9 -2 2 42 22 4
-9 -1 2 42 22 4
-9 0 2 42 22 4
-9 1 2 42 22 4
-9 2 2 42 22 4
-9 3 2 42 22 4
-9 4 2 42 22 4
-9 5 2 42 22 4
-9 6 2 42 22 4
-9 7 2 42 22 4
-9 8 2 42 22 4
8 -10 1 50 50 50
-10 -4 2 102 51 51
-10 -3 2 42 22 4
-10 -2 2 42 22 4
-10 -1 2 42 22 4
-10 0 2 42 22 4
-10 1 2 42 22 4
-10 2 2 42 22 4
-10 3 2 42 22 4
-10 4 2 42 22 4
-10 5 2 42 22 4
-10 6 2 42 22 4
-10 7 2 42 22 4
-10 8 2 42 22 4
9 -10 1 50 50 50
-11 -4 2 255 255 255
-11 0 2 42 22 4
-11 1 2 42 22 4
-11 2 2 42 22 4
-11 3 2 42 22 4
-11 4 2 42 22 4
-11 5 2 42 22 4
10 -10 1 102 51 51
-12 -4 2 255 255 255
-12 0 2 42 22 4
-12 1 2 42 22 4
-12 2 2 42 22 4
-12 3 2 42 22 4
-12 4 2 42 22 4
-12 5 2 42 22 4
4 -10 1 102 51 51
-13 -4 2 102 51 51
-13 0 2 42 22 4
-13 1 2 42 22 4
-13 2 2 42 22 4
-13 3 2 42 22 4
-13 4 2 42 22 4
-13 5 2 42 22 4
3 -10 1 50 50 50
-14 -4 2 102 51 51
2 -10 1 50 50 50
-15 -4 2 255 255 255
1 -10 1 102 51 51
-16 -4 2 255 255 255
-8 -10 1 102 51 51
-17 -4 2 102 51 51
-8 -10 0 42 22 4
-18 -4 2 102 51 51
-7 -10 0 42 22 4
-19 -4 2 102 51 51
-19 9 2 102 51 51
-20 -3 2 102 51 51
-20 -2 2 102 51 51
-20 -1 2 102 51 51
-20 0 2 102 51 51
-20 1 2 102 51 51
-20 2 2 102 51 51
-20 3 2 102 51 51
-20 4 2 102 51 51
-20 5 2 102 51 51
-20 6 2 102 51 51
-20 7 2 102 51 51
-20 8 2 102 51 51
14 2 3 102 51 51
14 3 3 102 51 51
13 0 3 102 51 51
13 1 3 102 51 51
13 4 3 102 51 51
13 5 3 102 51 51
12 -1 3 102 51 51
12 6 3 102 51 51
11 -2 3 102 51 51
11 7 3 102 51 51
10 -3 3 102 51 51
10 8 3 102 51 51
9 -4 3 102 51 51
9 -3 3 42 22 4
9 -2 3 42 22 4
9 -1 3 42 22 4
9 0 3 42 22 4
9 1 3 42 22 4
9 2 3 42 22 4
9 3 3 42 22 4
9 4 3 42 22 4
9 5 3 42 22 4
9 6 3 42 22 4
9 7 3 42 22 4
9 8 3 42 22 4
9 9 3 102 51 51
8 -4 3 102 51 51
8 -3 3 42 22 4
8 -2 3 42 22 4
8 -1 3 42 22 4
8 0 3 42 22 4
8 1 3 42 22 4
8 2 3 42 22 4
8 3 3 42 22 4
8 4 3 42 22 4
8 5 3 42 22 4
8 6 3 42 22 4
8 7 3 42 22 4
8 8 3 42 22 4
8 9 3 102 51 51
7 -4 3 102 51 51
7 -3 3 42 22 4
7 -2 3 42 22 4
7 -1 3 42 22 4
7 0 3 42 22 4
7 1 3 42 22 4
7 2 3 42 22 4
7 3 3 42 22 4
7 4 3 42 22 4
7 5 3 42 22 4
7 6 3 42 22 4
7 7 3 42 22 4
7 8 3 42 22 4
7 9 3 102 51 51
6 -4 3 102 51 51
6 -3 3 42 22 4
6 -2 3 42 22 4
6 -1 3 42 22 4
6 0 3 42 22 4
6 1 3 42 22 4
6 2 3 42 22 4
6 3 3 42 22 4
6 4 3 42 22 4
6 5 3 42 22 4
6 6 3 42 22 4
6 7 3 42 22 4
6 8 3 42 22 4
6 9 3 102 51 51
5 -4 3 102 51 51
5 -3 3 42 22 4
5 -2 3 42 22 4
5 -1 3 42 22 4
5 0 3 42 22 4
5 1 3 42 22 4
5 2 3 42 22 4
5 3 3 42 22 4
5 4 3 42 22 4
5 5 3 42 22 4
5 6 3 42 22 4
5 7 3 42 22 4
5 8 3 42 22 4
5 9 3 102 51 51
4 -4 3 102 51 51
4 -3 3 0 0 0
4 -2 3 0 0 0
4 -1 3 102 51 51
4 1 3 255 102 0
4 2 3 221 0 0
4 3 3 221 0 0
4 4 3 255 102 0
4 6 3 102 51 51
4 7 3 0 0 0
4 8 3 0 0 0
4 9 3 102 51 51
3 -4 3 102 51 51
3 9 3 102 51 51
2 -4 3 102 51 51
2 9 3 102 51 51
1 -4 3 102 51 51
1 -1 3 255 102 0
1 0 3 255 102 0
1 3 3 67 67 255
1 9 3 102 51 51
0 -4 3 102 51 51
0 -1 3 221 0 0
0 0 3 221 0 0
0 3 3 168 168 167
0 8 3 255 255 255
0 9 3 102 51 51
-1 -4 3 102 51 51
-1 -1 3 221 0 0
-1 0 3 221 0 0
-1 3 3 221 0 0
-1 4 3 0 0 153
-1 8 3 255 255 255
-1 9 3 102 51 51
-2 -4 3 102 51 51
-2 -1 3 255 102 0
-2 0 3 255 102 0
-2 3 3 255 102 0
-2 8 3 153 51 205
-2 9 3 102 51 51
-3 8 3 67 67 255
-3 9 3 102 51 51
-4 7 3 153 0 153
-4 8 3 255 255 255
-4 9 3 102 51 51
-5 -4 3 102 51 51
-5 -1 3 255 102 0
-5 0 3 255 102 0
-5 3 3 255 102 0
-5 7 3 255 255 255
-5 8 3 255 255 255
-5 9 3 102 51 51
-6 -4 3 102 51 51
-6 -1 3 221 0 0
-6 0 3 221 0 0
-6 3 3 221 0 0
-6 4 3 0 0 153
-6 7 3 153 0 153
-6 8 3 255 255 255
-6 9 3 102 51 51
-7 -4 3 102 51 51
-7 -1 3 221 0 0
-7 0 3 221 0 0
-7 3 3 168 168 167
-7 4 3 0 0 153
-7 7 3 255 255 255
-7 8 3 255 255 255
-7 9 3 102 51 51
-8 -4 3 102 51 51
-8 -1 3 255 102 0
-8 0 3 255 102 0
-8 9 3 102 51 51
-9 -4 3 102 51 51
-9 9 3 102 51 51
-10 -4 3 102 51 51
-10 0 3 0 255 134
-10 1 3 0 255 133
-10 2 3 0 255 133
-10 3 3 0 255 133
-10 4 3 0 255 133
-10 5 3 0 255 135
-10 9 3 102 51 51
-11 -4 3 102 51 51
-11 -3 3 0 0 0
-11 -2 3 0 0 0
-11 -1 3 102 51 51
-11 6 3 102 51 51
-11 7 3 0 0 0
-11 8 3 0 0 0
-11 9 3 102 51 51
-12 -4 3 102 51 51
-12 -3 3 42 22 4
-12 -2 3 42 22 4
-12 -1 3 102 51 51
-12 5 3 67 67 255
-12 6 3 102 51 51
-12 7 3 42 22 4
-12 8 3 42 22 4
-12 9 3 102 51 51
-13 -4 3 102 51 51
-13 -1 3 102 51 51
-13 4 3 0 0 153
-13 5 3 0 0 153
-13 6 3 102 51 51
-13 9 3 102 51 51
-14 -4 3 102 51 51
-14 0 3 102 51 51
-14 1 3 102 51 51
-14 2 3 102 51 51
-14 3 3 102 51 51
-14 4 3 102 51 51
-14 5 3 102 51 51
-14 9 3 102 51 51
-15 -4 3 102 51 51
-15 9 3 102 51 51
-16 -4 3 102 51 51
-16 9 3 102 51 51
-17 -4 3 102 51 51
-17 9 3 102 51 51
-18 -4 3 102 51 51
-18 9 3 102 51 51
-19 -4 3 102 51 51
-19 9 3 102 51 51
-20 -4 3 102 51 51
-20 9 3 102 51 51
-21 -3 3 102 51 51
-21 -2 3 102 51 51
-21 -1 3 102 51 51
-21 0 3 102 51 51
-21 1 3 102 51 51
-21 2 3 102 51 51
-21 3 3 102 51 51
-21 4 3 102 51 51
-21 5 3 102 51 51
-21 6 3 102 51 51
-21 7 3 102 51 51
-21 8 3 102 51 51
15 2 4 102 51 51
15 3 4 102 51 51
14 1 4 102 51 51
14 2 4 42 22 4
14 3 4 42 22 4
14 4 4 102 51 51
13 0 4 102 51 51
13 1 4 42 22 4
13 2 4 42 22 4
13 3 4 42 22 4
13 4 4 42 22 4
13 5 4 102 51 51
12 -1 4 102 51 51
12 0 4 42 22 4
12 1 4 42 22 4
12 2 4 42 22 4
12 3 4 42 22 4
12 4 4 42 22 4
12 5 4 42 22 4
12 6 4 102 51 51
11 -2 4 102 51 51
11 -1 4 42 22 4
11 0 4 42 22 4
11 1 4 42 22 4
11 2 4 42 22 4
11 3 4 42 22 4
11 4 4 42 22 4
11 5 4 42 22 4
11 6 4 42 22 4
11 7 4 102 51 51
10 -3 4 102 51 51
10 -2 4 0 0 0
10 -1 4 0 0 0
10 0 4 42 22 4
10 1 4 42 22 4
10 2 4 42 22 4
10 3 4 42 22 4
10 4 4 42 22 4
10 5 4 42 22 4
10 6 4 0 0 0
10 7 4 0 0 0
10 8 4 102 51 51
9 -4 4 102 51 51
9 -3 4 0 204 0
9 2 4 67 67 255
9 3 4 168 168 167
9 8 4 0 204 0
9 9 4 102 51 51
8 -4 4 102 51 51
8 9 4 102 51 51
7 -4 4 102 51 51
7 0 4 255 102 0
7 1 4 221 0 0
7 4 4 221 0 0
7 5 4 255 102 0
7 9 4 102 51 51
6 -4 4 102 51 51
6 0 4 255 102 0
6 1 4 221 0 0
6 4 4 221 0 0
6 5 4 255 102 0
6 9 4 102 51 51
5 -4 4 102 51 51
5 -1 4 42 22 4
5 0 4 50 50 50
5 1 4 50 50 50
5 2 4 50 50 50
5 3 4 50 50 50
5 4 4 50 50 50
5 5 4 50 50 50
5 6 4 42 22 4
5 9 4 102 51 51
0 3 4 168 168 168
0 8 4 255 255 255
-1 8 4 255 255 255
-2 8 4 255 255 255
0 3 16 168 168 168
0 3 15 168 168 168
0 3 14 168 168 168
0 3 13 168 168 168
0 3 12 168 168 168
9 3 12 168 168 168
-7 3 4 168 168 168
-7 3 11 168 168 168
0 3 11 168 168 168
-11 -4 4 102 51 51
-11 9 4 102 51 51
-12 -4 4 102 51 51
-12 -3 4 0 0 0
-12 -2 4 0 0 0
-12 -1 4 102 51 51
-12 6 4 102 51 51
-12 7 4 0 0 0
-12 8 4 0 0 0
-12 9 4 102 51 51
-13 -4 4 102 51 51
-13 -3 4 42 22 4
-13 -2 4 42 22 4
-13 -1 4 102 51 51
-13 6 4 102 51 51
-13 7 4 42 22 4
-13 8 4 42 22 4
-13 9 4 102 51 51
-14 -4 4 102 51 51
-14 0 4 102 51 51
-14 1 4 102 51 51
-14 2 4 102 51 51
-14 3 4 102 51 51
-14 4 4 102 51 51
-14 5 4 102 51 51
-14 9 4 102 51 51
-15 -4 4 102 51 51
-15 9 4 102 51 51
-16 -4 4 102 51 51
-16 9 4 102 51 51
-17 -4 4 102 51 51
-17 9 4 102 51 51
-18 -4 4 102 51 51
-18 9 4 102 51 51
-19 -4 4 102 51 51
-19 9 4 102 51 51
-20 -4 4 102 51 51
-20 9 4 102 51 51
-21 -3 4 102 51 51
-21 -2 4 102 51 51
-21 -1 4 102 51 51
-21 0 4 102 51 51
-21 1 4 102 51 51
-21 2 4 102 51 51
-21 3 4 102 51 51
-21 4 4 102 51 51
-21 5 4 102 51 51
-21 6 4 102 51 51
-21 7 4 102 51 51
-21 8 4 102 51 51
16 2 5 42 22 4
16 3 5 42 22 4
15 2 5 102 51 51
15 3 5 102 51 51
14 1 5 102 51 51
14 4 5 102 51 51
13 0 5 102 51 51
13 1 5 255 102 0
13 2 5 221 0 0
13 3 5 221 0 0
13 4 5 255 102 0
13 5 5 102 51 51
12 -1 5 102 51 51
12 0 5 0 204 0
12 5 5 0 204 0
12 6 5 102 51 51
11 -2 5 102 51 51
11 7 5 102 51 51
10 -3 5 102 51 51
10 0 5 42 22 4
10 1 5 50 50 50
10 2 5 50 50 50
10 3 5 50 50 50
10 4 5 50 50 50
10 5 5 42 22 4
10 8 5 102 51 51
9 -4 5 102 51 51
9 3 5 168 168 168
9 9 5 102 51 51
0 3 5 168 168 168
0 8 5 255 255 255
-1 8 5 255 255 255
-2 8 5 255 255 255
-7 3 5 168 168 168
-12 -4 5 102 51 51
-12 9 5 102 51 51
-13 -4 5 102 51 51
-13 -3 5 0 0 0
-13 -2 5 0 0 0
-13 -1 5 102 51 51
-13 0 5 102 51 51
-13 1 5 102 51 51
-13 2 5 102 51 51
-13 3 5 102 51 51
-13 4 5 102 51 51
-13 5 5 102 51 51
-13 6 5 102 51 51
-13 7 5 0 0 0
-13 8 5 0 0 0
-13 9 5 102 51 51
-14 -4 5 102 51 51
-14 -3 5 42 22 4
-14 -2 5 42 22 4
-14 -1 5 42 22 4
-14 0 5 42 22 4
-14 1 5 42 22 4
-14 2 5 42 22 4
-14 3 5 42 22 4
-14 4 5 42 22 4
-14 5 5 42 22 4
-14 6 5 42 22 4
-14 7 5 42 22 4
-14 8 5 42 22 4
-14 9 5 102 51 51
-15 -4 5 102 51 51
-15 -3 5 42 22 4
-15 -2 5 42 22 4
-15 -1 5 42 22 4
-15 0 5 42 22 4
-15 1 5 42 22 4
-15 2 5 42 22 4
-15 3 5 42 22 4
-15 4 5 42 22 4
-15 5 5 42 22 4
-15 6 5 42 22 4
-15 7 5 42 22 4
-15 8 5 42 22 4
-15 9 5 102 51 51
-16 -4 5 102 51 51
-16 -3 5 42 22 4
-16 -2 5 42 22 4
-16 -1 5 42 22 4
-16 0 5 42 22 4
-16 1 5 42 22 4
-16 2 5 42 22 4
-16 3 5 42 22 4
-16 4 5 42 22 4
-16 5 5 42 22 4
-16 6 5 42 22 4
-16 7 5 42 22 4
-16 8 5 42 22 4
-16 9 5 102 51 51
-17 -4 5 102 51 51
-17 -3 5 42 22 4
-17 -2 5 42 22 4
-17 -1 5 42 22 4
-17 0 5 42 22 4
-17 1 5 42 22 4
-17 2 5 42 22 4
-17 3 5 42 22 4
-17 4 5 42 22 4
-17 5 5 42 22 4
-17 6 5 42 22 4
-17 7 5 42 22 4
-17 8 5 42 22 4
-17 9 5 102 51 51
-18 -4 5 102 51 51
-18 -3 5 42 22 4
-18 -2 5 42 22 4
-18 -1 5 42 22 4
-18 0 5 42 22 4
-18 1 5 42 22 4
-18 2 5 42 22 4
-18 3 5 42 22 4
-18 4 5 42 22 4
-18 5 5 42 22 4
-18 6 5 42 22 4
-18 7 5 42 22 4
-18 8 5 42 22 4
-18 9 5 102 51 51
-19 -4 5 102 51 51
-19 -3 5 42 22 4
-19 -2 5 42 22 4
-19 -1 5 42 22 4
-19 0 5 42 22 4
-19 1 5 42 22 4
-19 2 5 42 22 4
-19 3 5 42 22 4
-19 4 5 42 22 4
-19 5 5 42 22 4
-19 6 5 42 22 4
-19 7 5 42 22 4
-19 8 5 42 22 4
-19 9 5 102 51 51
-20 -4 5 102 51 51
-20 -3 5 42 22 4
-20 -2 5 42 22 4
-20 -1 5 42 22 4
-20 0 5 42 22 4
-20 1 5 42 22 4
-20 2 5 42 22 4
-20 3 5 42 22 4
-20 4 5 42 22 4
-20 5 5 42 22 4
-20 6 5 42 22 4
-20 7 5 42 22 4
-20 8 5 42 22 4
-20 9 5 102 51 51
-21 -3 5 102 51 51
-21 -2 5 102 51 51
-21 -1 5 102 51 51
-21 0 5 102 51 51
-21 1 5 102 51 51
-21 2 5 102 51 51
-21 3 5 102 51 51
-21 4 5 102 51 51
-21 5 5 102 51 51
-21 6 5 102 51 51
-21 7 5 102 51 51
-21 8 5 102 51 51
17 2 6 42 22 4
17 3 6 42 22 4
16 2 6 42 22 4
16 3 6 42 22 4
15 2 6 42 22 4
15 3 6 42 22 4
9 3 6 168 168 168
-10 -8 0 42 22 4
0 3 6 168 168 168
10 -7 1 102 51 51
11 -7 1 50 50 50
-7 3 6 168 168 168
5 -7 1 50 50 50
-13 -4 6 102 51 51
-13 9 6 102 51 51
-14 -4 6 102 51 51
-14 -1 6 42 22 4
-14 0 6 50 50 50
-14 1 6 50 50 50
-14 2 6 50 50 50
-14 3 6 50 50 50
-14 4 6 50 50 50
-14 5 6 50 50 50
-14 6 6 42 22 4
-14 9 6 102 51 51
-15 -4 6 102 51 51
-15 9 6 102 51 51
-16 -4 6 102 51 51
-6 -7 1 50 50 50
-16 7 6 255 102 0
-16 9 6 102 51 51
-17 -4 6 102 51 51
12 -7 1 50 50 50
-17 1 6 255 102 0
13 -7 1 102 51 51
-9 -7 0 42 22 4
4 -7 1 102 51 51
14 -7 1 50 50 50
19 -8 0 42 22 4
19 -7 0 42 22 4
15 -7 1 50 50 50
18 -8 0 42 22 4
18 -7 0 42 22 4
-9 -8 0 42 22 4
17 -8 0 42 22 4
17 -7 0 42 22 4
-9 -7 1 0 0 153
16 -8 0 42 22 4
16 -7 0 42 22 4
-7 -7 1 0 0 153
15 -8 0 42 22 4
15 -7 0 42 22 4
14 2 5 102 51 51
14 -8 0 42 22 4
14 -7 0 42 22 4
14 3 5 102 51 51
13 -8 0 42 22 4
13 -7 0 42 22 4
0 -7 1 50 50 50
12 -8 0 42 22 4
12 -7 0 42 22 4
3 -7 1 50 50 50
11 -8 0 42 22 4
11 -7 0 42 22 4
16 -7 1 102 51 51
10 -8 0 42 22 4
10 -7 0 42 22 4
17 -7 1 50 50 50
9 -8 0 42 22 4
9 -7 0 42 22 4
2 -7 1 50 50 50
8 -8 0 42 22 4
8 -7 0 42 22 4
18 -7 1 50 50 50
7 -8 0 42 22 4
7 -7 0 42 22 4
19 -7 1 102 51 51
6 -8 0 42 22 4
6 -7 0 42 22 4
1 -7 1 102 51 51
5 -8 0 42 22 4
5 -7 0 42 22 4
-10 -7 1 102 51 51
4 -8 0 42 22 4
4 -7 0 42 22 4
-8 -7 0 42 22 4
3 -8 0 42 22 4
3 -7 0 42 22 4
-8 -8 0 42 22 4
2 -8 0 42 22 4
2 -7 0 42 22 4
-7 -7 0 42 22 4
1 -8 0 42 22 4
1 -7 0 42 22 4
-7 -8 0 42 22 4
0 -8 0 42 22 4
0 -7 0 42 22 4
-6 -7 0 42 22 4
-1 -8 0 42 22 4
-1 -7 0 42 22 4
-6 -8 0 42 22 4
-2 -8 0 42 22 4
-2 -7 0 42 22 4
-5 -7 0 42 22 4
-3 -8 0 42 22 4
-3 -7 0 42 22 4
-5 -8 0 42 22 4
-4 -8 0 42 22 4
-4 -7 0 42 22 4
-10 -10 0 42 22 4
-1 -10 1 50 50 50
-6 -10 1 50 50 50
-5 -10 1 102 51 51
-2 -10 1 102 51 51
-10 -10 2 0 0 153
-3 -10 1 50 50 50
-4 -10 1 50 50 50
-7 -10 1 67 67 255
-9 -10 1 0 0 153
-10 -10 1 0 0 153
-9 -10 0 42 22 4
0 -10 1 50 50 50
10 -10 0 42 22 4
9 -10 0 42 22 4
8 -10 0 42 22 4
7 -10 0 42 22 4
6 -10 0 42 22 4
5 -10 0 42 22 4
4 -10 0 42 22 4
3 -10 0 42 22 4
2 -10 0 42 22 4
1 -10 0 42 22 4
0 -10 0 42 22 4
-1 -10 0 42 22 4
-2 -10 0 42 22 4
-3 -10 0 42 22 4
-4 -10 0 42 22 4
-5 -10 0 42 22 4
-6 -10 0 42 22 4
8 9 0 102 51 51
7 9 0 102 51 51
6 9 0 102 51 51
5 9 0 102 51 51
4 9 0 102 51 51
3 9 0 102 51 51
2 9 0 102 51 51
1 9 0 102 51 51
0 9 0 102 51 51
-1 9 0 102 51 51
-2 9 0 102 51 51
-3 9 0 102 51 51
-4 9 0 102 51 51
-5 9 0 102 51 51
-6 9 0 102 51 51
-7 9 0 102 51 51
-8 9 0 102 51 51
-9 9 0 102 51 51
-10 9 0 102 51 51
-11 9 0 102 51 51
-12 9 0 102 51 51
-13 9 0 102 51 51
-14 9 0 102 51 51
-15 9 0 102 51 51
-16 9 0 102 51 51
-17 9 0 102 51 51
-18 9 0 102 51 51
8 9 1 102 51 51
7 9 1 102 51 51
6 9 1 102 51 51
5 9 1 102 51 51
4 9 1 102 51 51
3 9 1 102 51 51
2 9 1 102 51 51
1 9 1 102 51 51
0 9 1 102 51 51
-1 9 1 102 51 51
-2 9 1 102 51 51
-3 9 1 102 51 51
-4 9 1 102 51 51
-5 9 1 102 51 51
-6 9 1 102 51 51
-7 9 1 102 51 51
-8 9 1 102 51 51
-9 9 1 102 51 51
-10 9 1 102 51 51
-11 9 1 102 51 51
-12 9 1 102 51 51
-13 9 1 102 51 51
-14 9 1 102 51 51
-15 9 1 102 51 51
-16 9 1 102 51 51
-17 9 1 102 51 51
-18 9 1 102 51 51
8 9 2 102 51 51
7 9 2 102 51 51
6 9 2 102 51 51
5 9 2 102 51 51
4 9 2 102 51 51
3 9 2 102 51 51
2 9 2 102 51 51
1 9 2 102 51 51
0 9 2 102 51 51
-1 9 2 102 51 51
-2 9 2 102 51 51
-3 9 2 102 51 51
-4 9 2 102 51 51
-5 9 2 102 51 51
-6 9 2 102 51 51
-7 9 2 102 51 51
-8 9 2 102 51 51
-9 9 2 102 51 51
-10 9 2 102 51 51
-11 9 2 102 51 51
-12 9 2 102 51 51
-13 9 2 102 51 51
-14 9 2 102 51 51
-15 9 2 102 51 51
-16 9 2 102 51 51
-17 9 2 102 51 51
-18 9 2 102 51 51
