ply
format ascii 1.0
comment : MagicaVoxel @ Ephtracy
element vertex 1881
property float x
property float y
property float z
property uchar red
property uchar green
property uchar blue
end_header
-58 35 23 102 51 51
-58 34 23 102 51 51
-50 35 17 102 51 51
-50 34 17 102 51 51
-50 33 17 102 51 51
-43 23 16 50 50 50
-51 32 22 102 51 51
-51 32 21 102 51 51
-50 32 20 102 51 51
-50 33 18 102 51 51
-50 34 18 102 51 51
-50 35 19 102 51 51
-57 36 23 102 51 51
-50 33 19 102 51 51
-30 16 16 0 204 0
-33 16 16 0 204 0
-50 32 16 102 51 51
-56 36 23 102 51 51
-50 35 16 102 51 51
-55 36 23 102 51 51
-50 34 16 102 51 51
-54 36 23 102 51 51
-29 35 15 42 22 4
-53 36 23 102 51 51
-30 35 15 42 22 4
-52 36 23 102 51 51
-31 35 15 42 22 4
-51 36 23 102 51 51
-32 35 15 42 22 4
-39 36 19 102 51 51
-31 16 16 0 255 204
-28 19 16 0 0 153
-49 13 21 102 51 51
-48 13 19 102 51 51
-48 13 18 102 51 51
-28 27 15 0 204 0
-36 22 15 0 204 0
-42 23 15 0 0 153
-35 27 15 0 0 153
-35 22 15 67 67 255
-58 35 22 102 51 51
-58 34 22 102 51 51
-50 33 16 102 51 51
-50 32 19 102 51 51
-50 32 17 102 51 51
-40 27 14 42 22 4
-41 27 14 42 22 4
-50 35 18 102 51 51
-42 27 14 42 22 4
-29 26 14 42 22 4
-58 33 25 102 51 51
-57 27 15 42 22 4
-57 36 22 102 51 51
-42 22 15 67 67 255
-42 27 15 0 204 0
-40 22 15 255 102 0
-57 26 15 42 22 4
-40 27 15 255 102 0
-33 22 15 255 102 0
-33 27 15 255 102 0
-34 22 15 221 0 0
-34 27 15 221 0 0
-41 22 15 221 0 0
-41 27 15 221 0 0
-44 16 16 255 102 0
-45 16 16 255 102 0
-45 19 16 255 102 0
-44 19 16 255 102 0
-40 17 16 255 102 0
-40 18 16 255 102 0
-37 17 16 255 102 0
-57 25 15 42 22 4
-52 21 22 102 51 51
-29 36 16 102 51 51
-56 36 22 102 51 51
-37 18 16 255 102 0
-31 18 16 255 102 0
-15 14 15 42 22 4
-29 34 15 42 22 4
-30 36 16 102 51 51
-55 36 22 102 51 51
-30 34 15 42 22 4
-50 36 21 102 51 51
-32 18 16 255 102 0
-31 34 15 42 22 4
-31 36 16 102 51 51
-31 17 16 221 0 0
-32 17 16 221 0 0
-32 34 15 42 22 4
-54 36 22 102 51 51
-55 29 15 42 22 4
-32 36 16 102 51 51
-38 18 16 221 0 0
-58 35 20 102 51 51
-58 34 20 102 51 51
-38 17 16 221 0 0
-51 14 21 102 51 51
-33 36 16 102 51 51
-53 36 21 102 51 51
-51 14 22 102 51 51
-53 36 22 102 51 51
-50 14 20 102 51 51
-29 33 15 42 22 4
-34 36 16 102 51 51
-30 33 15 42 22 4
-52 36 22 102 51 51
-31 33 15 42 22 4
-51 36 22 102 51 51
-32 33 15 42 22 4
-35 36 16 102 51 51
-50 14 16 102 51 51
-50 14 19 102 51 51
-50 14 17 102 51 51
-15 36 16 102 51 51
-16 36 16 102 51 51
-36 36 16 102 51 51
-49 36 21 102 51 51
-17 36 16 102 51 51
-57 24 15 42 22 4
-57 23 15 42 22 4
-18 36 16 102 51 51
-37 36 16 102 51 51
-29 32 15 42 22 4
-50 36 22 102 51 51
-30 32 15 42 22 4
-40 36 19 102 51 51
-31 32 15 42 22 4
-38 36 16 102 51 51
-58 17 17 102 51 51
-57 16 17 102 51 51
-39 17 16 221 0 0
-32 32 15 42 22 4
-39 36 16 102 51 51
-39 18 16 221 0 0
-45 17 16 221 0 0
-44 17 16 221 0 0
-44 18 16 221 0 0
-19 36 16 102 51 51
-40 36 16 102 51 51
-45 18 16 221 0 0
-58 35 21 102 51 51
-58 34 21 102 51 51
-50 14 18 102 51 51
-20 36 16 102 51 51
-41 36 16 102 51 51
-56 13 25 102 51 51
-57 13 25 102 51 51
-51 13 24 102 51 51
-52 13 24 102 51 51
-21 36 16 102 51 51
-42 36 16 102 51 51
-53 13 24 102 51 51
-54 13 24 102 51 51
-55 13 24 102 51 51
-57 15 17 102 51 51
-22 36 16 102 51 51
-43 36 16 102 51 51
-57 14 17 102 51 51
-57 36 21 102 51 51
-57 21 16 102 51 51
-57 20 16 102 51 51
-29 31 15 42 22 4
-44 36 16 102 51 51
-57 19 16 102 51 51
-57 36 20 102 51 51
-30 31 15 42 22 4
-56 36 20 102 51 51
-31 31 15 42 22 4
-45 36 16 102 51 51
-32 31 15 42 22 4
-55 36 20 102 51 51
-29 29 15 42 22 4
-54 36 20 102 51 51
-30 29 15 42 22 4
-46 36 16 102 51 51
-31 29 15 42 22 4
-53 36 20 102 51 51
-32 29 15 42 22 4
-56 36 21 102 51 51
-29 30 15 42 22 4
-47 36 16 102 51 51
-30 30 15 42 22 4
-48 36 16 102 51 51
-31 30 15 42 22 4
-49 36 16 102 51 51
-32 30 15 42 22 4
-50 36 16 102 51 51
-33 35 15 42 22 4
-51 36 16 102 51 51
-34 35 15 42 22 4
-52 36 16 102 51 51
-35 35 15 42 22 4
-53 36 16 102 51 51
-36 35 15 42 22 4
-54 36 16 102 51 51
-37 35 15 42 22 4
-55 36 16 102 51 51
-38 35 15 42 22 4
-59 21 25 102 51 51
-57 18 16 102 51 51
-57 17 16 102 51 51
-56 16 16 102 51 51
-56 15 16 102 51 51
-56 14 16 102 51 51
-56 13 24 102 51 51
-23 13 16 102 51 51
-57 13 24 102 51 51
-56 34 16 102 51 51
-56 35 16 102 51 51
-39 35 15 42 22 4
-52 36 20 102 51 51
-40 35 15 42 22 4
-51 36 20 102 51 51
-41 35 15 42 22 4
-50 36 20 102 51 51
-42 36 18 102 51 51
-42 35 15 42 22 4
-49 36 20 102 51 51
-41 36 19 102 51 51
-43 35 15 42 22 4
-48 36 20 102 51 51
-58 35 25 102 51 51
-58 34 25 102 51 51
-24 13 16 102 51 51
-59 20 25 102 51 51
-51 13 23 102 51 51
-59 19 25 102 51 51
-59 18 25 102 51 51
-59 17 25 102 51 51
-58 16 25 102 51 51
-25 13 16 102 51 51
-58 15 25 102 51 51
-58 14 25 102 51 51
-48 13 17 102 51 51
-49 13 19 102 51 51
-49 13 18 102 51 51
-49 13 17 102 51 51
-52 35 23 102 51 51
-49 13 20 102 51 51
-28 23 15 67 67 255
-28 22 15 67 67 255
-57 36 25 102 51 51
-44 35 15 42 22 4
-29 22 15 67 67 255
-36 35 16 67 67 255
-56 36 25 102 51 51
-45 35 15 42 22 4
-46 35 15 42 22 4
-47 35 15 42 22 4
-29 35 16 67 67 255
-28 30 16 67 67 255
-48 35 15 42 22 4
-49 35 15 42 22 4
-50 35 15 42 22 4
-29 36 17 102 51 51
-54 36 21 102 51 51
-58 35 24 102 51 51
-33 34 15 42 22 4
-30 36 17 102 51 51
-58 34 24 102 51 51
-59 21 24 102 51 51
-34 34 15 42 22 4
-31 36 17 0 225 255
-59 20 24 102 51 51
-59 19 24 102 51 51
-35 34 15 42 22 4
-32 36 17 255 255 255
-59 18 24 102 51 51
-59 17 24 102 51 51
-42 36 19 102 51 51
-33 36 17 102 51 51
-58 16 24 102 51 51
-58 15 24 102 51 51
-43 36 19 102 51 51
-34 36 17 102 51 51
-58 14 24 102 51 51
-52 13 23 102 51 51
-44 36 19 102 51 51
-35 36 17 102 51 51
-26 13 16 102 51 51
-57 36 24 102 51 51
-45 36 19 102 51 51
-36 36 17 102 51 51
-36 34 15 42 22 4
-56 36 24 102 51 51
-46 36 19 102 51 51
-37 36 17 102 51 51
-37 34 15 42 22 4
-55 36 24 102 51 51
-47 36 19 102 51 51
-38 36 17 0 225 255
-38 34 15 42 22 4
-54 36 24 102 51 51
-28 34 16 0 0 153
-41 36 18 102 51 51
-39 36 17 255 255 255
-39 34 15 42 22 4
-51 36 21 102 51 51
-40 34 15 42 22 4
-41 34 15 42 22 4
-40 36 17 102 51 51
-53 36 24 102 51 51
-30 26 14 42 22 4
-50 35 20 102 51 51
-48 36 19 102 51 51
-41 36 17 102 51 51
-42 34 15 42 22 4
-52 36 24 102 51 51
-43 34 15 42 22 4
-44 34 15 42 22 4
-42 36 17 102 51 51
-45 34 15 42 22 4
-51 36 24 102 51 51
-49 36 19 102 51 51
-43 36 17 102 51 51
-46 34 15 42 22 4
-55 36 21 102 51 51
-47 34 15 42 22 4
-44 36 17 102 51 51
-48 34 15 42 22 4
-50 34 20 102 51 51
-50 36 19 102 51 51
-43 26 16 50 50 50
-50 33 20 102 51 51
-28 29 16 0 0 153
-49 34 15 42 22 4
-46 36 17 255 255 255
-50 32 18 102 51 51
-28 21 16 168 168 167
-51 31 22 102 51 51
-51 36 19 102 51 51
-47 36 17 102 51 51
-50 34 15 42 22 4
-48 36 17 102 51 51
-59 21 23 102 51 51
-49 36 17 102 51 51
-59 20 23 102 51 51
-50 36 17 102 51 51
-59 19 23 102 51 51
-51 36 17 102 51 51
-59 18 23 102 51 51
-52 36 17 102 51 51
-59 17 23 102 51 51
-53 36 17 102 51 51
-58 16 23 102 51 51
-54 36 17 102 51 51
-58 15 23 102 51 51
-55 36 17 102 51 51
-58 14 23 102 51 51
-56 36 17 102 51 51
-59 21 22 102 51 51
-59 20 22 102 51 51
-59 19 22 102 51 51
-59 18 22 102 51 51
-59 17 22 102 51 51
-58 16 22 102 51 51
-58 15 22 102 51 51
-58 14 22 102 51 51
-55 31 15 42 22 4
-27 13 16 102 51 51
-57 34 17 102 51 51
-57 35 17 102 51 51
-28 28 16 168 168 167
-27 22 16 102 51 51
-27 21 16 102 51 51
-27 20 16 102 51 51
-27 19 16 102 51 51
-27 18 16 102 51 51
-27 17 16 102 51 51
-27 16 16 102 51 51
-27 15 16 102 51 51
-27 22 15 102 51 51
-50 15 20 102 51 51
-31 26 14 42 22 4
-59 21 21 102 51 51
-31 33 17 255 255 255
-59 20 21 102 51 51
-29 36 18 102 51 51
-59 19 21 102 51 51
-30 36 18 102 51 51
-59 18 21 102 51 51
-31 36 18 255 255 255
-59 17 21 102 51 51
-32 36 18 255 255 255
-58 16 21 102 51 51
-58 15 21 102 51 51
-53 36 18 102 51 51
-58 14 21 102 51 51
-52 36 18 102 51 51
-59 21 20 102 51 51
-51 36 18 102 51 51
-33 33 15 42 22 4
-50 36 18 102 51 51
-27 34 16 102 51 51
-52 36 19 102 51 51
-45 36 18 255 255 255
-48 36 18 102 51 51
-33 36 18 102 51 51
-34 33 15 42 22 4
-27 33 16 102 51 51
-29 36 19 102 51 51
-35 33 15 42 22 4
-36 33 15 42 22 4
-49 36 18 102 51 51
-51 30 22 102 51 51
-51 29 22 102 51 51
-27 32 16 102 51 51
-32 36 19 102 51 51
-53 36 19 102 51 51
-51 20 22 102 51 51
-37 33 15 42 22 4
-34 36 18 102 51 51
-38 33 15 42 22 4
-52 36 21 102 51 51
-39 33 15 42 22 4
-40 33 15 42 22 4
-32 26 14 42 22 4
-41 33 15 42 22 4
-33 26 14 42 22 4
-42 33 15 42 22 4
-34 26 14 42 22 4
-54 36 19 102 51 51
-43 36 18 102 51 51
-40 36 18 102 51 51
-27 31 16 102 51 51
-35 36 18 102 51 51
-43 33 15 42 22 4
-50 17 20 102 51 51
-44 33 15 42 22 4
-47 36 18 102 51 51
-30 36 19 102 51 51
-56 22 15 42 22 4
-55 36 19 102 51 51
-35 36 19 102 51 51
-46 33 15 42 22 4
-47 33 15 42 22 4
-27 30 16 102 51 51
-54 36 18 102 51 51
-48 33 15 42 22 4
-36 36 18 102 51 51
-56 36 19 102 51 51
-55 36 18 102 51 51
-49 33 15 42 22 4
-56 36 18 102 51 51
-27 29 16 102 51 51
-50 16 20 102 51 51
-50 33 15 42 22 4
-59 20 20 102 51 51
-44 36 18 102 51 51
-27 28 16 102 51 51
-27 27 16 102 51 51
-57 36 19 102 51 51
-27 27 15 102 51 51
-37 36 18 102 51 51
-55 32 15 42 22 4
-46 36 18 255 255 255
-33 36 19 102 51 51
-59 19 20 102 51 51
-31 36 19 102 51 51
-59 18 20 102 51 51
-36 36 19 102 51 51
-15 23 14 42 22 4
-16 23 14 42 22 4
-59 17 20 102 51 51
-17 23 14 42 22 4
-38 36 19 102 51 51
-34 36 19 102 51 51
-38 36 18 255 255 255
-18 23 14 42 22 4
-58 16 20 102 51 51
-19 23 14 42 22 4
-58 15 20 102 51 51
-37 36 19 102 51 51
-20 23 14 42 22 4
-21 23 14 42 22 4
-22 23 14 42 22 4
-23 23 14 42 22 4
-24 23 14 42 22 4
-58 35 19 102 51 51
-58 34 19 102 51 51
-28 13 16 102 51 51
-35 26 14 42 22 4
-39 36 18 255 255 255
-50 34 19 102 51 51
-36 26 14 42 22 4
-58 33 24 102 51 51
-56 32 15 42 22 4
-56 31 15 42 22 4
-56 30 15 42 22 4
-56 29 15 42 22 4
-55 33 15 42 22 4
-58 14 20 102 51 51
-59 21 19 102 51 51
-59 20 19 102 51 51
-59 19 19 102 51 51
-59 18 19 102 51 51
-29 13 16 102 51 51
-37 26 14 42 22 4
-58 34 18 102 51 51
-58 35 18 102 51 51
-57 36 18 102 51 51
-55 35 15 42 22 4
-55 34 15 42 22 4
-54 34 15 42 22 4
-53 34 15 42 22 4
-55 30 15 42 22 4
-51 27 15 42 22 4
-52 28 15 42 22 4
-52 29 15 42 22 4
-53 30 15 42 22 4
-53 31 15 42 22 4
-54 32 15 42 22 4
-54 33 15 42 22 4
-38 26 14 42 22 4
-25 23 14 42 22 4
-59 17 19 102 51 51
-30 13 16 102 51 51
-53 13 23 102 51 51
-54 13 23 102 51 51
-55 13 23 102 51 51
-55 28 15 42 22 4
-31 13 16 102 51 51
-56 13 23 102 51 51
-32 13 16 102 51 51
-56 28 15 42 22 4
-33 13 16 102 51 51
-34 13 16 102 51 51
-52 34 15 42 22 4
-35 13 16 102 51 51
-54 27 15 42 22 4
-53 27 15 42 22 4
-52 27 15 42 22 4
-51 34 15 42 22 4
-57 13 23 102 51 51
-54 28 15 42 22 4
-53 28 15 42 22 4
-51 28 15 42 22 4
-54 35 15 42 22 4
-58 16 19 102 51 51
-54 29 15 42 22 4
-53 29 15 42 22 4
-51 29 15 42 22 4
-53 35 15 42 22 4
-50 13 22 102 51 51
-54 30 15 42 22 4
-52 30 15 42 22 4
-51 30 15 42 22 4
-52 35 15 42 22 4
-51 13 22 102 51 51
-54 31 15 42 22 4
-52 31 15 42 22 4
-51 31 15 42 22 4
-51 35 15 42 22 4
-52 13 22 102 51 51
-53 32 15 42 22 4
-52 32 15 42 22 4
-51 32 15 42 22 4
-51 33 15 42 22 4
-53 13 22 102 51 51
-53 33 15 42 22 4
-52 33 15 42 22 4
-50 29 15 42 22 4
-49 29 15 42 22 4
-48 29 15 42 22 4
-47 29 15 42 22 4
-46 29 15 42 22 4
-45 29 15 42 22 4
-44 29 15 42 22 4
-43 29 15 42 22 4
-42 29 15 42 22 4
-41 29 15 42 22 4
-40 29 15 42 22 4
-39 29 15 42 22 4
-38 29 15 42 22 4
-37 29 15 42 22 4
-36 29 15 42 22 4
-35 29 15 42 22 4
-34 29 15 42 22 4
-33 29 15 42 22 4
-50 28 15 42 22 4
-49 28 15 42 22 4
-48 28 15 42 22 4
-47 28 15 42 22 4
-46 28 15 42 22 4
-45 28 15 42 22 4
-44 28 15 42 22 4
-23 36 16 102 51 51
-24 36 16 102 51 51
-25 36 16 102 51 51
-26 36 16 102 51 51
-27 36 16 102 51 51
-28 36 16 102 51 51
-15 36 19 102 51 51
-16 36 19 102 51 51
-17 36 19 102 51 51
-18 36 19 102 51 51
-19 36 19 102 51 51
-50 30 15 42 22 4
-49 30 15 42 22 4
-48 30 15 42 22 4
-47 30 15 42 22 4
-46 30 15 42 22 4
-45 30 15 42 22 4
-44 30 15 42 22 4
-43 30 15 42 22 4
-42 30 15 42 22 4
-41 30 15 42 22 4
-40 30 15 42 22 4
-39 30 15 42 22 4
-38 30 15 42 22 4
-37 30 15 42 22 4
-36 30 15 42 22 4
-35 30 15 42 22 4
-34 30 15 42 22 4
-33 30 15 42 22 4
-50 27 15 42 22 4
-49 27 15 42 22 4
-48 27 15 42 22 4
-47 27 15 42 22 4
-46 27 15 42 22 4
-45 27 15 42 22 4
-44 27 15 42 22 4
-20 36 19 102 51 51
-21 36 19 102 51 51
-22 36 19 102 51 51
-23 36 19 102 51 51
-24 36 19 102 51 51
-25 36 19 102 51 51
-26 36 19 102 51 51
-27 36 19 102 51 51
-28 36 19 102 51 51
-15 36 17 102 51 51
-16 36 17 102 51 51
-50 31 15 42 22 4
-49 31 15 42 22 4
-48 31 15 42 22 4
-47 31 15 42 22 4
-46 31 15 42 22 4
-45 31 15 42 22 4
-44 31 15 42 22 4
-43 31 15 42 22 4
-42 31 15 42 22 4
-41 31 15 42 22 4
-40 31 15 42 22 4
-39 31 15 42 22 4
-38 31 15 42 22 4
-37 31 15 42 22 4
-36 31 15 42 22 4
-35 31 15 42 22 4
-34 31 15 42 22 4
-33 31 15 42 22 4
-54 13 22 102 51 51
-55 13 22 102 51 51
-56 13 22 102 51 51
-36 13 16 102 51 51
-37 13 16 102 51 51
-38 13 16 102 51 51
-39 13 16 102 51 51
-57 13 22 102 51 51
-50 13 21 102 51 51
-51 13 21 102 51 51
-52 13 21 102 51 51
-53 13 21 102 51 51
-54 13 21 102 51 51
-55 13 21 102 51 51
-56 13 21 102 51 51
-40 13 16 102 51 51
-41 13 16 102 51 51
-58 15 19 102 51 51
-50 32 15 42 22 4
-49 32 15 42 22 4
-48 32 15 42 22 4
-47 32 15 42 22 4
-46 32 15 42 22 4
-45 32 15 42 22 4
-44 32 15 42 22 4
-43 32 15 42 22 4
-42 32 15 42 22 4
-41 32 15 42 22 4
-40 32 15 42 22 4
-39 32 15 42 22 4
-38 32 15 42 22 4
-37 32 15 42 22 4
-36 32 15 42 22 4
-35 32 15 42 22 4
-34 32 15 42 22 4
-33 32 15 42 22 4
-42 13 16 102 51 51
-43 13 16 102 51 51
-44 13 16 102 51 51
-57 13 21 102 51 51
-50 13 20 102 51 51
-51 13 20 102 51 51
-52 13 20 102 51 51
-53 13 20 102 51 51
-54 13 20 102 51 51
-55 13 20 102 51 51
-56 27 15 42 22 4
-55 27 15 42 22 4
-56 13 20 102 51 51
-58 14 19 102 51 51
-45 13 16 102 51 51
-46 13 16 102 51 51
-47 13 16 102 51 51
-48 13 16 102 51 51
-26 23 14 42 22 4
-57 13 20 102 51 51
-39 26 14 42 22 4
-50 13 19 102 51 51
-40 26 14 42 22 4
-51 13 19 102 51 51
-41 26 14 42 22 4
-52 13 19 102 51 51
-43 22 16 50 50 50
-53 13 19 102 51 51
-50 17 19 102 51 51
-54 13 19 102 51 51
-50 16 19 102 51 51
-55 13 19 102 51 51
-50 15 19 102 51 51
-56 13 19 102 51 51
-49 13 16 102 51 51
-50 13 16 102 51 51
-51 13 16 102 51 51
-52 13 16 102 51 51
-27 23 14 42 22 4
-55 15 15 42 22 4
-54 15 15 42 22 4
-53 15 15 42 22 4
-52 15 15 42 22 4
-51 15 15 42 22 4
-50 15 15 42 22 4
-49 15 15 42 22 4
-48 15 15 42 22 4
-47 15 15 42 22 4
-46 15 15 42 22 4
-45 15 15 42 22 4
-44 15 15 42 22 4
-43 15 15 42 22 4
-42 15 15 42 22 4
-41 15 15 42 22 4
-40 15 15 42 22 4
-39 15 15 42 22 4
-38 15 15 42 22 4
-37 15 15 42 22 4
-36 15 15 42 22 4
-35 15 15 42 22 4
-34 15 15 42 22 4
-33 15 15 42 22 4
-32 15 15 42 22 4
-31 15 15 42 22 4
-30 15 15 42 22 4
-29 15 15 42 22 4
-55 16 15 42 22 4
-54 16 15 42 22 4
-53 16 15 42 22 4
-52 16 15 42 22 4
-51 16 15 42 22 4
-50 16 15 42 22 4
-49 16 15 42 22 4
-48 16 15 42 22 4
-47 16 15 42 22 4
-46 16 15 42 22 4
-45 16 15 42 22 4
-44 16 15 42 22 4
-43 16 15 42 22 4
-42 16 15 42 22 4
-41 16 15 42 22 4
-40 16 15 42 22 4
-39 16 15 42 22 4
-38 16 15 42 22 4
-37 16 15 42 22 4
-36 16 15 42 22 4
-35 16 15 42 22 4
-34 16 15 42 22 4
-33 16 15 42 22 4
-48 33 17 255 255 255
-31 16 15 42 22 4
-30 16 15 42 22 4
-29 16 15 42 22 4
-55 17 15 42 22 4
-54 17 15 42 22 4
-53 17 15 42 22 4
-52 17 15 42 22 4
-51 17 15 42 22 4
-50 17 15 42 22 4
-49 17 15 42 22 4
-48 17 15 42 22 4
-47 17 15 42 22 4
-46 17 15 42 22 4
-45 17 15 42 22 4
-44 17 15 42 22 4
-43 17 15 42 22 4
-42 17 15 42 22 4
-41 17 15 42 22 4
-40 17 15 42 22 4
-39 17 15 42 22 4
-38 17 15 42 22 4
-37 17 15 42 22 4
-36 17 15 42 22 4
-35 17 15 42 22 4
-34 17 15 42 22 4
-33 17 15 42 22 4
-32 17 15 42 22 4
-31 17 15 42 22 4
-30 17 15 42 22 4
-29 17 15 42 22 4
-56 18 15 42 22 4
-55 18 15 42 22 4
-54 18 15 42 22 4
-53 18 15 42 22 4
-52 18 15 42 22 4
-51 18 15 42 22 4
-50 18 15 42 22 4
-49 18 15 42 22 4
-48 18 15 42 22 4
-47 18 15 42 22 4
-46 18 15 42 22 4
-45 18 15 42 22 4
-44 18 15 42 22 4
-43 18 15 42 22 4
-42 18 15 42 22 4
-41 18 15 42 22 4
-40 18 15 42 22 4
-39 18 15 42 22 4
-38 18 15 42 22 4
-37 18 15 42 22 4
-36 18 15 42 22 4
-35 18 15 42 22 4
-34 18 15 42 22 4
-33 18 15 42 22 4
-32 18 15 42 22 4
-31 18 15 42 22 4
-30 18 15 42 22 4
-29 18 15 42 22 4
-56 19 15 42 22 4
-55 19 15 42 22 4
-54 19 15 42 22 4
-53 19 15 42 22 4
-52 19 15 42 22 4
-51 19 15 42 22 4
-50 19 15 42 22 4
-28 14 16 168 168 167
-48 19 15 42 22 4
-47 19 15 42 22 4
-46 19 15 42 22 4
-45 19 15 42 22 4
-44 19 15 42 22 4
-43 19 15 42 22 4
-42 19 15 42 22 4
-41 19 15 42 22 4
-40 19 15 42 22 4
-39 19 15 42 22 4
-38 19 15 42 22 4
-37 19 15 42 22 4
-36 19 15 42 22 4
-35 19 15 42 22 4
-34 19 15 42 22 4
-33 19 15 42 22 4
-32 19 15 42 22 4
-31 19 15 42 22 4
-30 19 15 42 22 4
-29 19 15 42 22 4
-56 20 15 42 22 4
-55 20 15 42 22 4
-54 20 15 42 22 4
-53 20 15 42 22 4
-52 20 15 42 22 4
-51 20 15 42 22 4
-50 20 15 42 22 4
-49 20 15 42 22 4
-48 20 15 42 22 4
-47 20 15 42 22 4
-46 20 15 42 22 4
-45 20 15 42 22 4
-44 20 15 42 22 4
-43 20 15 42 22 4
-42 20 15 42 22 4
-41 20 15 42 22 4
-40 20 15 42 22 4
-39 20 15 42 22 4
-38 20 15 42 22 4
-37 20 15 42 22 4
-36 20 15 42 22 4
-35 20 15 42 22 4
-34 20 15 42 22 4
-33 20 15 42 22 4
-32 20 15 42 22 4
-31 20 15 42 22 4
-30 20 15 42 22 4
-29 20 15 42 22 4
-56 21 15 42 22 4
-55 21 15 42 22 4
-54 21 15 42 22 4
-53 21 15 42 22 4
-52 21 15 42 22 4
-51 21 15 42 22 4
-50 21 15 42 22 4
-49 21 15 42 22 4
-48 21 15 42 22 4
-47 21 15 42 22 4
-46 21 15 42 22 4
-45 21 15 42 22 4
-44 21 15 42 22 4
-43 21 15 42 22 4
-42 21 15 42 22 4
-41 21 15 42 22 4
-40 21 15 42 22 4
-39 21 15 0 0 0
-38 21 15 0 0 0
-37 21 15 42 22 4
-36 21 15 42 22 4
-35 21 15 42 22 4
-34 21 15 42 22 4
-33 21 15 42 22 4
-32 21 15 0 0 0
-31 21 15 0 0 0
-30 21 15 42 22 4
-29 21 15 42 22 4
-58 33 23 102 51 51
-55 22 15 42 22 4
-54 22 15 42 22 4
-53 22 15 42 22 4
-52 22 15 42 22 4
-51 22 15 42 22 4
-50 22 15 42 22 4
-49 22 15 42 22 4
-48 22 15 42 22 4
-47 22 15 42 22 4
-46 22 15 42 22 4
-45 22 15 42 22 4
-44 22 15 42 22 4
-43 22 15 42 22 4
-29 21 16 50 50 50
-30 21 16 50 50 50
-33 21 16 50 50 50
-34 21 16 50 50 50
-35 21 16 168 168 167
-36 21 16 50 50 50
-37 21 16 50 50 50
-40 21 16 50 50 50
-41 21 16 50 50 50
-42 21 16 168 168 167
-43 21 16 67 67 255
-51 31 21 102 51 51
-51 30 21 102 51 51
-51 29 21 102 51 51
-59 21 18 102 51 51
-56 23 15 42 22 4
-55 23 15 42 22 4
-54 23 15 42 22 4
-53 23 15 42 22 4
-52 23 15 42 22 4
-51 23 15 42 22 4
-50 23 15 42 22 4
-49 23 15 42 22 4
-48 23 15 42 22 4
-47 23 15 42 22 4
-46 23 15 42 22 4
-45 23 15 42 22 4
-44 23 15 42 22 4
-17 36 17 0 225 255
-18 36 17 255 255 255
-19 36 17 102 51 51
-20 36 17 102 51 51
-21 36 17 102 51 51
-22 36 17 102 51 51
-23 36 17 102 51 51
-24 36 17 0 225 255
-25 36 17 255 255 255
-26 36 17 102 51 51
-27 36 17 102 51 51
-28 36 17 102 51 51
-15 36 18 102 51 51
-16 36 18 102 51 51
-17 36 18 255 255 255
-59 20 18 102 51 51
-56 24 15 42 22 4
-55 24 15 42 22 4
-54 24 15 42 22 4
-53 24 15 42 22 4
-52 24 15 42 22 4
-51 24 15 42 22 4
-50 24 15 42 22 4
-49 24 15 42 22 4
-48 24 15 42 22 4
-47 24 15 42 22 4
-46 24 15 42 22 4
-45 24 15 42 22 4
-44 24 15 42 22 4
-18 36 18 255 255 255
-19 36 18 102 51 51
-20 36 18 102 51 51
-21 36 18 102 51 51
-22 36 18 102 51 51
-23 36 18 102 51 51
-24 36 18 255 255 255
-25 36 18 255 255 255
-26 36 18 102 51 51
-27 36 18 102 51 51
-28 36 18 102 51 51
-28 23 14 42 22 4
-29 23 14 42 22 4
-30 23 14 42 22 4
-31 23 14 42 22 4
-59 19 18 102 51 51
-56 25 15 42 22 4
-55 25 15 42 22 4
-54 25 15 42 22 4
-53 25 15 42 22 4
-52 25 15 42 22 4
-51 25 15 42 22 4
-50 25 15 42 22 4
-49 25 15 42 22 4
-48 25 15 42 22 4
-47 25 15 42 22 4
-46 25 15 42 22 4
-45 25 15 42 22 4
-44 25 15 42 22 4
-32 23 14 42 22 4
-33 23 14 42 22 4
-34 23 14 42 22 4
-35 23 14 42 22 4
-36 23 14 42 22 4
-37 23 14 42 22 4
-38 23 14 42 22 4
-39 23 14 42 22 4
-40 23 14 42 22 4
-41 23 14 42 22 4
-15 35 15 42 22 4
-16 35 15 42 22 4
-17 35 15 42 22 4
-18 35 15 42 22 4
-19 35 15 42 22 4
-59 18 18 102 51 51
-56 26 15 42 22 4
-55 26 15 42 22 4
-54 26 15 42 22 4
-53 26 15 42 22 4
-52 26 15 42 22 4
-51 26 15 42 22 4
-50 26 15 42 22 4
-49 26 15 42 22 4
-48 26 15 42 22 4
-47 26 15 42 22 4
-46 26 15 42 22 4
-45 26 15 42 22 4
-44 26 15 42 22 4
-20 35 15 42 22 4
-21 35 15 42 22 4
-22 35 15 42 22 4
-23 35 15 42 22 4
-24 35 15 42 22 4
-25 35 15 42 22 4
-26 35 15 42 22 4
-27 35 15 42 22 4
-28 35 15 42 22 4
-15 34 15 42 22 4
-16 34 15 42 22 4
-17 34 15 42 22 4
-18 34 15 42 22 4
-19 34 15 42 22 4
-20 34 15 42 22 4
-57 13 19 102 51 51
-50 15 16 102 51 51
-50 13 18 102 51 51
-50 16 16 102 51 51
-51 13 18 102 51 51
-50 17 16 102 51 51
-52 13 18 102 51 51
-51 28 21 102 51 51
-53 13 18 102 51 51
-42 26 14 42 22 4
-54 13 18 102 51 51
-29 25 14 42 22 4
-55 13 18 102 51 51
-30 25 14 42 22 4
-56 13 18 102 51 51
-57 13 18 102 51 51
-59 17 18 102 51 51
-58 16 18 102 51 51
-58 15 18 102 51 51
-58 14 18 102 51 51
-50 13 17 102 51 51
-50 15 17 102 51 51
-51 13 17 102 51 51
-50 16 17 102 51 51
-52 13 17 102 51 51
-50 17 17 102 51 51
-53 13 17 102 51 51
-51 27 21 102 51 51
-54 13 17 102 51 51
-31 25 14 42 22 4
-55 13 17 102 51 51
-32 25 14 42 22 4
-56 13 17 102 51 51
-33 25 14 42 22 4
-15 13 16 102 51 51
-34 25 14 42 22 4
-58 21 17 102 51 51
-58 20 17 102 51 51
-58 19 17 102 51 51
-58 18 17 102 51 51
-16 13 16 102 51 51
-50 15 18 102 51 51
-17 13 16 102 51 51
-50 16 18 102 51 51
-18 13 16 102 51 51
-50 17 18 102 51 51
-19 13 16 102 51 51
-51 26 21 102 51 51
-20 13 16 102 51 51
-35 25 14 42 22 4
-21 13 16 102 51 51
-36 25 14 42 22 4
-22 13 16 102 51 51
-37 25 14 42 22 4
-38 25 14 42 22 4
-39 25 14 42 22 4
-40 25 14 42 22 4
-41 25 14 42 22 4
-42 25 14 42 22 4
-29 24 14 42 22 4
-30 24 14 42 22 4
-31 24 14 42 22 4
-32 24 14 42 22 4
-33 24 14 42 22 4
-34 24 14 42 22 4
-35 24 14 42 22 4
-36 24 14 42 22 4
-37 24 14 42 22 4
-38 24 14 42 22 4
-39 24 14 42 22 4
-40 24 14 42 22 4
-49 35 16 168 168 167
-42 35 16 168 168 167
-35 35 16 168 168 167
-28 35 16 168 168 167
-49 35 17 168 168 168
-49 35 18 168 168 168
-49 35 19 168 168 168
-42 35 17 168 168 168
-42 35 18 168 168 168
-42 35 19 168 168 168
-35 35 17 168 168 168
-35 35 18 168 168 168
-35 35 19 168 168 168
-28 35 17 168 168 168
-28 35 18 168 168 168
-28 35 19 168 168 168
-28 21 15 42 22 4
-27 21 15 42 22 4
-26 21 15 42 22 4
-25 21 15 42 22 4
-24 21 15 42 22 4
-23 21 15 42 22 4
-22 21 15 42 22 4
-21 21 15 42 22 4
-20 21 15 42 22 4
-19 21 15 42 22 4
-18 21 15 42 22 4
-17 21 15 42 22 4
-16 21 15 42 22 4
-15 21 15 42 22 4
-28 20 15 42 22 4
-27 20 15 42 22 4
-26 20 15 42 22 4
-25 20 15 42 22 4
-24 20 15 42 22 4
-23 20 15 42 22 4
-22 20 15 42 22 4
-21 20 15 42 22 4
-20 20 15 42 22 4
-19 20 15 42 22 4
-18 20 15 42 22 4
-17 20 15 42 22 4
-16 20 15 42 22 4
-15 20 15 42 22 4
-51 25 21 102 51 51
-51 24 21 102 51 51
-51 23 21 102 51 51
-51 22 21 102 51 51
-51 21 21 102 51 51
-51 20 21 102 51 51
-51 19 21 102 51 51
-51 18 21 102 51 51
-50 31 20 102 51 51
-50 30 20 102 51 51
-50 29 20 168 168 168
-51 29 20 102 51 51
-51 28 20 102 51 51
-51 27 20 102 51 51
-28 19 15 42 22 4
-27 19 15 42 22 4
-26 19 15 42 22 4
-25 19 15 42 22 4
-24 19 15 42 22 4
-23 19 15 42 22 4
-22 19 15 42 22 4
-21 19 15 42 22 4
-20 19 15 42 22 4
-19 19 15 42 22 4
-18 19 15 42 22 4
-17 19 15 42 22 4
-16 19 15 42 22 4
-15 19 15 42 22 4
-21 34 15 42 22 4
-22 34 15 42 22 4
-19 33 15 42 22 4
-20 33 15 42 22 4
-21 33 15 42 22 4
-22 33 15 42 22 4
-23 33 15 42 22 4
-24 33 15 42 22 4
-25 33 15 42 22 4
-26 33 15 42 22 4
-27 33 15 42 22 4
-28 33 15 42 22 4
-15 32 15 42 22 4
-16 32 15 42 22 4
-28 18 15 42 22 4
-27 18 15 42 22 4
-26 18 15 42 22 4
-25 18 15 42 22 4
-24 18 15 42 22 4
-23 18 15 42 22 4
-22 18 15 42 22 4
-21 18 15 42 22 4
-20 18 15 42 22 4
-19 18 15 42 22 4
-18 18 15 42 22 4
-17 18 15 42 22 4
-16 18 15 42 22 4
-15 18 15 42 22 4
-23 34 15 42 22 4
-24 34 15 42 22 4
-17 32 15 42 22 4
-18 32 15 42 22 4
-19 32 15 42 22 4
-20 32 15 42 22 4
-21 32 15 42 22 4
-22 32 15 42 22 4
-23 32 15 42 22 4
-24 32 15 42 22 4
-25 32 15 42 22 4
-26 32 15 42 22 4
-27 32 15 42 22 4
-28 32 15 42 22 4
-28 17 15 42 22 4
-27 17 15 42 22 4
-26 17 15 42 22 4
-25 17 15 42 22 4
-24 17 15 42 22 4
-23 17 15 42 22 4
-22 17 15 42 22 4
-21 17 15 42 22 4
-20 17 15 42 22 4
-19 17 15 42 22 4
-18 17 15 42 22 4
-17 17 15 42 22 4
-16 17 15 42 22 4
-15 17 15 42 22 4
-25 34 15 42 22 4
-26 34 15 42 22 4
-15 31 15 42 22 4
-16 31 15 42 22 4
-17 31 15 42 22 4
-18 31 15 42 22 4
-19 31 15 42 22 4
-20 31 15 42 22 4
-21 31 15 42 22 4
-22 31 15 42 22 4
-23 31 15 42 22 4
-24 31 15 42 22 4
-25 31 15 42 22 4
-26 31 15 42 22 4
-28 16 15 42 22 4
-27 16 15 42 22 4
-26 16 15 42 22 4
-25 16 15 42 22 4
-24 16 15 42 22 4
-23 16 15 42 22 4
-22 16 15 42 22 4
-21 16 15 42 22 4
-20 16 15 42 22 4
-19 16 15 42 22 4
-18 16 15 42 22 4
-17 16 15 42 22 4
-16 16 15 42 22 4
-15 16 15 42 22 4
-27 34 15 42 22 4
-28 34 15 42 22 4
-27 31 15 42 22 4
-28 31 15 42 22 4
-15 30 15 42 22 4
-16 30 15 42 22 4
-17 30 15 42 22 4
-18 30 15 42 22 4
-19 30 15 42 22 4
-20 30 15 42 22 4
-21 30 15 42 22 4
-22 30 15 42 22 4
-23 30 15 42 22 4
-24 30 15 42 22 4
-28 15 15 42 22 4
-27 15 15 42 22 4
-26 15 15 42 22 4
-25 15 15 42 22 4
-24 15 15 42 22 4
-23 15 15 42 22 4
-22 15 15 42 22 4
-21 15 15 42 22 4
-20 15 15 42 22 4
-19 15 15 42 22 4
-18 15 15 42 22 4
-17 15 15 42 22 4
-16 15 15 42 22 4
-15 15 15 42 22 4
-15 33 15 42 22 4
-16 33 15 42 22 4
-25 30 15 42 22 4
-26 30 15 42 22 4
-27 30 15 42 22 4
-28 30 15 42 22 4
-15 29 15 42 22 4
-16 29 15 42 22 4
-17 29 15 42 22 4
-18 29 15 42 22 4
-19 29 15 42 22 4
-20 29 15 42 22 4
-21 29 15 42 22 4
-22 29 15 42 22 4
-17 33 15 42 22 4
-18 33 15 42 22 4
-23 29 15 42 22 4
-24 29 15 42 22 4
-25 29 15 42 22 4
-26 29 15 42 22 4
-27 29 15 42 22 4
-28 29 15 42 22 4
-45 31 16 221 0 0
-45 33 16 255 102 0
-15 27 14 42 22 4
-16 27 14 42 22 4
-17 27 14 42 22 4
-18 27 14 42 22 4
-19 27 14 42 22 4
-20 27 14 42 22 4
-21 27 14 42 22 4
-22 27 14 42 22 4
-23 27 14 42 22 4
-24 27 14 42 22 4
-25 27 14 42 22 4
-26 27 14 42 22 4
-27 27 14 42 22 4
-28 27 14 42 22 4
-43 26 15 42 22 4
-29 28 16 50 50 50
-30 28 16 50 50 50
-33 28 16 50 50 50
-30 27 14 42 22 4
-31 27 14 42 22 4
-32 27 14 42 22 4
-39 32 16 221 0 0
-38 31 16 221 0 0
-39 31 16 221 0 0
-31 31 16 255 102 0
-32 31 16 255 102 0
-37 31 16 255 102 0
-44 32 16 221 0 0
-45 33 15 42 22 4
-16 14 15 42 22 4
-17 14 15 42 22 4
-18 14 15 42 22 4
-19 14 15 42 22 4
-20 14 15 42 22 4
-21 14 15 42 22 4
-22 14 15 42 22 4
-23 14 15 42 22 4
-24 14 15 42 22 4
-25 14 15 42 22 4
-26 14 15 42 22 4
-27 14 15 42 22 4
-28 14 15 42 22 4
-29 14 15 42 22 4
-30 14 15 42 22 4
-31 14 15 42 22 4
-32 14 15 42 22 4
-33 14 15 42 22 4
-34 14 15 42 22 4
-41 24 14 42 22 4
-42 24 14 42 22 4
-51 33 22 102 51 51
-51 34 22 102 51 51
-51 35 22 102 51 51
-40 28 15 42 22 4
-27 28 15 42 22 4
-51 33 21 102 51 51
-45 32 16 221 0 0
-52 28 22 102 51 51
-37 32 16 255 102 0
-40 31 16 255 102 0
-40 32 16 255 102 0
-47 35 16 0 0 153
-41 35 16 0 0 153
-43 35 16 67 67 255
-33 27 14 42 22 4
-39 28 15 0 0 0
-34 27 14 42 22 4
-32 32 16 221 0 0
-38 32 16 221 0 0
-35 27 14 42 22 4
-36 27 14 42 22 4
-28 25 14 42 22 4
-27 25 14 42 22 4
-26 25 14 42 22 4
-25 25 14 42 22 4
-24 25 14 42 22 4
-23 25 14 42 22 4
-22 25 14 42 22 4
-21 25 14 42 22 4
-20 25 14 42 22 4
-19 25 14 42 22 4
-18 25 14 42 22 4
-17 25 14 42 22 4
-16 25 14 42 22 4
-15 25 14 42 22 4
-44 30 16 255 102 0
-52 27 22 102 51 51
-37 27 14 42 22 4
-31 33 16 0 255 204
-30 33 16 0 204 0
-38 27 14 42 22 4
-39 27 14 42 22 4
-34 28 16 50 50 50
-35 28 16 168 168 167
-36 28 16 50 50 50
-37 28 16 50 50 50
-31 32 16 221 0 0
-33 33 16 0 204 0
-40 28 16 50 50 50
-41 28 16 50 50 50
-28 26 14 42 22 4
-27 26 14 42 22 4
-26 26 14 42 22 4
-25 26 14 42 22 4
-24 26 14 42 22 4
-23 26 14 42 22 4
-22 26 14 42 22 4
-21 26 14 42 22 4
-20 26 14 42 22 4
-19 26 14 42 22 4
-18 26 14 42 22 4
-17 26 14 42 22 4
-16 26 14 42 22 4
-15 26 14 42 22 4
-45 30 16 255 102 0
-52 26 22 102 51 51
-51 26 20 102 51 51
-51 17 21 102 51 51
-51 16 21 102 51 51
-35 14 15 42 22 4
-36 14 15 42 22 4
-37 14 15 42 22 4
-38 14 15 42 22 4
-39 14 15 42 22 4
-40 14 15 42 22 4
-41 14 15 42 22 4
-42 14 15 42 22 4
-43 14 15 42 22 4
-44 14 15 42 22 4
-45 14 15 42 22 4
-46 14 15 42 22 4
-51 15 22 102 51 51
-51 15 21 102 51 51
-47 14 15 42 22 4
-55 14 15 42 22 4
-48 14 15 42 22 4
-54 14 15 42 22 4
-28 28 15 42 22 4
-38 28 15 0 0 0
-29 28 15 42 22 4
-37 28 15 42 22 4
-30 28 15 42 22 4
-36 28 15 42 22 4
-44 33 16 255 102 0
-52 25 22 102 51 51
-49 14 15 42 22 4
-42 28 16 168 168 167
-43 27 16 50 50 50
-51 34 21 102 51 51
-43 28 16 67 67 255
-52 24 22 102 51 51
-52 23 22 102 51 51
-52 22 22 102 51 51
-31 28 15 0 0 0
-35 28 15 42 22 4
-32 28 15 0 0 0
-34 28 15 42 22 4
-33 28 15 42 22 4
-53 14 15 42 22 4
-50 14 15 42 22 4
-52 14 15 42 22 4
-51 14 15 42 22 4
-56 17 15 42 22 4
-57 22 15 42 22 4
-51 25 20 102 51 51
-51 24 20 102 51 51
-51 23 20 102 51 51
-51 17 22 102 51 51
-51 16 22 102 51 51
-51 22 20 102 51 51
-51 21 20 102 51 51
-45 36 17 0 225 255
-28 35 20 168 168 168
-35 35 20 168 168 168
-42 35 20 168 168 168
-49 35 20 168 168 168
-15 36 20 102 51 51
-16 36 20 102 51 51
-17 36 20 102 51 51
-18 36 20 102 51 51
-19 36 20 102 51 51
-20 36 20 102 51 51
-21 36 20 102 51 51
-22 36 20 102 51 51
-23 36 20 102 51 51
-24 36 20 102 51 51
-25 36 20 102 51 51
-26 36 20 102 51 51
-27 36 20 102 51 51
-47 36 20 102 51 51
-28 36 20 102 51 51
-46 36 20 102 51 51
-29 36 20 102 51 51
-45 36 20 102 51 51
-30 36 20 102 51 51
-44 36 20 102 51 51
-31 36 20 102 51 51
-43 36 20 102 51 51
-32 36 20 102 51 51
-42 36 20 102 51 51
-33 36 20 102 51 51
-41 36 20 102 51 51
-34 36 20 102 51 51
-40 36 20 102 51 51
-35 36 20 102 51 51
-39 36 20 102 51 51
-36 36 20 102 51 51
-38 36 20 102 51 51
-37 36 20 102 51 51
-51 19 22 102 51 51
-50 20 20 168 168 168
-51 20 20 102 51 51
-50 19 20 102 51 51
-51 18 22 102 51 51
-50 18 20 102 51 51
-50 31 19 102 51 51
-50 30 19 102 51 51
-50 29 19 168 168 168
-51 29 19 102 51 51
-44 31 16 221 0 0
-51 35 21 102 51 51
-15 28 15 42 22 4
-16 28 15 42 22 4
-17 28 15 42 22 4
-18 28 15 42 22 4
-19 28 15 42 22 4
-20 28 15 42 22 4
-21 28 15 42 22 4
-22 28 15 42 22 4
-23 28 15 42 22 4
-24 28 15 42 22 4
-42 28 15 42 22 4
-25 28 15 42 22 4
-41 28 15 42 22 4
-26 28 15 42 22 4
-28 24 14 42 22 4
-27 24 14 42 22 4
-26 24 14 42 22 4
-25 24 14 42 22 4
-24 24 14 42 22 4
-23 24 14 42 22 4
-22 24 14 42 22 4
-21 24 14 42 22 4
-20 24 14 42 22 4
-19 24 14 42 22 4
-18 24 14 42 22 4
-17 24 14 42 22 4
-16 24 14 42 22 4
-15 24 14 42 22 4
-43 25 15 0 0 0
-43 24 15 0 0 0
-29 27 14 42 22 4
-43 23 15 42 22 4
-43 27 15 42 22 4
-43 28 15 42 22 4
-51 28 19 102 51 51
-51 27 19 102 51 51
-51 22 19 102 51 51
-51 21 19 102 51 51
-50 20 19 168 168 168
-51 20 19 102 51 51
-50 19 19 102 51 51
-50 18 19 102 51 51
-50 31 18 102 51 51
-50 18 16 102 51 51
-50 19 16 102 51 51
-51 20 16 102 51 51
-50 20 16 168 168 167
-51 21 16 102 51 51
-50 22 16 0 255 134
-50 23 16 0 255 133
-50 24 16 0 255 133
-50 25 16 0 255 133
-50 26 16 0 255 133
-50 27 16 0 255 135
-51 28 16 102 51 51
-51 29 16 102 51 51
-50 29 16 168 168 167
-50 30 16 102 51 51
-50 31 16 102 51 51
-50 18 17 102 51 51
-50 19 17 102 51 51
-51 20 17 102 51 51
-50 20 17 168 168 168
-51 21 17 102 51 51
-51 28 17 102 51 51
-51 29 17 102 51 51
-50 29 17 168 168 168
-50 30 17 102 51 51
-50 31 17 102 51 51
-50 18 18 102 51 51
-50 19 18 102 51 51
-51 20 18 102 51 51
-50 20 18 168 168 168
-51 21 18 102 51 51
-51 28 18 102 51 51
-51 29 18 102 51 51
-50 29 18 168 168 168
-50 30 18 102 51 51
-42 22 14 42 22 4
-41 22 14 42 22 4
-40 22 14 42 22 4
-39 22 14 42 22 4
-38 22 14 42 22 4
-37 22 14 42 22 4
-36 22 14 42 22 4
-35 22 14 42 22 4
-34 22 14 42 22 4
-33 22 14 42 22 4
-32 22 14 42 22 4
-31 22 14 42 22 4
-30 22 14 42 22 4
-29 22 14 42 22 4
-28 22 14 42 22 4
-27 22 14 42 22 4
-26 22 14 42 22 4
-25 22 14 42 22 4
-24 22 14 42 22 4
-23 22 14 42 22 4
-22 22 14 42 22 4
-21 22 14 42 22 4
-20 22 14 42 22 4
-19 22 14 42 22 4
-18 22 14 42 22 4
-17 22 14 42 22 4
-16 22 14 42 22 4
-15 22 14 42 22 4
-42 23 14 42 22 4
-55 13 16 102 51 51
-54 13 16 102 51 51
-53 13 16 102 51 51
-58 22 16 102 51 51
-58 23 16 102 51 51
-58 24 16 102 51 51
-58 25 16 102 51 51
-58 26 16 102 51 51
-58 27 16 102 51 51
-57 28 16 102 51 51
-57 29 16 102 51 51
-57 30 16 102 51 51
-57 31 16 102 51 51
-57 32 16 102 51 51
-59 22 17 102 51 51
-59 23 17 102 51 51
-59 24 17 102 51 51
-59 25 17 102 51 51
-59 26 17 102 51 51
-59 27 17 102 51 51
-58 28 17 102 51 51
-58 29 17 102 51 51
-58 30 17 102 51 51
-58 31 17 102 51 51
-58 32 17 102 51 51
-60 22 18 102 51 51
-60 23 18 102 51 51
-60 24 18 102 51 51
-60 25 18 102 51 51
-60 26 18 102 51 51
-60 27 18 102 51 51
-59 28 18 102 51 51
-59 29 18 102 51 51
-59 30 18 102 51 51
-59 31 18 102 51 51
-59 32 18 102 51 51
-60 22 19 102 51 51
-60 23 19 102 51 51
-60 24 19 102 51 51
-60 25 19 102 51 51
-60 26 19 102 51 51
-60 27 19 102 51 51
-59 28 19 102 51 51
-59 29 19 102 51 51
-59 30 19 102 51 51
-59 31 19 102 51 51
-59 32 19 102 51 51
-60 22 20 102 51 51
-60 23 20 102 51 51
-60 24 20 102 51 51
-60 25 20 102 51 51
-60 26 20 102 51 51
-60 27 20 102 51 51
-59 28 20 102 51 51
-59 29 20 102 51 51
-59 30 20 102 51 51
-59 31 20 102 51 51
-59 32 20 102 51 51
-60 22 21 102 51 51
-60 23 21 102 51 51
-60 24 21 102 51 51
-60 25 21 102 51 51
-60 26 21 102 51 51
-60 27 21 102 51 51
-59 28 21 102 51 51
-59 29 21 102 51 51
-59 30 21 102 51 51
-59 31 21 102 51 51
-59 32 21 102 51 51
-60 22 22 102 51 51
-60 23 22 102 51 51
-60 24 22 102 51 51
-60 25 22 102 51 51
-60 26 22 102 51 51
-60 27 22 102 51 51
-59 28 22 102 51 51
-59 29 22 102 51 51
-59 30 22 102 51 51
-59 31 22 102 51 51
-59 32 22 102 51 51
-60 22 23 102 51 51
-60 23 23 102 51 51
-60 24 23 102 51 51
-60 25 23 102 51 51
-60 26 23 102 51 51
-60 27 23 102 51 51
-59 28 23 102 51 51
-59 29 23 102 51 51
-59 30 23 102 51 51
-59 31 23 102 51 51
-59 32 23 102 51 51
-60 22 24 102 51 51
-60 23 24 102 51 51
-60 24 24 102 51 51
-60 25 24 102 51 51
-60 26 24 102 51 51
-60 27 24 102 51 51
-59 28 24 102 51 51
-59 29 24 102 51 51
-59 30 24 102 51 51
-59 31 24 102 51 51
-59 32 24 102 51 51
-60 22 25 102 51 51
-60 23 25 102 51 51
-60 24 25 102 51 51
-60 25 25 102 51 51
-60 26 25 102 51 51
-60 27 25 102 51 51
-59 28 25 102 51 51
-59 29 25 102 51 51
-59 30 25 102 51 51
-59 31 25 102 51 51
-59 32 25 102 51 51
-56 33 16 102 51 51
-57 33 17 102 51 51
-58 33 18 102 51 51
-58 33 19 102 51 51
-58 33 20 102 51 51
-58 33 21 102 51 51
-58 33 22 102 51 51
-52 14 23 102 51 51
-52 14 24 102 51 51
-52 15 24 102 51 51
-52 16 24 102 51 51
-52 17 24 102 51 51
-52 18 24 102 51 51
-52 19 24 102 51 51
-52 20 24 102 51 51
-52 21 24 102 51 51
-52 22 24 102 51 51
-52 23 24 102 51 51
-52 24 24 102 51 51
-52 25 24 102 51 51
-52 26 24 102 51 51
-52 27 24 102 51 51
-52 28 24 102 51 51
-52 29 24 102 51 51
-52 30 24 102 51 51
-52 31 24 102 51 51
-52 32 24 102 51 51
-52 33 24 102 51 51
-52 34 24 102 51 51
-52 35 24 102 51 51
-52 15 23 102 51 51
-52 16 23 102 51 51
-52 17 23 102 51 51
-52 18 23 102 51 51
-52 19 23 102 51 51
-52 20 23 102 51 51
-52 21 23 102 51 51
-52 22 23 102 51 51
-52 23 23 102 51 51
-52 24 23 102 51 51
-52 25 23 102 51 51
-52 26 23 102 51 51
-52 27 23 102 51 51
-52 28 23 102 51 51
-52 29 23 102 51 51
-52 30 23 102 51 51
-52 31 23 102 51 51
-52 32 23 102 51 51
-52 33 23 102 51 51
-52 34 23 102 51 51
-28 15 16 67 67 255
-35 15 16 0 0 153
-49 14 16 168 168 167
-48 14 16 0 0 153
-44 14 16 67 67 255
-43 14 16 67 67 255
-42 14 16 168 168 167
-41 14 16 0 0 153
-36 14 16 0 0 153
-35 14 16 168 168 167
-34 14 16 67 67 255
-29 14 16 67 67 255
-49 19 15 42 22 4
-49 19 16 0 0 153
-49 16 16 153 50 205
-48 30 16 153 0 154
-48 32 16 153 0 154
-21 35 16 168 168 167
-21 35 17 168 168 168
-21 35 18 168 168 168
-21 35 19 168 168 168
-21 35 20 168 168 168
-27 14 16 102 51 51
-49 16 17 255 255 255
-49 17 16 255 255 255
-49 18 16 255 255 255
-49 18 17 255 255 255
-49 17 17 255 255 255
-49 18 18 255 255 255
-49 17 18 255 255 255
-49 16 18 255 255 255
-49 30 16 255 255 255
-49 31 16 255 255 255
-49 32 16 255 255 255
-48 31 16 255 255 255
-49 33 16 255 255 255
-48 33 16 255 255 255
-49 30 17 255 255 255
-49 31 17 255 255 255
-49 32 17 255 255 255
-49 33 17 255 255 255
-32 16 15 42 22 4
-32 16 16 255 255 255
-32 16 17 255 255 255
-31 16 17 255 255 255
-32 33 16 255 255 255
-32 33 17 255 255 255
-27 35 16 102 51 51
