ply
format ascii 1.0
comment : MagicaVoxel @ Ephtracy
element vertex 1881
property float x
property float y
property float z
property uchar red
property uchar green
property uchar blue
end_header
-43 22 18 102 51 51
-43 21 18 102 51 51
-35 22 12 102 51 51
-35 21 12 102 51 51
-35 20 12 102 51 51
-28 10 11 50 50 50
-36 19 17 102 51 51
-36 19 16 102 51 51
-35 19 15 102 51 51
-35 20 13 102 51 51
-35 21 13 102 51 51
-35 22 14 102 51 51
-42 23 18 102 51 51
-35 20 14 102 51 51
-15 3 11 0 204 0
-18 3 11 0 204 0
-35 19 11 102 51 51
-41 23 18 102 51 51
-35 22 11 102 51 51
-40 23 18 102 51 51
-35 21 11 102 51 51
-39 23 18 102 51 51
-14 22 10 42 22 4
-38 23 18 102 51 51
-15 22 10 42 22 4
-37 23 18 102 51 51
-16 22 10 42 22 4
-36 23 18 102 51 51
-17 22 10 42 22 4
-24 23 14 102 51 51
-16 3 11 0 255 204
-13 6 11 0 0 153
-34 0 16 102 51 51
-33 0 14 102 51 51
-33 0 13 102 51 51
-13 14 10 0 204 0
-21 9 10 0 204 0
-27 10 10 0 0 153
-20 14 10 0 0 153
-20 9 10 67 67 255
-43 22 17 102 51 51
-43 21 17 102 51 51
-35 20 11 102 51 51
-35 19 14 102 51 51
-35 19 12 102 51 51
-25 14 9 42 22 4
-26 14 9 42 22 4
-35 22 13 102 51 51
-27 14 9 42 22 4
-14 13 9 42 22 4
-43 20 20 102 51 51
-42 14 10 42 22 4
-42 23 17 102 51 51
-27 9 10 67 67 255
-27 14 10 0 204 0
-25 9 10 255 102 0
-42 13 10 42 22 4
-25 14 10 255 102 0
-18 9 10 255 102 0
-18 14 10 255 102 0
-19 9 10 221 0 0
-19 14 10 221 0 0
-26 9 10 221 0 0
-26 14 10 221 0 0
-29 3 11 255 102 0
-30 3 11 255 102 0
-30 6 11 255 102 0
-29 6 11 255 102 0
-25 4 11 255 102 0
-25 5 11 255 102 0
-22 4 11 255 102 0
-42 12 10 42 22 4
-37 8 17 102 51 51
-14 23 11 102 51 51
-41 23 17 102 51 51
-22 5 11 255 102 0
-16 5 11 255 102 0
0 1 10 42 22 4
-14 21 10 42 22 4
-15 23 11 102 51 51
-40 23 17 102 51 51
-15 21 10 42 22 4
-35 23 16 102 51 51
-17 5 11 255 102 0
-16 21 10 42 22 4
-16 23 11 102 51 51
-16 4 11 221 0 0
-17 4 11 221 0 0
-17 21 10 42 22 4
-39 23 17 102 51 51
-40 16 10 42 22 4
-17 23 11 102 51 51
-23 5 11 221 0 0
-43 22 15 102 51 51
-43 21 15 102 51 51
-23 4 11 221 0 0
-36 1 16 102 51 51
-18 23 11 102 51 51
-38 23 16 102 51 51
-36 1 17 102 51 51
-38 23 17 102 51 51
-35 1 15 102 51 51
-14 20 10 42 22 4
-19 23 11 102 51 51
-15 20 10 42 22 4
-37 23 17 102 51 51
-16 20 10 42 22 4
-36 23 17 102 51 51
-17 20 10 42 22 4
-20 23 11 102 51 51
-35 1 11 102 51 51
-35 1 14 102 51 51
-35 1 12 102 51 51
0 23 11 102 51 51
-1 23 11 102 51 51
-21 23 11 102 51 51
-34 23 16 102 51 51
-2 23 11 102 51 51
-42 11 10 42 22 4
-42 10 10 42 22 4
-3 23 11 102 51 51
-22 23 11 102 51 51
-14 19 10 42 22 4
-35 23 17 102 51 51
-15 19 10 42 22 4
-25 23 14 102 51 51
-16 19 10 42 22 4
-23 23 11 102 51 51
-43 4 12 102 51 51
-42 3 12 102 51 51
-24 4 11 221 0 0
-17 19 10 42 22 4
-24 23 11 102 51 51
-24 5 11 221 0 0
-30 4 11 221 0 0
-29 4 11 221 0 0
-29 5 11 221 0 0
-4 23 11 102 51 51
-25 23 11 102 51 51
-30 5 11 221 0 0
-43 22 16 102 51 51
-43 21 16 102 51 51
-35 1 13 102 51 51
-5 23 11 102 51 51
-26 23 11 102 51 51
-41 0 20 102 51 51
-42 0 20 102 51 51
-36 0 19 102 51 51
-37 0 19 102 51 51
-6 23 11 102 51 51
-27 23 11 102 51 51
-38 0 19 102 51 51
-39 0 19 102 51 51
-40 0 19 102 51 51
-42 2 12 102 51 51
-7 23 11 102 51 51
-28 23 11 102 51 51
-42 1 12 102 51 51
-42 23 16 102 51 51
-42 8 11 102 51 51
-42 7 11 102 51 51
-14 18 10 42 22 4
-29 23 11 102 51 51
-42 6 11 102 51 51
-42 23 15 102 51 51
-15 18 10 42 22 4
-41 23 15 102 51 51
-16 18 10 42 22 4
-30 23 11 102 51 51
-17 18 10 42 22 4
-40 23 15 102 51 51
-14 16 10 42 22 4
-39 23 15 102 51 51
-15 16 10 42 22 4
-31 23 11 102 51 51
-16 16 10 42 22 4
-38 23 15 102 51 51
-17 16 10 42 22 4
-41 23 16 102 51 51
-14 17 10 42 22 4
-32 23 11 102 51 51
-15 17 10 42 22 4
-33 23 11 102 51 51
-16 17 10 42 22 4
-34 23 11 102 51 51
-17 17 10 42 22 4
-35 23 11 102 51 51
-18 22 10 42 22 4
-36 23 11 102 51 51
-19 22 10 42 22 4
-37 23 11 102 51 51
-20 22 10 42 22 4
-38 23 11 102 51 51
-21 22 10 42 22 4
-39 23 11 102 51 51
-22 22 10 42 22 4
-40 23 11 102 51 51
-23 22 10 42 22 4
-44 8 20 102 51 51
-42 5 11 102 51 51
-42 4 11 102 51 51
-41 3 11 102 51 51
-41 2 11 102 51 51
-41 1 11 102 51 51
-41 0 19 102 51 51
-8 0 11 102 51 51
-42 0 19 102 51 51
-41 21 11 102 51 51
-41 22 11 102 51 51
-24 22 10 42 22 4
-37 23 15 102 51 51
-25 22 10 42 22 4
-36 23 15 102 51 51
-26 22 10 42 22 4
-35 23 15 102 51 51
-27 23 13 102 51 51
-27 22 10 42 22 4
-34 23 15 102 51 51
-26 23 14 102 51 51
-28 22 10 42 22 4
-33 23 15 102 51 51
-43 22 20 102 51 51
-43 21 20 102 51 51
-9 0 11 102 51 51
-44 7 20 102 51 51
-36 0 18 102 51 51
-44 6 20 102 51 51
-44 5 20 102 51 51
-44 4 20 102 51 51
-43 3 20 102 51 51
-10 0 11 102 51 51
-43 2 20 102 51 51
-43 1 20 102 51 51
-33 0 12 102 51 51
-34 0 14 102 51 51
-34 0 13 102 51 51
-34 0 12 102 51 51
-37 22 18 102 51 51
-34 0 15 102 51 51
-13 10 10 67 67 255
-13 9 10 67 67 255
-42 23 20 102 51 51
-29 22 10 42 22 4
-14 9 10 67 67 255
-21 22 11 67 67 255
-41 23 20 102 51 51
-30 22 10 42 22 4
-31 22 10 42 22 4
-32 22 10 42 22 4
-14 22 11 67 67 255
-13 17 11 67 67 255
-33 22 10 42 22 4
-34 22 10 42 22 4
-35 22 10 42 22 4
-14 23 12 102 51 51
-39 23 16 102 51 51
-43 22 19 102 51 51
-18 21 10 42 22 4
-15 23 12 102 51 51
-43 21 19 102 51 51
-44 8 19 102 51 51
-19 21 10 42 22 4
-16 23 12 0 225 255
-44 7 19 102 51 51
-44 6 19 102 51 51
-20 21 10 42 22 4
-17 23 12 255 255 255
-44 5 19 102 51 51
-44 4 19 102 51 51
-27 23 14 102 51 51
-18 23 12 102 51 51
-43 3 19 102 51 51
-43 2 19 102 51 51
-28 23 14 102 51 51
-19 23 12 102 51 51
-43 1 19 102 51 51
-37 0 18 102 51 51
-29 23 14 102 51 51
-20 23 12 102 51 51
-11 0 11 102 51 51
-42 23 19 102 51 51
-30 23 14 102 51 51
-21 23 12 102 51 51
-21 21 10 42 22 4
-41 23 19 102 51 51
-31 23 14 102 51 51
-22 23 12 102 51 51
-22 21 10 42 22 4
-40 23 19 102 51 51
-32 23 14 102 51 51
-23 23 12 0 225 255
-23 21 10 42 22 4
-39 23 19 102 51 51
-13 21 11 0 0 153
-26 23 13 102 51 51
-24 23 12 255 255 255
-24 21 10 42 22 4
-36 23 16 102 51 51
-25 21 10 42 22 4
-26 21 10 42 22 4
-25 23 12 102 51 51
-38 23 19 102 51 51
-15 13 9 42 22 4
-35 22 15 102 51 51
-33 23 14 102 51 51
-26 23 12 102 51 51
-27 21 10 42 22 4
-37 23 19 102 51 51
-28 21 10 42 22 4
-29 21 10 42 22 4
-27 23 12 102 51 51
-30 21 10 42 22 4
-36 23 19 102 51 51
-34 23 14 102 51 51
-28 23 12 102 51 51
-31 21 10 42 22 4
-40 23 16 102 51 51
-32 21 10 42 22 4
-29 23 12 102 51 51
-33 21 10 42 22 4
-35 21 15 102 51 51
-35 23 14 102 51 51
-28 13 11 50 50 50
-35 20 15 102 51 51
-13 16 11 0 0 153
-34 21 10 42 22 4
-31 23 12 255 255 255
-35 19 13 102 51 51
-13 8 11 168 168 167
-36 18 17 102 51 51
-36 23 14 102 51 51
-32 23 12 102 51 51
-35 21 10 42 22 4
-33 23 12 102 51 51
-44 8 18 102 51 51
-34 23 12 102 51 51
-44 7 18 102 51 51
-35 23 12 102 51 51
-44 6 18 102 51 51
-36 23 12 102 51 51
-44 5 18 102 51 51
-37 23 12 102 51 51
-44 4 18 102 51 51
-38 23 12 102 51 51
-43 3 18 102 51 51
-39 23 12 102 51 51
-43 2 18 102 51 51
-40 23 12 102 51 51
-43 1 18 102 51 51
-41 23 12 102 51 51
-44 8 17 102 51 51
-44 7 17 102 51 51
-44 6 17 102 51 51
-44 5 17 102 51 51
-44 4 17 102 51 51
-43 3 17 102 51 51
-43 2 17 102 51 51
-43 1 17 102 51 51
-40 18 10 42 22 4
-12 0 11 102 51 51
-42 21 12 102 51 51
-42 22 12 102 51 51
-13 15 11 168 168 167
-12 9 11 102 51 51
-12 8 11 102 51 51
-12 7 11 102 51 51
-12 6 11 102 51 51
-12 5 11 102 51 51
-12 4 11 102 51 51
-12 3 11 102 51 51
-12 2 11 102 51 51
-12 9 10 102 51 51
-35 2 15 102 51 51
-16 13 9 42 22 4
-44 8 16 102 51 51
-16 20 12 255 255 255
-44 7 16 102 51 51
-14 23 13 102 51 51
-44 6 16 102 51 51
-15 23 13 102 51 51
-44 5 16 102 51 51
-16 23 13 255 255 255
-44 4 16 102 51 51
-17 23 13 255 255 255
-43 3 16 102 51 51
-43 2 16 102 51 51
-38 23 13 102 51 51
-43 1 16 102 51 51
-37 23 13 102 51 51
-44 8 15 102 51 51
-36 23 13 102 51 51
-18 20 10 42 22 4
-35 23 13 102 51 51
-12 21 11 102 51 51
-37 23 14 102 51 51
-30 23 13 255 255 255
-33 23 13 102 51 51
-18 23 13 102 51 51
-19 20 10 42 22 4
-12 20 11 102 51 51
-14 23 14 102 51 51
-20 20 10 42 22 4
-21 20 10 42 22 4
-34 23 13 102 51 51
-36 17 17 102 51 51
-36 16 17 102 51 51
-12 19 11 102 51 51
-17 23 14 102 51 51
-38 23 14 102 51 51
-36 7 17 102 51 51
-22 20 10 42 22 4
-19 23 13 102 51 51
-23 20 10 42 22 4
-37 23 16 102 51 51
-24 20 10 42 22 4
-25 20 10 42 22 4
-17 13 9 42 22 4
-26 20 10 42 22 4
-18 13 9 42 22 4
-27 20 10 42 22 4
-19 13 9 42 22 4
-39 23 14 102 51 51
-28 23 13 102 51 51
-25 23 13 102 51 51
-12 18 11 102 51 51
-20 23 13 102 51 51
-28 20 10 42 22 4
-35 4 15 102 51 51
-29 20 10 42 22 4
-32 23 13 102 51 51
-15 23 14 102 51 51
-41 9 10 42 22 4
-40 23 14 102 51 51
-20 23 14 102 51 51
-31 20 10 42 22 4
-32 20 10 42 22 4
-12 17 11 102 51 51
-39 23 13 102 51 51
-33 20 10 42 22 4
-21 23 13 102 51 51
-41 23 14 102 51 51
-40 23 13 102 51 51
-34 20 10 42 22 4
-41 23 13 102 51 51
-12 16 11 102 51 51
-35 3 15 102 51 51
-35 20 10 42 22 4
-44 7 15 102 51 51
-29 23 13 102 51 51
-12 15 11 102 51 51
-12 14 11 102 51 51
-42 23 14 102 51 51
-12 14 10 102 51 51
-22 23 13 102 51 51
-40 19 10 42 22 4
-31 23 13 255 255 255
-18 23 14 102 51 51
-44 6 15 102 51 51
-16 23 14 102 51 51
-44 5 15 102 51 51
-21 23 14 102 51 51
0 10 9 42 22 4
-1 10 9 42 22 4
-44 4 15 102 51 51
-2 10 9 42 22 4
-23 23 14 102 51 51
-19 23 14 102 51 51
-23 23 13 255 255 255
-3 10 9 42 22 4
-43 3 15 102 51 51
-4 10 9 42 22 4
-43 2 15 102 51 51
-22 23 14 102 51 51
-5 10 9 42 22 4
-6 10 9 42 22 4
-7 10 9 42 22 4
-8 10 9 42 22 4
-9 10 9 42 22 4
-43 22 14 102 51 51
-43 21 14 102 51 51
-13 0 11 102 51 51
-20 13 9 42 22 4
-24 23 13 255 255 255
-35 21 14 102 51 51
-21 13 9 42 22 4
-43 20 19 102 51 51
-41 19 10 42 22 4
-41 18 10 42 22 4
-41 17 10 42 22 4
-41 16 10 42 22 4
-40 20 10 42 22 4
-43 1 15 102 51 51
-44 8 14 102 51 51
-44 7 14 102 51 51
-44 6 14 102 51 51
-44 5 14 102 51 51
-14 0 11 102 51 51
-22 13 9 42 22 4
-43 21 13 102 51 51
-43 22 13 102 51 51
-42 23 13 102 51 51
-40 22 10 42 22 4
-40 21 10 42 22 4
-39 21 10 42 22 4
-38 21 10 42 22 4
-40 17 10 42 22 4
-36 14 10 42 22 4
-37 15 10 42 22 4
-37 16 10 42 22 4
-38 17 10 42 22 4
-38 18 10 42 22 4
-39 19 10 42 22 4
-39 20 10 42 22 4
-23 13 9 42 22 4
-10 10 9 42 22 4
-44 4 14 102 51 51
-15 0 11 102 51 51
-38 0 18 102 51 51
-39 0 18 102 51 51
-40 0 18 102 51 51
-40 15 10 42 22 4
-16 0 11 102 51 51
-41 0 18 102 51 51
-17 0 11 102 51 51
-41 15 10 42 22 4
-18 0 11 102 51 51
-19 0 11 102 51 51
-37 21 10 42 22 4
-20 0 11 102 51 51
-39 14 10 42 22 4
-38 14 10 42 22 4
-37 14 10 42 22 4
-36 21 10 42 22 4
-42 0 18 102 51 51
-39 15 10 42 22 4
-38 15 10 42 22 4
-36 15 10 42 22 4
-39 22 10 42 22 4
-43 3 14 102 51 51
-39 16 10 42 22 4
-38 16 10 42 22 4
-36 16 10 42 22 4
-38 22 10 42 22 4
-35 0 17 102 51 51
-39 17 10 42 22 4
-37 17 10 42 22 4
-36 17 10 42 22 4
-37 22 10 42 22 4
-36 0 17 102 51 51
-39 18 10 42 22 4
-37 18 10 42 22 4
-36 18 10 42 22 4
-36 22 10 42 22 4
-37 0 17 102 51 51
-38 19 10 42 22 4
-37 19 10 42 22 4
-36 19 10 42 22 4
-36 20 10 42 22 4
-38 0 17 102 51 51
-38 20 10 42 22 4
-37 20 10 42 22 4
-35 16 10 42 22 4
-34 16 10 42 22 4
-33 16 10 42 22 4
-32 16 10 42 22 4
-31 16 10 42 22 4
-30 16 10 42 22 4
-29 16 10 42 22 4
-28 16 10 42 22 4
-27 16 10 42 22 4
-26 16 10 42 22 4
-25 16 10 42 22 4
-24 16 10 42 22 4
-23 16 10 42 22 4
-22 16 10 42 22 4
-21 16 10 42 22 4
-20 16 10 42 22 4
-19 16 10 42 22 4
-18 16 10 42 22 4
-35 15 10 42 22 4
-34 15 10 42 22 4
-33 15 10 42 22 4
-32 15 10 42 22 4
-31 15 10 42 22 4
-30 15 10 42 22 4
-29 15 10 42 22 4
-8 23 11 102 51 51
-9 23 11 102 51 51
-10 23 11 102 51 51
-11 23 11 102 51 51
-12 23 11 102 51 51
-13 23 11 102 51 51
0 23 14 102 51 51
-1 23 14 102 51 51
-2 23 14 102 51 51
-3 23 14 102 51 51
-4 23 14 102 51 51
-35 17 10 42 22 4
-34 17 10 42 22 4
-33 17 10 42 22 4
-32 17 10 42 22 4
-31 17 10 42 22 4
-30 17 10 42 22 4
-29 17 10 42 22 4
-28 17 10 42 22 4
-27 17 10 42 22 4
-26 17 10 42 22 4
-25 17 10 42 22 4
-24 17 10 42 22 4
-23 17 10 42 22 4
-22 17 10 42 22 4
-21 17 10 42 22 4
-20 17 10 42 22 4
-19 17 10 42 22 4
-18 17 10 42 22 4
-35 14 10 42 22 4
-34 14 10 42 22 4
-33 14 10 42 22 4
-32 14 10 42 22 4
-31 14 10 42 22 4
-30 14 10 42 22 4
-29 14 10 42 22 4
-5 23 14 102 51 51
-6 23 14 102 51 51
-7 23 14 102 51 51
-8 23 14 102 51 51
-9 23 14 102 51 51
-10 23 14 102 51 51
-11 23 14 102 51 51
-12 23 14 102 51 51
-13 23 14 102 51 51
0 23 12 102 51 51
-1 23 12 102 51 51
-35 18 10 42 22 4
-34 18 10 42 22 4
-33 18 10 42 22 4
-32 18 10 42 22 4
-31 18 10 42 22 4
-30 18 10 42 22 4
-29 18 10 42 22 4
-28 18 10 42 22 4
-27 18 10 42 22 4
-26 18 10 42 22 4
-25 18 10 42 22 4
-24 18 10 42 22 4
-23 18 10 42 22 4
-22 18 10 42 22 4
-21 18 10 42 22 4
-20 18 10 42 22 4
-19 18 10 42 22 4
-18 18 10 42 22 4
-39 0 17 102 51 51
-40 0 17 102 51 51
-41 0 17 102 51 51
-21 0 11 102 51 51
-22 0 11 102 51 51
-23 0 11 102 51 51
-24 0 11 102 51 51
-42 0 17 102 51 51
-35 0 16 102 51 51
-36 0 16 102 51 51
-37 0 16 102 51 51
-38 0 16 102 51 51
-39 0 16 102 51 51
-40 0 16 102 51 51
-41 0 16 102 51 51
-25 0 11 102 51 51
-26 0 11 102 51 51
-43 2 14 102 51 51
-35 19 10 42 22 4
-34 19 10 42 22 4
-33 19 10 42 22 4
-32 19 10 42 22 4
-31 19 10 42 22 4
-30 19 10 42 22 4
-29 19 10 42 22 4
-28 19 10 42 22 4
-27 19 10 42 22 4
-26 19 10 42 22 4
-25 19 10 42 22 4
-24 19 10 42 22 4
-23 19 10 42 22 4
-22 19 10 42 22 4
-21 19 10 42 22 4
-20 19 10 42 22 4
-19 19 10 42 22 4
-18 19 10 42 22 4
-27 0 11 102 51 51
-28 0 11 102 51 51
-29 0 11 102 51 51
-42 0 16 102 51 51
-35 0 15 102 51 51
-36 0 15 102 51 51
-37 0 15 102 51 51
-38 0 15 102 51 51
-39 0 15 102 51 51
-40 0 15 102 51 51
-41 14 10 42 22 4
-40 14 10 42 22 4
-41 0 15 102 51 51
-43 1 14 102 51 51
-30 0 11 102 51 51
-31 0 11 102 51 51
-32 0 11 102 51 51
-33 0 11 102 51 51
-11 10 9 42 22 4
-42 0 15 102 51 51
-24 13 9 42 22 4
-35 0 14 102 51 51
-25 13 9 42 22 4
-36 0 14 102 51 51
-26 13 9 42 22 4
-37 0 14 102 51 51
-28 9 11 50 50 50
-38 0 14 102 51 51
-35 4 14 102 51 51
-39 0 14 102 51 51
-35 3 14 102 51 51
-40 0 14 102 51 51
-35 2 14 102 51 51
-41 0 14 102 51 51
-34 0 11 102 51 51
-35 0 11 102 51 51
-36 0 11 102 51 51
-37 0 11 102 51 51
-12 10 9 42 22 4
-40 2 10 42 22 4
-39 2 10 42 22 4
-38 2 10 42 22 4
-37 2 10 42 22 4
-36 2 10 42 22 4
-35 2 10 42 22 4
-34 2 10 42 22 4
-33 2 10 42 22 4
-32 2 10 42 22 4
-31 2 10 42 22 4
-30 2 10 42 22 4
-29 2 10 42 22 4
-28 2 10 42 22 4
-27 2 10 42 22 4
-26 2 10 42 22 4
-25 2 10 42 22 4
-24 2 10 42 22 4
-23 2 10 42 22 4
-22 2 10 42 22 4
-21 2 10 42 22 4
-20 2 10 42 22 4
-19 2 10 42 22 4
-18 2 10 42 22 4
-17 2 10 42 22 4
-16 2 10 42 22 4
-15 2 10 42 22 4
-14 2 10 42 22 4
-40 3 10 42 22 4
-39 3 10 42 22 4
-38 3 10 42 22 4
-37 3 10 42 22 4
-36 3 10 42 22 4
-35 3 10 42 22 4
-34 3 10 42 22 4
-33 3 10 42 22 4
-32 3 10 42 22 4
-31 3 10 42 22 4
-30 3 10 42 22 4
-29 3 10 42 22 4
-28 3 10 42 22 4
-27 3 10 42 22 4
-26 3 10 42 22 4
-25 3 10 42 22 4
-24 3 10 42 22 4
-23 3 10 42 22 4
-22 3 10 42 22 4
-21 3 10 42 22 4
-20 3 10 42 22 4
-19 3 10 42 22 4
-18 3 10 42 22 4
-33 20 12 255 255 255
-16 3 10 42 22 4
-15 3 10 42 22 4
-14 3 10 42 22 4
-40 4 10 42 22 4
-39 4 10 42 22 4
-38 4 10 42 22 4
-37 4 10 42 22 4
-36 4 10 42 22 4
-35 4 10 42 22 4
-34 4 10 42 22 4
-33 4 10 42 22 4
-32 4 10 42 22 4
-31 4 10 42 22 4
-30 4 10 42 22 4
-29 4 10 42 22 4
-28 4 10 42 22 4
-27 4 10 42 22 4
-26 4 10 42 22 4
-25 4 10 42 22 4
-24 4 10 42 22 4
-23 4 10 42 22 4
-22 4 10 42 22 4
-21 4 10 42 22 4
-20 4 10 42 22 4
-19 4 10 42 22 4
-18 4 10 42 22 4
-17 4 10 42 22 4
-16 4 10 42 22 4
-15 4 10 42 22 4
-14 4 10 42 22 4
-41 5 10 42 22 4
-40 5 10 42 22 4
-39 5 10 42 22 4
-38 5 10 42 22 4
-37 5 10 42 22 4
-36 5 10 42 22 4
-35 5 10 42 22 4
-34 5 10 42 22 4
-33 5 10 42 22 4
-32 5 10 42 22 4
-31 5 10 42 22 4
-30 5 10 42 22 4
-29 5 10 42 22 4
-28 5 10 42 22 4
-27 5 10 42 22 4
-26 5 10 42 22 4
-25 5 10 42 22 4
-24 5 10 42 22 4
-23 5 10 42 22 4
-22 5 10 42 22 4
-21 5 10 42 22 4
-20 5 10 42 22 4
-19 5 10 42 22 4
-18 5 10 42 22 4
-17 5 10 42 22 4
-16 5 10 42 22 4
-15 5 10 42 22 4
-14 5 10 42 22 4
-41 6 10 42 22 4
-40 6 10 42 22 4
-39 6 10 42 22 4
-38 6 10 42 22 4
-37 6 10 42 22 4
-36 6 10 42 22 4
-35 6 10 42 22 4
-13 1 11 168 168 167
-33 6 10 42 22 4
-32 6 10 42 22 4
-31 6 10 42 22 4
-30 6 10 42 22 4
-29 6 10 42 22 4
-28 6 10 42 22 4
-27 6 10 42 22 4
-26 6 10 42 22 4
-25 6 10 42 22 4
-24 6 10 42 22 4
-23 6 10 42 22 4
-22 6 10 42 22 4
-21 6 10 42 22 4
-20 6 10 42 22 4
-19 6 10 42 22 4
-18 6 10 42 22 4
-17 6 10 42 22 4
-16 6 10 42 22 4
-15 6 10 42 22 4
-14 6 10 42 22 4
-41 7 10 42 22 4
-40 7 10 42 22 4
-39 7 10 42 22 4
-38 7 10 42 22 4
-37 7 10 42 22 4
-36 7 10 42 22 4
-35 7 10 42 22 4
-34 7 10 42 22 4
-33 7 10 42 22 4
-32 7 10 42 22 4
-31 7 10 42 22 4
-30 7 10 42 22 4
-29 7 10 42 22 4
-28 7 10 42 22 4
-27 7 10 42 22 4
-26 7 10 42 22 4
-25 7 10 42 22 4
-24 7 10 42 22 4
-23 7 10 42 22 4
-22 7 10 42 22 4
-21 7 10 42 22 4
-20 7 10 42 22 4
-19 7 10 42 22 4
-18 7 10 42 22 4
-17 7 10 42 22 4
-16 7 10 42 22 4
-15 7 10 42 22 4
-14 7 10 42 22 4
-41 8 10 42 22 4
-40 8 10 42 22 4
-39 8 10 42 22 4
-38 8 10 42 22 4
-37 8 10 42 22 4
-36 8 10 42 22 4
-35 8 10 42 22 4
-34 8 10 42 22 4
-33 8 10 42 22 4
-32 8 10 42 22 4
-31 8 10 42 22 4
-30 8 10 42 22 4
-29 8 10 42 22 4
-28 8 10 42 22 4
-27 8 10 42 22 4
-26 8 10 42 22 4
-25 8 10 42 22 4
-24 8 10 0 0 0
-23 8 10 0 0 0
-22 8 10 42 22 4
-21 8 10 42 22 4
-20 8 10 42 22 4
-19 8 10 42 22 4
-18 8 10 42 22 4
-17 8 10 0 0 0
-16 8 10 0 0 0
-15 8 10 42 22 4
-14 8 10 42 22 4
-43 20 18 102 51 51
-40 9 10 42 22 4
-39 9 10 42 22 4
-38 9 10 42 22 4
-37 9 10 42 22 4
-36 9 10 42 22 4
-35 9 10 42 22 4
-34 9 10 42 22 4
-33 9 10 42 22 4
-32 9 10 42 22 4
-31 9 10 42 22 4
-30 9 10 42 22 4
-29 9 10 42 22 4
-28 9 10 42 22 4
-14 8 11 50 50 50
-15 8 11 50 50 50
-18 8 11 50 50 50
-19 8 11 50 50 50
-20 8 11 168 168 167
-21 8 11 50 50 50
-22 8 11 50 50 50
-25 8 11 50 50 50
-26 8 11 50 50 50
-27 8 11 168 168 167
-28 8 11 67 67 255
-36 18 16 102 51 51
-36 17 16 102 51 51
-36 16 16 102 51 51
-44 8 13 102 51 51
-41 10 10 42 22 4
-40 10 10 42 22 4
-39 10 10 42 22 4
-38 10 10 42 22 4
-37 10 10 42 22 4
-36 10 10 42 22 4
-35 10 10 42 22 4
-34 10 10 42 22 4
-33 10 10 42 22 4
-32 10 10 42 22 4
-31 10 10 42 22 4
-30 10 10 42 22 4
-29 10 10 42 22 4
-2 23 12 0 225 255
-3 23 12 255 255 255
-4 23 12 102 51 51
-5 23 12 102 51 51
-6 23 12 102 51 51
-7 23 12 102 51 51
-8 23 12 102 51 51
-9 23 12 0 225 255
-10 23 12 255 255 255
-11 23 12 102 51 51
-12 23 12 102 51 51
-13 23 12 102 51 51
0 23 13 102 51 51
-1 23 13 102 51 51
-2 23 13 255 255 255
-44 7 13 102 51 51
-41 11 10 42 22 4
-40 11 10 42 22 4
-39 11 10 42 22 4
-38 11 10 42 22 4
-37 11 10 42 22 4
-36 11 10 42 22 4
-35 11 10 42 22 4
-34 11 10 42 22 4
-33 11 10 42 22 4
-32 11 10 42 22 4
-31 11 10 42 22 4
-30 11 10 42 22 4
-29 11 10 42 22 4
-3 23 13 255 255 255
-4 23 13 102 51 51
-5 23 13 102 51 51
-6 23 13 102 51 51
-7 23 13 102 51 51
-8 23 13 102 51 51
-9 23 13 255 255 255
-10 23 13 255 255 255
-11 23 13 102 51 51
-12 23 13 102 51 51
-13 23 13 102 51 51
-13 10 9 42 22 4
-14 10 9 42 22 4
-15 10 9 42 22 4
-16 10 9 42 22 4
-44 6 13 102 51 51
-41 12 10 42 22 4
-40 12 10 42 22 4
-39 12 10 42 22 4
-38 12 10 42 22 4
-37 12 10 42 22 4
-36 12 10 42 22 4
-35 12 10 42 22 4
-34 12 10 42 22 4
-33 12 10 42 22 4
-32 12 10 42 22 4
-31 12 10 42 22 4
-30 12 10 42 22 4
-29 12 10 42 22 4
-17 10 9 42 22 4
-18 10 9 42 22 4
-19 10 9 42 22 4
-20 10 9 42 22 4
-21 10 9 42 22 4
-22 10 9 42 22 4
-23 10 9 42 22 4
-24 10 9 42 22 4
-25 10 9 42 22 4
-26 10 9 42 22 4
0 22 10 42 22 4
-1 22 10 42 22 4
-2 22 10 42 22 4
-3 22 10 42 22 4
-4 22 10 42 22 4
-44 5 13 102 51 51
-41 13 10 42 22 4
-40 13 10 42 22 4
-39 13 10 42 22 4
-38 13 10 42 22 4
-37 13 10 42 22 4
-36 13 10 42 22 4
-35 13 10 42 22 4
-34 13 10 42 22 4
-33 13 10 42 22 4
-32 13 10 42 22 4
-31 13 10 42 22 4
-30 13 10 42 22 4
-29 13 10 42 22 4
-5 22 10 42 22 4
-6 22 10 42 22 4
-7 22 10 42 22 4
-8 22 10 42 22 4
-9 22 10 42 22 4
-10 22 10 42 22 4
-11 22 10 42 22 4
-12 22 10 42 22 4
-13 22 10 42 22 4
0 21 10 42 22 4
-1 21 10 42 22 4
-2 21 10 42 22 4
-3 21 10 42 22 4
-4 21 10 42 22 4
-5 21 10 42 22 4
-42 0 14 102 51 51
-35 2 11 102 51 51
-35 0 13 102 51 51
-35 3 11 102 51 51
-36 0 13 102 51 51
-35 4 11 102 51 51
-37 0 13 102 51 51
-36 15 16 102 51 51
-38 0 13 102 51 51
-27 13 9 42 22 4
-39 0 13 102 51 51
-14 12 9 42 22 4
-40 0 13 102 51 51
-15 12 9 42 22 4
-41 0 13 102 51 51
-42 0 13 102 51 51
-44 4 13 102 51 51
-43 3 13 102 51 51
-43 2 13 102 51 51
-43 1 13 102 51 51
-35 0 12 102 51 51
-35 2 12 102 51 51
-36 0 12 102 51 51
-35 3 12 102 51 51
-37 0 12 102 51 51
-35 4 12 102 51 51
-38 0 12 102 51 51
-36 14 16 102 51 51
-39 0 12 102 51 51
-16 12 9 42 22 4
-40 0 12 102 51 51
-17 12 9 42 22 4
-41 0 12 102 51 51
-18 12 9 42 22 4
0 0 11 102 51 51
-19 12 9 42 22 4
-43 8 12 102 51 51
-43 7 12 102 51 51
-43 6 12 102 51 51
-43 5 12 102 51 51
-1 0 11 102 51 51
-35 2 13 102 51 51
-2 0 11 102 51 51
-35 3 13 102 51 51
-3 0 11 102 51 51
-35 4 13 102 51 51
-4 0 11 102 51 51
-36 13 16 102 51 51
-5 0 11 102 51 51
-20 12 9 42 22 4
-6 0 11 102 51 51
-21 12 9 42 22 4
-7 0 11 102 51 51
-22 12 9 42 22 4
-23 12 9 42 22 4
-24 12 9 42 22 4
-25 12 9 42 22 4
-26 12 9 42 22 4
-27 12 9 42 22 4
-14 11 9 42 22 4
-15 11 9 42 22 4
-16 11 9 42 22 4
-17 11 9 42 22 4
-18 11 9 42 22 4
-19 11 9 42 22 4
-20 11 9 42 22 4
-21 11 9 42 22 4
-22 11 9 42 22 4
-23 11 9 42 22 4
-24 11 9 42 22 4
-25 11 9 42 22 4
-34 22 11 168 168 167
-27 22 11 168 168 167
-20 22 11 168 168 167
-13 22 11 168 168 167
-34 22 12 168 168 168
-34 22 13 168 168 168
-34 22 14 168 168 168
-27 22 12 168 168 168
-27 22 13 168 168 168
-27 22 14 168 168 168
-20 22 12 168 168 168
-20 22 13 168 168 168
-20 22 14 168 168 168
-13 22 12 168 168 168
-13 22 13 168 168 168
-13 22 14 168 168 168
-13 8 10 42 22 4
-12 8 10 42 22 4
-11 8 10 42 22 4
-10 8 10 42 22 4
-9 8 10 42 22 4
-8 8 10 42 22 4
-7 8 10 42 22 4
-6 8 10 42 22 4
-5 8 10 42 22 4
-4 8 10 42 22 4
-3 8 10 42 22 4
-2 8 10 42 22 4
-1 8 10 42 22 4
0 8 10 42 22 4
-13 7 10 42 22 4
-12 7 10 42 22 4
-11 7 10 42 22 4
-10 7 10 42 22 4
-9 7 10 42 22 4
-8 7 10 42 22 4
-7 7 10 42 22 4
-6 7 10 42 22 4
-5 7 10 42 22 4
-4 7 10 42 22 4
-3 7 10 42 22 4
-2 7 10 42 22 4
-1 7 10 42 22 4
0 7 10 42 22 4
-36 12 16 102 51 51
-36 11 16 102 51 51
-36 10 16 102 51 51
-36 9 16 102 51 51
-36 8 16 102 51 51
-36 7 16 102 51 51
-36 6 16 102 51 51
-36 5 16 102 51 51
-35 18 15 102 51 51
-35 17 15 102 51 51
-35 16 15 168 168 168
-36 16 15 102 51 51
-36 15 15 102 51 51
-36 14 15 102 51 51
-13 6 10 42 22 4
-12 6 10 42 22 4
-11 6 10 42 22 4
-10 6 10 42 22 4
-9 6 10 42 22 4
-8 6 10 42 22 4
-7 6 10 42 22 4
-6 6 10 42 22 4
-5 6 10 42 22 4
-4 6 10 42 22 4
-3 6 10 42 22 4
-2 6 10 42 22 4
-1 6 10 42 22 4
0 6 10 42 22 4
-6 21 10 42 22 4
-7 21 10 42 22 4
-4 20 10 42 22 4
-5 20 10 42 22 4
-6 20 10 42 22 4
-7 20 10 42 22 4
-8 20 10 42 22 4
-9 20 10 42 22 4
-10 20 10 42 22 4
-11 20 10 42 22 4
-12 20 10 42 22 4
-13 20 10 42 22 4
0 19 10 42 22 4
-1 19 10 42 22 4
-13 5 10 42 22 4
-12 5 10 42 22 4
-11 5 10 42 22 4
-10 5 10 42 22 4
-9 5 10 42 22 4
-8 5 10 42 22 4
-7 5 10 42 22 4
-6 5 10 42 22 4
-5 5 10 42 22 4
-4 5 10 42 22 4
-3 5 10 42 22 4
-2 5 10 42 22 4
-1 5 10 42 22 4
0 5 10 42 22 4
-8 21 10 42 22 4
-9 21 10 42 22 4
-2 19 10 42 22 4
-3 19 10 42 22 4
-4 19 10 42 22 4
-5 19 10 42 22 4
-6 19 10 42 22 4
-7 19 10 42 22 4
-8 19 10 42 22 4
-9 19 10 42 22 4
-10 19 10 42 22 4
-11 19 10 42 22 4
-12 19 10 42 22 4
-13 19 10 42 22 4
-13 4 10 42 22 4
-12 4 10 42 22 4
-11 4 10 42 22 4
-10 4 10 42 22 4
-9 4 10 42 22 4
-8 4 10 42 22 4
-7 4 10 42 22 4
-6 4 10 42 22 4
-5 4 10 42 22 4
-4 4 10 42 22 4
-3 4 10 42 22 4
-2 4 10 42 22 4
-1 4 10 42 22 4
0 4 10 42 22 4
-10 21 10 42 22 4
-11 21 10 42 22 4
0 18 10 42 22 4
-1 18 10 42 22 4
-2 18 10 42 22 4
-3 18 10 42 22 4
-4 18 10 42 22 4
-5 18 10 42 22 4
-6 18 10 42 22 4
-7 18 10 42 22 4
-8 18 10 42 22 4
-9 18 10 42 22 4
-10 18 10 42 22 4
-11 18 10 42 22 4
-13 3 10 42 22 4
-12 3 10 42 22 4
-11 3 10 42 22 4
-10 3 10 42 22 4
-9 3 10 42 22 4
-8 3 10 42 22 4
-7 3 10 42 22 4
-6 3 10 42 22 4
-5 3 10 42 22 4
-4 3 10 42 22 4
-3 3 10 42 22 4
-2 3 10 42 22 4
-1 3 10 42 22 4
0 3 10 42 22 4
-12 21 10 42 22 4
-13 21 10 42 22 4
-12 18 10 42 22 4
-13 18 10 42 22 4
0 17 10 42 22 4
-1 17 10 42 22 4
-2 17 10 42 22 4
-3 17 10 42 22 4
-4 17 10 42 22 4
-5 17 10 42 22 4
-6 17 10 42 22 4
-7 17 10 42 22 4
-8 17 10 42 22 4
-9 17 10 42 22 4
-13 2 10 42 22 4
-12 2 10 42 22 4
-11 2 10 42 22 4
-10 2 10 42 22 4
-9 2 10 42 22 4
-8 2 10 42 22 4
-7 2 10 42 22 4
-6 2 10 42 22 4
-5 2 10 42 22 4
-4 2 10 42 22 4
-3 2 10 42 22 4
-2 2 10 42 22 4
-1 2 10 42 22 4
0 2 10 42 22 4
0 20 10 42 22 4
-1 20 10 42 22 4
-10 17 10 42 22 4
-11 17 10 42 22 4
-12 17 10 42 22 4
-13 17 10 42 22 4
0 16 10 42 22 4
-1 16 10 42 22 4
-2 16 10 42 22 4
-3 16 10 42 22 4
-4 16 10 42 22 4
-5 16 10 42 22 4
-6 16 10 42 22 4
-7 16 10 42 22 4
-2 20 10 42 22 4
-3 20 10 42 22 4
-8 16 10 42 22 4
-9 16 10 42 22 4
-10 16 10 42 22 4
-11 16 10 42 22 4
-12 16 10 42 22 4
-13 16 10 42 22 4
-30 18 11 221 0 0
-30 20 11 255 102 0
0 14 9 42 22 4
-1 14 9 42 22 4
-2 14 9 42 22 4
-3 14 9 42 22 4
-4 14 9 42 22 4
-5 14 9 42 22 4
-6 14 9 42 22 4
-7 14 9 42 22 4
-8 14 9 42 22 4
-9 14 9 42 22 4
-10 14 9 42 22 4
-11 14 9 42 22 4
-12 14 9 42 22 4
-13 14 9 42 22 4
-28 13 10 42 22 4
-14 15 11 50 50 50
-15 15 11 50 50 50
-18 15 11 50 50 50
-15 14 9 42 22 4
-16 14 9 42 22 4
-17 14 9 42 22 4
-24 19 11 221 0 0
-23 18 11 221 0 0
-24 18 11 221 0 0
-16 18 11 255 102 0
-17 18 11 255 102 0
-22 18 11 255 102 0
-29 19 11 221 0 0
-30 20 10 42 22 4
-1 1 10 42 22 4
-2 1 10 42 22 4
-3 1 10 42 22 4
-4 1 10 42 22 4
-5 1 10 42 22 4
-6 1 10 42 22 4
-7 1 10 42 22 4
-8 1 10 42 22 4
-9 1 10 42 22 4
-10 1 10 42 22 4
-11 1 10 42 22 4
-12 1 10 42 22 4
-13 1 10 42 22 4
-14 1 10 42 22 4
-15 1 10 42 22 4
-16 1 10 42 22 4
-17 1 10 42 22 4
-18 1 10 42 22 4
-19 1 10 42 22 4
-26 11 9 42 22 4
-27 11 9 42 22 4
-36 20 17 102 51 51
-36 21 17 102 51 51
-36 22 17 102 51 51
-25 15 10 42 22 4
-12 15 10 42 22 4
-36 20 16 102 51 51
-30 19 11 221 0 0
-37 15 17 102 51 51
-22 19 11 255 102 0
-25 18 11 255 102 0
-25 19 11 255 102 0
-32 22 11 0 0 153
-26 22 11 0 0 153
-28 22 11 67 67 255
-18 14 9 42 22 4
-24 15 10 0 0 0
-19 14 9 42 22 4
-17 19 11 221 0 0
-23 19 11 221 0 0
-20 14 9 42 22 4
-21 14 9 42 22 4
-13 12 9 42 22 4
-12 12 9 42 22 4
-11 12 9 42 22 4
-10 12 9 42 22 4
-9 12 9 42 22 4
-8 12 9 42 22 4
-7 12 9 42 22 4
-6 12 9 42 22 4
-5 12 9 42 22 4
-4 12 9 42 22 4
-3 12 9 42 22 4
-2 12 9 42 22 4
-1 12 9 42 22 4
0 12 9 42 22 4
-29 17 11 255 102 0
-37 14 17 102 51 51
-22 14 9 42 22 4
-16 20 11 0 255 204
-15 20 11 0 204 0
-23 14 9 42 22 4
-24 14 9 42 22 4
-19 15 11 50 50 50
-20 15 11 168 168 167
-21 15 11 50 50 50
-22 15 11 50 50 50
-16 19 11 221 0 0
-18 20 11 0 204 0
-25 15 11 50 50 50
-26 15 11 50 50 50
-13 13 9 42 22 4
-12 13 9 42 22 4
-11 13 9 42 22 4
-10 13 9 42 22 4
-9 13 9 42 22 4
-8 13 9 42 22 4
-7 13 9 42 22 4
-6 13 9 42 22 4
-5 13 9 42 22 4
-4 13 9 42 22 4
-3 13 9 42 22 4
-2 13 9 42 22 4
-1 13 9 42 22 4
0 13 9 42 22 4
-30 17 11 255 102 0
-37 13 17 102 51 51
-36 13 15 102 51 51
-36 4 16 102 51 51
-36 3 16 102 51 51
-20 1 10 42 22 4
-21 1 10 42 22 4
-22 1 10 42 22 4
-23 1 10 42 22 4
-24 1 10 42 22 4
-25 1 10 42 22 4
-26 1 10 42 22 4
-27 1 10 42 22 4
-28 1 10 42 22 4
-29 1 10 42 22 4
-30 1 10 42 22 4
-31 1 10 42 22 4
-36 2 17 102 51 51
-36 2 16 102 51 51
-32 1 10 42 22 4
-40 1 10 42 22 4
-33 1 10 42 22 4
-39 1 10 42 22 4
-13 15 10 42 22 4
-23 15 10 0 0 0
-14 15 10 42 22 4
-22 15 10 42 22 4
-15 15 10 42 22 4
-21 15 10 42 22 4
-29 20 11 255 102 0
-37 12 17 102 51 51
-34 1 10 42 22 4
-27 15 11 168 168 167
-28 14 11 50 50 50
-36 21 16 102 51 51
-28 15 11 67 67 255
-37 11 17 102 51 51
-37 10 17 102 51 51
-37 9 17 102 51 51
-16 15 10 0 0 0
-20 15 10 42 22 4
-17 15 10 0 0 0
-19 15 10 42 22 4
-18 15 10 42 22 4
-38 1 10 42 22 4
-35 1 10 42 22 4
-37 1 10 42 22 4
-36 1 10 42 22 4
-41 4 10 42 22 4
-42 9 10 42 22 4
-36 12 15 102 51 51
-36 11 15 102 51 51
-36 10 15 102 51 51
-36 4 17 102 51 51
-36 3 17 102 51 51
-36 9 15 102 51 51
-36 8 15 102 51 51
-30 23 12 0 225 255
-13 22 15 168 168 168
-20 22 15 168 168 168
-27 22 15 168 168 168
-34 22 15 168 168 168
0 23 15 102 51 51
-1 23 15 102 51 51
-2 23 15 102 51 51
-3 23 15 102 51 51
-4 23 15 102 51 51
-5 23 15 102 51 51
-6 23 15 102 51 51
-7 23 15 102 51 51
-8 23 15 102 51 51
-9 23 15 102 51 51
-10 23 15 102 51 51
-11 23 15 102 51 51
-12 23 15 102 51 51
-32 23 15 102 51 51
-13 23 15 102 51 51
-31 23 15 102 51 51
-14 23 15 102 51 51
-30 23 15 102 51 51
-15 23 15 102 51 51
-29 23 15 102 51 51
-16 23 15 102 51 51
-28 23 15 102 51 51
-17 23 15 102 51 51
-27 23 15 102 51 51
-18 23 15 102 51 51
-26 23 15 102 51 51
-19 23 15 102 51 51
-25 23 15 102 51 51
-20 23 15 102 51 51
-24 23 15 102 51 51
-21 23 15 102 51 51
-23 23 15 102 51 51
-22 23 15 102 51 51
-36 6 17 102 51 51
-35 7 15 168 168 168
-36 7 15 102 51 51
-35 6 15 102 51 51
-36 5 17 102 51 51
-35 5 15 102 51 51
-35 18 14 102 51 51
-35 17 14 102 51 51
-35 16 14 168 168 168
-36 16 14 102 51 51
-29 18 11 221 0 0
-36 22 16 102 51 51
0 15 10 42 22 4
-1 15 10 42 22 4
-2 15 10 42 22 4
-3 15 10 42 22 4
-4 15 10 42 22 4
-5 15 10 42 22 4
-6 15 10 42 22 4
-7 15 10 42 22 4
-8 15 10 42 22 4
-9 15 10 42 22 4
-27 15 10 42 22 4
-10 15 10 42 22 4
-26 15 10 42 22 4
-11 15 10 42 22 4
-13 11 9 42 22 4
-12 11 9 42 22 4
-11 11 9 42 22 4
-10 11 9 42 22 4
-9 11 9 42 22 4
-8 11 9 42 22 4
-7 11 9 42 22 4
-6 11 9 42 22 4
-5 11 9 42 22 4
-4 11 9 42 22 4
-3 11 9 42 22 4
-2 11 9 42 22 4
-1 11 9 42 22 4
0 11 9 42 22 4
-28 12 10 0 0 0
-28 11 10 0 0 0
-14 14 9 42 22 4
-28 10 10 42 22 4
-28 14 10 42 22 4
-28 15 10 42 22 4
-36 15 14 102 51 51
-36 14 14 102 51 51
-36 9 14 102 51 51
-36 8 14 102 51 51
-35 7 14 168 168 168
-36 7 14 102 51 51
-35 6 14 102 51 51
-35 5 14 102 51 51
-35 18 13 102 51 51
-35 5 11 102 51 51
-35 6 11 102 51 51
-36 7 11 102 51 51
-35 7 11 168 168 167
-36 8 11 102 51 51
-35 9 11 0 255 134
-35 10 11 0 255 133
-35 11 11 0 255 133
-35 12 11 0 255 133
-35 13 11 0 255 133
-35 14 11 0 255 135
-36 15 11 102 51 51
-36 16 11 102 51 51
-35 16 11 168 168 167
-35 17 11 102 51 51
-35 18 11 102 51 51
-35 5 12 102 51 51
-35 6 12 102 51 51
-36 7 12 102 51 51
-35 7 12 168 168 168
-36 8 12 102 51 51
-36 15 12 102 51 51
-36 16 12 102 51 51
-35 16 12 168 168 168
-35 17 12 102 51 51
-35 18 12 102 51 51
-35 5 13 102 51 51
-35 6 13 102 51 51
-36 7 13 102 51 51
-35 7 13 168 168 168
-36 8 13 102 51 51
-36 15 13 102 51 51
-36 16 13 102 51 51
-35 16 13 168 168 168
-35 17 13 102 51 51
-27 9 9 42 22 4
-26 9 9 42 22 4
-25 9 9 42 22 4
-24 9 9 42 22 4
-23 9 9 42 22 4
-22 9 9 42 22 4
-21 9 9 42 22 4
-20 9 9 42 22 4
-19 9 9 42 22 4
-18 9 9 42 22 4
-17 9 9 42 22 4
-16 9 9 42 22 4
-15 9 9 42 22 4
-14 9 9 42 22 4
-13 9 9 42 22 4
-12 9 9 42 22 4
-11 9 9 42 22 4
-10 9 9 42 22 4
-9 9 9 42 22 4
-8 9 9 42 22 4
-7 9 9 42 22 4
-6 9 9 42 22 4
-5 9 9 42 22 4
-4 9 9 42 22 4
-3 9 9 42 22 4
-2 9 9 42 22 4
-1 9 9 42 22 4
0 9 9 42 22 4
-27 10 9 42 22 4
-40 0 11 102 51 51
-39 0 11 102 51 51
-38 0 11 102 51 51
-43 9 11 102 51 51
-43 10 11 102 51 51
-43 11 11 102 51 51
-43 12 11 102 51 51
-43 13 11 102 51 51
-43 14 11 102 51 51
-42 15 11 102 51 51
-42 16 11 102 51 51
-42 17 11 102 51 51
-42 18 11 102 51 51
-42 19 11 102 51 51
-44 9 12 102 51 51
-44 10 12 102 51 51
-44 11 12 102 51 51
-44 12 12 102 51 51
-44 13 12 102 51 51
-44 14 12 102 51 51
-43 15 12 102 51 51
-43 16 12 102 51 51
-43 17 12 102 51 51
-43 18 12 102 51 51
-43 19 12 102 51 51
-45 9 13 102 51 51
-45 10 13 102 51 51
-45 11 13 102 51 51
-45 12 13 102 51 51
-45 13 13 102 51 51
-45 14 13 102 51 51
-44 15 13 102 51 51
-44 16 13 102 51 51
-44 17 13 102 51 51
-44 18 13 102 51 51
-44 19 13 102 51 51
-45 9 14 102 51 51
-45 10 14 102 51 51
-45 11 14 102 51 51
-45 12 14 102 51 51
-45 13 14 102 51 51
-45 14 14 102 51 51
-44 15 14 102 51 51
-44 16 14 102 51 51
-44 17 14 102 51 51
-44 18 14 102 51 51
-44 19 14 102 51 51
-45 9 15 102 51 51
-45 10 15 102 51 51
-45 11 15 102 51 51
-45 12 15 102 51 51
-45 13 15 102 51 51
-45 14 15 102 51 51
-44 15 15 102 51 51
-44 16 15 102 51 51
-44 17 15 102 51 51
-44 18 15 102 51 51
-44 19 15 102 51 51
-45 9 16 102 51 51
-45 10 16 102 51 51
-45 11 16 102 51 51
-45 12 16 102 51 51
-45 13 16 102 51 51
-45 14 16 102 51 51
-44 15 16 102 51 51
-44 16 16 102 51 51
-44 17 16 102 51 51
-44 18 16 102 51 51
-44 19 16 102 51 51
-45 9 17 102 51 51
-45 10 17 102 51 51
-45 11 17 102 51 51
-45 12 17 102 51 51
-45 13 17 102 51 51
-45 14 17 102 51 51
-44 15 17 102 51 51
-44 16 17 102 51 51
-44 17 17 102 51 51
-44 18 17 102 51 51
-44 19 17 102 51 51
-45 9 18 102 51 51
-45 10 18 102 51 51
-45 11 18 102 51 51
-45 12 18 102 51 51
-45 13 18 102 51 51
-45 14 18 102 51 51
-44 15 18 102 51 51
-44 16 18 102 51 51
-44 17 18 102 51 51
-44 18 18 102 51 51
-44 19 18 102 51 51
-45 9 19 102 51 51
-45 10 19 102 51 51
-45 11 19 102 51 51
-45 12 19 102 51 51
-45 13 19 102 51 51
-45 14 19 102 51 51
-44 15 19 102 51 51
-44 16 19 102 51 51
-44 17 19 102 51 51
-44 18 19 102 51 51
-44 19 19 102 51 51
-45 9 20 102 51 51
-45 10 20 102 51 51
-45 11 20 102 51 51
-45 12 20 102 51 51
-45 13 20 102 51 51
-45 14 20 102 51 51
-44 15 20 102 51 51
-44 16 20 102 51 51
-44 17 20 102 51 51
-44 18 20 102 51 51
-44 19 20 102 51 51
-41 20 11 102 51 51
-42 20 12 102 51 51
-43 20 13 102 51 51
-43 20 14 102 51 51
-43 20 15 102 51 51
-43 20 16 102 51 51
-43 20 17 102 51 51
-37 1 18 102 51 51
-37 1 19 102 51 51
-37 2 19 102 51 51
-37 3 19 102 51 51
-37 4 19 102 51 51
-37 5 19 102 51 51
-37 6 19 102 51 51
-37 7 19 102 51 51
-37 8 19 102 51 51
-37 9 19 102 51 51
-37 10 19 102 51 51
-37 11 19 102 51 51
-37 12 19 102 51 51
-37 13 19 102 51 51
-37 14 19 102 51 51
-37 15 19 102 51 51
-37 16 19 102 51 51
-37 17 19 102 51 51
-37 18 19 102 51 51
-37 19 19 102 51 51
-37 20 19 102 51 51
-37 21 19 102 51 51
-37 22 19 102 51 51
-37 2 18 102 51 51
-37 3 18 102 51 51
-37 4 18 102 51 51
-37 5 18 102 51 51
-37 6 18 102 51 51
-37 7 18 102 51 51
-37 8 18 102 51 51
-37 9 18 102 51 51
-37 10 18 102 51 51
-37 11 18 102 51 51
-37 12 18 102 51 51
-37 13 18 102 51 51
-37 14 18 102 51 51
-37 15 18 102 51 51
-37 16 18 102 51 51
-37 17 18 102 51 51
-37 18 18 102 51 51
-37 19 18 102 51 51
-37 20 18 102 51 51
-37 21 18 102 51 51
-13 2 11 67 67 255
-20 2 11 0 0 153
-34 1 11 168 168 167
-33 1 11 0 0 153
-29 1 11 67 67 255
-28 1 11 67 67 255
-27 1 11 168 168 167
-26 1 11 0 0 153
-21 1 11 0 0 153
-20 1 11 168 168 167
-19 1 11 67 67 255
-14 1 11 67 67 255
-34 6 10 42 22 4
-34 6 11 0 0 153
-34 3 11 153 50 205
-33 17 11 153 0 154
-33 19 11 153 0 154
-6 22 11 168 168 167
-6 22 12 168 168 168
-6 22 13 168 168 168
-6 22 14 168 168 168
-6 22 15 168 168 168
-12 1 11 102 51 51
-34 3 12 255 255 255
-34 4 11 255 255 255
-34 5 11 255 255 255
-34 5 12 255 255 255
-34 4 12 255 255 255
-34 5 13 255 255 255
-34 4 13 255 255 255
-34 3 13 255 255 255
-34 17 11 255 255 255
-34 18 11 255 255 255
-34 19 11 255 255 255
-33 18 11 255 255 255
-34 20 11 255 255 255
-33 20 11 255 255 255
-34 17 12 255 255 255
-34 18 12 255 255 255
-34 19 12 255 255 255
-34 20 12 255 255 255
-17 3 10 42 22 4
-17 3 11 255 255 255
-17 3 12 255 255 255
-16 3 12 255 255 255
-17 20 11 255 255 255
-17 20 12 255 255 255
-12 22 11 102 51 51
