ply
format ascii 1.0
comment : MagicaVoxel @ Ephtracy
element vertex 650
property float x
property float y
property float z
property uchar red
property uchar green
property uchar blue
end_header
-40 16 15 255 227 49
-39 17 15 255 227 49
-40 17 15 255 227 49
-39 18 15 255 227 49
-40 18 15 255 227 49
-38 16 16 50 50 50
-41 16 16 50 50 50
-34 23 15 255 102 0
-34 25 15 255 102 0
-33 21 14 42 22 4
-50 21 15 102 51 51
-49 21 15 42 22 4
-41 17 16 50 50 50
-49 22 15 42 22 4
-41 18 16 50 50 50
-38 17 16 50 50 50
-38 18 16 50 50 50
-33 19 17 255 255 254
-34 19 17 255 255 254
-35 19 17 255 255 254
-36 19 17 255 255 254
-37 19 17 255 255 254
-38 19 17 255 255 254
-30 22 15 42 22 4
-39 19 17 255 255 254
-40 19 17 255 255 254
-41 19 17 255 255 254
-42 19 17 255 255 254
-43 19 17 255 255 254
-44 19 17 255 255 254
-38 18 15 42 22 4
-45 19 17 255 255 254
-46 19 17 255 255 254
-39 25 15 221 0 0
-38 25 15 255 102 0
-38 17 15 42 22 4
-43 21 15 0 0 153
-47 23 15 0 255 133
-48 23 14 255 227 49
-34 20 16 0 0 153
-35 15 16 0 0 153
-34 15 16 0 0 153
-45 23 14 42 22 4
-43 20 16 67 67 255
-37 15 16 50 50 50
-38 12 15 42 22 4
-38 16 15 42 22 4
-37 12 15 42 22 4
-51 23 15 42 22 4
-44 22 14 42 22 4
-49 23 14 255 227 49
-36 12 15 42 22 4
-39 19 16 255 255 254
-35 12 15 42 22 4
-38 15 16 42 22 4
-34 13 16 67 67 255
-43 22 14 42 22 4
-50 23 15 42 22 4
-35 23 15 221 0 0
-28 22 16 0 0 153
-34 12 16 42 22 4
-50 23 16 102 51 51
-34 12 15 42 22 4
-38 13 15 42 22 4
-42 22 14 42 22 4
-41 22 14 42 22 4
-40 22 14 42 22 4
-41 24 15 255 102 0
-37 13 15 42 22 4
-36 13 15 42 22 4
-35 13 15 42 22 4
-34 13 15 42 22 4
-54 23 16 102 51 51
-36 22 14 42 22 4
-32 21 15 67 67 255
-31 22 15 67 67 255
-45 22 14 42 22 4
-32 19 17 102 51 51
-36 15 16 50 50 50
-35 25 15 221 0 0
-29 21 15 102 51 51
-44 27 16 255 255 255
-38 14 15 42 22 4
-46 21 15 0 204 0
-34 14 16 0 0 153
-37 14 15 42 22 4
-36 14 15 42 22 4
-35 14 15 42 22 4
-34 14 15 42 22 4
-40 19 16 255 255 254
-49 22 17 102 51 51
-38 15 15 42 22 4
-37 15 15 42 22 4
-45 24 14 42 22 4
-45 26 14 42 22 4
-36 15 15 42 22 4
-31 20 15 102 51 51
-35 12 16 0 0 153
-47 27 16 168 168 168
-32 26 14 42 22 4
-42 27 15 67 67 255
-35 15 15 42 22 4
-34 15 15 42 22 4
-45 25 14 42 22 4
-32 25 14 42 22 4
-34 15 17 0 0 153
-40 25 15 221 0 0
-46 27 15 0 204 0
-32 19 16 102 51 51
-33 19 16 102 51 51
-30 23 15 42 22 4
-32 22 14 42 22 4
-30 26 15 42 22 4
-47 21 14 42 22 4
-41 16 15 42 22 4
-41 17 15 42 22 4
-39 22 14 42 22 4
-38 22 14 42 22 4
-36 12 16 67 67 255
-46 26 14 255 227 49
-29 23 15 42 22 4
-28 23 15 42 22 4
-32 23 14 42 22 4
-30 21 15 42 22 4
-50 27 16 102 51 51
-47 13 15 42 22 4
-41 29 15 102 51 51
-52 27 17 102 51 51
-40 29 15 102 51 51
-47 12 15 42 22 4
-52 26 15 102 51 51
-45 29 16 102 51 51
-45 29 15 102 51 51
-49 25 18 102 51 51
-49 24 18 102 51 51
-49 23 18 102 51 51
-40 24 15 221 0 0
-48 22 14 255 227 49
-47 22 15 0 255 134
-49 22 16 102 51 51
-43 27 15 255 255 255
-49 23 17 102 51 51
-36 27 14 42 22 4
-47 27 14 42 22 4
-30 25 15 42 22 4
-29 25 15 42 22 4
-28 25 15 42 22 4
-35 27 14 42 22 4
-40 27 14 42 22 4
-48 25 14 255 227 49
-34 27 14 42 22 4
-51 22 15 42 22 4
-31 21 15 42 22 4
-52 23 15 42 22 4
-46 21 14 255 227 49
-45 21 14 42 22 4
-44 21 14 42 22 4
-43 21 14 42 22 4
-42 21 14 42 22 4
-52 22 15 102 51 51
-45 19 15 102 51 51
-45 19 16 102 51 51
-41 18 15 42 22 4
-39 16 15 255 227 49
-53 22 16 102 51 51
-42 20 15 42 22 4
-42 19 16 102 51 51
-29 21 16 102 51 51
-30 20 16 102 51 51
-28 21 16 102 51 51
-32 20 15 42 22 4
-33 20 15 42 22 4
-31 20 16 102 51 51
-31 19 17 102 51 51
-37 22 14 42 22 4
-52 22 16 102 51 51
-47 27 18 102 51 51
-32 19 15 102 51 51
-33 19 15 102 51 51
-30 19 17 102 51 51
-29 20 17 102 51 51
-33 23 14 42 22 4
-34 23 14 255 227 48
-35 23 14 255 227 48
-36 23 14 42 22 4
-37 23 14 42 22 4
-38 23 14 42 22 4
-39 23 14 42 22 4
-40 23 14 42 22 4
-41 23 14 42 22 4
-42 23 14 42 22 4
-43 23 14 42 22 4
-44 23 14 42 22 4
-35 20 16 0 0 153
-44 20 16 0 0 153
-33 22 14 42 22 4
-34 22 14 42 22 4
-35 22 14 42 22 4
-33 27 14 42 22 4
-48 26 14 255 227 49
-37 19 15 102 51 51
-37 19 16 102 51 51
-37 20 15 42 22 4
-43 20 15 42 22 4
-34 19 16 102 51 51
-34 19 15 102 51 51
-27 22 15 102 51 51
-39 27 14 42 22 4
-52 25 15 42 22 4
-47 19 17 102 51 51
-44 29 16 102 51 51
-51 25 15 42 22 4
-43 29 16 102 51 51
-47 5 16 50 50 50
-27 23 15 42 22 4
-50 5 16 50 50 50
-28 22 15 102 51 51
-26 22 16 102 51 51
-27 22 16 102 51 51
-28 28 17 102 51 51
-42 13 15 42 22 4
-40 19 15 255 227 49
-48 20 15 102 51 51
-42 14 15 42 22 4
-29 28 17 102 51 51
-47 19 16 102 51 51
-39 14 15 42 22 4
-40 14 15 42 22 4
-41 14 15 42 22 4
-43 13 15 42 22 4
-43 14 15 42 22 4
-41 19 15 102 51 51
-44 13 15 42 22 4
-28 20 17 102 51 51
-25 23 16 102 51 51
-44 14 15 42 22 4
-45 14 15 42 22 4
-36 19 16 102 51 51
-27 21 17 102 51 51
-44 12 16 42 22 4
-26 23 15 42 22 4
-42 19 15 102 51 51
-35 19 16 102 51 51
-41 21 14 42 22 4
-40 21 14 255 227 49
-39 21 14 255 227 49
-45 13 15 42 22 4
-41 12 16 42 22 4
-24 23 17 102 51 51
-47 26 18 102 51 51
-41 15 16 42 22 4
-47 14 15 42 22 4
-35 20 15 42 22 4
-36 20 15 42 22 4
-47 25 18 102 51 51
-30 29 17 102 51 51
-46 19 16 102 51 51
-47 24 18 102 51 51
-39 15 15 255 227 49
-38 19 16 102 51 51
-50 25 15 42 22 4
-38 20 15 42 22 4
-39 20 15 0 0 0
-40 15 15 255 227 49
-41 15 15 42 22 4
-43 19 15 102 51 51
-55 23 17 102 51 51
-38 12 16 0 0 153
-34 20 15 42 22 4
-35 19 15 102 51 51
-37 12 16 0 0 153
-36 19 15 102 51 51
-45 12 15 42 22 4
-38 21 14 42 22 4
-37 21 14 42 22 4
-44 12 15 42 22 4
-39 19 15 255 227 49
-38 19 15 102 51 51
-38 27 14 42 22 4
-36 21 14 42 22 4
-44 19 16 102 51 51
-35 21 14 42 22 4
-37 27 14 42 22 4
-53 23 15 42 22 4
-44 19 15 102 51 51
-43 12 15 42 22 4
-50 21 16 102 51 51
-49 20 16 102 51 51
-42 12 15 42 22 4
-45 20 15 42 22 4
-45 15 15 42 22 4
-51 21 16 102 51 51
-44 15 15 42 22 4
-42 12 16 50 50 50
-43 15 15 42 22 4
-42 15 15 42 22 4
-47 20 15 42 22 4
-41 12 15 42 22 4
-53 21 17 102 51 51
-43 19 16 102 51 51
-44 15 16 42 22 4
-46 20 15 42 22 4
-48 20 16 102 51 51
-54 22 17 102 51 51
-47 15 15 42 22 4
-48 19 17 102 51 51
-47 23 18 102 51 51
-44 20 15 42 22 4
-31 28 16 102 51 51
-39 13 15 42 22 4
-29 22 15 42 22 4
-40 13 15 42 22 4
-40 20 15 0 0 0
-41 13 15 42 22 4
-47 22 18 102 51 51
-26 21 17 102 51 51
-47 21 18 102 51 51
-48 26 18 102 51 51
-28 27 16 102 51 51
-47 19 15 102 51 51
-47 12 16 42 22 4
-46 19 15 102 51 51
-49 19 17 102 51 51
-30 28 16 102 51 51
-46 12 15 42 22 4
-46 15 15 42 22 4
-46 14 15 42 22 4
-46 13 15 42 22 4
-47 15 16 42 22 4
-32 29 16 102 51 51
-33 29 16 102 51 51
-25 22 17 102 51 51
-46 15 16 50 50 50
-45 15 16 50 50 50
-43 15 16 50 50 50
-42 15 16 50 50 50
-48 25 18 102 51 51
-50 20 17 102 51 51
-41 20 15 42 22 4
-48 24 18 102 51 51
-41 19 16 102 51 51
-48 23 18 102 51 51
-48 22 18 102 51 51
-31 29 17 102 51 51
-34 21 14 42 22 4
-29 27 16 102 51 51
-52 21 17 102 51 51
-31 23 14 42 22 4
-31 22 14 42 22 4
-46 12 16 50 50 50
-45 12 16 50 50 50
-32 21 14 42 22 4
-43 12 16 50 50 50
-27 27 17 102 51 51
-39 12 15 42 22 4
-51 20 17 102 51 51
-40 12 15 42 22 4
-29 24 16 0 204 0
-47 23 14 255 227 49
-43 27 16 255 255 255
-49 24 14 255 227 49
-50 24 16 102 51 51
-25 24 16 67 67 255
-46 22 14 255 227 49
-49 24 15 0 0 153
-26 24 16 0 0 153
-47 24 15 0 255 133
-49 26 15 42 22 4
-50 24 17 102 51 51
-28 24 30 168 168 168
-28 24 29 168 168 168
-28 24 28 168 168 168
-28 24 27 168 168 168
-28 24 26 168 168 168
-28 24 25 168 168 168
-28 24 24 168 168 168
-28 24 23 168 168 168
-28 24 22 168 168 168
-28 24 21 168 168 168
-28 24 20 168 168 168
-28 24 19 168 168 168
-28 24 18 168 168 168
-28 24 17 168 168 168
-28 24 16 168 168 167
-33 24 14 42 22 4
-34 24 14 42 22 4
-35 24 14 42 22 4
-36 24 14 42 22 4
-37 24 14 42 22 4
-38 24 14 255 227 48
-39 24 14 255 227 48
-40 24 14 255 227 48
-41 24 14 255 227 48
-42 24 14 42 22 4
-43 24 14 42 22 4
-44 24 14 42 22 4
-47 26 14 255 227 49
-46 25 14 255 227 49
-23 24 17 102 51 51
-24 24 16 102 51 51
-25 24 15 102 51 51
-26 24 15 42 22 4
-53 24 15 42 22 4
-54 24 15 42 22 4
-55 24 16 102 51 51
-56 24 17 102 51 51
-31 24 14 42 22 4
-32 24 14 42 22 4
-41 25 15 255 102 0
-27 24 15 42 22 4
-28 24 15 42 22 4
-29 24 15 42 22 4
-30 24 15 42 22 4
-50 24 15 42 22 4
-51 24 15 42 22 4
-52 24 15 42 22 4
-48 24 14 255 227 49
-50 22 15 42 22 4
-48 21 15 42 22 4
-44 27 15 255 255 255
-47 26 15 0 255 135
-47 27 15 168 168 167
-47 25 15 0 255 133
-48 27 17 102 51 51
-48 21 17 102 51 51
-49 25 15 67 67 255
-49 25 14 255 227 49
-38 24 15 255 102 0
-47 27 17 168 168 168
-47 22 14 255 227 49
-49 25 17 102 51 51
-50 25 16 102 51 51
-32 28 16 0 0 153
-26 25 16 67 67 255
-48 21 16 102 51 51
-32 27 15 0 0 153
-49 26 16 102 51 51
-49 26 17 102 51 51
-44 26 15 153 0 153
-39 24 15 221 0 0
-43 26 15 255 255 255
-33 27 15 67 67 255
-48 27 16 102 51 51
-47 21 17 168 168 168
-47 21 16 168 168 168
-47 21 15 168 168 167
-34 26 14 42 22 4
-35 26 14 42 22 4
-36 26 14 42 22 4
-37 26 14 42 22 4
-38 26 14 42 22 4
-39 26 14 42 22 4
-40 26 14 42 22 4
-41 26 14 42 22 4
-42 26 14 42 22 4
-43 26 14 42 22 4
-44 26 14 42 22 4
-47 25 14 255 227 49
-46 24 14 255 227 49
-33 25 14 42 22 4
-34 25 14 255 227 48
-35 25 14 255 227 48
-36 25 14 42 22 4
-37 25 14 42 22 4
-38 25 14 255 227 48
-39 25 14 255 227 48
-40 25 14 255 227 48
-41 25 14 255 227 48
-42 25 14 42 22 4
-43 25 14 42 22 4
-44 25 14 42 22 4
-47 24 14 255 227 49
-46 23 14 255 227 49
-34 29 15 102 51 51
-34 29 16 102 51 51
-27 26 15 102 51 51
-39 29 15 102 51 51
-38 29 15 102 51 51
-36 29 16 102 51 51
-35 29 16 102 51 51
-27 25 15 42 22 4
-27 26 16 102 51 51
-26 26 16 102 51 51
-36 29 15 102 51 51
-35 29 15 102 51 51
-42 29 15 102 51 51
-28 26 15 42 22 4
-29 26 15 42 22 4
-49 29 17 102 51 51
-51 27 16 102 51 51
-45 28 15 42 22 4
-36 28 15 42 22 4
-26 25 15 102 51 51
-24 25 17 102 51 51
-25 25 16 102 51 51
-34 28 15 42 22 4
-44 28 15 42 22 4
-42 29 16 102 51 51
-48 28 16 102 51 51
-40 28 15 42 22 4
-50 26 15 42 22 4
-51 26 15 42 22 4
-54 25 16 102 51 51
-55 25 17 102 51 51
-41 28 15 42 22 4
-42 28 15 42 22 4
-51 28 17 102 51 51
-46 28 15 42 22 4
-50 28 17 102 51 51
-35 28 15 42 22 4
-54 26 17 102 51 51
-47 29 17 102 51 51
-53 25 15 42 22 4
-47 28 15 42 22 4
-43 28 15 42 22 4
-44 29 15 102 51 51
-43 29 15 102 51 51
-41 29 16 102 51 51
-40 29 16 102 51 51
-39 28 15 42 22 4
-48 29 17 102 51 51
-38 28 15 42 22 4
-26 27 17 102 51 51
-32 29 17 102 51 51
-29 27 15 102 51 51
-31 28 15 102 51 51
-31 27 15 42 22 4
-30 27 15 42 22 4
-39 29 16 102 51 51
-38 29 16 102 51 51
-32 28 15 42 22 4
-25 26 17 102 51 51
-53 27 17 102 51 51
-37 28 15 42 22 4
-37 29 16 102 51 51
-37 29 15 102 51 51
-47 29 16 102 51 51
-46 29 16 102 51 51
-31 26 14 42 22 4
-31 25 14 42 22 4
-33 28 15 42 22 4
-49 27 15 42 22 4
-48 27 15 42 22 4
-32 27 14 42 22 4
-41 27 14 42 22 4
-48 28 15 102 51 51
-42 27 14 42 22 4
-43 27 14 42 22 4
-44 27 14 42 22 4
-45 27 14 42 22 4
-46 27 14 255 227 49
-53 26 16 102 51 51
-33 26 14 42 22 4
-52 26 16 102 51 51
-50 27 15 102 51 51
-47 29 15 102 51 51
-46 29 15 102 51 51
-49 28 16 102 51 51
-32 29 15 102 51 51
-33 29 15 102 51 51
-50 12 15 42 22 4
-49 12 15 42 22 4
-48 12 15 42 22 4
-50 13 15 42 22 4
-49 13 15 42 22 4
-48 13 15 42 22 4
-50 14 15 42 22 4
-49 14 15 42 22 4
-48 14 15 42 22 4
-50 15 15 42 22 4
-49 15 15 42 22 4
-48 15 15 42 22 4
-50 12 16 42 22 4
-50 13 16 50 50 50
-50 14 16 50 50 50
-50 15 16 42 22 4
-49 15 16 50 50 50
-48 15 16 50 50 50
-50 6 15 42 22 4
-49 6 15 42 22 4
-48 6 15 42 22 4
-47 6 15 42 22 4
-50 7 15 42 22 4
-49 7 15 42 22 4
-48 7 15 42 22 4
-47 7 15 42 22 4
-50 8 15 42 22 4
-49 8 15 42 22 4
-48 8 15 42 22 4
-47 8 15 42 22 4
-50 9 15 42 22 4
-49 9 15 42 22 4
-48 9 15 42 22 4
-47 9 15 42 22 4
-50 10 15 42 22 4
-49 10 15 42 22 4
-48 10 15 42 22 4
-47 10 15 42 22 4
-50 11 15 42 22 4
-49 11 15 42 22 4
-48 11 15 42 22 4
-47 11 15 42 22 4
-50 6 16 42 22 4
-47 6 16 42 22 4
-50 7 16 50 50 50
-47 7 16 50 50 50
-50 8 16 50 50 50
-47 8 16 50 50 50
-50 9 16 42 22 4
-47 9 16 42 22 4
-50 10 16 50 50 50
-47 10 16 50 50 50
-50 11 16 50 50 50
-47 11 16 50 50 50
-50 0 15 42 22 4
-49 0 15 42 22 4
-48 0 15 42 22 4
-47 0 15 42 22 4
-50 1 15 42 22 4
-49 1 15 42 22 4
-48 1 15 42 22 4
-47 1 15 42 22 4
-50 2 15 42 22 4
-49 2 15 42 22 4
-48 2 15 42 22 4
-47 2 15 42 22 4
-50 3 15 42 22 4
-49 3 15 42 22 4
-48 3 15 42 22 4
-47 3 15 42 22 4
-50 4 15 42 22 4
-49 4 15 42 22 4
-48 4 15 42 22 4
-47 4 15 42 22 4
-50 5 15 42 22 4
-49 5 15 42 22 4
-48 5 15 42 22 4
-47 5 15 42 22 4
-50 0 16 42 22 4
-47 0 16 42 22 4
-50 1 16 50 50 50
-47 1 16 50 50 50
-50 2 16 50 50 50
-47 2 16 50 50 50
-50 3 16 42 22 4
-47 3 16 42 22 4
-50 4 16 50 50 50
-47 4 16 50 50 50
-39 12 16 50 50 50
-40 12 16 50 50 50
