ply
format ascii 1.0
comment : MagicaVoxel @ Ephtracy
element vertex 666
property float x
property float y
property float z
property uchar red
property uchar green
property uchar blue
end_header
-40 16 15 42 22 4
-39 17 15 42 22 4
-40 17 15 42 22 4
-39 18 15 42 22 4
-40 18 15 42 22 4
-38 16 16 50 50 50
-41 16 16 50 50 50
-26 13 15 42 22 4
-27 15 16 50 50 50
-28 15 16 50 50 50
-26 12 16 42 22 4
-30 12 15 42 22 4
-41 17 16 50 50 50
-34 14 15 42 22 4
-41 18 16 50 50 50
-38 17 16 50 50 50
-38 18 16 50 50 50
-45 15 16 0 0 153
-46 14 16 67 67 255
-32 13 15 42 22 4
-45 15 15 42 22 4
-34 12 15 42 22 4
-46 15 15 42 22 4
-29 25 16 0 204 0
-46 14 15 42 22 4
-45 14 15 42 22 4
-41 13 15 42 22 4
-40 13 15 42 22 4
-20 12 16 42 22 4
-18 15 16 50 50 50
-38 18 15 42 22 4
-40 12 16 50 50 50
-35 12 15 42 22 4
-43 12 16 50 50 50
-38 12 15 42 22 4
-38 17 15 42 22 4
-39 12 15 42 22 4
-40 12 15 42 22 4
-41 12 15 42 22 4
-42 12 15 42 22 4
-19 15 16 50 50 50
-21 12 16 50 50 50
-43 15 16 0 0 153
-44 15 16 67 67 255
-46 13 16 0 0 153
-45 12 16 0 0 153
-38 16 15 42 22 4
-46 12 16 0 0 153
-35 15 16 42 22 4
-36 12 15 42 22 4
-28 14 15 42 22 4
-27 12 16 50 50 50
-32 14 15 42 22 4
-32 15 15 42 22 4
-33 15 15 42 22 4
-34 15 15 42 22 4
-42 13 15 42 22 4
-43 13 15 42 22 4
-37 12 15 42 22 4
-35 15 15 42 22 4
-36 15 15 42 22 4
-37 15 15 42 22 4
-39 15 15 42 22 4
-40 15 15 42 22 4
-41 15 15 42 22 4
-44 12 16 42 22 4
-43 15 15 42 22 4
-22 12 16 50 50 50
-22 12 15 42 22 4
-23 15 16 42 22 4
-20 15 15 42 22 4
-24 15 15 42 22 4
-25 15 16 50 50 50
-46 12 17 0 0 153
-27 13 15 42 22 4
-20 14 15 42 22 4
-19 14 15 42 22 4
-18 14 15 42 22 4
-33 12 15 42 22 4
-32 12 15 42 22 4
-41 14 15 42 22 4
-42 14 15 42 22 4
-31 12 15 42 22 4
-32 15 16 42 22 4
-33 15 16 50 50 50
-21 15 15 42 22 4
-17 12 16 42 22 4
-34 15 16 50 50 50
-29 12 15 42 22 4
-30 13 15 42 22 4
-32 12 16 42 22 4
-34 13 15 42 22 4
-28 13 15 42 22 4
-27 14 15 42 22 4
-33 12 16 50 50 50
-22 13 15 42 22 4
-26 14 15 42 22 4
-20 12 15 42 22 4
-25 13 15 42 22 4
-24 13 15 42 22 4
-23 13 15 42 22 4
-29 12 16 42 22 4
-38 15 16 42 22 4
-43 14 15 42 22 4
-44 14 15 42 22 4
-22 14 15 42 22 4
-28 12 16 50 50 50
-23 12 15 42 22 4
-34 12 16 50 50 50
-29 14 15 42 22 4
-30 15 15 42 22 4
-44 15 15 42 22 4
-31 15 16 50 50 50
-21 15 16 50 50 50
-41 16 15 42 22 4
-41 17 15 42 22 4
-30 12 16 50 50 50
-29 15 15 42 22 4
-31 15 15 42 22 4
-37 12 16 50 50 50
-18 12 16 50 50 50
-22 15 15 42 22 4
-36 12 16 50 50 50
-33 14 15 42 22 4
-35 12 16 42 22 4
-33 13 15 42 22 4
-37 15 16 50 50 50
-20 15 16 42 22 4
-23 14 15 42 22 4
-19 12 15 42 22 4
-36 15 16 50 50 50
-28 15 15 42 22 4
-18 12 15 42 22 4
-26 15 15 42 22 4
-17 12 15 42 22 4
-19 13 15 42 22 4
-28 12 15 42 22 4
-30 15 16 50 50 50
-21 13 15 42 22 4
-41 15 16 42 22 4
-40 14 15 42 22 4
-24 14 15 42 22 4
-23 12 16 42 22 4
-25 14 15 42 22 4
-24 12 16 50 50 50
-25 12 16 50 50 50
-23 15 15 42 22 4
-25 15 15 42 22 4
-29 15 16 42 22 4
-27 15 15 42 22 4
-42 12 16 50 50 50
-31 13 15 42 22 4
-27 12 15 42 22 4
-24 15 16 50 50 50
-39 14 15 42 22 4
-19 12 16 50 50 50
-20 13 15 42 22 4
-17 14 15 42 22 4
-38 14 15 42 22 4
-37 14 15 42 22 4
-36 14 15 42 22 4
-17 15 15 42 22 4
-41 18 15 42 22 4
-39 16 15 42 22 4
-21 12 15 42 22 4
-31 14 15 42 22 4
-29 13 15 42 22 4
-35 14 15 42 22 4
-31 12 16 50 50 50
-30 14 15 42 22 4
-21 14 15 42 22 4
-24 12 15 42 22 4
-25 12 15 42 22 4
-43 12 15 42 22 4
-18 15 15 42 22 4
-19 15 15 42 22 4
-17 13 15 42 22 4
-18 13 15 42 22 4
-39 13 15 42 22 4
-38 13 15 42 22 4
-37 13 15 42 22 4
-36 13 15 42 22 4
-35 13 15 42 22 4
-42 15 15 42 22 4
-41 12 16 42 22 4
-44 12 15 42 22 4
-38 12 16 42 22 4
-26 12 15 42 22 4
-39 12 16 50 50 50
-42 15 16 0 0 153
-46 13 15 42 22 4
-22 15 16 50 50 50
-17 15 16 42 22 4
-45 13 15 42 22 4
-44 13 15 42 22 4
-26 15 16 42 22 4
-46 12 15 42 22 4
-45 12 15 42 22 4
-34 30 15 102 51 51
-34 30 16 102 51 51
-37 19 15 102 51 51
-37 19 16 102 51 51
-37 20 15 42 22 4
-43 20 15 42 22 4
-34 19 16 102 51 51
-34 19 15 102 51 51
-27 22 15 102 51 51
-27 27 15 102 51 51
-39 30 15 102 51 51
-47 19 17 102 51 51
-38 30 15 102 51 51
-50 21 15 102 51 51
-36 30 16 102 51 51
-35 30 16 102 51 51
-27 23 15 42 22 4
-27 26 15 42 22 4
-28 22 15 102 51 51
-26 22 16 102 51 51
-27 22 16 102 51 51
-27 27 16 102 51 51
-26 27 16 102 51 51
-40 19 15 102 51 51
-48 20 15 102 51 51
-36 30 15 102 51 51
-35 30 15 102 51 51
-47 19 16 102 51 51
-42 30 15 102 51 51
-28 27 15 102 51 51
-29 27 15 42 22 4
-49 30 17 102 51 51
-51 28 16 102 51 51
-41 19 15 102 51 51
-45 29 15 42 22 4
-24 24 16 102 51 51
-25 23 16 102 51 51
-36 29 15 42 22 4
-26 26 15 102 51 51
-36 19 16 102 51 51
-25 24 15 102 51 51
-26 24 15 42 22 4
-26 23 15 102 51 51
-23 25 17 102 51 51
-35 19 16 102 51 51
-24 25 16 102 51 51
-25 25 15 102 51 51
-26 25 15 42 22 4
-24 26 17 102 51 51
-25 26 16 102 51 51
-24 23 17 102 51 51
-23 24 17 102 51 51
-34 29 15 42 22 4
-44 29 15 42 22 4
-35 20 15 42 22 4
-36 20 15 42 22 4
-56 24 17 102 51 51
-42 30 16 102 51 51
-46 19 16 102 51 51
-55 24 16 102 51 51
-48 29 16 102 51 51
-38 19 16 102 51 51
-49 21 15 102 51 51
-38 20 15 42 22 4
-39 20 15 0 0 0
-40 29 15 42 22 4
-50 27 15 42 22 4
-43 19 15 102 51 51
-55 23 17 102 51 51
-51 27 15 102 51 51
-34 20 15 42 22 4
-35 19 15 102 51 51
-54 26 16 102 51 51
-36 19 15 102 51 51
-55 26 17 102 51 51
-53 25 15 42 22 4
-54 25 15 102 51 51
-41 29 15 42 22 4
-39 19 15 102 51 51
-38 19 15 102 51 51
-50 22 15 42 22 4
-55 25 16 102 51 51
-44 19 16 102 51 51
-56 25 17 102 51 51
-48 21 15 42 22 4
-53 23 15 102 51 51
-44 19 15 102 51 51
-42 29 15 42 22 4
-50 21 16 102 51 51
-49 20 16 102 51 51
-51 29 17 102 51 51
-45 20 15 42 22 4
-46 29 15 42 22 4
-51 21 16 102 51 51
-50 29 17 102 51 51
-53 24 15 42 22 4
-35 29 15 42 22 4
-54 27 17 102 51 51
-47 20 15 42 22 4
-54 24 15 102 51 51
-53 21 17 102 51 51
-43 19 16 102 51 51
-47 30 17 102 51 51
-46 20 15 42 22 4
-48 20 16 102 51 51
-54 22 17 102 51 51
-53 26 15 102 51 51
-48 19 17 102 51 51
-47 29 15 42 22 4
-44 20 15 42 22 4
-43 29 15 42 22 4
-44 30 15 102 51 51
-29 22 15 42 22 4
-43 30 15 102 51 51
-40 20 15 0 0 0
-41 30 16 102 51 51
-40 30 16 102 51 51
-26 21 17 102 51 51
-39 29 15 42 22 4
-48 30 17 102 51 51
-38 29 15 42 22 4
-47 19 15 102 51 51
-26 28 17 102 51 51
-46 19 15 102 51 51
-49 19 17 102 51 51
-32 30 17 102 51 51
-29 28 15 102 51 51
-31 29 15 102 51 51
-31 28 15 42 22 4
-30 28 15 102 51 51
-39 30 16 102 51 51
-38 30 16 102 51 51
-32 29 15 42 22 4
-25 22 17 102 51 51
-25 27 17 102 51 51
-53 28 17 102 51 51
-37 29 15 42 22 4
-37 30 16 102 51 51
-37 30 15 102 51 51
-50 20 17 102 51 51
-41 20 15 42 22 4
-47 30 16 102 51 51
-41 19 16 102 51 51
-46 30 16 102 51 51
-31 27 14 42 22 4
-31 26 14 42 22 4
-31 25 14 42 22 4
-33 29 15 42 22 4
-31 24 14 42 22 4
-31 23 14 42 22 4
-31 22 14 42 22 4
-49 28 15 102 51 51
-48 28 15 42 22 4
-32 21 14 42 22 4
-32 28 14 42 22 4
-41 28 14 42 22 4
-48 29 15 102 51 51
-51 20 17 102 51 51
-42 28 14 42 22 4
-52 21 17 102 51 51
-43 28 14 42 22 4
-44 28 14 42 22 4
-45 28 14 42 22 4
-46 28 14 42 22 4
-53 27 16 102 51 51
-33 27 14 42 22 4
-27 21 17 102 51 51
-28 20 17 102 51 51
-29 20 17 102 51 51
-30 19 17 102 51 51
-33 19 15 102 51 51
-32 19 15 102 51 51
-52 27 16 102 51 51
-52 22 16 102 51 51
-50 28 15 102 51 51
-31 19 17 102 51 51
-31 20 16 102 51 51
-33 20 15 42 22 4
-32 20 15 42 22 4
-28 21 16 102 51 51
-30 20 16 102 51 51
-29 21 16 102 51 51
-31 21 15 42 22 4
-30 21 15 102 51 51
-47 30 15 102 51 51
-46 30 15 102 51 51
-33 19 16 102 51 51
-32 19 16 102 51 51
-31 20 15 102 51 51
-29 21 15 102 51 51
-32 19 17 102 51 51
-54 23 16 102 51 51
-49 29 16 102 51 51
-32 30 15 102 51 51
-33 30 15 102 51 51
-27 28 17 102 51 51
-29 28 16 102 51 51
-31 30 17 102 51 51
-33 30 16 102 51 51
-32 30 16 102 51 51
-30 29 16 102 51 51
-28 28 16 102 51 51
-31 29 16 102 51 51
-30 30 17 102 51 51
-29 29 17 102 51 51
-28 29 17 102 51 51
-45 30 15 102 51 51
-45 30 16 102 51 51
-42 19 15 102 51 51
-42 19 16 102 51 51
-42 20 15 42 22 4
-53 22 16 102 51 51
-45 19 16 102 51 51
-45 19 15 102 51 51
-52 22 15 102 51 51
-52 27 15 102 51 51
-40 30 15 102 51 51
-52 28 17 102 51 51
-41 30 15 102 51 51
-50 28 16 102 51 51
-43 30 16 102 51 51
-44 30 16 102 51 51
-52 23 15 42 22 4
-52 26 15 42 22 4
-51 22 15 102 51 51
-39 28 14 42 22 4
-27 25 15 42 22 4
-28 25 15 42 22 4
-29 25 15 42 22 4
-30 25 15 42 22 4
-48 27 14 42 22 4
-28 23 15 42 22 4
-29 23 15 42 22 4
-33 28 14 42 22 4
-40 26 15 255 102 0
-50 25 15 42 22 4
-51 25 15 42 22 4
-52 25 15 42 22 4
-27 24 15 42 22 4
-28 24 15 42 22 4
-47 21 14 42 22 4
-49 22 15 42 22 4
-34 28 14 42 22 4
-30 23 15 42 22 4
-29 24 15 42 22 4
-30 24 15 42 22 4
-48 26 14 42 22 4
-48 25 14 42 22 4
-40 28 14 42 22 4
-35 28 14 42 22 4
-39 23 15 255 102 0
-50 24 15 42 22 4
-51 24 15 42 22 4
-52 24 15 42 22 4
-28 26 15 42 22 4
-29 26 15 42 22 4
-30 26 15 42 22 4
-48 24 14 42 22 4
-47 28 14 42 22 4
-30 22 15 42 22 4
-48 23 14 42 22 4
-51 23 15 42 22 4
-50 23 15 42 22 4
-40 23 15 255 102 0
-36 28 14 42 22 4
-49 27 15 42 22 4
-37 28 14 42 22 4
-48 22 14 42 22 4
-38 28 14 42 22 4
-34 23 15 221 0 0
-50 26 15 42 22 4
-51 26 15 42 22 4
-30 27 15 42 22 4
-47 22 14 42 22 4
-32 22 14 42 22 4
-47 23 14 42 22 4
-32 23 14 42 22 4
-47 24 14 42 22 4
-32 24 14 42 22 4
-47 25 14 42 22 4
-32 25 14 42 22 4
-47 26 14 42 22 4
-32 26 14 42 22 4
-47 27 14 42 22 4
-32 27 14 42 22 4
-46 21 14 42 22 4
-45 21 14 42 22 4
-44 21 14 42 22 4
-43 21 14 42 22 4
-42 21 14 42 22 4
-41 21 14 42 22 4
-40 21 14 42 22 4
-39 21 14 42 22 4
-38 21 14 42 22 4
-37 21 14 42 22 4
-36 21 14 42 22 4
-35 21 14 42 22 4
-34 21 14 42 22 4
-33 21 14 42 22 4
-46 22 14 42 22 4
-45 22 14 42 22 4
-44 22 14 42 22 4
-43 22 14 42 22 4
-42 22 14 42 22 4
-41 22 14 42 22 4
-40 22 14 42 22 4
-39 22 14 42 22 4
-38 22 14 42 22 4
-37 22 14 42 22 4
-36 22 14 42 22 4
-35 22 14 42 22 4
-34 22 14 42 22 4
-33 22 14 42 22 4
-46 23 14 42 22 4
-45 23 14 42 22 4
-44 23 14 42 22 4
-43 23 14 42 22 4
-42 23 14 42 22 4
-41 23 14 42 22 4
-40 23 14 42 22 4
-39 23 14 42 22 4
-38 23 14 42 22 4
-37 23 14 42 22 4
-36 23 14 42 22 4
-35 23 14 42 22 4
-34 23 14 42 22 4
-33 23 14 42 22 4
-46 24 14 42 22 4
-45 24 14 42 22 4
-44 24 14 42 22 4
-43 24 14 42 22 4
-42 24 14 42 22 4
-41 24 14 42 22 4
-40 24 14 42 22 4
-39 24 14 42 22 4
-38 24 14 42 22 4
-37 24 14 42 22 4
-36 24 14 42 22 4
-35 24 14 42 22 4
-34 24 14 42 22 4
-33 24 14 42 22 4
-46 25 14 42 22 4
-45 25 14 42 22 4
-44 25 14 42 22 4
-43 25 14 42 22 4
-42 25 14 42 22 4
-41 25 14 42 22 4
-40 25 14 42 22 4
-39 25 14 42 22 4
-38 25 14 42 22 4
-37 25 14 42 22 4
-36 25 14 42 22 4
-35 25 14 42 22 4
-34 25 14 42 22 4
-33 25 14 42 22 4
-46 26 14 42 22 4
-45 26 14 42 22 4
-44 26 14 42 22 4
-43 26 14 42 22 4
-42 26 14 42 22 4
-41 26 14 42 22 4
-40 26 14 42 22 4
-39 26 14 42 22 4
-38 26 14 42 22 4
-37 26 14 42 22 4
-36 26 14 42 22 4
-35 26 14 42 22 4
-34 26 14 42 22 4
-33 26 14 42 22 4
-46 27 14 42 22 4
-45 27 14 42 22 4
-44 27 14 42 22 4
-43 27 14 42 22 4
-42 27 14 42 22 4
-41 27 14 42 22 4
-40 27 14 42 22 4
-39 27 14 42 22 4
-38 27 14 42 22 4
-37 27 14 42 22 4
-36 27 14 42 22 4
-35 27 14 42 22 4
-34 27 14 42 22 4
-28 25 16 168 168 167
-28 25 17 168 168 168
-28 25 18 168 168 168
-28 25 19 168 168 168
-28 25 20 168 168 168
-28 25 21 168 168 168
-28 25 22 168 168 168
-28 25 23 168 168 168
-28 25 24 168 168 168
-28 25 25 168 168 168
-28 25 26 168 168 168
-28 25 27 168 168 168
-28 25 28 168 168 168
-28 25 29 168 168 168
-28 25 30 168 168 168
-48 22 15 168 168 167
-48 27 15 168 168 167
-48 22 16 168 168 168
-48 22 17 168 168 168
-48 27 16 168 168 168
-48 27 17 168 168 168
-38 15 15 42 22 4
-50 25 17 102 51 51
-48 25 18 102 51 51
-47 26 15 0 255 135
-47 25 15 0 255 133
-47 24 15 0 255 133
-47 23 15 0 255 134
-38 20 16 0 204 0
-41 20 16 0 204 0
-33 28 15 67 67 255
-48 27 18 102 51 51
-49 22 17 102 51 51
-49 22 16 102 51 51
-33 26 15 255 102 0
-48 26 18 102 51 51
-49 27 17 102 51 51
-49 27 16 102 51 51
-39 26 15 255 102 0
-33 23 15 255 102 0
-32 28 15 0 0 153
-49 23 18 102 51 51
-49 24 18 102 51 51
-48 23 18 102 51 51
-47 22 15 0 204 0
-26 25 16 0 0 153
-44 20 16 67 67 255
-31 22 15 67 67 255
-32 21 15 67 67 255
-49 25 15 0 0 153
-46 28 15 67 67 255
-46 15 16 42 22 4
-26 26 16 67 67 255
-32 29 16 0 0 153
-50 26 16 102 51 51
-48 22 18 102 51 51
-49 25 18 102 51 51
-50 24 17 102 51 51
-48 24 18 102 51 51
-49 26 17 102 51 51
-49 26 18 102 51 51
-50 23 16 102 51 51
-25 25 16 67 67 255
-28 22 16 0 0 153
-49 23 17 102 51 51
-50 25 16 102 51 51
-50 24 16 102 51 51
-40 25 15 221 0 0
-39 25 15 221 0 0
-40 24 15 221 0 0
-39 24 15 221 0 0
-34 26 15 221 0 0
-49 23 14 42 22 4
-49 24 14 42 22 4
-49 25 14 42 22 4
-49 26 14 42 22 4
-49 26 15 67 67 255
-47 27 15 0 204 0
-44 21 15 0 0 153
-45 20 16 0 0 153
-44 27 15 153 0 153
-44 28 15 255 255 255
-45 28 15 255 255 255
-45 27 15 255 255 255
-45 28 16 255 255 255
-44 28 16 255 255 255
