ply
format ascii 1.0
comment : MagicaVoxel @ Ephtracy
element vertex 666
property float x
property float y
property float z
property uchar red
property uchar green
property uchar blue
end_header
-3 -5 1 42 22 4
-2 -4 1 42 22 4
-3 -4 1 42 22 4
-2 -3 1 42 22 4
-3 -3 1 42 22 4
-1 -5 2 50 50 50
-4 -5 2 50 50 50
11 -8 1 42 22 4
10 -6 2 50 50 50
9 -6 2 50 50 50
11 -9 2 42 22 4
7 -9 1 42 22 4
-4 -4 2 50 50 50
3 -7 1 42 22 4
-4 -3 2 50 50 50
-1 -4 2 50 50 50
-1 -3 2 50 50 50
-8 -6 2 0 0 153
-9 -7 2 67 67 255
5 -8 1 42 22 4
-8 -6 1 42 22 4
3 -9 1 42 22 4
-9 -6 1 42 22 4
8 4 2 0 204 0
-9 -7 1 42 22 4
-8 -7 1 42 22 4
-4 -8 1 42 22 4
-3 -8 1 42 22 4
17 -9 2 42 22 4
19 -6 2 50 50 50
-1 -3 1 42 22 4
-3 -9 2 50 50 50
2 -9 1 42 22 4
-6 -9 2 50 50 50
-1 -9 1 42 22 4
-1 -4 1 42 22 4
-2 -9 1 42 22 4
-3 -9 1 42 22 4
-4 -9 1 42 22 4
-5 -9 1 42 22 4
18 -6 2 50 50 50
16 -9 2 50 50 50
-6 -6 2 0 0 153
-7 -6 2 67 67 255
-9 -8 2 0 0 153
-8 -9 2 0 0 153
-1 -5 1 42 22 4
-9 -9 2 0 0 153
2 -6 2 42 22 4
1 -9 1 42 22 4
9 -7 1 42 22 4
10 -9 2 50 50 50
5 -7 1 42 22 4
5 -6 1 42 22 4
4 -6 1 42 22 4
3 -6 1 42 22 4
-5 -8 1 42 22 4
-6 -8 1 42 22 4
0 -9 1 42 22 4
2 -6 1 42 22 4
1 -6 1 42 22 4
0 -6 1 42 22 4
-2 -6 1 42 22 4
-3 -6 1 42 22 4
-4 -6 1 42 22 4
-7 -9 2 42 22 4
-6 -6 1 42 22 4
15 -9 2 50 50 50
15 -9 1 42 22 4
14 -6 2 42 22 4
17 -6 1 42 22 4
13 -6 1 42 22 4
12 -6 2 50 50 50
-9 -9 3 0 0 153
10 -8 1 42 22 4
17 -7 1 42 22 4
18 -7 1 42 22 4
19 -7 1 42 22 4
4 -9 1 42 22 4
5 -9 1 42 22 4
-4 -7 1 42 22 4
-5 -7 1 42 22 4
6 -9 1 42 22 4
5 -6 2 42 22 4
4 -6 2 50 50 50
16 -6 1 42 22 4
20 -9 2 42 22 4
3 -6 2 50 50 50
8 -9 1 42 22 4
7 -8 1 42 22 4
5 -9 2 42 22 4
3 -8 1 42 22 4
9 -8 1 42 22 4
10 -7 1 42 22 4
4 -9 2 50 50 50
15 -8 1 42 22 4
11 -7 1 42 22 4
17 -9 1 42 22 4
12 -8 1 42 22 4
13 -8 1 42 22 4
14 -8 1 42 22 4
8 -9 2 42 22 4
-1 -6 2 42 22 4
-6 -7 1 42 22 4
-7 -7 1 42 22 4
15 -7 1 42 22 4
9 -9 2 50 50 50
14 -9 1 42 22 4
3 -9 2 50 50 50
8 -7 1 42 22 4
7 -6 1 42 22 4
-7 -6 1 42 22 4
6 -6 2 50 50 50
16 -6 2 50 50 50
-4 -5 1 42 22 4
-4 -4 1 42 22 4
7 -9 2 50 50 50
8 -6 1 42 22 4
6 -6 1 42 22 4
0 -9 2 50 50 50
19 -9 2 50 50 50
15 -6 1 42 22 4
1 -9 2 50 50 50
4 -7 1 42 22 4
2 -9 2 42 22 4
4 -8 1 42 22 4
0 -6 2 50 50 50
17 -6 2 42 22 4
14 -7 1 42 22 4
18 -9 1 42 22 4
1 -6 2 50 50 50
9 -6 1 42 22 4
19 -9 1 42 22 4
11 -6 1 42 22 4
20 -9 1 42 22 4
18 -8 1 42 22 4
9 -9 1 42 22 4
7 -6 2 50 50 50
16 -8 1 42 22 4
-4 -6 2 42 22 4
-3 -7 1 42 22 4
13 -7 1 42 22 4
14 -9 2 42 22 4
12 -7 1 42 22 4
13 -9 2 50 50 50
12 -9 2 50 50 50
14 -6 1 42 22 4
12 -6 1 42 22 4
8 -6 2 42 22 4
10 -6 1 42 22 4
-5 -9 2 50 50 50
6 -8 1 42 22 4
10 -9 1 42 22 4
13 -6 2 50 50 50
-2 -7 1 42 22 4
18 -9 2 50 50 50
17 -8 1 42 22 4
20 -7 1 42 22 4
-1 -7 1 42 22 4
0 -7 1 42 22 4
1 -7 1 42 22 4
20 -6 1 42 22 4
-4 -3 1 42 22 4
-2 -5 1 42 22 4
16 -9 1 42 22 4
6 -7 1 42 22 4
8 -8 1 42 22 4
2 -7 1 42 22 4
6 -9 2 50 50 50
7 -7 1 42 22 4
16 -7 1 42 22 4
13 -9 1 42 22 4
12 -9 1 42 22 4
-6 -9 1 42 22 4
19 -6 1 42 22 4
18 -6 1 42 22 4
20 -8 1 42 22 4
19 -8 1 42 22 4
-2 -8 1 42 22 4
-1 -8 1 42 22 4
0 -8 1 42 22 4
1 -8 1 42 22 4
2 -8 1 42 22 4
-5 -6 1 42 22 4
-4 -9 2 42 22 4
-7 -9 1 42 22 4
-1 -9 2 42 22 4
11 -9 1 42 22 4
-2 -9 2 50 50 50
-5 -6 2 0 0 153
-9 -8 1 42 22 4
15 -6 2 50 50 50
20 -6 2 42 22 4
-8 -8 1 42 22 4
-7 -8 1 42 22 4
11 -6 2 42 22 4
-9 -9 1 42 22 4
-8 -9 1 42 22 4
3 9 1 102 51 51
3 9 2 102 51 51
0 -2 1 102 51 51
0 -2 2 102 51 51
0 -1 1 42 22 4
-6 -1 1 42 22 4
3 -2 2 102 51 51
3 -2 1 102 51 51
10 1 1 102 51 51
10 6 1 102 51 51
-2 9 1 102 51 51
-10 -2 3 102 51 51
-1 9 1 102 51 51
-13 0 1 102 51 51
1 9 2 102 51 51
2 9 2 102 51 51
10 2 1 42 22 4
10 5 1 42 22 4
9 1 1 102 51 51
11 1 2 102 51 51
10 1 2 102 51 51
10 6 2 102 51 51
11 6 2 102 51 51
-3 -2 1 102 51 51
-11 -1 1 102 51 51
1 9 1 102 51 51
2 9 1 102 51 51
-10 -2 2 102 51 51
-5 9 1 102 51 51
9 6 1 102 51 51
8 6 1 42 22 4
-12 9 3 102 51 51
-14 7 2 102 51 51
-4 -2 1 102 51 51
-8 8 1 42 22 4
13 3 2 102 51 51
12 2 2 102 51 51
1 8 1 42 22 4
11 5 1 102 51 51
1 -2 2 102 51 51
12 3 1 102 51 51
11 3 1 42 22 4
11 2 1 102 51 51
14 4 3 102 51 51
2 -2 2 102 51 51
13 4 2 102 51 51
12 4 1 102 51 51
11 4 1 42 22 4
13 5 3 102 51 51
12 5 2 102 51 51
13 2 3 102 51 51
14 3 3 102 51 51
3 8 1 42 22 4
-7 8 1 42 22 4
2 -1 1 42 22 4
1 -1 1 42 22 4
-19 3 3 102 51 51
-5 9 2 102 51 51
-9 -2 2 102 51 51
-18 3 2 102 51 51
-11 8 2 102 51 51
-1 -2 2 102 51 51
-12 0 1 102 51 51
-1 -1 1 42 22 4
-2 -1 1 0 0 0
-3 8 1 42 22 4
-13 6 1 42 22 4
-6 -2 1 102 51 51
-18 2 3 102 51 51
-14 6 1 102 51 51
3 -1 1 42 22 4
2 -2 1 102 51 51
-17 5 2 102 51 51
1 -2 1 102 51 51
-18 5 3 102 51 51
-16 4 1 42 22 4
-17 4 1 102 51 51
-4 8 1 42 22 4
-2 -2 1 102 51 51
-1 -2 1 102 51 51
-13 1 1 42 22 4
-18 4 2 102 51 51
-7 -2 2 102 51 51
-19 4 3 102 51 51
-11 0 1 42 22 4
-16 2 1 102 51 51
-7 -2 1 102 51 51
-5 8 1 42 22 4
-13 0 2 102 51 51
-12 -1 2 102 51 51
-14 8 3 102 51 51
-8 -1 1 42 22 4
-9 8 1 42 22 4
-14 0 2 102 51 51
-13 8 3 102 51 51
-16 3 1 42 22 4
2 8 1 42 22 4
-17 6 3 102 51 51
-10 -1 1 42 22 4
-17 3 1 102 51 51
-16 0 3 102 51 51
-6 -2 2 102 51 51
-10 9 3 102 51 51
-9 -1 1 42 22 4
-11 -1 2 102 51 51
-17 1 3 102 51 51
-16 5 1 102 51 51
-11 -2 3 102 51 51
-10 8 1 42 22 4
-7 -1 1 42 22 4
-6 8 1 42 22 4
-7 9 1 102 51 51
8 1 1 42 22 4
-6 9 1 102 51 51
-3 -1 1 0 0 0
-4 9 2 102 51 51
-3 9 2 102 51 51
11 0 3 102 51 51
-2 8 1 42 22 4
-11 9 3 102 51 51
-1 8 1 42 22 4
-10 -2 1 102 51 51
11 7 3 102 51 51
-9 -2 1 102 51 51
-12 -2 3 102 51 51
5 9 3 102 51 51
8 7 1 102 51 51
6 8 1 102 51 51
6 7 1 42 22 4
7 7 1 102 51 51
-2 9 2 102 51 51
-1 9 2 102 51 51
5 8 1 42 22 4
12 1 3 102 51 51
12 6 3 102 51 51
-16 7 3 102 51 51
0 8 1 42 22 4
0 9 2 102 51 51
0 9 1 102 51 51
-13 -1 3 102 51 51
-4 -1 1 42 22 4
-10 9 2 102 51 51
-4 -2 2 102 51 51
-9 9 2 102 51 51
6 6 0 42 22 4
6 5 0 42 22 4
6 4 0 42 22 4
4 8 1 42 22 4
6 3 0 42 22 4
6 2 0 42 22 4
6 1 0 42 22 4
-12 7 1 102 51 51
-11 7 1 42 22 4
5 0 0 42 22 4
5 7 0 42 22 4
-4 7 0 42 22 4
-11 8 1 102 51 51
-14 -1 3 102 51 51
-5 7 0 42 22 4
-15 0 3 102 51 51
-6 7 0 42 22 4
-7 7 0 42 22 4
-8 7 0 42 22 4
-9 7 0 42 22 4
-16 6 2 102 51 51
4 6 0 42 22 4
10 0 3 102 51 51
9 -1 3 102 51 51
8 -1 3 102 51 51
7 -2 3 102 51 51
4 -2 1 102 51 51
5 -2 1 102 51 51
-15 6 2 102 51 51
-15 1 2 102 51 51
-13 7 1 102 51 51
6 -2 3 102 51 51
6 -1 2 102 51 51
4 -1 1 42 22 4
5 -1 1 42 22 4
9 0 2 102 51 51
7 -1 2 102 51 51
8 0 2 102 51 51
6 0 1 42 22 4
7 0 1 102 51 51
-10 9 1 102 51 51
-9 9 1 102 51 51
4 -2 2 102 51 51
5 -2 2 102 51 51
6 -1 1 102 51 51
8 0 1 102 51 51
5 -2 3 102 51 51
-17 2 2 102 51 51
-12 8 2 102 51 51
5 9 1 102 51 51
4 9 1 102 51 51
10 7 3 102 51 51
8 7 2 102 51 51
6 9 3 102 51 51
4 9 2 102 51 51
5 9 2 102 51 51
7 8 2 102 51 51
9 7 2 102 51 51
6 8 2 102 51 51
7 9 3 102 51 51
8 8 3 102 51 51
9 8 3 102 51 51
-8 9 1 102 51 51
-8 9 2 102 51 51
-5 -2 1 102 51 51
-5 -2 2 102 51 51
-5 -1 1 42 22 4
-16 1 2 102 51 51
-8 -2 2 102 51 51
-8 -2 1 102 51 51
-15 1 1 102 51 51
-15 6 1 102 51 51
-3 9 1 102 51 51
-15 7 3 102 51 51
-4 9 1 102 51 51
-13 7 2 102 51 51
-6 9 2 102 51 51
-7 9 2 102 51 51
-15 2 1 42 22 4
-15 5 1 42 22 4
-14 1 1 102 51 51
-2 7 0 42 22 4
10 4 1 42 22 4
9 4 1 42 22 4
8 4 1 42 22 4
7 4 1 42 22 4
-11 6 0 42 22 4
9 2 1 42 22 4
8 2 1 42 22 4
4 7 0 42 22 4
-3 5 1 255 102 0
-13 4 1 42 22 4
-14 4 1 42 22 4
-15 4 1 42 22 4
10 3 1 42 22 4
9 3 1 42 22 4
-10 0 0 42 22 4
-12 1 1 42 22 4
3 7 0 42 22 4
7 2 1 42 22 4
8 3 1 42 22 4
7 3 1 42 22 4
-11 5 0 42 22 4
-11 4 0 42 22 4
-3 7 0 42 22 4
2 7 0 42 22 4
-2 2 1 255 102 0
-13 3 1 42 22 4
-14 3 1 42 22 4
-15 3 1 42 22 4
9 5 1 42 22 4
8 5 1 42 22 4
7 5 1 42 22 4
-11 3 0 42 22 4
-10 7 0 42 22 4
7 1 1 42 22 4
-11 2 0 42 22 4
-14 2 1 42 22 4
-13 2 1 42 22 4
-3 2 1 255 102 0
1 7 0 42 22 4
-12 6 1 42 22 4
0 7 0 42 22 4
-11 1 0 42 22 4
-1 7 0 42 22 4
3 2 1 221 0 0
-13 5 1 42 22 4
-14 5 1 42 22 4
7 6 1 42 22 4
-10 1 0 42 22 4
5 1 0 42 22 4
-10 2 0 42 22 4
5 2 0 42 22 4
-10 3 0 42 22 4
5 3 0 42 22 4
-10 4 0 42 22 4
5 4 0 42 22 4
-10 5 0 42 22 4
5 5 0 42 22 4
-10 6 0 42 22 4
5 6 0 42 22 4
-9 0 0 42 22 4
-8 0 0 42 22 4
-7 0 0 42 22 4
-6 0 0 42 22 4
-5 0 0 42 22 4
-4 0 0 42 22 4
-3 0 0 42 22 4
-2 0 0 42 22 4
-1 0 0 42 22 4
0 0 0 42 22 4
1 0 0 42 22 4
2 0 0 42 22 4
3 0 0 42 22 4
4 0 0 42 22 4
-9 1 0 42 22 4
-8 1 0 42 22 4
-7 1 0 42 22 4
-6 1 0 42 22 4
-5 1 0 42 22 4
-4 1 0 42 22 4
-3 1 0 42 22 4
-2 1 0 42 22 4
-1 1 0 42 22 4
0 1 0 42 22 4
1 1 0 42 22 4
2 1 0 42 22 4
3 1 0 42 22 4
4 1 0 42 22 4
-9 2 0 42 22 4
-8 2 0 42 22 4
-7 2 0 42 22 4
-6 2 0 42 22 4
-5 2 0 42 22 4
-4 2 0 42 22 4
-3 2 0 42 22 4
-2 2 0 42 22 4
-1 2 0 42 22 4
0 2 0 42 22 4
1 2 0 42 22 4
2 2 0 42 22 4
3 2 0 42 22 4
4 2 0 42 22 4
-9 3 0 42 22 4
-8 3 0 42 22 4
-7 3 0 42 22 4
-6 3 0 42 22 4
-5 3 0 42 22 4
-4 3 0 42 22 4
-3 3 0 42 22 4
-2 3 0 42 22 4
-1 3 0 42 22 4
0 3 0 42 22 4
1 3 0 42 22 4
2 3 0 42 22 4
3 3 0 42 22 4
4 3 0 42 22 4
-9 4 0 42 22 4
-8 4 0 42 22 4
-7 4 0 42 22 4
-6 4 0 42 22 4
-5 4 0 42 22 4
-4 4 0 42 22 4
-3 4 0 42 22 4
-2 4 0 42 22 4
-1 4 0 42 22 4
0 4 0 42 22 4
1 4 0 42 22 4
2 4 0 42 22 4
3 4 0 42 22 4
4 4 0 42 22 4
-9 5 0 42 22 4
-8 5 0 42 22 4
-7 5 0 42 22 4
-6 5 0 42 22 4
-5 5 0 42 22 4
-4 5 0 42 22 4
-3 5 0 42 22 4
-2 5 0 42 22 4
-1 5 0 42 22 4
0 5 0 42 22 4
1 5 0 42 22 4
2 5 0 42 22 4
3 5 0 42 22 4
4 5 0 42 22 4
-9 6 0 42 22 4
-8 6 0 42 22 4
-7 6 0 42 22 4
-6 6 0 42 22 4
-5 6 0 42 22 4
-4 6 0 42 22 4
-3 6 0 42 22 4
-2 6 0 42 22 4
-1 6 0 42 22 4
0 6 0 42 22 4
1 6 0 42 22 4
2 6 0 42 22 4
3 6 0 42 22 4
9 4 2 168 168 167
9 4 3 168 168 168
9 4 4 168 168 168
9 4 5 168 168 168
9 4 6 168 168 168
9 4 7 168 168 168
9 4 8 168 168 168
9 4 9 168 168 168
9 4 10 168 168 168
9 4 11 168 168 168
9 4 12 168 168 168
9 4 13 168 168 168
9 4 14 168 168 168
9 4 15 168 168 168
9 4 16 168 168 168
-11 1 1 168 168 167
-11 6 1 168 168 167
-11 1 2 168 168 168
-11 1 3 168 168 168
-11 6 2 168 168 168
-11 6 3 168 168 168
-1 -6 1 42 22 4
-13 4 3 102 51 51
-11 4 4 102 51 51
-10 5 1 0 255 135
-10 4 1 0 255 133
-10 3 1 0 255 133
-10 2 1 0 255 134
-1 -1 2 0 204 0
-4 -1 2 0 204 0
4 7 1 67 67 255
-11 6 4 102 51 51
-12 1 3 102 51 51
-12 1 2 102 51 51
4 5 1 255 102 0
-11 5 4 102 51 51
-12 6 3 102 51 51
-12 6 2 102 51 51
-2 5 1 255 102 0
4 2 1 255 102 0
5 7 1 0 0 153
-12 2 4 102 51 51
-12 3 4 102 51 51
-11 2 4 102 51 51
-10 1 1 0 204 0
11 4 2 0 0 153
-7 -1 2 67 67 255
6 1 1 67 67 255
5 0 1 67 67 255
-12 4 1 0 0 153
-9 7 1 67 67 255
-9 -6 2 42 22 4
11 5 2 67 67 255
5 8 2 0 0 153
-13 5 2 102 51 51
-11 1 4 102 51 51
-12 4 4 102 51 51
-13 3 3 102 51 51
-11 3 4 102 51 51
-12 5 3 102 51 51
-12 5 4 102 51 51
-13 2 2 102 51 51
12 4 2 67 67 255
9 1 2 0 0 153
-12 2 3 102 51 51
-13 4 2 102 51 51
-13 3 2 102 51 51
-3 4 1 221 0 0
-2 4 1 221 0 0
-3 3 1 221 0 0
-2 3 1 221 0 0
3 5 1 221 0 0
-12 2 0 42 22 4
-12 3 0 42 22 4
-12 4 0 42 22 4
-12 5 0 42 22 4
-12 5 1 67 67 255
-10 6 1 0 204 0
-7 0 1 0 0 153
-8 -1 2 0 0 153
-7 6 1 153 0 153
-7 7 1 255 255 255
-8 7 1 255 255 255
-8 6 1 255 255 255
-8 7 2 255 255 255
-7 7 2 255 255 255
